Workbook
Name _Toc94971774: コミットできないファイル!#REF!
Name _Toc94971774: バージョン番号の採番ルール!#REF!
Name _Toc94971774: 構成管理対象!#REF!
Name _Toc94971774: 構成管理方法!#REF!
Name _Toc94971774: 考え方!#REF!
Name _Toc94971774: 利用ルール!#REF!
Name _Toc94971775: コミットできないファイル!#REF!
Name _Toc94971775: バージョン番号の採番ルール!#REF!
Name _Toc94971775: 構成管理対象!#REF!
Name _Toc94971775: 構成管理方法!#REF!
Name _Toc94971775: 考え方!#REF!
Name _Toc94971775: 利用ルール!#REF!

Sheet タイトル
G11: =I40 -> 学生勤務管理システム
G14: =I44 -> 構成管理基準書
G20: =I51 -> 【 Ver 1.2 】
K28: =I47 -> 38888
K31: =I49 -> 41395
B38: 見出し部タイトル制御テーブル
B39: タイトル項目 | I39: タイトル項目埋め込み内容
B40: ①システム名 | I40: 学生勤務管理システム
B41: ②サブシステム名
B42: ③分類名
B43: ④作業工程名 | I43: 開発基準策定
B44: ⑤ドキュメント代表名 | I44: 構成管理基準書
B45: ⑥ドキュメント詳細名 | I45: ※ページ毎に個別入力
B46: ⑦作成者 | I46: 鳥羽 哲也
B47: ⑧作成日 | I47: 38888
B48: ⑦改定者 | I48: ※ページ毎に個別入力
B49: ⑧改定日 | I49: 41395
B50: ⑨管理記号 | I50: DUA026
B51: ⑩Ｖｅｒ | I51: 【 Ver 1.2 】
B53: （注1） ①～⑤は、埋め込み内容の先頭１文字は空白にする。
B55: （注2） ⑦と⑧でシート毎に異なる場合は、各シートの該当項目に直接、作成者、作成日を入力する。
B57: (注3） 文字はタイトル部：ＭＳゴシック、本文部：ＭＳ明朝で統一
B59: （注4） 管理番号は、ドキュメント体系の管理番号を使用する。
B61: （注5） ドキュメントＩＤの付け方
C63: 管理記号-分類区分（任意に設定）
C65: ※管理記号は、別紙 プロジェクト計画書のドキュメント体系を参照
B67: (注6） システム階層の概要
C69: システム名 | J69: ⇒ | L69: 人事給与システム
D71: サブシステム名 | J71: ⇒ | L71: 人事システム
L72: 給与システム
L73: 移行システム
E75: 機能名
F78: 処理名

Sheet 改訂履歴
A1: 改訂履歴 | G1: =タイトル!I44 -> 構成管理基準書
A3: No | E3: Ver | J3: 新規／改訂日 | R3: 区分 | W3: 改訂箇所 | AH3: 改訂理由 | BR3: 新規／改訂者
W4: 頁 | AA4: 項番
A5: 1 | E5: 1 | J5: =タイトル!I47 -> 38888 | R5: 新規 | AH5: 新規作成 | BR5: =タイトル!I46 -> 鳥羽 哲也
A6: 2 | E6: 1.1 | J6: 39414 | R6: 修正 | AH6: 構成管理基準を、実態に合わせて修正。 | BR6: 鳥羽 哲也
A7: 3 | E7: 1.2 | J7: 41395 | R7: 修正 | AH7: 利用ルール、コミットできないファイル/フォルダを追記 | BR7: 鳥羽 哲也

Sheet 目次
C1: 目次
C5: １． 構成管理対象
C7: ２． ソフトウェア（開発物件）の構成管理
C8: とテスト・本番リリースの考え方
C10: ３． ソフトウェア（開発物件）の構成管理方法
C12: ４． バージョン番号の採番ルール

Sheet 構成管理対象
A1: システム名 | I1: =タイトル!I40 -> 学生勤務管理システム | AE1: 工 程 | AL1: =タイトル!I43 -> 開発基準策定 | BG1: 作 成 | BK1: 鳥羽 哲也 | BU1: =タイトル!I47 -> 38888 | CD1: 管理記号 | CI1: =タイトル!I50 -> DUA026
A2: サブシステム名 | AE2: ドキュメント | AL2: =タイトル!I44 -> 構成管理基準書 | BG2: 改 訂
B5: １． 構成管理対象
D7: 構成管理対象と管理方法は、以下の通りとする。
D8: 管理対象となる環境・サーバ・対象物が複数存在するため、その対象ごとに管理を行う。
E10: 環境 | R10: サーバ | AA10: 対象 | BE10: 管理方法
E11: 本番環境 | R11: Web/AP/帳票サーバ | AA11: ハードウェア | BE11: ドキュメント（構成管理表）による管理
AA12: ソフトウェア(プロダクト製品) | BE12: ドキュメント（構成管理表）による管理
AA13: 環境定義 | BE13: ドキュメント（構成管理表）による管理
AA14: ソフトウェア（開発物件） | AP14: Webコンテンツ | BE14: バージョン管理システムによる管理
AP15: 帳票レイアウト・定義 | BE15: バージョン管理システムによる管理
AP16: 業務アプリケーション(ソース) | BE16: バージョン管理システムによる管理
R17: DBサーバ | AA17: ハードウェア | BE17: ドキュメント（構成管理表）による管理
AA18: ソフトウェア(プロダクト製品) | BE18: ドキュメント（構成管理表）による管理
AA19: 環境定義 | BE19: ドキュメント（構成管理表）による管理
AA20: ソフトウェア（開発物件） | AP20: DB定義 | BE20: ドキュメント（構成管理表）による管理
E21: テスト環境 | R21: Web/AP/帳票サーバ | AA21: ハードウェア | BE21: ドキュメント（構成管理表）による管理
AA22: ソフトウェア(プロダクト製品) | BE22: ドキュメント（構成管理表）による管理
AA23: 環境定義 | BE23: ドキュメント（構成管理表）による管理
AA24: ソフトウェア（開発物件） | AP24: Webコンテンツ | BE24: バージョン管理システムによる管理
AP25: 帳票レイアウト・定義 | BE25: バージョン管理システムによる管理
AP26: 業務アプリケーション(ソース) | BE26: バージョン管理システムによる管理
R27: DBサーバ | AA27: ハードウェア | BE27: ドキュメント（構成管理表）による管理
AA28: ソフトウェア(プロダクト製品) | BE28: ドキュメント（構成管理表）による管理
AA29: 環境定義 | BE29: ドキュメント（構成管理表）による管理
AA30: ソフトウェア（開発物件） | AP30: DB定義 | BE30: ドキュメント（構成管理表）による管理
E31: 開発環境(KSS) | R31: Web/AP/帳票サーバ | AA31: ハードウェア | BE31: ドキュメント（構成管理表）による管理
AA32: ソフトウェア(プロダクト製品) | BE32: ドキュメント（構成管理表）による管理
AA33: 環境定義 | BE33: ドキュメント（構成管理表）による管理
AA34: ソフトウェア（開発物件） | AP34: Webコンテンツ | BE34: バージョン管理システムによる管理
AP35: 帳票レイアウト・定義 | BE35: バージョン管理システムによる管理
AP36: 業務アプリケーション(ソース) | BE36: バージョン管理システムによる管理
R37: DBサーバ | AA37: ハードウェア | BE37: ドキュメント（構成管理表）による管理
AA38: ソフトウェア(プロダクト製品) | BE38: ドキュメント（構成管理表）による管理
AA39: 環境定義 | BE39: ドキュメント（構成管理表）による管理
AA40: ソフトウェア（開発物件） | AP40: DB定義 | BE40: ドキュメント（構成管理表）による管理

Sheet 考え方
A1: システム名 | I1: =タイトル!I40 -> 学生勤務管理システム | AE1: 工 程 | AL1: =タイトル!I43 -> 開発基準策定 | BG1: 作 成 | BK1: 鳥羽 哲也 | BU1: =タイトル!I47 -> 38888 | CD1: 管理記号 | CI1: =タイトル!I50 -> DUA026
A2: サブシステム名 | AE2: ドキュメント | AL2: =タイトル!I44 -> 構成管理基準書 | BG2: 改 訂 | BK2: 鳥羽 哲也 | BU2: 39414
B5: ２． ソフトウェア（開発物件）の構成管理とテスト・本番リリースの考え方
D7: ソフトウェア（開発物件）の構成管理と、テスト、修正および本番リリースについての考え方は、以下の通り。
D8: 画面とバッチ処理では、稼動するサーバや環境が異なるため、リポジトリ（バージョン管理データベース）を分割する。
D10: （１） 単体テスト完了後に、ベースライン(トランク：幹)への登録を行う。
N12: 時間の流れ→
E16: 単体テスト完了 | N16: ベースライン登録
D18: （２） 組合せ・総合・運用テスト前にタグ付けを行い、静止点を作成する。
R23: タグ(tags/test/YYYY-MM-DD)を付ける
D25: （３） 組合せ・総合・運用テスト中に不具合が発生した場合は、トランクにのみ修正を加える。
H26: タイミングを見計らってタグを付ける。
V29: 不具合発生
AB31: 修正を行う。 | AV31: タグ(tags/test/YYYY-MM-DD)を付ける
D33: （４） 本番環境へのリリース時にタグ付けを行い、リリースを行う。
H34: バージョン番号は、1.0から0.1ずつカウントアップする。
AC39: 本番機にリリースする | BC39: 本番機にリリースする
AA41: バージョンタグ(tags/release/1.0)を付ける | BA41: バージョンタグ(tags/release/1.1)を付ける

Sheet 構成管理方法
A1: システム名 | I1: =タイトル!I40 -> 学生勤務管理システム | AE1: 工 程 | AL1: =タイトル!I43 -> 開発基準策定 | BG1: 作 成 | BK1: 鳥羽 哲也 | BU1: =タイトル!I47 -> 38888 | CD1: 管理記号 | CI1: =タイトル!I50 -> DUA026
A2: サブシステム名 | AE2: ドキュメント | AL2: =タイトル!I44 -> 構成管理基準書 | BG2: 改 訂 | BK2: 鳥羽 哲也 | BU2: 39414
B5: ３． ソフトウェア（開発物件）の構成管理方法
D7: ソフトウェア（開発物件）については、バージョン管理システムを利用して管理を行う。
D9: （１） ベースライン登録（初回のみ）
E16: 開発者
E18: ① | G18: 単体テスト完了後に、ベースラインに開発物一式を追加する。
D20: （２） 修正（開発機）
E27: 開発者
E29: ① | G29: トランクへの修正を行う。
E30: ② | G30: 単体テスト完了後に、修正したものを更新する。
D32: （３） タグ付け（開発機）
E39: 業務チーム
E43: ① | G43: 組合せテスト時に、タグ付けを行う。
E44: ② | G44: タグ情報に基づいて、テスト環境に反映し、テストを行う。
D49: （４） リリース（本番機）
E58: 開発チーム
E62: ① | G62: 組合せテスト完了後に、バージョンタグを付ける。
E63: ② | G63: タグ情報に基づいて、リリースモジュールを作成し、リリースを行う。

Sheet バージョン番号の採番ルール
A1: システム名 | I1: =タイトル!I40 -> 学生勤務管理システム | AE1: 工 程 | AL1: =タイトル!I43 -> 開発基準策定 | BG1: 作 成 | BK1: 鳥羽 哲也 | BU1: =タイトル!I47 -> 38888 | CD1: 管理記号 | CI1: =タイトル!I50 -> DUA026
A2: サブシステム名 | AE2: ドキュメント | AL2: =タイトル!I44 -> 構成管理基準書 | BG2: 改 訂 | BK2: 鳥羽 哲也 | BU2: 39414
B5: ４． バージョン番号の採番ルール
C7: ・ | D7: バージョン番号は、「メジャーバージョン」.「マイナーバージョン」で構成する。
C9: ・ | D9: マイナーバージョンは、リリース用のタグを行う際に採番する。「0」～の連番とする。
D10: メジャーバージョンが上がるまで、永遠にカウントアップする。
C12: ・ | D12: メジャーバージョンは、初回リリース時と大幅な機能追加を行う際に採番する。「0」～の連番とする。
D13: 永遠にカウントアップする。
D14: メジャーバージョンが上がったタイミングで、マイナーバージョンを0にリセットする。
C16: ・ | D16: メジャーバージョンは、本番環境に初回リリースするタイミングと、大幅な機能追加等を行ったタイミングで行う。
C17: ・ | D17: 1.x以降に、総合テスト環境へリリースする場合は、本番リリースのバージョン番号にRCx(xは数字)を後ろにつける。
D18: (RC: Release Candidate リリース候補)

Sheet 利用ルール
A1: システム名 | I1: =タイトル!I40 -> 学生勤務管理システム | AE1: 工 程 | AL1: =タイトル!I43 -> 開発基準策定 | BG1: 作 成 | BK1: 鳥羽 哲也 | BU1: 41395 | CD1: 管理記号 | CI1: =タイトル!I50 -> DUA026
A2: サブシステム名 | AE2: ドキュメント | AL2: =タイトル!I44 -> 構成管理基準書 | BG2: 改 訂
B5: ５． 利用ルール
C7: 【ルール】
D8: ・ | E8: 設計書やオブジェクトはコミットしない。
D10: ・ | E10: 作成途中のものはコミットしない。単体テストが完了したもののみコミットする。
E11: (リビジョンを無駄に上げると、リポジトリが肥大化します)
D13: ・ | E13: 常に無視するフォルダ/ファイル(別紙参照)は、あらかじめクライアントに追加しておくこと。
E14: (TortoiseSVNの例)
E15: *.o *.lo *.la *.al .libs *.so *.so.[0-9]* *.a *.pyc *.pyo *.rej *~ #*# .#* .*.swp .DS_Store
E16: *.obj *\obj *.exe *.scc *.suo *.ncb *.user *.opt *.clw *.aps *.vcl *.vco *.vcb ・・・ | AG16: ←追加
D29: ・ | E29: ワークスペース内で無視するフォルダ/ファイルは、バージョン管理から除外し、無視リストに追加すること。
E30: (TortoiseSVNの例)
C49: 【コミット時の制限】
D50: ※ | E50: 以下のルールを守らないと、コミットできません。
E51: (フックスクリプトによりコミットエラーにします)
D53: ・ | E53: 階層は次のようにする。
E54: /svn
E55: └ | F55: /xxxx_project | M55: (作番先頭4桁_英数字30桁)
F56: ├ | G56: /trunk | V56: ← 普段コミットするところ
F57: │ | G57: ├ | H57: /アプリ1
F58: │ | G58: │ | H58: └ | I58: 最新のソース
F59: │ | G59: └ | H59: /アプリ2
F60: │ | H60: └ | I60: 最新のソース
F61: ├ | G61: /branches | V61: ← 枝分かれさせるときにコピーするところ
F62: │ | G62: └ | H62: /日付_xxxx | M62: (日付は西暦8桁。_xxxx部分は任意)
F63: │ | H63: ├ | I63: /アプリ1
F64: │ | H64: │ | I64: └ | J64: 枝分かれしたソース
F65: │ | H65: └ | I65: /アプリ2
F66: │ | I66: └ | J66: 枝分かれしたソース
F67: └ | G67: /tags | V67: ← リリース時などのストップモーション
G68: └ | H68: /日付_xxxx | M68: (日付は西暦8桁。_xxxx部分は任意)
H69: ├ | I69: /アプリ1
H70: │ | I70: └ | J70: リリース等のタグ
H71: └ | I71: /アプリ2
I72: └ | J72: リリース等のタグ
E73: または
E74: /svn
E75: └ | F75: /xxxx_project | M75: (作番先頭4桁_英数字30桁)
F76: ├ | G76: /trunk | V76: ← 普段コミットするところ
...

Sheet コミットできないファイル
A1: システム名 | I1: =タイトル!I40 -> 学生勤務管理システム | AE1: 工 程 | AL1: =タイトル!I43 -> 開発基準策定 | BG1: 作 成 | BK1: 鳥羽 哲也 | BU1: 41395 | CD1: 管理記号 | CI1: =タイトル!I50 -> DUA026
A2: サブシステム名 | AE2: ドキュメント | AL2: =タイトル!I44 -> 構成管理基準書 | BG2: 改 訂
B5: ６． コミットが許可されないフォルダ/ファイルリスト
D7: 正規表現で下記を含むフォルダ/ファイルはコミットできません。(大文字小文字を区別しません)
D8: 下記リストは、予告なく随時見直します。
D10: 【許可されないフォルダ】 | S10: 【許可されないファイル】
D11: オブジェクトフォルダ | S11: オブジェクト・中間ファイル | AH11: AccessDB | AW11: サムネイル
D12: bin/.+ | S12: \.o | AH12: \.ldb | AW12: thumbs\.db
D13: obj/.+ | S13: \.lo
D14: debug/.+ | S14: \.la | AH14: アーカイブ | AW14: ドキュメント
D15: release/.+ | S15: \.al | AH15: \.zip | AW15: 設計.*\.xls
D16: dbg/.+ | S16: \.libs | AH16: \.lzh | AW16: 設計.*\.doc
D17: rel/.+ | S17: \.so | AH17: \.tar | AW17: 設計.*\.xlsx
D18: classes/.+ | S18: \.a | AH18: \.taz | AW18: 設計.*\.docx
D19: build/.+ | S19: \.pyc | AH19: \.tgz | AW19: 設計.*\.xlsm
D20: publish/.+ | S20: \.pyo | AH20: \.gz | AW20: 設計.*\.docm
S21: \.rej | AH21: \.rar | AW21: 設計.*\.xlsb
D22: 設定 | S22: \.ds_store | AH22: \.7z | AW22: 設計.*\.docb
D23: \.metadata/.+ | S23: \.swp | AH23: \.cab | AW23: 項目定義
S24: \.obj | AH24: \.bz2
D25: ドキュメント | S25: \.exe | AH25: \.ace | AW25: ゴミ
D26: document(s)?/.+ | S26: \.scc | AH26: \.arj | AW26: コピー
D27: 設計.*/.+ | S27: \.suo | AH27: \.gca | AW27: 新規テキスト
S28: \.ncb | AW28: 新規Microsoft
D29: ゴミ | S29: \.user | AW29: \([0-9]+\)\.
D30: work/.+ | S30: \.opt | AW30: \.bak
D31: t(e)?mp/.+ | S31: \.clw | AW31: \.old
D32: 新しい.*/.+ | S32: \.aps | AW32: \.log
S33: \.vcl | AW33: \.pid
S34: \.vco | AW34: \.t(e)?mp
S35: \.vcb | AW35: \.d(u)?mp
S36: \.vcc | AW36: \.[0-9]+
S37: \.vcw | AW37: \.mine
S38: \.ilk | AW38: \.r[0-9]+
S39: \.pch
S40: \.pdb
S41: \.sbr
S42: \.wsp
S43: \.mak
S44: \.class
