Workbook
Name _Toc94971774: '0.はじめに'!$C$26
Name _Toc94971774: '1.2開発環境の概要'!$C$66
Name _Toc94971774: '1.3Seasar2について'!$C$120
Name _Toc94971774: '1.4プロジェクトの説明'!#REF!
Name _Toc94971774: '1.5テスト方法'!#REF!
Name _Toc94971774: '1.全般'!$C$33
Name _Toc94971774: '10.プログラミング－帳票印刷編'!$C$29
Name _Toc94971774: '2.ＡＯＰ'!$C$29
Name _Toc94971774: '3.画面遷移方式'!$C$29
Name _Toc94971774: '4.例外処理'!$C$35
Name _Toc94971774: '5.画面グループ設定'!$C$42
Name _Toc94971774: '6.プログラミング－ＨＴＭＬ編'!$C$26
Name _Toc94971774: '7.プログラミング－アクションクラス編'!$C$50
Name _Toc94971774: '8.プログラミング－画面ＢＥＡＮ編'!$C$26
Name _Toc94971774: '9.プログラミング－ＤＢアクセス編'!$C$26
Name _Toc94971775: '0.はじめに'!#REF!
Name _Toc94971775: '1.2開発環境の概要'!#REF!
Name _Toc94971775: '1.3Seasar2について'!#REF!
Name _Toc94971775: '1.4プロジェクトの説明'!#REF!
Name _Toc94971775: '1.5テスト方法'!#REF!
Name _Toc94971775: '1.全般'!#REF!
Name _Toc94971775: '10.プログラミング－帳票印刷編'!#REF!
Name _Toc94971775: '2.ＡＯＰ'!#REF!
Name _Toc94971775: '3.画面遷移方式'!#REF!
Name _Toc94971775: '4.例外処理'!#REF!
Name _Toc94971775: '5.画面グループ設定'!#REF!
Name _Toc94971775: '6.プログラミング－ＨＴＭＬ編'!#REF!
Name _Toc94971775: '7.プログラミング－アクションクラス編'!#REF!
Name _Toc94971775: '8.プログラミング－画面ＢＥＡＮ編'!#REF!
Name _Toc94971775: '9.プログラミング－ＤＢアクセス編'!#REF!
Name シート数: Sheet3!$E$3

Sheet タイトル
G11: =I40 -> 学生勤務管理システム
G14: =I44 -> コーディング基準書
G17: =I42 -> フレームワーク使用の手引き
G20: =I51 -> 【 Ver 1.0 】
K28: =I47 -> 39021
K31: 2013年 5月24日改訂
B38: 見出し部タイトル制御テーブル
B39: タイトル項目 | I39: タイトル項目埋め込み内容
B40: ①システム名 | I40: 学生勤務管理システム
B41: ②サブシステム名
B42: ③分類名 | I42: フレームワーク使用の手引き
B43: ④作業工程名 | I43: 開発基準策定
B44: ⑤ドキュメント代表名 | I44: コーディング基準書
B45: ⑥ドキュメント詳細名 | I45: ※ページ毎に個別入力
B46: ⑦作成者 | I46: 岡井計允
B47: ⑧作成日 | I47: 39021
B48: ⑦改定者 | I48: ※ページ毎に個別入力
B49: ⑧改定日 | I49: ※ページ毎に個別入力
B50: ⑨管理記号 | I50: DUA024
B51: ⑩Ｖｅｒ | I51: 【 Ver 1.0 】
B53: （注1） ①～⑤は、埋め込み内容の先頭１文字は空白にする。
B55: （注2） ⑦と⑧でシート毎に異なる場合は、各シートの該当項目に直接、作成者、作成日を入力する。
B57: (注3） 文字はタイトル部：ＭＳゴシック、本文部：ＭＳ明朝で統一
B59: （注4） 管理番号は、ドキュメント体系の管理番号を使用する。
B61: （注5） ドキュメントＩＤの付け方
C63: 管理記号-分類区分（任意に設定）
C65: ※管理記号は、別紙 プロジェクト計画書のドキュメント体系を参照
B67: (注6） システム階層の概要
C69: システム名 | J69: ⇒ | L69: 人事給与システム
D71: サブシステム名 | J71: ⇒ | L71: 人事システム
L72: 給与システム
L73: 移行システム
E75: 機能名
F78: 処理名

Sheet 改訂履歴
A1: 改訂履歴 | G1: =タイトル!I42 -> フレームワーク使用の手引き
A3: No | E3: Ver | J3: 新規／改訂日 | R3: 区分 | W3: 改訂箇所 | AH3: 改訂理由 | BR3: 新規／改訂者
W4: 頁 | AA4: 項番
A5: 1 | E5: 1 | J5: =タイトル!I47 -> 39021 | AH5: 新規作成
A6: 2 | E6: 1.1 | J6: 41418 | AH6: 新規案件に合わせて見直し | BR6: 鳥羽哲也
A7: 3 | E7: 1.2 | J7: 41793 | AH7: 9.プログラミング－ＤＢアクセス編に説明追記 | BR7: 山下一星

Sheet 目次
C1: 目次
C5: ０． はじめに | AK5: ６． プログラミング－ＨＴＭＬ編
AL6: ６．１ 共通レイアウト
C7: １． 全般 | AL7: ６．２ 共通の宣言とレイアウト継承
D8: １．１ インストール及び起動 | AL8: ６．３ ｊｓファイルの定義
D9: １．２ 開発環境の概要 | AL9: ６．４ body の定義
D10: １．３ Seasar2について | AL10: ６．５ form タグの定義
D11: １．４ 各プロジェクトの説明 | AL11: ６．６ ガイダンス行の定義
D12: １．５ テスト方法 | AL12: ６．７ プロパティの設定
AL13: ６．８ ＩＤの定義
C14: ２． ＡＯＰ | AL14: ６．９ アクションの設定
D15: ２．１ ＡＯＰを利用する機能 | AL15: ６．１０ 一覧形式表示
D16: ２．２ アクセスログ出力 | AL16: ６．１１ ポップアップ
D17: ２．３ ログイン認証 | AL17: ６．１２ ファイルアップロード
D18: ２．４ 重複レコード追加時のエラー処理 | AL18: ６．１３ 権限による制御
D19: ２．５ 排他エラー処理 | AL19: ６．１４ 入力制御
D20: ２．６ ガイダンスメッセージのクリア | AL20: ６．１５ 表示制御
D21: ２．７ 画面情報管理
AK22: ７． プログラミング－アクションクラス編
C23: ３． 画面遷移方式 | AL23: ７．１ クラス構成
D24: ３．１ ナビゲーションルール | AL24: ７．２ アクションインターフェース
D25: ３．２ 設定方法 | AL25: ７．３ アクションクラス
D26: ３．３ ANCHORタグの禁止事項 | AL26: ７．４ ロジックインターフェース
AL27: ７．５ ロジッククラス
C28: ４． 例外処理 | AL28: ７．６ 画面情報の定義
D29: ４．１ 例外処理の考え方 | AL29: ７．７ 画面ＢＥＡＮの参照/変更
D30: ４．２ エラーページの設定による例外処理 | AL30: ７．８ 共通部品の利用
D31: ４．３ ＡＯＰによる例外処理 | AL31: ７．９ アクションメソッドの定義
AL32: ７．１０ 画面遷移
C33: ５． 画面グループ設定 | AL33: ７．１１ 画面間でのデータの引継
D34: ５．１ タブ形式画面のグループ設定 | AL34: ７．１２ ソースの構成
D35: ５．２ ポップアップ画面設定 | AL35: ７．１３ コーディング例
D36: ５．３ 設定例 | AL36: ７．１４ ログ出力
C38: 目次
C42: ８． プログラミング－画面ＢＥＡＮ編
D43: ８．１ クラス構成
D44: ８．２ 画面ＢＥＡＮ
D45: ８．３ 一覧用ＤＴＯ
D46: ８．４ プロパティの型
D47: ８．５ プロパティの初期化
...

Sheet 0.はじめに
A1: システム名 | I1: =タイトル!I40 -> 学生勤務管理システム | AE1: 工 程 | AL1: =タイトル!I43 -> 開発基準策定 | BI1: 作 成 | BM1: =タイトル!I46 -> 岡井計允 | BW1: =タイトル!I47 -> 39021 | CF1: 管理記号 | CK1: =タイトル!I50 -> DUA024
A2: サブシステム名 | AE2: ドキュメント | AL2: =タイトル!I44 -> コーディング基準書 | BI2: 改 訂
AL3: =タイトル!I42 -> フレームワーク使用の手引き
B5: ０．はじめに
C7: 本ドキュメントは、フレームワークの概要・使用方法と、プロジェクト独自のコーディングルールを示したもので、プログラム作成の工程において、生産性・保守性の向上を目的としている。
C8: コーディングを行うにあたっては、各種コーディングルールを厳守した上で、本ドキュメントに記述の方式・ルールも厳守すること。
C9: なお、他ドキュメントで示される基準と、本書内で記述する内容に重複する部分や矛盾する部分がある場合は、本書記載のルールを優先する。
C11: （参考基準書）
D13: ・ネーミング基準書
D14: ・コーディング基準書（Javaコーディング基準編）
D15: ・コーディング基準書（画面作成基準編）
D16: ・コーディング基準書（帳票作成基準編）
D17: ・ログメッセージ基準
D18: ・プログラム共通設計書 | W18: 他
C20: Seasar2 フレームワークの詳細については、下記ページを参照のこと。
D22: http://www.seasar.org/index.html

Sheet 1.全般
A1: システム名 | I1: =タイトル!I40 -> 学生勤務管理システム | AE1: 工 程 | AL1: =タイトル!I43 -> 開発基準策定 | BI1: 作 成 | BM1: 鳥羽哲也 | BW1: =タイトル!I47 -> 39021 | CF1: 管理記号 | CK1: =タイトル!I50 -> DUA024
A2: サブシステム名 | AE2: ドキュメント | AL2: =タイトル!I44 -> コーディング基準書 | BI2: 改 訂
AL3: =タイトル!I42 -> フレームワーク使用の手引き
B5: １． 全般
C7: １．１ インストール及び起動
D9: 1) | F9: 案件用に作成した eclipse の入った zip を C:\ に展開する。
F10: (C:\ 以外では正しく動作しない)
D11: 2) | F11: 展開した eclipse.exe を実行する。
F12: (起動が遅くなってきたときは、引数に -clean をつけて起動すると再構成される。)
D15: Eclipseのセットアップ手順は、
D16: 「Z:\#開発\DUSK_同志社大学\DUSK2210同志社次期システム\01.教務システム\A000：プロジェクト管理\900：社内開発機\20.構築\統合開発環境(Eclipse)\統合開発環境(Eclipse)の準備.xlsx」
D17: を参照のこと。

Sheet 1.2開発環境の概要
A1: システム名 | I1: =タイトル!I40 -> 学生勤務管理システム | AE1: 工 程 | AL1: =タイトル!I43 -> 開発基準策定 | BI1: 作 成 | BM1: 鳥羽哲也 | BW1: =タイトル!I47 -> 39021 | CF1: 管理記号 | CK1: =タイトル!I50 -> DUA024
A2: サブシステム名 | AE2: ドキュメント | AL2: =タイトル!I44 -> コーディング基準書 | BI2: 改 訂
AL3: =タイトル!I42 -> フレームワーク使用の手引き
C5: １．２ 開発環境の概要
D7: 1) | F7: 概要
F9: 開発環境は、下図の青破線で囲まれた構成となっている。実際の開発には、ブラウザとデータベース、バージョン管理システムを別途用意する必要がある。
F10: 作成する物としては、業務ロジック、DAO部品等と、画面に関しては画面HTML等、帳票に関しては、帳票レイアウト等となる。
F24: http://localhost:8080/xxxx/
F25: で、アクセスする。
D49: 2) | F49: 組み込まれているプラグイン
E51: 開発が標準化に沿って容易に行えるように、Pleiades に組み込まれているプラグイン以外に、以下のプラグインが組み込まれている。
E52: 環境を合わせる必要があるため、勝手にプラグインを追加、削除しないこと。
E54: 種別 | M54: プラグイン名 | AG54: 用途
E55: テスト | M55: 舞姫プラグイン | AG55: Tomcatで起動するコンテキストを選択
M56: djUnit | AG56: テストカバレッジを計測
E57: 静的チェック | M57: CheckStyle | AG57: コードのスタイルをチェック
M58: FindBugs | AG58: 潜在バグを検索
M59: ステップカウンター | AG59: ステップ数をカウント
E60: エディタ | M60: S2JSFプラグイン | AG60: S2JSF用HTMLの作成を補助
M61: Kijimuna | AG61: .dicon(Seasar2の設定ファイル)の作成を補助
D63: 3) | F63: 各プラグインの使い方
F65: ・ | G65: 舞姫プラグイン
G72: 起動するコンテキストにチェックを入れる。起動したくないコンテキストのチェックを外す。
G73: 不要なコンテキストを動作させないため、起動が速くなる。
F93: ・ | G93: エディタ関連(S2JSF、Kijimuna)
G94: 通常のエディタの使い方と同じ。[CTRL]+[SPACE]での補完も行える。
G96: Kijimuna(.diconエディタ)は、警告を抑止しているにもかかわらず警告が出ることがある。(バグだと思われる)
G97: 警告を無視するか、[ウィンドウ]-[設定]で[Kijimuna]タブを開き、[OK]を押して警告を消す。
F137: ・ | G137: djUnit
G138: Javaの単体テストは、通常JUnitを用いて行うが、今回は djUnit を用いてテストを行う。
G151: テストケース実行時に、「JUnitテスト」ではなく「djUnitテスト」を選択する。
BY153: 同時にカバレッジレポートが作成される
BY154: カバレッジが 100% になること。
G163: 正常に終了するまで、テストを実行する。
G164: エラーや失敗となった場合は、バグ管理票に記載する。
G165: テストのやり方の詳細については、後述する。

Sheet 1.3Seasar2について
A1: システム名 | I1: =タイトル!I40 -> 学生勤務管理システム | AE1: 工 程 | AL1: =タイトル!I43 -> 開発基準策定 | BI1: 作 成 | BM1: 鳥羽哲也 | BW1: =タイトル!I47 -> 39021 | CF1: 管理記号 | CK1: =タイトル!I50 -> DUA024
A2: サブシステム名 | AE2: ドキュメント | AL2: =タイトル!I44 -> コーディング基準書 | BI2: 改 訂
AL3: =タイトル!I42 -> フレームワーク使用の手引き
C5: １．３ Seasar2について
D7: 本開発環境は、Seasar2フレームワークを前提に構成されている。
D8: ここでは、Seasar2フレームワークについて、簡単に説明する。
D10: 1) | F10: Seasar2の機能について
F12: Seasar2には、大きく分けてDIとAOPという2つの機能が存在する。
F14: ・ | G14: DI(依存性注入:Dependency Injection)・・・コンポーネント間の依存性をソースから排除し、外部の設定ファイルより注入する。
G16: 以前のアプリケーションでは、利用したい側が部品を作成(new文を使ってインスタンス化)する必要があった。（コンポーネント同士が依存し合っている状態）
G22: DIコンテナを利用したアプリケーションでは、部品はコンテナが用意(インスタンス化)し、利用する側に渡して(セットして)くれる。(依存性を後から注入する)
G31: この事により、主にテスト時に威力を発揮する。
G32: 以前のアプリケーションでは、部品とアプリケーションが依存しているため、部品から異常が発生した場合のテストなどが非常にやりにくい。
G38: これに対して、DIを利用したアプリケーションでは、テスト時にはテスト用の部品に置き換えることで、簡単にテストが行えるようになる。
F50: ・ | G50: AOP(アスペクト指向プログラム)・・・オブジェクト指向ではうまく分離できない特徴(クラスをまたがる共通の機能)を、アスペクトとして分離する機能
G52: 以前のアプリケーションでは、ログを出力したり、トランザクション管理をするためには、当然プログラム内に記述する必要がある。
G53: そのため、アプリケーションによって、ログの出力がバラバラだったり忘れたり、トランザクションを開始しなかったりすることがある。
G61: AOPを用いたアプリケーションでは、アプリケーション内にコードを記述することなく、機能を追加することができる。
G62: そのため、ログ出力やトランザクション処理を忘れたり、出力結果がバラバラになることがない。
F81: ・ | G81: 今回利用するその他の機能
G83: S2JSF | K83: ･･･ | N83: HTMLに専用属性(m:xxx)を記述することで、プレゼンテーション層を作成する。
N84: JSPではないため、プレゼンテーション層から直接DBを参照するといったルール違反を防ぐことができることもメリットの一つ。
G85: S2DAO | K85: ･･･ | N85: コードを記述することなく、データベースの入出力を行う。O/R マッピング。
D95: 2) | F95: アプリケーション階層(画面)
F97: 画面のアプリケーション階層は、次のようになる。
F98: プレゼンテーション層、サービス層、データアクセス層にコントローラを加えて、MVCモデルを構成する。
F100: 階層図 | AS100: 流れ
D140: 3) | F140: アプリケーション階層(バッチ)
F142: バッチのアプリケーション階層は、次のようになる。
F143: 画面のようにサーブレットからコンテナを利用できないため、バッチドライバから利用する。業務ロジックは、バッチジョブインターフェイスを実装する。
F144: アプリケーション階層は、サービス層とデータアクセス層だけのシンプルな構成である。
F146: 階層図
F167: 流れ
F177: 画面からバッチ部品を利用してJavaVMを起動し、バッチプログラム
F178: を実行する。

Sheet 1.4プロジェクトの説明
A1: システム名 | I1: =タイトル!I40 -> 学生勤務管理システム | AE1: 工 程 | AL1: =タイトル!I43 -> 開発基準策定 | BI1: 作 成 | BM1: 鳥羽哲也 | BW1: =タイトル!I47 -> 39021 | CF1: 管理記号 | CK1: =タイトル!I50 -> DUA024
A2: サブシステム名 | AE2: ドキュメント | AL2: =タイトル!I44 -> コーディング基準書 | BI2: 改 訂
AL3: =タイトル!I42 -> フレームワーク使用の手引き
C5: １．４ 各プロジェクトの説明
D7: 本開発環境に用意されているプロジェクトは、以下の表の通りである。
D8: これらのプロジェクトに、必要な画面やクラスを作成し、システムを開発する。
D10: プロジェクト名 | N10: プロジェクトの用途 | AR10: 作成/修正
D11: common | N11: 共通部品等 | AR11: 一部対象
D12: batch | N12: バッチプログラム | AR12: 一部対象
D13: batch-scripts | N13: バッチ用スクリプト | AR13: 対象
D14: front | N14: フロント画面用CSS | AR14: 修正不可
D15: kyomu | N15: 画面プログラム | AR15: 一部対象
D16: kyoin | AR16: 一部対象
D17: gakusei | AR17: 一部対象
D18: kokai | AR18: 一部対象
D19: job-manage-server | N19: ジョブ管理サーバー | AR19: 修正不可
D20: testframework | N20: テスティングフレームワーク | AR20: 修正不可
D22: 作成/修正が一部対象となっているものについて、以降、詳細を記述する。
D49: 1) | F49: 共通 プロジェクト
E51: 画面・バッチで利用する共通部品などを納めたプロジェクト。下図の桃色部分に相当する。
E63: ディレクトリ/ファイル | AB63: 説明 | AU63: 作成/修正
E64: WEB-INF | AB64: WEBコンテンツ | AU64: －
F65: build | AB65: jarファイル等 | AU65: 修正不可
F66: doc | AB66: Javadocファイル | AU66: 対象※1
F67: layout | AB67: レイアウトファイル | AU67: 修正不可
F68: lib | AB68: ライブラリ | AU68: 修正不可
F69: lib4junit | AB69: Junit実行用ライブラリ | AU69: 修正不可
F70: libsrc | AB70: ライブラリソース | AU70: 修正不可
F71: tests | AB71: 部品のテストケース | AU71: 修正不可
F72: src | AB72: ソース | AU72: －
G73: jp.co.kssinet.zzzz9999.common.aop | AB73: AOP部品 | AU73: 修正不可
G74: jp.co.kssinet.zzzz9999.common.buhin | AB74: 共通部品 | AU74: 修正不可
G75: jp.co.kssinet.zzzz9999.common.dao.schema1 | AB75: DBのschema1インスタンス用DAO部品 | AU75: 対象
G76: jp.co.kssinet.zzzz9999.common.dao.schema2 | AB76: DBのschema2インスタンス用DAO部品 | AU76: 対象
G77: jp.co.kssinet.zzzz9999.common.servlet | AB77: サーブレット部品 | AU77: 修正不可
G78: jp.co.kssinet.zzzz9999.common.taglibs | AB78: taglib部品 | AU78: 修正不可
F79: resources | AB79: リソース | AU79: －
G80: param_ut*.dicon | AB80: JDBC接続パラメータ設定 | AU80: 対象
G81: param_ut*.dicon 以外の .diconファイル | AB81: フレームワーク設定 | AU81: 修正不可
G82: *.properties | AB82: プロパティファイル | AU82: 修正不可
...

Sheet 1.5テスト方法
A1: システム名 | I1: =タイトル!I40 -> 学生勤務管理システム | AE1: 工 程 | AL1: =タイトル!I43 -> 開発基準策定 | BI1: 作 成 | BM1: 鳥羽哲也 | BW1: =タイトル!I47 -> 39021 | CF1: 管理記号 | CK1: =タイトル!I50 -> DUA024
A2: サブシステム名 | AE2: ドキュメント | AL2: =タイトル!I44 -> コーディング基準書 | BI2: 改 訂
AL3: =タイトル!I42 -> フレームワーク使用の手引き
C5: １．５ テスト方法
D7: 1.1 章で述べた通り、ツールとしては djUnit を用いてテストを行うが、JUnit のテストケースをそのまま記述するのではなく、テスティングフレームワークを用いてテストを行う。
D8: ここでは概要について記述する。詳細については、「フレームワーク機能設計書（テストツール版）」を参照。
D10: 単体テストの概要
D11: (プログラム一本ごとに実施)
E39: 準備データ、入力データ、期待値データ、テーブル期待値データを、Excelシートに記述する。
E40: 全テストケースをテストできるようにテストドライバを実装し、単体テストを実施する。
E41: テスト実施結果から、バグ管理票と単体テスト結果報告書を作成する。

Sheet 2.ＡＯＰ
A1: システム名 | I1: =タイトル!I40 -> 学生勤務管理システム | AE1: 工 程 | AL1: =タイトル!I43 -> 開発基準策定 | BI1: 作 成 | BM1: =タイトル!I46 -> 岡井計允 | BW1: =タイトル!I47 -> 39021 | CF1: 管理記号 | CK1: =タイトル!I50 -> DUA024
A2: サブシステム名 | AE2: ドキュメント | AL2: =タイトル!I44 -> コーディング基準書 | BI2: 改 訂
AL3: =タイトル!I42 -> フレームワーク使用の手引き
B5: ２． ＡＯＰ
D7: 本フレームワークではＡＯＰの機能を利用している。
D8: ＡＯＰとは Aspect Oriented Programming（アスペクト指向プログラミング）の略で、プログラム本来の目的とは異なる処理を内部に埋め込まず、外から織り込むように作る手法である。
C10: ２．１ ＡＯＰを利用する機能
D12: 本フレームワークでは、下記の機能をＡＯＰで実現する。
E14: (1) | G14: トレース出力
E15: (2) | G15: 例外時のログ出力
E16: (3) | G16: トランザクション制御
E17: (4) | G17: アクセスログ出力
E18: (5) | G18: ログイン認証
E19: (6) | G19: 重複レコード追加時のエラー処理
E20: (7) | G20: 排他エラー処理
E21: (8) | G21: ガイダンスメッセージのクリア
E22: (9) | G22: 画面情報管理
E24: ※ (4) ～ (9) は、本プロジェクトの独自ＡＯＰ
D26: これらの処理をプログラマが意識する必要はほとんどなく、業務ロジックのみに専念することができる。
C28: ２．２ アクセスログ出力（AccessLogInterceptor）
D30: アクション処理が実行されたとき、データベースにログを出力する機能で、出力の対象は、アクションクラスのインターフェースに定義した全てのメソッドである。
D31: この機能により、アクションクラスにメソッドを定義するだけで、そのアクション処理時のログを記録することができる。
C33: ２．３ ログイン認証（LoginCertifyInterceptor）
D35: ログインユーザ情報の管理と、それを利用したログイン認証を行う機能で、実行のタイミングは、アクションクラスのインターフェースに定義したメソッドの呼び出し時である。
D36: この機能により、アクションクラスにメソッドを定義するだけで、不正アクセスを防止するための認証チェックを行うことができる。
D37: 認証エラーの場合は、例外（ログイン認証エラー）を投げている。これはフレームワークによって適切に処理され、結果、ログイン認証エラーページへ遷移する。
D38: また、画面ヘッダ部へのログインユーザ情報の表示もこの機能の中で行っている。
C40: ２．４ 重複レコード追加時のエラー処理（DuplicateInsertInterceptor）
D42: レコードの追加処理時に、キーの重複するレコードが他ユーザにより既に作成されている場合に、排他エラーメッセージをガイダンスエリアに設定する機能である。
D43: Seasarフレームワークでは、例外発生時の処理を独自実装することができるが、本プロジェクトフレームワークでは SQLRuntimeException のうち、重複例外である場合のみこの処理を行う。
D45: ※ 発生した例外（SQLRuntimeException）の内容が重複エラーかどうかで判断をする。エラーコードは、データベースシステムによって異なる。
C49: ２．５ 排他エラー処理（HaitaMessageInterceptor）
D51: Seasar フレームワーク（S2Dao）では、テーブルに "timestamp" という名前で Timestamp 型の排他制御用カラムを定義するだけで、自動的に排他制御を行うことができる。
D52: テーブルの更新時に、この timestamp カラムの値と、JavaBeans の timestamp プロパティの値とを比較し、異なっていれば NotSingleRowUpdatedRuntimeException を投げる仕組みである。
D53: 本プロジェクトフレームワークでは、この例外が発生した時の独自実装として、ガイダンスエリアに排他エラーメッセージを設定するという処理を行う。
D54: プログラマは、テーブルに排他制御用カラムが必要であることさえ理解しておけば、排他制御に関する特別な処理を意識する必要なく更新処理を作成することができる。
C56: ２．６ ガイダンスメッセージのクリア（GuidanceClearInterceptor）
D58: ガイダンスエリアに表示したメッセージをクリアする機能で、実行のタイミングは、アクションクラスのインターフェースに定義したメソッドの呼び出し時である（ただし、initialize メソッドは除く）。
D59: あるボタンを押したタイミングで設定されたメッセージは、次のボタンを押したときにクリアするという仕組みを実現している。
C61: ２．７ 画面情報管理（NavigationInterceptor）
...

Sheet 3.画面遷移方式
A1: システム名 | I1: =タイトル!I40 -> 学生勤務管理システム | AE1: 工 程 | AL1: =タイトル!I43 -> 開発基準策定 | BI1: 作 成 | BM1: =タイトル!I46 -> 岡井計允 | BW1: =タイトル!I47 -> 39021 | CF1: 管理記号 | CK1: =タイトル!I50 -> DUA024
A2: サブシステム名 | AE2: ドキュメント | AL2: =タイトル!I44 -> コーディング基準書 | BI2: 改 訂
AL3: =タイトル!I42 -> フレームワーク使用の手引き
B5: ３． 画面遷移方式
D7: 本フレームワークにおいて、画面遷移のコントロールは設定ファイル "faces-config.xml" にて行う。
C9: ３．１ ナビゲーションルール
D11: 画面遷移は faces-config.xml に定義したナビゲーションルールに基づいて行われる。
E13: ナビゲーションルールの記述例
F14: <navigation-rule>
G15: <from-outcome>C010101G</from-outcome>
G16: <to-view-id>/html/c01/c0101/C010101G.html</to-view-id>
F17: </navigation-rule>
D19: 上記の例では、アクションの戻り値として "C010101G" を指定すると、C010101G.html に遷移することを意味している。
C21: ３．２ 設定方法
D23: faces-config.xml の記述ルールを以下に示す。
E25: ・ひとつの遷移につき、navigation-rule タグをひとつ定義する。
E26: ・from-outcome タグには、ハイフンなしの画面ＩＤを指定する。
E27: ・to-view-id には、from-outcome に指定した画面ＩＤに対応する画面を指定する。（アプリケーションルートからの相対パス）
E28: ・ナビゲーションルールは、全ての画面に対して定義する。（画面数分の navigation-rule タグが記述されることになる。）
D30: faces-config の記述方法はこの限りではないが、定義を簡素化するために、本プロジェクトにおいては上記ルールを厳守することとする。
C32: ３．３ ANCHORタグの禁止事項
D34: ＨＴＭＬのソース中に anchor タグの href 属性で遷移先を直接指定する方法は、外部サイトへの遷移を除き禁止とする。

Sheet 4.例外処理
A1: システム名 | I1: =タイトル!I40 -> 学生勤務管理システム | AE1: 工 程 | AL1: =タイトル!I43 -> 開発基準策定 | BI1: 作 成 | BM1: =タイトル!I46 -> 岡井計允 | BW1: =タイトル!I47 -> 39021 | CF1: 管理記号 | CK1: =タイトル!I50 -> DUA024
A2: サブシステム名 | AE2: ドキュメント | AL2: =タイトル!I44 -> コーディング基準書 | BI2: 改 訂
AL3: =タイトル!I42 -> フレームワーク使用の手引き
B5: ４． 例外処理
C7: ４．１ 例外処理の考え方
D9: 例外処理はフレームワークにより行うため、業務ロジックについては基本的に例外処理について意識する必要はない。
D10: 本システムでは、次の例外を想定する。
E12: ・ログイン認証エラー
E13: ・システムエラー
E14: ・排他エラー
C16: ４．２ エラーページの設定による例外処理
D18: ログイン認証エラーとシステムエラーの場合、特定のページに遷移する仕組みをとっている。
D19: これは、設定ファイル（jsfErrorPage.dicon）に下記の記述をすることで実現している。
E21: <component class="org.seasar.jsf.runtime.ErrorPageManagerImpl">
F22: <initMethod name="addErrorPage">
G23: <arg>@java.lang.Throwable@class</arg>
G24: <arg>"/html/c99/c9901/C990101G.html"</arg>
F25: </initMethod>
F26: <initMethod name="addErrorPage">
G27: <arg>@jp.co.kssinet.zzzz9999.common.aop.LoginRuntimeException@class</arg>
G28: <arg>"/html/c99/c9901/C990102G.html"</arg>
F29: </initMethod>
E30: </component>
D32: アプリケーションで例外が発生した場合（全ての例外の種類に対して）、C990101G.html（システムエラー画面）に遷移し、そのうち、ログイン認証エラー（LoginRuntimeException ）の場合は、
D33: C990102G.html（ログイン認証エラー画面）に遷移することを意味する。
C35: ４．３ ＡＯＰによる例外処理
D37: 排他例外については、『ＡＯＰ』の章での説明の通り、ＡＯＰの機能を利用して処理している。
D38: 排他例外が発生した場合、フレームワークにより、画面にエラーメッセージを表示する。

Sheet 5.画面グループ設定
A1: システム名 | I1: =タイトル!I40 -> 学生勤務管理システム | AE1: 工 程 | AL1: =タイトル!I43 -> 開発基準策定 | BI1: 作 成 | BM1: =タイトル!I46 -> 岡井計允 | BW1: =タイトル!I47 -> 39021 | CF1: 管理記号 | CK1: =タイトル!I50 -> DUA024
A2: サブシステム名 | AE2: ドキュメント | AL2: =タイトル!I44 -> コーディング基準書 | BI2: 改 訂
AL3: =タイトル!I42 -> フレームワーク使用の手引き
B5: ５． 画面グループ設定
D7: 画面ヘッダ部のナビゲーション行等の表示や、画面遷移に関する処理はフレームワークによって自動的に行われる。
D8: タブ形式画面やポップアップ画面は、それを実現する上で特殊な処理が必要なため、設定ファイル "gamen-group.xml" に、以下の設定を行う。
E10: gamen-group.xml
E11: <?xml version="1.0"?>
E13: <gamen-groups>
F15: タブグループ設定
F17: ポップアップ画面設定
E19: </gamen-groups>
D21: ※ | F21: 以降の説明中で表現される「画面ＩＤ」は、画面アクションクラスに定数定義する画面ＩＤ(GAMEN_ID)と同一である必要がある。
F22: 画面アクションクラスに「public static final GAMEN_ID = "C010101G"」と定義するため、「C010101G」と記述する必要がある。
C24: ５．１ タブ形式画面のグループ設定
D26: 同一画面に表示されるタブ形式の画面グループであることを、フレームワークに認識させるための設定である。
D27: タブ画面が存在する場合は、同一画面で表示される単位毎に下記の設定を行う。
E29: <group name="グループ名">
F30: <gamen-id>画面ＩＤ１</gamen-id>
F31: <gamen-id>画面ＩＤ２</gamen-id>
F32: <gamen-id>画面ＩＤ３</gamen-id>
F33: ・・・
E34: </group>
E36: ・<group> タグの name 属性には、そのグループの名前を付ける。
E37: ・name 属性は、他のグループと重複しない唯一の名前を付ける。
E38: ・複数のグループが存在する場合の、記述順のルールはない。
E39: ・子タグの <gamen-id> タグに、そのグループに属する画面のＩＤを設定する。
E40: ・同一グループ内に重複するＩＤは設定できない。
E41: ・<gamen-id> タグの記述順のルールはない。
D43: なお、同一画面ＩＤ内でタブ切り替えを行うような画面は、この設定の対象外である。
C49: ５．２ ポップアップ画面設定
D51: ポップアップは画面遷移ではないため、これらの画面をフレームワークの処理の対象外にするための設定である。
D52: ポップアップ画面が存在する場合は、下記の設定を行う。
E54: <popup>
F55: <gamen-id>画面ＩＤ１</gamen-id>
F56: <gamen-id>画面ＩＤ２</gamen-id>
F57: <gamen-id>画面ＩＤ３</gamen-id>
F58: ・・・
E59: </popup>
E61: ・<popup> タグは、ファイル内にひとつだけ定義する。
...

Sheet 6.プログラミング－ＨＴＭＬ編
A1: システム名 | I1: =タイトル!I40 -> 学生勤務管理システム | AE1: 工 程 | AL1: =タイトル!I43 -> 開発基準策定 | BI1: 作 成 | BM1: =タイトル!I46 -> 岡井計允 | BW1: =タイトル!I47 -> 39021 | CF1: 管理記号 | CK1: =タイトル!I50 -> DUA024
A2: サブシステム名 | AE2: ドキュメント | AL2: =タイトル!I44 -> コーディング基準書 | BI2: 改 訂
AL3: =タイトル!I42 -> フレームワーク使用の手引き
B5: ６． プログラミング－ＨＴＭＬ編
C7: ６．１ 共通レイアウト
D9: 本フレームワークでは、画面の共通レイアウトを定義することにより、各々の画面でレイアウトを継承することが可能となっている。
D10: 本システムでは、次の４つの共通定義を行う。
E12: ・共通レイアウト（layout.html）
E13: ・ヘッダ部（header.html）
E14: ・メニュー部（menu.html）
E15: ・ガイダンス行（guidance.html）
D17: これらの関係を下記に示す。 ※それぞれの関係を示すためのものであり、実際のソースとは異なる。
D19: 共通レイアウト（layout.html） | AQ19: ヘッダ（header.html）
AQ20: ・・・
E21: (共通の定義を記述) | AQ21: <body>
AR22: <span m:inject="s:insert">
D23: <body>
E24: <span m:inject="s:insert" m:src="/WEB-INF/layout/header.html"/> | AS24: (ヘッダ部の定義を記述)
E25: <span m:inject="s:insert" m:name="body"/>
E26: <span m:inject="s:insert" m:src="/WEB-INF/layout/menu.html"/> | AR26: </span>
D27: </body> | AQ27: </body> | BJ27: メニュー（menu.html）
D28: </html> | AQ28: ・・・ | BJ28: ・・・
BJ29: <body>
D30: 各画面 | BK30: <span m:inject="s:insert">
D31: <!DOCTYPE html PUBLIC …>
D32: <html lang="ja" | BL32: (メニュー部の定義を記述)
D33: xmlns:m="http://www.seasar.org/maya"
D34: m:extends="/WEB-INF/layout/layout.html"> | BK34: </span>
D35: <head> | BJ35: </body>
D36: <title></title> | BJ36: ・・・
D37: </head> | AQ37: ガイダンス（guidance.html）
D38: <body> | AQ38: ・・・
E39: <span m:inject="s:insert" m:name="body"> | AQ39: <body>
F40: (ボディ部等の定義を記述) | AR40: <span m:inject="s:insert">
F41: <span m:inject="s:insert" m:src="/WEB-INF/layout/guidance.html"/>
F42: (ボタン行等の定義を記述) | AS42: (ガイダンス行の定義を記述)
E43: </span>
D44: </body> | AR44: </span>
D45: ・・・ | AQ45: </body>
AQ46: ・・・
...

Sheet 7.プログラミング－アクションクラス編
A1: システム名 | I1: =タイトル!I40 -> 学生勤務管理システム | AE1: 工 程 | AL1: =タイトル!I43 -> 開発基準策定 | BI1: 作 成 | BM1: =タイトル!I46 -> 岡井計允 | BW1: =タイトル!I47 -> 39021 | CF1: 管理記号 | CK1: =タイトル!I50 -> DUA024
A2: サブシステム名 | AE2: ドキュメント | AL2: =タイトル!I44 -> コーディング基準書 | BI2: 改 訂
AL3: =タイトル!I42 -> フレームワーク使用の手引き
B5: ７． プログラミング－アクションクラス編
C7: ７．１ クラス構成
D9: １つの画面(HTML)につき、必ず１つの画面処理を定義したインターフェース（以下、アクションインターフェイス）とその実装クラス（以下、アクションクラス）、
D10: および、必要に応じて１つの入出力処理を定義したインターフェース（以下、ロジックインターフェイス）とその実装クラス（以下、ロジッククラス）を作成する。
D12: 画面
D22: アクション
D33: ロジック
C50: ７．２ アクションインターフェース
D52: アクションインターフェースには、その画面で使用するアクションメソッド（ＨＴＭＬ内で、m:action の設定を行うメソッド）を全て定義する。
D53: アクションメソッドは、引数なしで戻り値は必ず String とする。また、initialize メソッドを必ず定義する。
E55: 例：画面ＩＤ「C010101G」の場合
E57: public interface C010101gAction {
E58: public String initialize();
E59: ・・・
E60: }
C62: ７．３ アクションクラス
D64: アクションクラスは、前述のアクションインターフェースの実装を行う。
D65: このクラスには、画面のイベント処理に応じた入力チェック、画面Beanとのやりとり、ロジックの呼び出しと画面遷移を記述する。
D66: データベースのキー存在チェックなど、簡易にできるものはここで行っておく。(複雑な処理の途中で判定するようなものは、ロジックで行う。)
D67: また、単純にキーをセットして検索するのみ、画面遷移のみなど、処理と呼べるようなものがない場合は、ロジックを呼び出す必要はない。
E69: 例：画面ＩＤ「C010101G」の場合
E71: public class C010101gActionImpl implements C010101gAction {
E72: private C010101gBean c010101g; //画面Bean
E73: ・・・
E74: public String イベントメソッド() {
E75: 入力チェック
E76: 画面BeanからロジックDtoへのセット
E77: ロジックの処理の呼び出し
E78: ロジックDtoから画面Beanへのセット
E79: ガイダンスへのメッセージのセット
E80: return 遷移先
E81: }
... E83: }
C93: ７．４ ロジックインターフェース
D95: ロジックインターフェースには、その処理で使用するメソッドを定義する。
D96: ロジックメソッドは、引数・戻り値は任意とする。
E98: 例：画面ＩＤ「C010101G」の場合
...

Sheet 8.プログラミング－画面ＢＥＡＮ編
A1: システム名 | I1: =タイトル!I40 -> 学生勤務管理システム | AE1: 工 程 | AL1: =タイトル!I43 -> 開発基準策定 | BI1: 作 成 | BM1: =タイトル!I46 -> 岡井計允 | BW1: =タイトル!I47 -> 39021 | CF1: 管理記号 | CK1: =タイトル!I50 -> DUA024
A2: サブシステム名 | AE2: ドキュメント | AL2: =タイトル!I44 -> コーディング基準書 | BI2: 改 訂
AL3: =タイトル!I42 -> フレームワーク使用の手引き
B5: ８． プログラミング－画面ＢＥＡＮ編
C7: ８．１ クラス構成
D9: １つの画面につき、必ず１つの画面 Bean を作成する。
D10: また、画面内に一覧表示がある場合は、そのリストの要素として Dto も作成する。Dto は、１つの一覧に対して１つ必要である。
C22: ８．２ 画面ＢＥＡＮ
D24: 画面に関するデータは、すべて画面 Bean に保持する。画面 Bean は、これらのプロパティとその getter/setter のみで構成する。※
D25: ここで言う、「画面に関するデータ」とは、次のようなものである。
E27: ・画面に表示するデータ
E28: ・画面で入力するデータ
E29: ・画面に表示されないデータ（selectOneRadio の selectedIndex 等）
E30: ・画面の状態を管理するデータ（フラグ等）
E31: ・他画面からの引継情報
D33: getter/setter メソッドの、javadoc コメントは省略する。
D35: ※ 一部例外として、一覧表示用のリストがプロパティとして存在する場合で、そのリストの行選択をラジオボタンかチェックボックスで行う場合のみ、
D36: そのリストのサイズを返すメソッドが必要。（JavaScript で使用するため）
D37: このメソッドの名称は「get + 一覧のプロパティ名 + Size」とする。
E39: 例：syokuinDtoList プロパティ（リスト）のサイズを返すメソッドを定義する場合
E41: public int getSyokuinDtoListSize() {
E42: return syokuinDtoList.size();
E43: }
C49: ８．３ 一覧用ＤＴＯ
D51: 一覧形式で表示するリストの１行分のデータを保持する。リスト用 Dto は、これらのプロパティとその getter/setter のみで構成する。
D52: 「１行分のデータ」とは、次のようなものである。
E54: ・画面に表示するデータ
E55: ・画面で入力するデータ（チェックボックスの ON/OFF の値等）
E56: ・画面には表示しないが保持しておく必要があるデータ（日付項目がキーである場合の西暦データ等）
D58: getter/setter メソッドの、javadoc コメントは省略する。
C60: ８．４ プロパティの型
D62: 画面 Bean および、一覧用 Dto に定義するプロパティの型は、下記の通りとする。
E64: 種別 | Q64: 型
E65: 入力項目 | Q65: String | Z65: ※ リストボックスの選択や、ラジオボタンの選択を含む
E66: チェックボックス | Q66: boolean
E67: 表示項目 | Q67: String
E68: 一覧リスト | Q68: Dtoの配列
E69: リストボックス | Q69: Dtoの配列
E70: アップロードファイル | Q70: UploadedFile
E71: 内部変数
...

Sheet 9.プログラミング－ＤＢアクセス編
A1: システム名 | I1: =タイトル!I40 -> 学生勤務管理システム | AE1: 工 程 | AL1: =タイトル!I43 -> 開発基準策定 | BI1: 作 成 | BM1: =タイトル!I46 -> 岡井計允 | BW1: =タイトル!I47 -> 39021 | CF1: 管理記号 | CK1: =タイトル!I50 -> DUA024
A2: サブシステム名 | AE2: ドキュメント | AL2: =タイトル!I44 -> コーディング基準書 | BI2: 改 訂 | BM2: 山下一星 | BW2: 41793
AL3: =タイトル!I42 -> フレームワーク使用の手引き
B5: ９． プログラミング－ＤＢアクセス編
C7: ９．１ クラス構成
D9: １つのテーブルにつき、必ず１つの JavaBeans（Dto）と Dao インターフェースを作成する。
D10: また、Dao のメソッドに関連付ける SQL ファイルの作成も必要となる。
D11: それぞれの関係は下記のようになる。
C24: ９．２ JavaBeans
D26: JavaBeans（Dto）は、テーブルと関連付けるためのクラスである。
D28: ９．２．１ テーブルとの関連付け（TABLE アノテーション）
E30: テーブルとの関連付けには、TABLE アノテーションを使用する。TABLE アノテーションは、下記の例に示すような定数定義である。
F32: 例：テーブル物理名が "SaiyoKihon" の場合
F34: public static final String TABLE = "SaiyoKihon";
D36: ９．２．２ カラムとの関連付け（COLUMN アノテーション）
E38: カラムとの関連付けには、COLUMN アノテーションを使用する。COLUMN アノテーションは、下記の例に示すような定数定義である。
F40: 例：gokakuCode プロパティに、物理名が "gokakuCode" のカラムを関連付ける場合
F42: public static final String gokakuCode_COLUMN = "gokakuCode";
E44: 上記の例では、gokakuCode プロパティに、gokakuCode カラムを関連付けることを意味している。
E46: プロパティ名とカラム名が一致する場合、COLUMN アノテーションは省略することができる。
D49: ９．２．３ プロパティと getter/setter
E51: カラムに対応する変数を宣言し、それらの getter/setter メソッドを実装することで、そのカラムのデータの操作を行う。
E52: プロパティの名称は、特に理由がない限り、カラム名と一致させること。
E54: カラムのデータ型と、プロパティの型の例は下記の通り。
F56: カラムのデータ型 | O56: プロパティの型
F57: NUMBER | O57: BigDecimal | Z57: ※ プリミティブ型は使用しないこと
F58: NCHAR | O58: String | Z58: ※ SQL Serverの場合は、CHAR2,VARCHAR2,NCHAR2,NVARCHAR2 を CHAR,VARCHAR,NCHAR,NVARCHAR と読み替えること。
F59: NVARCHAR2
F60: CHAR
F61: VARCHAR2
F62: TIMESTAMP | O62: Timestamp
E64: String のプロパティの getter メソッドでは、必ずフォーマットユーティリティ（FormatUtil）の trimStringRight メソッドで右側スペースを削除すること。
F66: 例：物理名が "gokakuCode" で、データ型が "NVARCHAR2" のカラムが、gokakuCode プロパティに関連付けられている場合
F68: private String gokakuCode; | AJ68: カラム名とプロパティ名が同名であるため、COLUMN アノテーションを省略している。
F70: public String getGokakuCode() {
F71: return FormatUtil.trimStringRight(gokakuCode);
F72: }
F74: public void setGokakuCode(String gokakuCode) {
F75: this.gokakuCode = gokakuCode;
F76: }
...

Sheet 10.プログラミング－帳票印刷編
A1: システム名 | I1: =タイトル!I40 -> 学生勤務管理システム | AE1: 工 程 | AL1: =タイトル!I43 -> 開発基準策定 | BI1: 作 成 | BM1: =タイトル!I46 -> 岡井計允 | BW1: =タイトル!I47 -> 39021 | CF1: 管理記号 | CK1: =タイトル!I50 -> DUA024
A2: サブシステム名 | AE2: ドキュメント | AL2: =タイトル!I44 -> コーディング基準書 | BI2: 改 訂
AL3: =タイトル!I42 -> フレームワーク使用の手引き
B5: １０． プログラミング－帳票印刷編
C7: １０．１ 帳票印刷の仕組み
D9: 帳票印刷処理は、下記の図に示すような仕組みにより行われる。
N12: アクションクラス
AR15: common.js
F22: layout.html
F26: header.html
F33: ①アクションクラスで PDF 印刷用のデータソース（ＣＳＶファイル）を作成する。
F34: ②データ作成後、C021302sBean に PDF ファイル名をセットする。
F35: ③自画面遷移(return null）する。
F36: ④共通レイアウト（layout.html）の初期化イベントが発生し、共通 JavaScript（common.js）の initWindow（画面共通の初期処理スクリプト）が呼び出される。
F37: ⑤initWindow から pdfPrint を呼び出す。
F38: ⑥pdfPrint は、C021302sBean のプロパティ（ファイル名）の値が入っていれば、印刷処理を行う。
D40: 画面でファイルの作成を監視しており、作成されたタイミングで印刷が開始される仕組みである。
D41: 印刷対象ファイルが存在するかどうかは、ファイル名がセットされているかどうかで判断しているため、各々のアクションクラスでは、印刷データの作成とファイル名のセットだけをすれば良い。
C49: １０．２ 印刷処理（データ作成）の流れ
D51: PDF のデータソースにはＣＳＶを使用する。ＣＳＶの作成には、テキストファイル部品を使用する。
D52: 以下にデータの作成の基本的な流れ（テキストファイル部品の使用方法を含む）を示す。
E54: ①Dao 等により、出力データを取得する。
E55: ②データリソースリストを作成する（新規にリストを作成する）。
E56: ③データソースマップ（データソースリストの要素）を作成する（新規にマップを作成する）。
E57: ④ファイルエンコードをシステム依存（ENCODING_SYSTEM）に設定する。(Windows-31Jで出力する場合。UTF-8の場合は、UTF-8を指定する。) | BU57: UTF-8を指定すること。
E58: ⑤ファイルタイプをＣＳＶに設定する。
E59: ⑥ＣＳＶファイル名を設定する。
E60: ⑦セッションフラグを True に設定する。
E61: ⑧ファイルの作成を開始する。
E62: ⑨ヘッダデータ（ＣＳＶファイル出力メソッドに渡すリスト）を作成する。
E63: ⑩ＣＳＶファイル出力メソッドにより、ヘッダ行を出力する。
E64: ⑪明細データ（ＣＳＶファイル出力メソッドに渡すリスト）を作成する。
E65: ⑫ＣＳＶファイル出力メソッドにより、明細行を出力する。
E66: ⑬ファイルの作成を終了する。
E67: ⑭データソースマップに、データソース（ファイル名）を設定する。
E68: ⑮データソースマップを、データソースリストに追加する。
E69: ⑯印刷部品のダウンロード/直接印刷用 PDF ファイル作成メソッドにより、PDF ファイルを作成する。
... E77: ※ 基本的な流れであるため、帳票によっては複雑になる可能性もある。

Sheet Sheet3
G2: １． 全般
D3: シート数： | E3: 14 | H3: １．１ インストール及び起動
H4: １．２ 開発環境の概要
H5: １．３ Seasar2について
H6: １．４ 各プロジェクトの説明
H7: １．５ テスト方法
G9: ２． ＡＯＰ
H10: ２．１ ＡＯＰを利用する機能
H11: ２．２ アクセスログ出力（AccessLogInterceptor）
H12: ２．３ ログイン認証（LoginCertifyInterceptor）
H13: ２．４ 重複レコード追加時のエラー処理（DuplicateInsertInterceptor）
H14: ２．５ 排他エラー処理（HaitaMessageInterceptor）
H15: ２．６ ガイダンスメッセージのクリア（GuidanceClearInterceptor）
H16: ２．７ 画面情報管理（NavigationInterceptor）
G18: ３． 画面遷移方式
H19: ３．１ ナビゲーションルール
H20: ３．２ 設定方法
H21: ３．３ ANCHORタグの禁止事項
G23: ４． 例外処理
H24: ４．１ 例外処理の考え方
H25: ４．２ エラーページの設定による例外処理
H26: ４．３ ＡＯＰによる例外処理
G28: ５． 画面グループ設定
H29: ５．１ タブ形式画面のグループ設定
H30: ５．２ ポップアップ画面設定
H31: ５．３ 設定例
G33: ６． プログラミング－ＨＴＭＬ編
H34: ６．１ 共通レイアウト
H35: ６．２ 共通の宣言とレイアウト継承
H36: ６．３ ｊｓファイルの定義
H37: ６．４ body の定義
H38: ６．５ form タグの定義
H39: ６．６ ガイダンス行の定義
H40: ６．７ プロパティの設定
H41: ６．８ ＩＤの定義
H42: ６．９ アクションの設定
H43: ６．１０ 一覧形式表示
H44: ６．１１ ポップアップ
H45: ６．１２ ファイルアップロード
... H48: ６．１５ 表示制御
...

Sheet Sheet1
A1: システム名 | I1: =タイトル!I40 -> 学生勤務管理システム | AE1: 工 程 | AL1: =タイトル!I43 -> 開発基準策定 | BI1: 作 成 | BM1: =タイトル!I46 -> 岡井計允 | BW1: =タイトル!I47 -> 39021 | CF1: 管理記号 | CK1: =タイトル!I50 -> DUA024
A2: サブシステム名 | AE2: ドキュメント | AL2: =タイトル!I44 -> コーディング基準書 | BI2: 改 訂
AL3: =タイトル!I42 -> フレームワーク使用の手引き
B5: １１． その他
C7: 実際の開発に当たっては、「開発ルールブック」も参照のこと。
