Workbook
Name _Toc94971774: バッチ処理概要!#REF!
Name _Toc94971774: 画面レイアウト!#REF!
Name _Toc94971774: 管理テーブル!#REF!
Name _Toc94971774: 実装方式!#REF!
Name _Toc94971775: バッチ処理概要!#REF!
Name _Toc94971775: 画面レイアウト!#REF!
Name _Toc94971775: 管理テーブル!#REF!
Name _Toc94971775: 実装方式!#REF!
Name シート数: #REF!

Sheet タイトル
G11: =I40 -> 学生勤務管理システム
G14: =I44 -> コーディング基準書
G17: =I42 -> バッチ処理編
G20: =I51 -> 【 Ver 2.0 】
B38: 見出し部タイトル制御テーブル
B39: タイトル項目 | I39: タイトル項目埋め込み内容
B40: ①システム名 | I40: 学生勤務管理システム
B41: ②サブシステム名
B42: ③分類名 | I42: バッチ処理編
B43: ④作業工程名 | I43: 開発基準策定
B44: ⑤ドキュメント代表名 | I44: コーディング基準書
B45: ⑥ドキュメント詳細名 | I45: ※ページ毎に個別入力
B46: ⑦作成者 | I46: 鳥羽哲也
B47: ⑧作成日 | I47: 38985
B48: ⑦改定者 | I48: ※ページ毎に個別入力
B49: ⑧改定日 | I49: ※ページ毎に個別入力
B50: ⑨管理記号 | I50: DUA024
B51: ⑩Ｖｅｒ | I51: 【 Ver 2.0 】
B53: （注1） ①～⑤は、埋め込み内容の先頭１文字は空白にする。
B55: （注2） ⑦と⑧でシート毎に異なる場合は、各シートの該当項目に直接、作成者、作成日を入力する。
B57: (注3） 文字はタイトル部：ＭＳゴシック、本文部：ＭＳ明朝で統一
B59: （注4） 管理番号は、ドキュメント体系の管理番号を使用する。
B61: （注5） ドキュメントＩＤの付け方
C63: 管理記号-分類区分（任意に設定）
C65: ※管理記号は、別紙 プロジェクト計画書のドキュメント体系を参照
B67: (注6） システム階層の概要
C69: システム名 | J69: ⇒ | L69: 人事給与システム
D71: サブシステム名 | J71: ⇒ | L71: 人事システム
L72: 給与システム
L73: 移行システム
E75: 機能名
F78: 処理名

Sheet 改訂履歴
A1: 改訂履歴 | G1: =タイトル!I42 -> バッチ処理編
A3: No | E3: Ver | J3: 新規／改訂日 | R3: 区分 | W3: 改訂箇所 | AH3: 改訂理由 | BR3: 新規／改訂者
W4: 頁 | AA4: 項番
A5: 1 | E5: 1 | J5: =タイトル!I47 -> 38985 | R5: 新規 | AH5: 新規作成 | BR5: =タイトル!$I$46 -> 鳥羽哲也
A6: 2 | E6: 1.1 | J6: 39028 | R6: 変更 | AA6: 5 | AH6: 実装方式を追加 | BR6: 鳥羽哲也
A7: 3 | E7: 1.2 | J7: 39030 | R7: 変更 | AA7: 5.3 | AH7: リカバリの方式を追加 | BR7: 鳥羽哲也
A8: 4 | E8: 1.3 | J8: 39031 | R8: 変更 | AA8: 4 | AH8: 管理テーブルの項目を修正 | BR8: 鳥羽哲也
AA9: 5.4 | AH9: 部品のネーミングルールを修正 | BR9: 鳥羽哲也
A10: 5 | E10: 2 | J10: 41418 | R10: 変更 | AH10: バッチ処理の方式を変更 | BR10: 鳥羽哲也

Sheet 目次
C1: 目次
C4: １．画面デザイン | AC4: ･･･ | AE4: 1
D5: １．１ バッチ起動画面
D6: １．２ エラー確認画面
C10: ２．バッチ処理の流れ(必ず10秒未満で終わる処理) | AC10: ･･･ | AE10: 5
D11: ２．１ 実行
D12: ２．２ エラー確認
C14: ３．バッチ処理の流れ(10秒以上かかる可能性がある処理) | AC14: ･･･ | AE14: 7
D15: ３．１ 実行
D16: ３．２ 状況照会
D17: ３．３ エラー確認
C19: ４． 管理テーブル | AC19: ･･･ | AE19: 9
D20: ４．１ バッチ管理テーブル
D21: ４．２ エラー確認テーブル
C23: ５． 実装方式 | AC23: ･･･ | AE23: 10
D24: ５．１ 実装
D25: ５．２ クラスの構成
D26: ５．３ 実行メソッドの構成
D27: ５．４ 機能分割のための部品化について
D28: ５．５ 業務での共通部品化について

Sheet 画面レイアウト
A1: システム名 | I1: =タイトル!I40 -> 学生勤務管理システム | AE1: 工 程 | AL1: =タイトル!I43 -> 開発基準策定 | BI1: 作 成 | BM1: =タイトル!I46 -> 鳥羽哲也 | BW1: =タイトル!I47 -> 38985 | CF1: 管理記号 | CK1: =タイトル!I50 -> DUA024
A2: サブシステム名 | I2: =タイトル!I41 | AE2: ドキュメント | AL2: =タイトル!I44 -> コーディング基準書 | BI2: 改 訂
B5: １． 画面デザイン
C7: １．１ バッチ起動画面
C49: １．４ エラー確認画面

Sheet バッチ処理概要
A1: システム名 | I1: =タイトル!I40 -> 学生勤務管理システム | AE1: 工 程 | AL1: =タイトル!I43 -> 開発基準策定 | BI1: 作 成 | BM1: =タイトル!I46 -> 鳥羽哲也 | BW1: =タイトル!I47 -> 38985 | CF1: 管理記号 | CK1: =タイトル!I50 -> DUA024
A2: サブシステム名 | I2: =タイトル!I41 | AE2: ドキュメント | AL2: =タイトル!I44 -> コーディング基準書 | BI2: 改 訂
B5: ３． バッチ処理の流れ
C7: ３．１ 状況照会
AT20: RMIメッセージ
AT21: (S2RMIを利用)
CA22: 実行ボタン一つにつき、バッチ
CA23: プログラムは一本です。
D29: 画面の流れ
E30: ① | F30: 画面を開いたタイミングで、バッチ管理テーブルとエラー管理テーブルを確認する。データがない場合は、空のデータを作成しておく。
F31: バッチ管理テーブルのステータスが「正常終了」であれば、「実行」ボタンを表示し、「エラー確認」ボタンを隠す。
F32: バッチ管理テーブルのステータスが「異常終了」であれば、画面に「エラー終了しています」等を表示し、「実行」ボタン、「エラー確認」ボタンを表示する。
E33: ② | F33: バッチ管理テーブルのステータスが「実行中」であれば、ジョブ管理部品でジョブの状況確認を行う。
F34: ジョブが終了していればステータスを「正常終了」か「異常終了」に変更し、①と同様の画面表示を行う。
F35: ジョブが実行中であれば、画面に「処理実行中」等のメッセージを表示する。「実行」ボタン、「エラー確認」ボタンを隠す。
E36: ③ | F36: ジョブが終了するまで、定期的にジョブの状態を確認する。
C49: ３．２ 実行
AT65: RMIメッセージ
AT66: (S2RMIを利用) | CA66: 実行ボタン一つにつき、バッチ
CA67: プログラムは一本です。
D73: 画面の流れ
E74: ① | F74: 「実行」ボタン押下。画面アクションの「実行ボタン押下」が呼ばれる
E75: ② | F75: ジョブ管理部品の「ジョブ実行」が呼ばれる
E76: ③ | F76: ジョブ管理サービスがバッチを実行する。バッチ管理テーブルのステータスを「実行中」に更新し、エラー管理テーブルをクリアする。
F77: 起動しなかった場合は、バッチ管理テーブルを「異常終了」に更新する。ガイダンスに「起動できませんでした。システム管理者にお問い合わせください。」等のメッセージを表示。
E78: ④ | F78: バッチファイルでJavaのプログラムを実行する。
E79: ⑤ | F79: ジョブ管理サービスから実行中のステータスが返されたら、実行ボタン、エラー確認ボタンを隠す。
C93: ３．３ エラー確認
D95: （２．２ エラー確認と同一処理）
D117: 画面の流れ
D118: ①バッチ管理テーブルを見て、レコードがないか「正常終了」であれば、「実行」ボタンを表示し、「エラー確認」ボタンを隠す。
E119: 「異常終了」であれば、画面に「エラー終了しています」等を表示し、「実行」ボタン、「エラー確認」ボタンを隠す。
D120: ②「エラー確認」ボタン押下。画面アクションの「エラー確認ボタン押下」が呼ばれる
D121: ③「バッチの処理ID」と「バッチの処理名」を渡してエラー確認画面に遷移する。
E122: 初期処理で、遷移時に渡された処理IDで、エラー確認テーブルから情報を取得し、表示する。
D123: ④印刷ボタン押下時は、PDFで印刷を行う。

Sheet 管理テーブル
A1: システム名 | I1: =タイトル!I40 -> 学生勤務管理システム | AE1: 工 程 | AL1: =タイトル!I43 -> 開発基準策定 | BI1: 作 成 | BM1: =タイトル!I46 -> 鳥羽哲也 | BW1: =タイトル!I47 -> 38985 | CF1: 管理記号 | CK1: =タイトル!I50 -> DUA024
A2: サブシステム名 | I2: =タイトル!I41 | AE2: ドキュメント | AL2: =タイトル!I44 -> コーディング基準書 | BI2: 改 訂
B5: ４． 管理テーブル
C7: ４．１ バッチ管理テーブル
E9: ÑサーバID | M9: ÑバッチID | U9: ÑログインID | AC9: ステータス
E10: VARCHAR(1) | M10: VARCHAR(8) | U10: VARCHAR(8) | AC10: NUMBER(1)
U11: 人毎でない場合 | AC11: 0 | AD11: 正常終了
U12: 空文字 | AC12: 1 | AD12: 実行中
AC13: 2 | AD13: 異常終了
AC14: 3 | AD14: 強制終了
C15: ４．２ エラー確認テーブル
E17: ÑサーバID | M17: ÑバッチID | U17: ÑログインID | AC17: Ñ連番 | AK17: 日付 | AS17: 時間 | BA17: エラー情報
E18: VARCHAR(1) | M18: VARCHAR(8) | U18: VARCHAR(8) | AC18: NUMBER(4) | AK18: NUMBER(8) | AS18: NUMBER(6) | BA18: NVARCHAR2(100)
U19: 人毎でない場合 | AC19: 処理IDごと | AK19: YYYYMMDD | AS19: HHMMSS
U20: 空文字 | AC20: INSERT前に加算
AC21: 1～9999

Sheet 実装方式
A1: システム名 | I1: =タイトル!I40 -> 学生勤務管理システム | AE1: 工 程 | AL1: =タイトル!I43 -> 開発基準策定 | BI1: 作 成 | BM1: =タイトル!I46 -> 鳥羽哲也 | BW1: =タイトル!I47 -> 38985 | CF1: 管理記号 | CK1: =タイトル!I50 -> DUA024
A2: サブシステム名 | I2: =タイトル!I41 | AE2: ドキュメント | AL2: =タイトル!I44 -> コーディング基準書 | BI2: 改 訂 | BM2: 鳥羽哲也 | BW2: 39030
B5: ５． 実装方式
C7: ５．１ 実装
D9: ・ | E9: バッチ処理を作成する場合は、バッチジョブ(BatchJob)インターフェイスを実装する。
E10: クラス名は、処理ID(先頭大文字、以降小文字)＋BatchImplとする。(ネーミング基準書より)
F12: クラス図
D26: ・ | E26: 実行時には、バッチドライバから、コミット件数設定メソッドでコミット件数がセットされた後、実行メソッドが呼び出される。
E27: 実行メソッドの戻り値で、処理の結果(正常終了/異常終了)を返す。
F29: シーケンス図
C49: ５．２ クラスの構成
E51: バッチ処理クラスの構成は次の通りとする。
AT53: Xxxxxxxxは、バッチの処理ID
E75: 定数を使う場合は、定数の定義を行う
F76: private static final 型 変数名 = 値;
E78: 部品のセッタのところで、必要な部品のセッタを定義する。
F79: setTransactionManager() は、トランザクション処理を行うために、必要となる。
E81: 実際の処理は、実行メソッド内に記述する。
E83: その他、必要なコンストラクタやメソッドを定義する。
C93: ５．３ 実行メソッドの構成
E95: 実行メソッドは、各処理によって微妙に異なると思われるが、概ね次のような形式で実装する。
AJ97: トランザクションの適宜コミットについて
AK99: 大量のデータを全件処理するまでコミットしない作りの場合、UNDO領域に大量のトランザクションデータが書き込まれてしまい、
AK100: システムのダウンや性能劣化等を引き起こしてしまう。
AK101: 反対に、一件ごとにコミットしてしまうと、トランザクション処理がネックとなって、バッチ処理の性能が劣化してしまう。
AK102: そこで、外部から渡されたコミット件数ごとに、トランザクションのコミットと開始を行うこととする。
AJ104: トランザクションの適宜コミットに関連したリカバリ処理
AK106: 再処理を行うためには、通常はリカバリ処理(赤太字の処理)が必要となる。
AK107: 処理済みのデータを読み飛ばすために、現在のキーを記録しておき、リカバリ時は次のキーから処理を行う。
AK108: 上記以外にもリカバリのための対策が必要な場合は、各処理で必要な対策を講ずること。
AK118: 実行前に全件削除するなどで、先頭から単に再処理すれば良い場合は、リカバリ処理（赤太字の処理）は必要ないが、
AK119: 全件処理は時間が掛かるため、そうしなければ処理ができない場合を除いて、そうしないこと。
AK129: 途中でコミットしてしまうとリカバリができない場合は、データの事前チェックを行う。
C137: ５．４ 機能分割のための部品化について
E139: バッチ処理が内部的に複数の機能に分かれており、それらを分割したい場合は、機能ごとに部品化して作成する。
AA145: 部品化
E152: 部品化する場合は、各部品ごとに処理ID+連番2桁をつける。
E153: 処理IDは親プログラムと同一とする。
F155: インターフェイス
G156: AaaaaaabNNLogic
...
