Workbook
Name _Toc94971774: '1.前提条件'!#REF!
Name _Toc94971774: '3.制御'!#REF!
Name _Toc94971774: '5.ＣＳＳコーディング基準'!#REF!
Name _Toc94971774: '6.ＨＴＭＬコーディング基準'!#REF!
Name _Toc94971774: '7.JavaScript コーディング基準'!#REF!
Name _Toc94971774: '8.AJAXコーディング基準'!#REF!
Name _Toc94971774: 添付資料!#REF!
Name _Toc94971774: 別紙!#REF!
Name _Toc94971775: '1.前提条件'!#REF!
Name _Toc94971775: '3.制御'!#REF!
Name _Toc94971775: '5.ＣＳＳコーディング基準'!#REF!
Name _Toc94971775: '6.ＨＴＭＬコーディング基準'!#REF!
Name _Toc94971775: '7.JavaScript コーディング基準'!#REF!
Name _Toc94971775: '8.AJAXコーディング基準'!#REF!
Name _Toc94971775: 添付資料!#REF!
Name _Toc94971775: 別紙!#REF!
Name シート数: #REF!

Sheet タイトル
G11: =I40 -> 学生勤務管理システム
G14: =I44 -> コーディング基準書
G17: =I42 -> 画面(HTML等)編
G20: =I51 -> 【 Ver 1.0 】
B38: 見出し部タイトル制御テーブル
B39: タイトル項目 | I39: タイトル項目埋め込み内容
B40: ①システム名 | I40: 学生勤務管理システム
B41: ②サブシステム名
B42: ③分類名 | I42: 画面(HTML等)編
B43: ④作業工程名 | I43: プロジェクト管理
B44: ⑤ドキュメント代表名 | I44: コーディング基準書
B45: ⑥ドキュメント詳細名 | I45: ※ページ毎に個別入力
B46: ⑦作成者 | I46: 鳥羽 哲也
B47: ⑧作成日 | I47: 41417
B48: ⑦改定者 | I48: ※ページ毎に個別入力
B49: ⑧改定日 | I49: ※ページ毎に個別入力
B50: ⑨管理記号 | I50: DUA024
B51: ⑩Ｖｅｒ | I51: 【 Ver 1.0 】
B53: （注1） ①～⑤は、埋め込み内容の先頭１文字は空白にする。
B55: （注2） ⑦と⑧でシート毎に異なる場合は、各シートの該当項目に直接、作成者、作成日を入力する。
B57: (注3） 文字はタイトル部：ＭＳゴシック、本文部：ＭＳ明朝で統一
B59: （注4） 管理番号は、ドキュメント体系の管理番号を使用する。
B61: （注5） ドキュメントＩＤの付け方
C63: 管理記号-分類区分（任意に設定）
C65: ※管理記号は、別紙 プロジェクト計画書のドキュメント体系を参照
B67: (注6） システム階層の概要
C69: システム名 | J69: ⇒ | L69: 人事給与システム
D71: サブシステム名 | J71: ⇒ | L71: 人事システム
L72: 給与システム
L73: 移行システム
E75: 機能名
F78: 処理名

Sheet 改訂履歴
A1: 改訂履歴 | G1: =タイトル!I42 -> 画面(HTML等)編
A3: No | E3: Ver | J3: 新規／改訂日 | R3: 区分 | W3: 改訂箇所 | AH3: 改訂理由 | BR3: 新規／改訂者
W4: 頁 | AA4: 項番
A5: 1 | E5: 1 | J5: =タイトル!I47 -> 41417 | R5: 新規 | AH5: 新規作成 | BR5: =タイトル!I46 -> 鳥羽 哲也
A6: 2 | E6: 1.1 | J6: 41473 | R6: 修正 | AA6: 6.5 | AH6: 一部インデントを使用するように追記 | BR6: 中村 恒太郎
AA7: 6.7 | AH7: レイアウト構成の基準を追加 | BR7: 中村 恒太郎

Sheet 目次
C1: 目次
C5: １． 前提条件 | AC5: ･･･ | AE5: 1 | AK5: ７． JavaScript コーディング基準 | BK5: ･･･ | BM5: 14
AL6: ７．１ 変数
AL7: ７．２ 関数
AL8: ７．３ コメント
C9: ２． 欠番 | AL9: ７．４ その他
C11: ３． 制御 | AC11: ･･･ | AE11: 9 | AK11: （添付資料） | BK11: ･･･ | BM11: 15
D12: ３．１ フォーカス制御 | AL12: １． コーディング例
D13: ３．２ 操作性の考慮
C15: ４． 欠番
C17: ５． ＣＳＳコーディング基準 | AC17: ･･･ | AE17: 11
D18: ５．１ コーディング基準
D19: ５．２ クラス構成
C21: ６． ＨＴＭＬコーディング基準 | AC21: ･･･ | AE21: 12
D22: ６．１ ドキュメントタイプ
D23: ６．２ 言語
D24: ６．３ ヘッダ
D25: ６．４ コーディング基準
D26: ６．５ フォーマット
D27: ６．６ スタイルの適用

Sheet 1.前提条件
A1: システム名 | I1: =タイトル!I40 -> 学生勤務管理システム | AE1: 工 程 | AL1: =タイトル!I43 -> プロジェクト管理 | BI1: 作 成 | BM1: =タイトル!I46 -> 鳥羽 哲也 | BW1: =タイトル!I47 -> 41417 | CF1: 管理記号 | CK1: =タイトル!I50 -> DUA024
A2: サブシステム名 | I2: =タイトル!I41 | AE2: ドキュメント | AL2: =タイトル!I44 -> コーディング基準書 | BI2: 改 訂
AL3: =タイトル!I42 -> 画面(HTML等)編
B5: １． 前提条件
C7: １．１ 概要/目的
D9: ・HTMLやCSSのコードを統一するため、コーディング基準を定める。

Sheet 3.制御
A1: システム名 | I1: =タイトル!I40 -> 学生勤務管理システム | AE1: 工 程 | AL1: =タイトル!I43 -> プロジェクト管理 | BI1: 作 成 | BM1: =タイトル!I46 -> 鳥羽 哲也 | BW1: =タイトル!I47 -> 41417 | CF1: 管理記号 | CK1: =タイトル!I50 -> DUA024
A2: サブシステム名 | I2: =タイトル!I41 | AE2: ドキュメント | AL2: =タイトル!I44 -> コーディング基準書 | BI2: 改 訂
AL3: =タイトル!I42 -> 画面(HTML等)編
B5: ３． 制御
C7: ３．１ フォーカス制御
D9: ・初期表示時、フォーカスは左上の項目に設定する。（終了ボタンは除く）
D10: ・Tab キーで、フォーカスを左上から右下へ順に移動する。
C12: ３．２ 操作性の考慮
D14: ・Esc・Enter・Backspace キーを機能しないようにする。
D15: ・右クリックでの操作ができないようにする。
D16: ・デフォルトボタンを設定しない。
D17: ・ラジオボタンとチェックボックスは、初期表示時は未選択状態にする。
D18: ・ボタンの連続クリックに対して誤作動しないように制御する。
D19: ・入力項目には、IME制御・桁数制限の設定をする。
E21: 代表的な入力項目の設定標準
E22: 入力項目 | K22: IME制御 | Q22: 桁数 | Z22: 備考
E23: 郵便番号 | K23: 使用不可 | Q23: 3桁-4桁 | Z23: 2項目に分割
E24: 日付 | K24: 使用不可 | Q24: 4桁-2桁-2桁 | Z24: 3項目に分割
E25: コード | K25: 使用不可 | Q25: （※１、※２）
E26: 金額 | K26: 使用不可 | Q26: 12桁（符号含む） | Z26: カンマ編集しない
E27: 全角文字 | K27: オン | Q27: -
E28: 半角文字 | K28: 使用不可 | Q28: - | Z28: 電話番号、メールアドレス等
E30: （※１）コードについては、フル桁入力を基本とする。
E31: （※２）コードにおける英字の大文字／小文字については、区別するものとする。

Sheet 5.ＣＳＳコーディング基準
A1: システム名 | I1: =タイトル!I40 -> 学生勤務管理システム | AE1: 工 程 | AL1: =タイトル!I43 -> プロジェクト管理 | BI1: 作 成 | BM1: =タイトル!I46 -> 鳥羽 哲也 | BW1: =タイトル!I47 -> 41417 | CF1: 管理記号 | CK1: =タイトル!I50 -> DUA024
A2: サブシステム名 | I2: =タイトル!I41 | AE2: ドキュメント | AL2: =タイトル!I44 -> コーディング基準書 | BI2: 改 訂
AL3: =タイトル!I42 -> 画面(HTML等)編
B5: ５． ＣＳＳコーディング基準
D7: ・領域の定義、背景色、文字色、文字サイズの具体的な設定は、スタイルシートで行う。
D8: ・スタイルの設定は、共通の外部ファイルに全て記述する。
D9: ・その画面しか使用しないスタイルは、画面ＩＤ.cssファイルを作成し、そこに記述する。
C10: ５．１ コーディング基準
D12: ・css ファイルの先頭には、"@charset "UTF-8";"を記述する。
D13: ・タグ、属性名は全て小文字で記述する。
D14: ・クラス名の先頭は小文字のアルファベットとする。
D15: ・書式は下記の例に従う。
E16: 例：
E17: table {
E18: word-break: break-all;
E19: border-collapse: collapse;
E20: padding: 0;
E21: margin: 0;
E22: }
C24: ５．２ クラス構成
D26: ・HTML に記述する際の、生産性・保守性等を考慮した構成にする。
D27: ※添付資料参照

Sheet 6.ＨＴＭＬコーディング基準
A1: システム名 | I1: =タイトル!I40 -> 学生勤務管理システム | AE1: 工 程 | AL1: =タイトル!I43 -> プロジェクト管理 | BI1: 作 成 | BM1: =タイトル!I46 -> 鳥羽 哲也 | BW1: =タイトル!I47 -> 41417 | CF1: 管理記号 | CK1: =タイトル!I50 -> DUA024
A2: サブシステム名 | I2: =タイトル!I41 | AE2: ドキュメント | AL2: =タイトル!I44 -> コーディング基準書 | BI2: 改 訂
AL3: =タイトル!I42 -> 画面(HTML等)編
B5: ６． ＨＴＭＬコーディング基準
C7: XHTML 1.0 移行型 とする。
C9: ６．１ XML宣言
D11: ・Internet Explorer 6 および 7 に、XML宣言があるとレンダリングモードが切り替わらないバグがあるため、XML宣言は行わない。
D12: (文字セットが UTF-8 の場合は、XML宣言を省略してもよい)
C14: ６．２ ドキュメントタイプ
D16: ・ファイルの先頭には必ず下記のドキュメントタイプを記述する。
E18: <!DOCTYPE html PUBLIC "-//W3C//DTD XHTML 1.0 Transitional//EN" "http://www.w3.org/TR/xhtml1/DTD/xhtml1-transitional.dtd">
C20: ６．３ 言語/名前空間
D22: ・言語およびXML名前空間を明示するため、HTMLタグに下記の記述を行う。
E24: <html lang="ja" xml:lang="ja" xmlns="http://www.w3.org/1999/xhtml">
C26: ６．４ ヘッダ
D28: ・<head>タグ内には下記の記述を行う。
E30: <meta http-equiv="Content-Type" content="text/html; charset=UTF-8" />
E31: <meta http-equiv="Content-Script-Type" content="text/javascript" />
E32: <meta http-equiv="X-UA-Compatible" content="IE=EmulateIE7" />
E33: <link rel="stylesheet" type="text/css" href="common.css" />
E34: <script type="text/javascript" src="common.js"></script>
C36: ６．４ コーディング基準
D38: ・W3Cが公式に発表している正しい文法で記述する。W3Cで廃棄予定または推奨していない技術は使用しない。
D39: ・タグ、属性名は全て小文字で記述する。
D40: ・スタイルシートを利用し基本的な色、文字フォントなど統一をはかること。
D41: ・属性値は全て""（ダブルクォーテーション）で囲む。
D42: ・画面のボタンには画像を使用し、title 属性でガイド(ツールチップ)を表示させること。
D43: ・JavaScript（window.status）で、ステータスバーを書き換えない。
C49: ６．５ フォーマット
D51: ・TAB、スペースなどでインデントをつけないこと。(インデントをつけると、Internet Explorerで半角空白が表示されてしまう場合があるため。)
D52: ただし、項番6.7で後述する”Layer8”の内容エリアはTABスペースでインデントをつける。（ソースを見やすくするため。）
D53: ・1行にいくつも要素を並べるような記述は推奨しない。(上と同様の理由)
E54: 良い例：
E55: <td>a</td>
E56: <td>b</td>
E57: 悪い例：
E58: <td>a</td><td>b</td>
D59: ・タグが入れ子になる場合は、下記の例のように上位の層のタグの後ろで改行する。
E60: 例：
E61: <table width="900">
...

Sheet 7.JavaScript コーディング基準
A1: システム名 | I1: =タイトル!I40 -> 学生勤務管理システム | AE1: 工 程 | AL1: =タイトル!I43 -> プロジェクト管理 | BI1: 作 成 | BM1: =タイトル!I46 -> 鳥羽 哲也 | BW1: =タイトル!I47 -> 41417 | CF1: 管理記号 | CK1: =タイトル!I50 -> DUA024
A2: サブシステム名 | I2: =タイトル!I41 | AE2: ドキュメント | AL2: =タイトル!I44 -> コーディング基準書 | BI2: 改 訂
AL3: =タイトル!I42 -> 画面(HTML等)編
B5: ７． JavaScript コーディング基準
C7: ７．１ 変数
D9: ・変数は下記の形式で宣言を記述する。
E11: var sample = 10;
D13: ・変数は明示的に宣言する。
C15: ７．２ 関数
D17: ・関数定義には、function キーワードを使用し、下記の形式で記述する。
E19: function sample(a, b) {
E20: ．．．
E21: }
C23: ７．３ コメント
D25: ・function のコメントは下記の形式で記述する。
E27: /*
E28: * function の処理概要
E29: *
E30: * @author 作者名 作成日(yyyy/mm/dd)
E31: * @param パラメータの変数名 パラメータの説明
E32: * @return 戻り値の説明
E33: */
D35: ・変数のコメントは下記の形式で記述する。コメントの前には1行の空行を入れる。
E37: // 変数の説明
C39: ７．４ その他
D41: ・文の終わりのセミコロンを省略しない。
D42: ・オブジェクトの階層は省略せずに記述する。
D43: ・オブジェクトの参照は、DOMを利用すること。オブジェクトは可能な限り、ByNameではなくByIdで一意に検索すること。
D44: ・JavaScript は、共通の外部ファイルに全て記述する。
D45: ・Java コーディング基準のうち、JavaScript に適用できるものに関してはそれに従う。

Sheet 8.AJAXコーディング基準
A1: システム名 | I1: =タイトル!I40 -> 学生勤務管理システム | AE1: 工 程 | AL1: =タイトル!I43 -> プロジェクト管理 | BI1: 作 成 | BM1: =タイトル!I46 -> 鳥羽 哲也 | BW1: =タイトル!I47 -> 41417 | CF1: 管理記号 | CK1: =タイトル!I50 -> DUA024
A2: サブシステム名 | I2: =タイトル!I41 | AE2: ドキュメント | AL2: =タイトル!I44 -> コーディング基準書 | BI2: 改 訂
AL3: =タイトル!I42 -> 画面(HTML等)編
B5: ８． AJAX コーディング基準
C7: ８．１ 使用可能範囲
E9: リストボックス等を動的に生成する必要がある場合は、AJAXを使用した画面設計を行う。
E11: 例：
G12: 都道府県 | S12: ▼ | AY12: 都道府県 | BE12: 京都府 | BK12: ▼
G13: 市区町村 | M13: 京都府 | S13: △ | W13: ▼ | AY13: 市区町村 | BO13: ▼
M14: 滋賀県 | X14: JSON(京都府) | AO14: JSON(市区町村リスト) | BE14: 京都市北区 | BO14: △
M15: 大阪府 | BE15: 京都市上京区
M16: 兵庫県 | BE16: 京都市中京区
M17: 奈良県 | BE17: 京都市東山区
M18: 和歌山県 | BE18: 京都市下京区
M19: 北海道 | BE19: 京都市南区
M20: 青森県 | S20: ▽ | BE20: 京都市右京区
BE21: 京都市伏見区 | BO21: ▽
E23: また、バッチ処理の状況確認などでも使用する。
E25: 例：
G27: 画面より、定期的にポーリング
H29: 状況確認画面 | AY29: 状況確認画面
X32: JSON(問合せキー) | AO32: JSON(進捗状況) | BB32: 進捗率:70%
BB33: ■ | BC33: ■ | BD33: ■ | BE33: ■ | BF33: ■ | BG33: ■ | BH33: ■

Sheet 添付資料
A1: システム名 | I1: =タイトル!I40 -> 学生勤務管理システム | AE1: 工 程 | AL1: =タイトル!I43 -> プロジェクト管理 | BI1: 作 成 | BM1: =タイトル!I46 -> 鳥羽 哲也 | BW1: =タイトル!I47 -> 41417 | CF1: 管理記号 | CK1: =タイトル!I50 -> DUA024
A2: サブシステム名 | I2: =タイトル!I41 | AE2: ドキュメント | AL2: =タイトル!I44 -> コーディング基準書 | BI2: 改 訂
AL3: =タイトル!I42 -> 画面(HTML等)編
B5: （添付資料）
C7: １．コーディング例
D9: 例①：奇数行と偶数行でセルの色を変える場合
D10: 悪い例 | AC10: 良い例
E11: 【CSS】 | AD11: 【CSS】
E12: /* 奇数行 左詰め | AD12: /* 奇数行 */
E13: td.oddleft { | AD13: tr.odd {
E14: background-color: #ffffff; | AD14: background-color: #ffffff;
E15: text-align: left; | AD15: }
E16: } | AD16: /* 偶数行 */
E17: /* 偶数行 左詰め | AD17: tr.even {
E18: td.evenleft { | AD18: background-color: #eeeeff;
E19: background-color: #eeeeff; | AD19: }
E20: text-align: left; | AD20: /* 左詰め */
E21: } | AD21: td.left {
E22: /* 奇数行 中央揃え | AD22: text-align: left;
... E27: /* 偶数行 中央揃え | AD27: }
E28: td.evencenter {
E29: background-color: #eeeeff;
E30: text-align: center;
E31: }
E33: 【HTML】 | AD33: 【HTML】
E34: <tr> | AD34: <tr class="odd">
E35: <td class="oddleft">foo</td> | AD35: <td class="left">foo</td>
E36: <td class="oddcenter">foo</td> | AD36: <td class="center">foo</td>
E37: </tr> | AD37: </tr>
E38: <tr> | AD38: <tr class="even">
E39: <td class="evenleft">bar</td> | AD39: <td class="left">foo</td>
E40: <td class="evencenter">bar</td> | AD40: <td class="center">foo</td>
E41: </tr> | AD41: </tr>
D44: 左の例の CSS の場合、セル（td タグ）をひとつ記述するたびに奇数行か偶数行かの判断が必要となるが、右の例では、行単位で奇数/偶数の設定を行っているため、セル単位では左詰か中央揃えか
D45: のみを意識すればよい。
D46: また、レイアウトの変更などで奇数行と偶数行が入れ替わるような場合に、左の例では td タグの数だけ修正が必要となるが、右の例では、tr タグの数だけ修正すればよい。
D49: 例②：検索部の行数に応じて内容部のスタイルを決定する場合
D50: 悪い例 | AC50: 良い例
E51: 【CSS】 | AD51: 【CSS】
E52: /* 内容部 検索行が2行 */ | AD52: /* 内容部 検索行が2行 */
...

Sheet 別紙
BB17: 関連性チェックを行う。
BB18: 処理を行う(画面I/Oは行わない)
AC19: 画面入出力と簡易な項目チェックを行う | BB19: ただし、ファイルダウンロードなどは、Streamを呼び出し元からsetterでセットしてもらう。
AC20: トランザクション管理を行う
AC35: 画面入出力と項目チェックを行う
AC36: トランザクション管理を行う
BB39: 関連性チェックを行う。
BB40: 処理を行う(画面I/Oは行わない)
BB41: ただし、ファイルダウンロードなどは、Streamを呼び出し元からsetterでセットしてもらう。
AC57: 画面入出力と項目チェックを行う
AC58: トランザクション管理を行う
Y65: span injectで挿入
BB68: 関連性チェックを行う。
BB69: 処理を行う(画面I/Oは行わない)
BB125: Logicがないため、jUnitでテストしづらい
BB135: Logicがないため、jUnitでテストしづらい
BZ149: 構造が分からなくなるため禁止。
BB169: 構造が分からなくなるため禁止。
