Workbook
Name _Toc94971774: '0.はじめに'!$C$27
Name _Toc94971774: '1.命名規則'!$C$27
Name _Toc94971774: '2.ファイルの構成'!#REF!
Name _Toc94971774: '3.フォーマット'!#REF!
Name _Toc94971774: '4.コメント'!#REF!
Name _Toc94971774: '5.ステートメント'!#REF!
Name _Toc94971774: '6.コーディング規約'!#REF!
Name _Toc94971774: '7.その他'!#REF!
Name _Toc94971775: '0.はじめに'!#REF!
Name _Toc94971775: '1.命名規則'!#REF!
Name _Toc94971775: '2.ファイルの構成'!#REF!
Name _Toc94971775: '3.フォーマット'!#REF!
Name _Toc94971775: '4.コメント'!#REF!
Name _Toc94971775: '5.ステートメント'!#REF!
Name _Toc94971775: '6.コーディング規約'!#REF!
Name _Toc94971775: '7.その他'!#REF!
Name シート数: #REF!

Sheet タイトル
G11: =I40 -> 学生勤務管理システム
G14: =I44 -> コーディング基準書
G17: =I42 -> Java コーディング基準編
G20: =I51 -> 【 Ver 1.0 】
B38: 見出し部タイトル制御テーブル
B39: タイトル項目 | I39: タイトル項目埋め込み内容
B40: ①システム名 | I40: 学生勤務管理システム
B41: ②サブシステム名
B42: ③分類名 | I42: Java コーディング基準編
B43: ④作業工程名 | I43: 開発基準策定
B44: ⑤ドキュメント代表名 | I44: コーディング基準書
B45: ⑥ドキュメント詳細名 | I45: ※ページ毎に個別入力
B46: ⑦作成者 | I46: 鳥羽 哲也
B47: ⑧作成日 | I47: 41390
B48: ⑦改定者 | I48: ※ページ毎に個別入力
B49: ⑧改定日 | I49: ※ページ毎に個別入力
B50: ⑨管理記号 | I50: DUA024
B51: ⑩Ｖｅｒ | I51: 【 Ver 1.0 】
B53: （注1） ①～⑤は、埋め込み内容の先頭１文字は空白にする。
B55: （注2） ⑦と⑧でシート毎に異なる場合は、各シートの該当項目に直接、作成者、作成日を入力する。
B57: (注3） 文字はタイトル部：ＭＳゴシック、本文部：ＭＳ明朝で統一
B59: （注4） 管理番号は、ドキュメント体系の管理番号を使用する。
B61: （注5） ドキュメントＩＤの付け方
C63: 管理記号-分類区分（任意に設定）
C65: ※管理記号は、別紙 プロジェクト計画書のドキュメント体系を参照
B67: (注6） システム階層の概要
C69: システム名 | J69: ⇒ | L69: 人事給与システム
D71: サブシステム名 | J71: ⇒ | L71: 人事システム
L72: 給与システム
L73: 移行システム
E75: 機能名
F78: 処理名

Sheet 改訂履歴
A1: 改訂履歴 | G1: =タイトル!I42 -> Java コーディング基準編
A3: No | E3: Ver | J3: 新規／改訂日 | R3: 区分 | W3: 改訂箇所 | AH3: 改訂理由 | BR3: 新規／改訂者
W4: 頁 | AA4: 項番
A5: 1 | E5: 1 | J5: =タイトル!I47 -> 41390 | R5: 新規 | AH5: 新規作成 | BR5: =タイトル!I46 -> 鳥羽 哲也

Sheet 目次
C1: 目次
C4: ０．はじめに | AK4: ５． ステートメント
AL5: ５．１ 単一の文
C6: １． 命名規則 | AL6: ５．２ 複合文
D7: １．１ 全般 | AL7: ５．３ return 文
D8: １．２ パッケージ名 | AL8: ５．４ if-else 文
D9: １．３ クラス名全般 | AL9: ５．５ 三項演算子
D10: １．４ 例外クラス名 | AL10: ５．６ for 文
D11: １．５ 実装クラス名 | AL11: ５．７ for-each 文
D12: １．６ 抽象クラス名 | AL12: ５．８ while 文
D13: １．７ インターフェース名 | AL13: ５．９ do-while 文
D14: １．８ メソッド名 | AL14: ５．１０ switch 文
D15: １．９ 変数名全般 | AL15: ５．１１ try-catch 文
D16: １．１０ スコープが狭い変数
D17: １．１１ ループカウンタ | AK17: ６． コーディング規約
D18: １．１２ boolean 変数 | AL18: ６．１ 宣言
D19: １．１３ 定数 | AL19: ６．２ 変数
AL20: ６．３ 定数
C21: ２． ファイルの構成 | AL21: ６．４ クラス
D22: ２．１ ソースの構成 | AL22: ６．５ メソッド
D23: ２．２ import宣言 | AL23: ６．６ 文字操作
D24: ２．３ クラスの構成 | AL24: ６．７ 数値
C26: ３． フォーマット | AK26: ７． その他
D27: ３．１ タブ | AL27: ７．１ ソースコードレベルでの注意点
D28: ３．２ 行の長さ | AL28: ７．２ パフォーマンスを考慮したコーディング
D29: ３．３ 行の折り返し
D30: ３．４ 空白行
D31: ３．５ 空白スペース
C33: ４． コメント
D34: ４．１ クラス
D35: ４．２ フィールド
D36: ４．３ メソッド
D37: ４．４ コメントのフォーマット

Sheet 0.はじめに
A1: システム名 | I1: =タイトル!I40 -> 学生勤務管理システム | AE1: 工 程 | AL1: =タイトル!I43 -> 開発基準策定 | BI1: 作 成 | BM1: =タイトル!I46 -> 鳥羽 哲也 | BW1: =タイトル!I47 -> 41390 | CF1: 管理記号 | CK1: =タイトル!I50 -> DUA024
A2: サブシステム名 | I2: =タイトル!I41 | AE2: ドキュメント | AL2: =タイトル!I44 -> コーディング基準書 | BI2: 改 訂
AL3: =タイトル!I42 -> Java コーディング基準編
B5: ０． はじめに
E7: 本基準書は、同志社大学殿学生勤務管理システム開発（以降，本プロジェクト）に関する全てのJavaソースコードのコーディングレベルとフォーマットを統一させることにより、
E8: 汎用性、保守性、拡張性を向上させることを目的とするものである。

Sheet 1.命名規則
A1: システム名 | I1: =タイトル!I40 -> 学生勤務管理システム | AE1: 工 程 | AL1: =タイトル!I43 -> 開発基準策定 | BI1: 作 成 | BM1: =タイトル!I46 -> 鳥羽 哲也 | BW1: =タイトル!I47 -> 41390 | CF1: 管理記号 | CK1: =タイトル!I50 -> DUA024
A2: サブシステム名 | I2: =タイトル!I41 | AE2: ドキュメント | AL2: =タイトル!I44 -> コーディング基準書 | BI2: 改 訂
AL3: =タイトル!I42 -> Java コーディング基準編
B5: １． 命名規則
C7: １．１ 全般
D9: ・意味のある単語の連結により命名する。
D10: ・略語は使用しない。略語の場合、それが何を表現するか不可解な場合が多く、コードの可読性の低下から保守・拡張を困難する可能性がある。
E11: ただし、略語が一般的に認知されている場合は使用してもよい。
E12: 良い例：serverName, clientName, sqlDatabase
E13: 悪い例：str1, str2, fn
D14: ・大文字と小文字だけで名前を区別しない。
D15: ・クラスやメソッドを命名する際には、英語の対義語を意識する。
E16: 例：
E17: add/remove
E18: insert/delete
E19: get/set
E20: start/stop
E21: begin/end
E22: send/receive
E23: first/last
E24: get/release
E25: put/get
E26: up/down
E27: show/hide
... E34: next/previous
C36: １．２ パッケージ名
D38: パッケージ名はすべて小文字とする。
D39: 先頭は"jp.co.kssinet.作番"とし、それ以降については各プロジェクトで基準を設ける。
E40: 例：jp.co.kssinet.ksui2070
C49: １．３ クラス名全般
D51: クラス名の先頭は大文字とする。複数の単語で構成される場合、各単語の先頭を大文字とする。
E52: 例：MySampleClass
C54: １．４ 例外クラス名
D56: 例外クラスの名前の最後には"Exception"を付ける。
E57: 例：SampleException
C59: １．５ 実装クラス名
D61: インターフェースとの区別が必要であれば、最後に"Impl"を付ける。
E62: 例：SampleClassImpl
C64: １．６ 抽象クラス名
D66: 適当な名前がない場合は、"Abstract"を含むサブクラス名を連想させる名前を付ける。
...

Sheet 2.ファイルの構成
A1: システム名 | I1: =タイトル!I40 -> 学生勤務管理システム | AE1: 工 程 | AL1: =タイトル!I43 -> 開発基準策定 | BI1: 作 成 | BM1: =タイトル!I46 -> 鳥羽 哲也 | BW1: =タイトル!I47 -> 41390 | CF1: 管理記号 | CK1: =タイトル!I50 -> DUA024
A2: サブシステム名 | I2: =タイトル!I41 | AE2: ドキュメント | AL2: =タイトル!I44 -> コーディング基準書 | BI2: 改 訂
AL3: =タイトル!I42 -> Java コーディング基準編
B5: ２． ファイルの構成
C7: ２．１ ソースの構成
D9: ・Javaソースファイルは、下記の順に従い構成する。
E10: ①package宣言
E11: ②import宣言
E12: ③クラスコメント/インターフェースコメント
E13: ④クラス/インターフェース宣言
D14: ・1つのファイルには1つのクラス/インターフェースのみを記述する。
C16: ２．２ import宣言
D18: ・importするクラス名を明示的に記述する。"*"を使用しないこと。
E19: 理由：
E20: 依存性を明確化する。多くの*を使ったimportがあると読み手が苦労する。
D21: ・import文を複数記述する場合は、カテゴリ単位で整理して記述する。順序は下記を参照。
E22: ①JavaAPI
E23: ②ライブラリ/フレームワーク
E24: ③業務アプリケーション
D25: ・カテゴリ間には空行を1行挿入する。
C27: ２．３ クラスの構成
D29: ・クラスは下記の順に従い構成する。
E30: ①クラス宣言
E31: ②定数
E32: ③インスタンス変数
E33: ④コンストラクタ
E34: ⑤メソッド
D35: ・クラスメンバーは下記の順に従い記述する。
E36: ①public
E37: ②protected
E38: ③パッケージレベル（アクセス修飾子なし）
E39: ④private
E40: ただし、メソッドについては機能単位でのグルーピングを優先する。

Sheet 3.フォーマット
A1: システム名 | I1: =タイトル!I40 -> 学生勤務管理システム | AE1: 工 程 | AL1: =タイトル!I43 -> 開発基準策定 | BI1: 作 成 | BM1: =タイトル!I46 -> 鳥羽 哲也 | BW1: =タイトル!I47 -> 41390 | CF1: 管理記号 | CK1: =タイトル!I50 -> DUA024
A2: サブシステム名 | I2: =タイトル!I41 | AE2: ドキュメント | AL2: =タイトル!I44 -> コーディング基準書 | BI2: 改 訂
AL3: =タイトル!I42 -> Java コーディング基準編
B5: ３． フォーマット
C7: ３．１ タブ
D9: タブの長さは4スペース分とし、これをインデントの単位とする。
C11: ３．２ 行の長さ
D13: 1行の長さは半角100文字以下を目安とする。
C15: ３．３ 行の折り返し
D17: 1行で書ききれない場合、以下の原則に基づいて複数の行に分割する。ただし、Eclipse 使用の場合はフォーマッターを利用する。
E18: ①コンマの後で区切る。
F19: 例：
F20: someMethod(longExpression1, longExpression2, longExpression3,
F21: longExpression4, longExpression5);
E23: ②extends/implements/throws節で区切る。
F24: 例：
F25: public class LongNameClassImplemenation
F26: extends AbstractImplementation,
F27: implements Serializable, Cloneable {
F28: ...
F29: ...
F30: }
E32: ③優先度の低い演算子の前で区切る。
F33: 例：
F34: longName1 = longName2 * (longName3 + longName4 - longName5)
F35: + 4 * longname6; // こちらの方が良い
F37: longName1 = longName2 * (longName3 + longName4
E38: - longName5) + 4 * longname6; // これは避ける
E49: ④前の行の同じレベルの記述とインデントを合わせる。
F50: 例：
F51: someMethod(int anArg, Object anotherArg, String yetAnotherArg,
F52: Object andStillAnother) {
F53: ...
F54: }
E56: ⑤以上①～④のルールで右に偏ってしまう場合は、8個分の半角スペースを使用する。
F57: 例：
F58: private static synchronized horkingLongMethodName(int anArg,
F59: Object anotherArg, String yetAnotherArg,
F60: Object andStillAnother) {
F61: ...
...

Sheet 4.コメント
A1: システム名 | I1: =タイトル!I40 -> 学生勤務管理システム | AE1: 工 程 | AL1: =タイトル!I43 -> 開発基準策定 | BI1: 作 成 | BM1: =タイトル!I46 -> 鳥羽 哲也 | BW1: =タイトル!I47 -> 41390 | CF1: 管理記号 | CK1: =タイトル!I50 -> DUA024
A2: サブシステム名 | I2: =タイトル!I41 | AE2: ドキュメント | AL2: =タイトル!I44 -> コーディング基準書 | BI2: 改 訂
AL3: =タイトル!I42 -> Java コーディング基準編
B5: ４． コメント
D7: Java のプログラムでは2種類のコメントを記述することができる。
D8: (1) | F8: インプリメンテーションコメント
F9: コードを読む手助けをするためのコメント。"/*..*/"形式と"//.."形式で記述できる。
D10: (2) | F10: ドキュメンテーションコメント
F11: API ドキュメントを、javadoc コマンドにより自動生成するためのコメント。"/**..*/"形式で記述する。
D12: コメントは何をしているのかではなく、何故そうしているのかを書くこと。
D14: クラスの入った各パッケージには、パッケージコメント(package.html)を作成すること。
E16: <html>
E17: <body>
E18: 所属<br> | V18: ←分類（共通・所属等）
E19: 業務ID J01 組織・定数管理<br> | V19: ←機能IDと機能名
E20: 機能ID J0101 組織改正<br> | V20: ←処理IDと処理名
E21: </body>
E22: </html>
C24: ４．１ クラス
D26: Javadoc 形式コメントを使用する。クラスのコメントには下記の項目を記述する。
D27: ・クラス名
D28: ・クラスの処理概要
D29: ・作者名
D30: ・作成日
E32: 例：
E33: /**
E34: * クラス名 : 日本語クラス名<br>
E35: * <br>
E36: * 処理概要 : クラスの処理概要1行目<br>
E37: * クラスの処理概要2行目<br>
E38: * クラスの処理概要3行目<br>
E39: *
E40: * @author 作者名 作成日(yyyy/mm/dd)
E41: */
E42: public class ．．．
C49: ４．２ フィールド
D51: Javadoc 形式コメントを使用する。public や private に関わらず必ず記述する。
E52: 例：
E53: /**
E54: * フィールドの説明
...

Sheet 5.ステートメント
A1: システム名 | I1: =タイトル!I40 -> 学生勤務管理システム | AE1: 工 程 | AL1: =タイトル!I43 -> 開発基準策定 | BI1: 作 成 | BM1: =タイトル!I46 -> 鳥羽 哲也 | BW1: =タイトル!I47 -> 41390 | CF1: 管理記号 | CK1: =タイトル!I50 -> DUA024
A2: サブシステム名 | I2: =タイトル!I41 | AE2: ドキュメント | AL2: =タイトル!I44 -> コーディング基準書 | BI2: 改 訂
AL3: =タイトル!I42 -> Java コーディング基準編
B5: ５． ステートメント
C7: ５．１ 単一の文
D9: 1つの行には、1つの文だけを書く
E10: 良い例：
E11: i++;
E12: j++;
E13: 悪い例：
E14: i++; j++;
C16: ５．２ 複合文
D18: 複合文とは中括弧で囲まれた複数の文を含む文のことである。
D19: 複合文は下記に従って記述すること。
D20: ・"{" は、その複合文を開始する最初の行に書き、"{"の後ろで改行する。
D21: ・複合文の中にあるすべての文は、その複合文の1つ上のレベルにインデントする。
D22: ・"}"は新しい行に書き、複合文の開始行と同じレベルでインデントする。
D23: ・制御文中にステートメントが1つしかない場合も中括弧を用いて囲む。
E24: 理由：
E25: 括弧の付け忘れなどによるバグを起こすことなく新しい文を追加することができる。
E26: 良い例：
E27: if (condition) {
E28: i++;
E29: }
E30: 悪い例：
E31: if (condition) i++;
C33: ５．３ return 文
D35: return文の返り値には、小括弧を使用しない。
E36: 良い例：
E37: return true;
E38: 悪い例：
E39: return(true);
C49: ５．４ if-else 文
D51: if-else 文は、以下の形式に従って記述する。
E53: if (条件) {
E54: 文;
E55: }
E57: if (条件) {
E58: 文;
E59: } else {
...

Sheet 6.コーディング規約
A1: システム名 | I1: =タイトル!I40 -> 学生勤務管理システム | AE1: 工 程 | AL1: =タイトル!I43 -> 開発基準策定 | BI1: 作 成 | BM1: =タイトル!I46 -> 鳥羽 哲也 | BW1: =タイトル!I47 -> 41390 | CF1: 管理記号 | CK1: =タイトル!I50 -> DUA024
A2: サブシステム名 | I2: =タイトル!I41 | AE2: ドキュメント | AL2: =タイトル!I44 -> コーディング基準書 | BI2: 改 訂
AL3: =タイトル!I42 -> Java コーディング基準編
B5: ６． コーディング規約
C7: ６．１ 宣言
D9: (1) | F9: 変数の宣言
F10: ①1行につき１つの宣言だけを記述する。
G11: 良い例：
G12: int level;
G13: int size;
G14: 悪い例：
G15: int level, size;
F17: ②変数の初期化は宣言したときに行う。
G18: 理由：
G19: 初期化に関するバグを最小化する。
F20: ③ローカル変数は、使用する直前で宣言する。
G21: 理由：
G22: ローカル変数のスコープを明確にし、可読性を向上させるため。
G23: 良い例：
G24: void myMethod() {
G25: int int1 = 10;
G26: sampleMethod(int1);
G27: ...
G29: int int2 = 20;
G30: sampleMethod(int2);
G31: ...
G32: }
G33: 悪い例：
... G42: }
F49: ④for 文の中で使用するカウンタについては、小括弧内で宣言する。
G50: 例：
G51: for (int i = 0; i < length; i++) {
G52: ...
G53: }
D55: (2) | F55: 配列の宣言
F56: 配列の宣言には Type[] arrayName を使用する。
G57: 良い例：
G58: String[] arg;
G59: 悪い例：
G60: String arg[];
...

Sheet 7.その他
A1: システム名 | I1: =タイトル!I40 -> 学生勤務管理システム | AE1: 工 程 | AL1: =タイトル!I43 -> 開発基準策定 | BI1: 作 成 | BM1: =タイトル!I46 -> 鳥羽 哲也 | BW1: =タイトル!I47 -> 41390 | CF1: 管理記号 | CK1: =タイトル!I50 -> DUA024
A2: サブシステム名 | I2: =タイトル!I41 | AE2: ドキュメント | AL2: =タイトル!I44 -> コーディング基準書 | BI2: 改 訂
AL3: =タイトル!I42 -> Java コーディング基準編
B5: ７． その他
C7: ７．１ ソースコードレベルでの注意点
D9: ・static 変数は使用しない。（static final は除く）
E10: 理由：
E11: どのオブジェクトがどのタイミングで値を変更しているかが特定できなくなる。
D12: ・static メソッドはユーティリティメソッドのみとする。
D13: ・if for while 等のネストは３階層までとする。
E14: 理由：
E15: 階層が深くなると、処理の流れが把握しにくくなり、バグ発生の原因となる。
D16: ・抽象クラスはなるべく使用せず、インターフェースを多用すること。
E17: 理由：
E18: インターフェースは複数 implements できるが、クラスの extends は1つ。後の拡張性を考慮。
D19: ・オブジェクトの参照にはインターフェースを利用すること。
E20: オブジェクトを参照する際は、そのオブジェクトの実装クラスを用いて宣言できるが、実装クラスに適切なインターフェースが存在している場合は、必ずインターフェースを用いて宣言する。
D21: ・推奨されない API を使用しない。
D22: ・クラス、メソッド、変数、定数等の宣言は適切なアクセス権限で行う。
D23: ・スーパークラスのインスタンス変数をサブクラスでオーバーライドしない。
D24: ・引数のタイプによるメソッドのオーバーロードは避ける。
D25: ・スーパークラスで private 宣言されているメソッドと同じ名前のメソッドをサブクラスで定義しない。
D26: ・メンバ変数とメソッドの引数が同名となる場合は、メンバ変数に明示的に "this." を付加する。
D27: ・複数の変数に同じ値を代入しようとして、これを1つの文で書いてはいけない。
E28: 例：
E29: a = b = c + d;
D30: ・Object 型の変数を使用しない。Listなども Object 型のまま使用せず、総称型の定義を行ってから使用する。
E31: 理由：
E32: Object 型は全てのクラスの親クラスとなるため、何でも入れられてしまう便利さとは逆に、何が入っているか分からなくなる。
D33: ・finallyブロックを活用し、リソースのクローズ処理等を確実に行うようにする。
E34: 理由：
E35: リソースリークするため。
D36: ・(割り込み処理で使用する)ステート変数は volatile 修飾子を使用する。
C38: ７．２ パフォーマンスを考慮したコーディング
D40: 稼動パフォーマンスを考え、以下の点に注意する。ただし、読みやすさ、保守のしやすさを優先する。
D41: ・繰り返し処理の中でのオブジェクト生成は最小限にする。
D42: ・繰り返し処理の内部で try ブロックは使用しない。
D43: ・ブロック途中で明らかに使用を終えた変数には明示的に null を代入する
D44: ・空メソッドや不要コードを除去する。
D45: ・なるべく、Vector や ArrayList よりも配列を使用する。
...
