Workbook
Name _Toc94971774: '①ＴＡ・②ＳＡ(年度初め)'!#REF!
Name _Toc94971774: '①ＴＡ・②ＳＡ(年度途中)'!#REF!
Name _Toc94971774: ③ＲＡ・ＲＳ!#REF!
Name _Toc94971774: ④ＬＡ!#REF!
Name _Toc94971774: ⑤チューター!#REF!
Name _Toc94971774: ⑥学生アルバイト!#REF!
Name _Toc94971774: その他業務!#REF!
Name _Toc94971775: '①ＴＡ・②ＳＡ(年度初め)'!#REF!
Name _Toc94971775: '①ＴＡ・②ＳＡ(年度途中)'!#REF!
Name _Toc94971775: ③ＲＡ・ＲＳ!#REF!
Name _Toc94971775: ④ＬＡ!#REF!
Name _Toc94971775: ⑤チューター!#REF!
Name _Toc94971775: ⑥学生アルバイト!#REF!
Name _Toc94971775: その他業務!#REF!

Sheet タイトル
G21: =I50 -> 学生勤務管理システム
G24: =I54 -> 業務フロー
G27: =I51
G30: =I61 -> 【 Ver 1.20 】
J37: =TEXT(I57,"yyyy年")&IF(LEFT(TEXT(I57,"mm"),1)="0"," ","")&TEXT(I57,"m月")&IF(LEFT(TEXT(I57,"dd"),1)="0"," ","")&TEXT(I57,"d日")&"作成" -> 2023年 9月 6日作成
J39: =IF(I59=" ※ページ毎に個別入力"," 年 月 日改訂",TEXT(I59,"yyyy年")&IF(LEFT(TEXT(I59,"mm"),1)="0"," ","")&TEXT(I59,"m月")&IF(LEFT(TEXT(I59,"dd"),1)="0"," ","")&TEXT(I59,"d日")&"改訂") -> 2024年 3月12日改訂
B48: 見出し部タイトル制御テーブル
B49: タイトル項目 | I49: タイトル項目埋め込み内容
B50: ①システム名 | I50: 学生勤務管理システム
B51: ②サブシステム名
B52: ③分類名
B53: ④作業工程名 | I53: 要件定義
B54: ⑤ドキュメント代表名 | I54: 業務フロー
B55: ⑥ドキュメント詳細名 | I55: ※ページ毎に個別入力
B56: ⑦作成者 | I56: ＫＳＳ
B57: ⑧作成日 | I57: 45175
B58: ⑦改訂者 | I58: ＫＳＳ
B59: ⑧改訂日 | I59: 45363
B60: ⑨管理記号 | I60: DUB020
B61: ⑩Ｖｅｒ | I61: ="【 Ver " & TEXT(MAX(改訂履歴!E5:E1001),"0.00") & " 】" -> 【 Ver 1.20 】
B63: （注1） ①～⑤は、埋め込み内容の先頭１文字は空白にする。
B65: （注2） ⑦と⑧でシート毎に異なる場合は、各シートの該当項目に直接、作成者、作成日を入力する。
B67: (注3） 文字はタイトル部：ＭＳゴシック、本文部：ＭＳ明朝で統一
B69: （注4） 管理番号は、ドキュメント体系の管理番号を使用する。
B71: （注5） ドキュメントＩＤの付け方
C73: 管理記号-分類区分（任意に設定）
C75: ※管理記号は、別紙 プロジェクト計画書のドキュメント体系を参照

Sheet 改訂履歴
A1: 改訂履歴 | G1: =タイトル!I52
A3: No | E3: Ver | J3: 新規／改訂日 | R3: 区分 | AH3: 改訂理由 | BR3: 新規／改訂者
W4: 項番
A5: 1 | E5: 1 | J5: =タイトル!I57 -> 45175 | R5: 新規 | AH5: 新規作成 | BR5: 木田 優
A6: 2 | E6: 1.1 | J6: 45190 | R6: 変更 | W6: ①ＴＡ・②ＳＡ(年度初め) | AH6: ・雇用マスタの取込一覧の情報をRFP2.3.2.(1)と合わせる。 ・事務室が承認する前に勤務データ仮集計と勤務アラートリストの出力を行う。 ・差戻の場合に学生ではなく、差し戻す先を指定できるように変更。 | BR6: 木田 優
A7: 3 | J7: 45190 | R7: 変更 | W7: ①ＴＡ・②ＳＡ(年度初め) | AH7: ・事務室が承認する前に勤務データ仮集計と勤務アラートリストの出力を行う。 | BR7: 木田 優
A8: 4 | J8: 45190 | R8: 変更 | W8: ③RA | AH8: ・事務室が承認する前に勤務データ仮集計と勤務アラートリストの出力を行う。 | BR8: 木田 優
A9: 5 | J9: 45190 | R9: 変更 | W9: その他業務 | AH9: ・代理入力したときに学生に代理入力済みメールを送信する。 ・支給日マスタ連携後に支払給与月マスタの支払給与日と締め処理予定日をメンテナンスするように変更。 | BR9: 木田 優
A10: 6 | E10: 1.2 | J10: 45363 | R10: 変更 | W10: 全般 | AH10: 2024/3/12時点の運用想定に基づき、フローを修正 | BR10: 木田 優

Sheet ①ＴＡ・②ＳＡ(年度初め)
A1: システム名 | I1: =タイトル!I50 -> 学生勤務管理システム | AE1: 工 程 | AL1: =タイトル!I53 -> 要件定義 | BI1: 作 成 | BM1: =タイトル!I56 -> ＫＳＳ | BW1: =タイトル!I57 -> 45175 | CF1: 管理記号 | CK1: =タイトル!I60 -> DUB020
A2: サブシステム名 | I2: =タイトル!I51 | AE2: ドキュメント | AL2: =タイトル!I54 -> 業務フロー | BI2: 改 訂 | BM2: ＫＳＳ | BW2: 45363
I3: =" "&(RIGHT(CELL("filename",I3),LEN(CELL("filename",I3))-FIND("]",CELL("filename",I3)))) -> ①ＴＡ・②ＳＡ(年度初め) | AL3: =タイトル!I52
A4: 業務 | Y4: 雇用情報・雇用者登録
A5: 時期 | F5: 業務名 | Y5: 入出力情報 | AQ5: 機能名 | BI5: 機能
A7: 3月下旬 | F7: 雇用の募集を行う。
B8: ～
A9: 4月 | G9: 学部事務室
H10: ＴＡ・ＳＡの募集 | AA10: ＴＡ・ＳＡの募集リスト | BJ10: ＴＡ：ティーチング・アシスタント
BJ11: ＳＡ：スチューデント・アシスタント
G14: 教員・事務長等
H15: ＴＡ・ＳＡの申請 | AA15: ＴＡ・ＳＡの申請届
F17: 申請届から雇用リストを作成し、
F18: 雇用情報を一括取込する。
G19: 学部事務室
H20: ＴＡ・ＳＡの申請受付 | AA20: 任用学生リスト
H21: 候補者名簿の作成
BJ22: 雇用リストより作成された雇用データを取込み、学生勤務管理ＤＢに登録する。
G23: 京田辺校地教務課 | BJ23: ＜取込データ＞
H24: 候補者名簿から任用学生リスト作成 | BK24: 項目名 | BV24: 補足説明
H25: 候補者名簿から複数身分ＩＤリスト作成 | AA25: 複数身分ＩＤリスト | BK25: 雇用情報通番
BK26: 雇用年度
BK27: 社員番号 | BV27: 利用者の場合は学生ID
BK28: 職種
G29: 給与厚生課 | AR29: CZ-010-04G | BK29: 雇用部課所属コード
H30: 雇用情報取込 | AA30: 雇用リスト | AS30: 雇用情報取込 | BK30: 予算区分
AA31: （ＴＡ・ＳＡの申請より） | BK31: 科目コード
BK32: クラスコード
BK33: 担当教員
BK34: 雇用開始日
BK35: 雇用終了日
BK36: 業務コード
BK37: 予算コード
BK38: 配分先コード
BK39: 業務内容等
F40: 人事給与システムに取り込むための | BK40: 複数身分ＩＤ
F41: 複数身分ＩＤデータと | BK41: 個別単価
F42: 給与単価リストを出力する。
H43: 複数身分ＩＤデータの出力 | Z43: CZ-010-03C | AR43: CZ-010-01G | BJ43: 雇用情報を出力する | CT43: RFP 2.3.2(4)
H44: 給与単価リストの出力 | AA44: 複数身分ＩＤデータ | AS44: 雇用情報一覧 | BJ44: ＜帳票項目＞ | CT44: 雇用情報の社員番号、複数身分ID、雇用開始日、雇用終了日等を人事給与システム取込用ファイル（複数身分登録および複数身分単価登録）として出力できること。取込用レイアウトは別紙03,04参照。 また、出力時には複数身分IDに応じた所属コード、職級、給与単価等も併せて出力できること。（所属コード、職級、給与単価のマスタは2.2.1.(13)(14)(15)で登録したものを参照する。）
...

Sheet ①ＴＡ・②ＳＡ(年度途中)
A1: システム名 | I1: =タイトル!I50 -> 学生勤務管理システム | AE1: 工 程 | AL1: =タイトル!I53 -> 要件定義 | BI1: 作 成 | BM1: =タイトル!I56 -> ＫＳＳ | BW1: =タイトル!I57 -> 45175 | CF1: 管理記号 | CK1: =タイトル!I60 -> DUB020
A2: サブシステム名 | I2: =タイトル!I51 | AE2: ドキュメント | AL2: =タイトル!I54 -> 業務フロー | BI2: 改 訂 | BM2: ＫＳＳ | BW2: 45363
I3: =" "&(RIGHT(CELL("filename",I3),LEN(CELL("filename",I3))-FIND("]",CELL("filename",I3)))) -> ①ＴＡ・②ＳＡ(年度途中) | AL3: =タイトル!I52
A4: 業務 | Y4: 雇用情報・雇用者登録
A5: 時期 | F5: 業務名 | Y5: 入出力情報 | AQ5: 機能名 | BI5: 機能
A7: 9月下旬 | F7: 雇用の募集を行う。 | BJ7: ※①ＴＡ・②ＳＡ（年度初め）と同様のため、省略し、差異の箇所だけ抜粋。
B8: ～
A9: 10月 | G9: 学部事務室
H10: ＴＡ・ＳＡの募集 | AA10: ＴＡ・ＳＡの募集リスト
G14: 教員・事務長等
H15: ＴＡ・ＳＡの申請 | AA15: ＴＡ・ＳＡの申請届
F17: 申請届から雇用リストを作成し、
F18: 雇用情報を一括取込する。
G19: 学部事務室
H20: ＴＡ・ＳＡの申請受付 | AA20: 任用学生リスト
H21: 候補者名簿の作成
G23: 京田辺校地教務課
H24: 候補者名簿から任用学生リスト作成
H25: 候補者名簿から複数身分ＩＤリスト作成 | AA25: 複数身分ＩＤリスト
G29: 給与厚生課 | AR29: CZ-010-04G
H30: 雇用情報取込 | AA30: 雇用リスト | AS30: 雇用情報取込
AA31: （ＴＡ・ＳＡの申請より）
H33: 雇用情報新規作成 | AR33: CZ-010-02G | BJ33: ※件数が少ない場合は、雇用情報取込機能を使用せず、雇用情報新規登録
AS34: 雇用情報編集 | BK34: 画面を使用して、登録するケースもある。
F37: 人事給与システムに取り込むための
F38: 複数身分ＩＤデータと
F39: 給与単価リストを出力する。
H40: 複数身分ＩＤデータの出力 | Z40: CZ-010-03C | AR40: CZ-010-01G
H41: 給与単価リストの出力 | AA41: 複数身分ＩＤデータ | AS41: 雇用情報一覧
AA42: （職種別） | AT42: 雇用情報ＣＳＶ出力
Z44: CZ-010-03C
AA45: 給与単価リスト
A49: 業務 | Y49: 勤務時間の登録、承認
A51: 随時
F52: 勤務時間の入力と承認申請を行う。
G53: 学生 | AR53: GA-010-01G
H54: 勤務情報の登録 | AA54: 勤務情報 | AS54: 勤務入力
AA55: （雇用情報・勤務時間）
AU56: 承認申請
F57: 勤務時間の申請に対して、承認/差戻を
...

Sheet ③ＲＡ・ＲＳ
A1: システム名 | I1: =タイトル!I50 -> 学生勤務管理システム | AE1: 工 程 | AL1: =タイトル!I53 -> 要件定義 | BI1: 作 成 | BM1: =タイトル!I56 -> ＫＳＳ | BW1: =タイトル!I57 -> 45175 | CF1: 管理記号 | CK1: =タイトル!I60 -> DUB020
A2: サブシステム名 | I2: =タイトル!I51 | AE2: ドキュメント | AL2: =タイトル!I54 -> 業務フロー | BI2: 改 訂 | BM2: ＫＳＳ | BW2: 45363
I3: =" "&(RIGHT(CELL("filename",I3),LEN(CELL("filename",I3))-FIND("]",CELL("filename",I3)))) -> ③ＲＡ・ＲＳ | AL3: =タイトル!I52
A4: 業務 | Y4: 雇用情報・雇用者登録
A5: 時期 | F5: 業務名 | Y5: 入出力情報 | AQ5: 機能名 | BI5: 機能
A7: 3月下旬 | F7: 雇用の募集を行う。 | BJ7: ※①ＴＡ・②ＳＡ（年度初め）と同様のため、省略し、差異の箇所だけ抜粋。
B8: ～
A9: 4月 | G9: 学部事務室・予算管理部課
H10: ＲＡ・ＲＳの募集 | AA10: ＲＡ・ＲＳの募集リスト | BJ10: ＲＡ：リサーチ・アシスタント
G11: ※外部資金で雇用する場合は | BJ11: ＲＳ：研究活動等支援員
H12: 研究企画課が募集
G14: 教員・事務長等
H15: ＲＡの申請 | AA15: ＲＡ・ＲＳの申請届
F17: 申請届から雇用リストを作成し、
F18: 雇用情報を一括取込する。
G19: 学部事務室・予算管理部課
H20: ＲＡ・ＲＳの申請受付 | AA20: 任用学生リスト
G21: ※外部資金で雇用する場合は
H22: 研究企画課が申請受付
G24: 研究企画課
H25: 候補者名簿の作成 | AA25: 複数身分ＩＤリスト
H26: 候補者名簿から任用学生リスト作成
H27: 候補者名簿から複数身分ＩＤリスト作成
G29: 給与厚生課 | AR29: CZ-010-04G
H30: 雇用情報取込 | AA30: 雇用リスト | AS30: 雇用情報取込
AA31: （ＲＡ・ＲＳの申請より）
F33: 人事給与システムに取り込むための
F34: 複数身分ＩＤデータと
F35: 給与単価リストを出力する。
H36: 複数身分ＩＤデータの出力 | Z36: CZ-010-03C | AR36: CZ-010-01G
H37: 給与単価リストの出力 | AA37: 複数身分ＩＤデータ | AS37: 雇用情報一覧
AA38: （職種別） | AT38: 雇用情報ＣＳＶ出力
Z40: CZ-010-03C
AA41: 給与単価リスト
A45: 業務 | Y45: 勤務時間の登録、承認
A47: 随時
F48: 勤務時間の入力と承認申請を行う。
G49: 学生 | AR49: GA-010-01G
H50: 勤務情報の登録 | AA50: 勤務情報 | AS50: 勤務入力
AA51: （雇用情報・勤務時間）
...

Sheet ④ＬＡ
A1: システム名 | I1: =タイトル!I50 -> 学生勤務管理システム | AE1: 工 程 | AL1: =タイトル!I53 -> 要件定義 | BI1: 作 成 | BM1: =タイトル!I56 -> ＫＳＳ | BW1: =タイトル!I57 -> 45175 | CF1: 管理記号 | CK1: =タイトル!I60 -> DUB020
A2: サブシステム名 | I2: =タイトル!I51 | AE2: ドキュメント | AL2: =タイトル!I54 -> 業務フロー | BI2: 改 訂 | BM2: ＫＳＳ | BW2: 45363
I3: =" "&(RIGHT(CELL("filename",I3),LEN(CELL("filename",I3))-FIND("]",CELL("filename",I3)))) -> ④ＬＡ | AL3: =タイトル!I52
A4: 業務 | Y4: 雇用情報・雇用者登録
A5: 時期 | F5: 業務名 | Y5: 入出力情報 | AQ5: 機能名 | BI5: 機能
A7: 3月下旬 | F7: 雇用の募集を行う。 | BJ7: ※①ＴＡ・②ＳＡ（年度初め）と同様のため、省略し、差異の箇所だけ抜粋。
B8: ～
A9: 4月 | G9: 学習支援・教育開発センター
H10: ＬＡの募集 | AA10: ＬＡの募集リスト | BJ10: ＬＡ：ラーニング・アシスタント
G14: 学生
H15: ＬＡの応募 | AA15: ＬＡの応募
G19: 学習支援・教育開発センター
H20: ＬＡの選考 | AA20: ＬＡの選考
F22: 募集リストから雇用リストを作成し、
F23: 雇用情報を一括取込する。
H24: 選考結果から任用学生リスト作成
AA25: 任用学生リスト
G29: 給与厚生課
H30: 任用学生リストから複数身分ＩＤ | AA30: 複数身分ＩＤリスト
H31: リスト作成
H34: 雇用情報取込 | AR34: CZ-010-04G
AA35: 雇用リスト | AS35: 雇用情報取込
AA36: （ＬＡの募集より）
F38: 人事給与システムに取り込むための
F39: 複数身分ＩＤデータと
F40: 給与単価リストを出力する。
H41: 複数身分ＩＤデータの出力 | Z41: CZ-010-03C | AR41: CZ-010-01G
H42: 給与単価リストの出力 | AA42: 複数身分ＩＤデータ | AS42: 雇用情報一覧
AA43: （職種別） | AT43: 雇用情報ＣＳＶ出力
Z45: CZ-010-03C
AA46: 給与単価リスト
A50: 業務 | Y50: 勤務時間の登録、承認
A52: 随時
F53: 勤務時間の入力と承認申請を行う。
G54: 学生 | AR54: GA-010-01G
H55: 勤務情報の登録 | AA55: 勤務情報 | AS55: 勤務入力
AA56: （雇用情報・勤務時間）
AU57: 承認申請
F58: 勤務時間の申請に対して、承認/差戻を
F59: 行う。
...

Sheet ⑤チューター
A1: システム名 | I1: =タイトル!I50 -> 学生勤務管理システム | AE1: 工 程 | AL1: =タイトル!I53 -> 要件定義 | BI1: 作 成 | BM1: =タイトル!I56 -> ＫＳＳ | BW1: =タイトル!I57 -> 45175 | CF1: 管理記号 | CK1: =タイトル!I60 -> DUB020
A2: サブシステム名 | I2: =タイトル!I51 | AE2: ドキュメント | AL2: =タイトル!I54 -> 業務フロー | BI2: 改 訂 | BM2: ＫＳＳ | BW2: 45363
I3: =" "&(RIGHT(CELL("filename",I3),LEN(CELL("filename",I3))-FIND("]",CELL("filename",I3)))) -> ⑤チューター | AL3: =タイトル!I52
A4: 業務 | Y4: 雇用情報・雇用者登録
A5: 時期 | F5: 業務名 | Y5: 入出力情報 | AQ5: 機能名 | BI5: 機能
A7: 3月下旬 | F7: 雇用の募集を行う。 | BJ7: ※①ＴＡ・②ＳＡ（年度初め）と同様のため、省略し、差異の箇所だけ抜粋。
B8: ～
A9: 4月 | G9: 留学生課
H10: チューターの任用 | AA10: チューターの任用
F12: 雇用リストを作成し、
F13: 雇用情報を一括取込する。
H14: 任用学生リスト作成
AA15: 任用学生リスト
G19: 給与厚生課
H20: 任用学生リストから複数身分ＩＤ | AA20: 複数身分ＩＤリスト
H21: リスト作成
H24: 雇用情報取込 | AR24: CZ-010-04G
AA25: 雇用リスト | AS25: 雇用情報取込
F28: 人事給与システムに取り込むための
F29: 複数身分ＩＤデータと
F30: 給与単価リストを出力する。
H31: 複数身分ＩＤデータの出力 | Z31: CZ-010-03C | AR31: CZ-010-01G
H32: 給与単価リストの出力 | AA32: 複数身分ＩＤデータ | AS32: 雇用情報一覧
AA33: （職種別） | AT33: 雇用情報ＣＳＶ出力
Z35: CZ-010-03C
AA36: 給与単価リスト
A40: 業務 | Y40: 勤務時間の登録、承認
A42: 随時
F43: 勤務時間の入力と承認申請を行う。
G44: 学生 | AR44: GA-010-01G
H45: 勤務情報の登録 | AA45: 勤務情報 | AS45: 勤務入力
AA46: （雇用情報・勤務時間）
AU47: 承認申請
F48: 勤務時間の申請に対して、承認/差戻を
F49: 行う。
G50: 担当教員 | AR50: CK-010-01G
H51: 勤務データの承認 | AS51: 勤務データ承認
BD52: 差戻
AU53: 承認
G55: 雇用部課業務担当者 | AR55: CK-010-01G
...

Sheet ⑥学生アルバイト
A1: システム名 | I1: =タイトル!I50 -> 学生勤務管理システム | AE1: 工 程 | AL1: =タイトル!I53 -> 要件定義 | BI1: 作 成 | BM1: =タイトル!I56 -> ＫＳＳ | BW1: =タイトル!I57 -> 45175 | CF1: 管理記号 | CK1: =タイトル!I60 -> DUB020
A2: サブシステム名 | I2: =タイトル!I51 | AE2: ドキュメント | AL2: =タイトル!I54 -> 業務フロー | BI2: 改 訂 | BM2: ＫＳＳ | BW2: 45363
I3: =" "&(RIGHT(CELL("filename",I3),LEN(CELL("filename",I3))-FIND("]",CELL("filename",I3)))) -> ⑥学生アルバイト | AL3: =タイトル!I52
A4: 業務 | Y4: 雇用情報・雇用者登録
A5: 時期 | F5: 業務名 | Y5: 入出力情報 | AQ5: 機能名 | BI5: 機能
A7: 随時 | F7: 雇用の募集を行う。 | BJ7: ※①ＴＡ・②ＳＡ（年度初め）と同様のため、省略し、差異の箇所だけ抜粋。
G9: 雇用事務室
H10: 学生アルバイトの雇用 | AA10: 学生アルバイトの雇用
F12: 雇用リストを作成し、
F13: 雇用情報を一括取込する。
H14: 雇用情報登録 | AR14: CZ-010-02G | BJ14: ※雇用情報取込機能を使用せず、雇用情報新規登録画面を使用する。
H15: （学生を紐づけ登録） | AA15: 雇用リスト | AS15: 雇用情報編集
F18: 人事給与システムに取り込むための
F19: 複数身分ＩＤデータと
F20: 給与単価リストを出力する。
G21: 給与厚生課 | Z21: CZ-010-03C | AR21: CZ-010-01G
H22: 複数身分ＩＤデータの出力 | AA22: 複数身分ＩＤデータ | AS22: 雇用情報一覧
H23: 給与単価リストの出力 | AA23: （職種別） | AT23: 雇用情報ＣＳＶ出力
Z25: CZ-010-03C
AA26: 給与単価リスト
A30: 業務 | Y30: 勤務時間の登録、承認
A32: 随時
F33: 勤務時間の入力と承認申請を行う。
G34: 学生 | AR34: GA-010-01G
H35: 勤務情報の登録 | AA35: 勤務情報 | AS35: 勤務入力
AA36: （雇用情報・勤務時間）
AU37: 承認申請
F38: 勤務時間の申請に対して、承認/差戻を
F39: 行う。
G40: 雇用部課業務担当者 | AR40: CK-010-01G
H41: 勤務データの承認 | AS41: 勤務データ承認
BD42: 差戻
AU43: 承認
G45: 雇用部課事務長 | AR45: CK-010-01G
H46: 勤務データの承認 | AS46: 勤務データ承認
BD47: 差戻
AU48: 承認
A50: 業務 | Y50: 給与計算用データの出力
A52: 月次 | F52: 勤務データを確定し、給与計算用データを
F53: 出力する。
...

Sheet その他業務
A1: システム名 | I1: =タイトル!I50 -> 学生勤務管理システム | AE1: 工 程 | AL1: =タイトル!I53 -> 要件定義 | BI1: 作 成 | BM1: =タイトル!I56 -> ＫＳＳ | BW1: =タイトル!I57 -> 45175 | CF1: 管理記号 | CK1: =タイトル!I60 -> DUB020
A2: サブシステム名 | I2: =タイトル!I51 | AE2: ドキュメント | AL2: =タイトル!I54 -> 業務フロー | BI2: 改 訂 | BM2: ＫＳＳ | BW2: 45363
I3: =" "&(RIGHT(CELL("filename",I3),LEN(CELL("filename",I3))-FIND("]",CELL("filename",I3)))) -> その他業務 | AL3: =タイトル!I52
A4: 業務 | Y4: 勤務記録の代理入力
A5: 時期 | F5: 業務名 | Y5: 入出力情報 | AQ5: 機能名 | BI5: 機能
A7: 必要都度 | F7: 勤務時間の代理入力を行う
G8: 代理入力者 | AR8: GA-010-01G | BJ8: 学生に代わり、勤務記録の代理入力を行う。
H9: 勤務代理入力 | AA9: 勤務情報 | AS9: 勤務代理入力 | BJ9: 代理入力された勤務記録は所定の承認フローで処理する。
AA10: （雇用情報・勤務時間） | BJ10: ※代理入力した学生に対して、代理入力済みメールを送信する。
G13: 承認者 | AR13: CK-010-01G | BJ13: 承認された勤務データは次の承認者へ回付する。
H14: 勤務承認 | AS14: 勤務データ承認
AU16: 承認
G18: 承認者 | AR18: CK-010-01G | BJ18: 差戻された勤務記録は、学生へ差戻する。
H19: 勤務差戻 | AS19: 勤務データ承認
AU21: 差戻
G23: 学生 | AR23: GA-010-01G | BJ23: 勤務記録を修正して、再申請する。
H24: 勤務修正 | AS24: 勤務入力
A27: 業務 | Y27: 勤務記録の代理承認
A29: 必要都度 | F29: 承認者の代理として承認する
G30: 管理者 | AR30: CZ-020-02G
H31: 社員マスタで対象の承認者の | AS31: 社員マスタ編集
H32: 兼任・代理承認を許可する
H35: 兼任・代理承認 | AR35: CK-030-01G | BJ35: 兼任・代理承認したい承認者を選択する
AS36: 兼任・代理承認
H40: 勤務承認 | AR40: CK-010-01G
AS41: 勤務データ承認
AU43: 承認
AR45: 次の承認者へ・・・・
A47: 業務 | Y47: 勤務登録確定督促・勤務承認督促
A49: 必要都度 | F49: 学生へ勤務登録の確定を督促する
G50: 毎月1日に督促バッチを自動実行 | BJ50: 勤務情報が差戻になっている学生へ督促メールを送信する。
AS51: 督促バッチ
AU53: 督促
G55: 学生 | AR55: GA-010-01G | BJ55: 勤務情報を登録確定にする。
H56: 勤務入力 | AS56: 勤務入力
F60: 教員へ勤務承認を督促する
G61: 毎月1日に督促バッチを自動実行 | BJ61: 勤務情報が未承認になっている教員へ督促メールを送信する。
AS62: 督促バッチ
AU64: 督促
G66: 教員又は職員 | AR66: CK-010-01G | BJ66: 勤務情報を承認する。
...
