Workbook
Name AitemDic: #REF!

Sheet タイトル
G11: =I40 -> 学生勤務管理システム
G14: =I44 -> GA-010_勤務入力
G17: =I42
G20: =I51 -> 【 Ver 1.16 】
J27: =TEXT(I47,"yyyy年")&IF(LEFT(TEXT(I47,"mm"),1)="0"," ","")&TEXT(I47,"m月")&IF(LEFT(TEXT(I47,"dd"),1)="0"," ","")&TEXT(I47,"d日")&"作成" -> 2023年10月 2日作成
J29: =IF(I49=" ※ページ毎に個別入力"," 年 月 日改訂",TEXT(I49,"yyyy年")&IF(LEFT(TEXT(I49,"mm"),1)="0"," ","")&TEXT(I49,"m月")&IF(LEFT(TEXT(I49,"dd"),1)="0"," ","")&TEXT(I49,"d日")&"改訂") -> 2025年11月13日改訂
B38: 見出し部タイトル制御テーブル
B39: タイトル項目 | I39: タイトル項目埋め込み内容
B40: ①システム名 | I40: 学生勤務管理システム
B41: ②サブシステム名 | I41: 共通機能
B42: ③分類名
B43: ④作業工程名 | I43: 機能設計
B44: ⑤ドキュメント代表名 | I44: GA-010_勤務入力
B45: ⑥ドキュメント詳細名 | I45: ※ページ毎に個別入力
B46: ⑦作成者 | I46: 木田 優
B47: ⑧作成日 | I47: 45201
B48: ⑦改定者 | I48: ※ページ毎に個別入力
B49: ⑧改定日 | I49: =TEXT(MAX(改訂履歴!J5:J993),"yyyy/mm/dd") -> 2025/11/13
B50: ⑨管理記号 | I50: DUC010
B51: ⑩Ｖｅｒ | I51: ="【 Ver " & TEXT(MAX(改訂履歴!E5:E993),"0.00") & " 】" -> 【 Ver 1.16 】

Sheet 改訂履歴
A1: 改訂履歴
A3: No | E3: Ver | J3: 新規／改訂日 | R3: 区分 | W3: 改訂箇所 | AH3: 改訂理由 | BR3: 新規／改訂者
W4: 頁 | AA4: 機能
A5: 1 | E5: 1 | J5: =タイトル!I47 -> 45201 | R5: 新規 | AH5: 新規作成 | BR5: 木田 優
A6: 2 | E6: 1.01 | J6: 45217 | R6: 変更 | AH6: 学生、教員、担当者、管理者の制限を明文化 雇用情報の表示内容を変更 差戻の勤務情報を表示した時に差戻理由をガイダンス行に表示 補足資料2を追加 | BR6: 木田 優
A7: 3 | J7: 45223 | R7: 変更 | AH7: 勤務入力時のエラーチェックを追記 | BR7: 木田 優
A8: 4 | J8: 45223 | R8: 変更 | AH8: 勤務入力の修正・差戻する時の制御を変更 | BR8: 木田 優
A9: 5 | E9: 1.02 | J9: 45239 | R9: 変更 | AH9: 画面遷移図でカレンダーコントロールを削除 学生の勤務入力で雇用年度外になった雇用情報は選択できないように制御 | BR9: 木田 優
A10: 6 | E10: 1.03 | J10: 45267 | R10: 変更 | AH10: 兼任・代理承認時のイメージを追記 | BR10: 木田 優
A11: 7 | E11: 1.04 | J11: 45303 | R11: 変更 | AA11: 画面遷移図 勤務入力（学生） | AH11: ホーム画面から勤務入力画面に遷移した場合、戻るボタンを非表示に変更 | BR11: 木田 優
A12: 8 | J12: 45303 | R12: 変更 | AA12: 勤務入力（教員・担当者） | AH12: キャンセルボタンの廃止 | BR12: 木田 優
A13: 9 | E13: 1.05 | J13: 45630 | R13: 変更 | AA13: 勤務入力（管理者） | AH13: 勤務入力（管理者）の利用ユーザーに「担当者」を追加 （2024年度改修_項番1） | BR13: 木田 優
A14: 10 | E14: 1.06 | J14: 45642 | R14: 変更 | AA14: 勤務入力（学生） 勤務入力（教員・担当者） | AH14: 給与改定日を過ぎた後に給与改定日前の勤務入力はできないようにする （2024年度改修_項番5） | BR14: 木田 優
A15: 11 | E15: 1.07 | J15: 45642 | R15: 変更 | AA15: 勤務入力（教員・担当者） 勤務入力（管理者・担当者） | AH15: 差戻者を差戻先に文言変更 （2024年度保守） | BR15: 木田 優
A16: 12 | E16: 1.08 | J16: 45701 | R16: 変更 | AA16: 勤務入力（学生） 勤務入力（教員・担当者） | AH16: エラーチェックに年度切替時の登録エラーを追記 | BR16: 木田 優
A17: 13 | E17: 1.09 | J17: 45814 | R17: 変更 | AA17: 勤務入力（学生） 勤務入力（教員・担当者） | AH17: 職種が一般以外の場合、勤務内容を必須項目とするように変更 （2025年度改修_項番1） | BR17: 木田 優
A18: 14 | E18: 1.1 | J18: 45817 | R18: 変更 | AA18: 勤務入力（学生） | AH18: システム日付＜勤務日の場合、エラーを表示する （2025年度改修_項番5） | BR18: 木田 優
A19: 15 | E19: 1.11 | J19: 45818 | R19: 変更 | AA19: 勤務入力（教員・担当者） 勤務入力（管理者・担当者） | AH19: 勤務情報入力日（勤務情報最終更新日）の項目を追加する （2025年度改修_項番6） | BR19: 木田 優
A20: 16 | E20: 1.12 | J20: 45818 | R20: 変更 | AA20: 勤務入力（学生） 勤務入力（教員・担当者） | AH20: RAの場合の雇用情報の表示に雇用部課を追加する 雇用期間外の雇用情報は勤務入力で選択できないようにする （2025年度改修_項番7） | BR20: 木田 優
A21: 17 | E21: 1.13 | J21: 45819 | R21: 変更 | AA21: 勤務入力（学生） 勤務入力（教員・担当者） | AH21: 教員はメール送信有効・無効フラグを追加し、メール通知が許可されている教員のみメール送信する（学生へは常に送信） （2025年度改修_項番11） | BR21: 木田 優
A22: 18 | E22: 1.14 | J22: 45855 | R22: 変更 | AA22: 勤務入力（学生） | AH22: 勤務時間ワーニングメッセージの職種合計の対象職種からSAを除外する ←廃止 （2025年度改修_項番2） | BR22: 木田 優
A23: 19 | E23: 1.15 | J23: 45909 | R23: 変更 | AA23: 勤務入力（教員・担当者） | AH23: 差戻メールについても、メール通知が許可されている教員のみメール送信する（2025年度改修_項番11） | BR23: 木田 優
A24: 20 | E24: 1.16 | J24: 45974 | R24: 変更 | AA24: 勤務入力（教員・担当者） 勤務入力（管理者・担当者） | AH24: 勤務情報入力日のタイトルを勤務情報最終更新日に変更する （2025年度保守_項番51） | BR24: 木田 優

Sheet 機能概要・画面遷移図
A1: システム名 | I1: =タイトル!I40 -> 学生勤務管理システム | AE1: 工 程 | AL1: =タイトル!I43 -> 機能設計 | BI1: 作 成 | BM1: =タイトル!I46 -> 木田 優 | BW1: =タイトル!I47 -> 45201 | CF1: 管理記号 | CK1: =タイトル!I50 -> DUC010
A2: サブシステム名 | I2: =タイトル!I41 -> 共通機能 | AE2: ドキュメント | AL2: =タイトル!I44 -> GA-010_勤務入力 | BI2: 改 訂 | BM2: 木田 優 | BW2: 45239
A4: 機能名称 | I4: =" " & RIGHT(タイトル!I44,LEN(タイトル!I44)-8) -> 勤務入力 | AL4: 機能ＩＤ | AS4: =LEFT(タイトル!I44,7) -> GA-010 | BI4: 利用想定ユーザー | BT4: 全ユーザー
A5: 機 能 概 要
B7: 学生が勤務時間を登録する時に使用する。
B8: ※次ページに教員、担当者が代理入力する場合の画面遷移図を記載。
A10: 画 面 遷 移 図
C13: ○ホーム画面 | AZ13: ○勤務入力画面
D14: （CC-020-01G） | BA14: （GA-010-01G）
V15: 勤務入力ボタン
BT16: 登録確定ボタン
BU17: 次の承認者が教員の場合、メールを送信
AD31: ○勤務情報一覧画面
AE32: （GA-010-02G）
S33: 勤務情報一覧ボタン | AW33: 選択ボタン
BM36: 戻るボタン
BM37: 勤務情報一覧画面から遷移した場合
A48: 機 能 概 要
B50: 教員、担当者が勤務時間を代理登録する時に使用する。
A53: 画 面 遷 移 図
C56: ○ホーム画面 | BB56: ○勤務入力画面
D57: （CC-020-01G） | BC57: （GA-010-01G）
V58: 勤務代理入力ボタン
BV59: 代理入力ボタン
BW60: 次の承認者が教員の場合、メールを送信
AD74: ○勤務データ承認画面
AE75: （CK-010-01G）
S76: 勤務データ承認ボタン | AW76: 選択ボタン
BM79: 戻るボタン
BM80: 勤務データ承認画面から遷移した場合
AX83: 登録（修正・差戻）ボタン
AY84: 修正時は学生へメールを送信
AY85: 差戻時は差戻者が学生又は教員の場合、
AZ86: メールを送信
A91: 機 能 概 要
B93: 管理者が勤務時間を照会する時に使用する。
A96: 画 面 遷 移 図
C99: ○ホーム画面 | BB99: ○勤務入力画面
D100: （CC-020-01G） | BC100: （GA-010-01G）
AD117: ○勤務データ照会画面
...

Sheet 勤務入力（学生）
A1: システム名 | I1: =タイトル!I40 -> 学生勤務管理システム | AE1: 工 程 | AL1: 機能設計 | BI1: 作 成 | BM1: =タイトル!I46 -> 木田 優 | BW1: =タイトル!I47 -> 45201 | CF1: 管理記号 | CK1: =タイトル!I50 -> DUC010
A2: サブシステム名 | I2: 共通機能 | AE2: ドキュメント | AL2: =タイトル!I44 -> GA-010_勤務入力 | BI2: 改 訂 | BM2: 木田 優 | BW2: 45855
A4: 画面名称 | I4: =" " & RIGHT(CELL("filename",A1),LEN(CELL("filename",A1))-FIND("]",CELL("filename",A1))) -> 勤務入力（学生） | AL4: 画面ＩＤ | AS4: GA-010-01G | BI4: 利用想定ユーザー | BT4: 学生
A5: 画面レイアウト | BI5: 機能概要
BJ7: ・ | BK7: 勤務時間を登録する時に使用する画面。
BJ8: ・ | BK8: 勤務時間の登録確定（承認申請）、削除をすることが可能。
BI12: 画面説明 （処理内容・アクション等）
BJ14: ・ | BK14: 勤務日のカレンダーを押下すると、カレンダーを表示する。
BJ16: ・ | BK16: 登録確定ボタンを押下すると、バリデーション、エラーチェックを行い、
BK17: 表示されている内容を登録し、承認申請を行う。
BK18: ※次の承認者が教員の場合、教員へ承認依頼メールを送信する。
BL19: ただし、メール通知が許可されている教員のみ | CT19: 2025年度改修_項番11
BJ21: ・ | BK21: 削除ボタンを押下すると、削除の確認ダイアログを表示する。
BJ23: ・ | BK23: ホーム画面から勤務入力を表示した場合は、戻るボタンは非表示
BJ25: ・ | BK25: 勤務情報一覧画面から勤務入力を表示した場合は、戻るボタンは表示
A37: リストボックス
A38: 項目名 | K38: 内容 | AW38: 並び順 | BI38: 権限による画面制御
A39: 雇用情報 | K39: 職種+曜日講時+科目+クラスコード+主担当教員（姓） [LA]職種+雇用部課名 [一般]職種+雇用部課名+業務内容等 | AW39: 昇順
BJ40: ユーザ区分が学生の場合は、学生勤務入力用画面として表示
A41: 開始時刻（時） | K41: 5～22 | AW41: 昇順 | BJ41: ユーザ区分が教員、担当者の場合は、勤務代理入力用画面として表示する。
A42: 開始時刻（分） | K42: 00～59 | AW42: 昇順 | BK42: ※勤務入力（教員・担当者）参照
A43: 終了時刻（時） | K43: 5～22 | AW43: 昇順 | BI43: 一覧の並び順
A44: 終了時刻（分） | K44: 00～59 | AW44: 昇順
A45: 控除時間（時） | K45: 0～6 | AW45: 昇順
A46: 控除時間（分） | K46: 00～59 | AW46: 昇順
A47: 校地移動 | K47: しない・する | AW47: 昇順
A48: 画 面 補 足 説 明
B50: 〇勤務入力を新規登録する場合 | AW50: ○出力項目
C51: 【新規登録画面】 | AW51: 項目名 | BF51: 編集内容等
AW52: 支給日 | BF52: 勤務日から支給対象となる給与支給日を表示 yyyy/m/d
AW53: ステータス
AW55: ○入力項目
AW56: 項目名 | BK56: 入力必須 | BP56: 桁数 | BS56: 入力制限等
AW57: 勤務日 | BK57: 〇 | BP57: - | BS57: 西暦日付 yyyy/m/d
AW58: 雇用情報 | BK58: 〇 | BP58: - | BS58: リストボックス 雇用年度の範囲外又は雇用期間外の雇用情報は表示しない 職種毎に表示する情報が変動します 詳細は※1参照
CT60: 2025年度改修_項番7
AW62: 開始時刻（時） | BK62: 〇 | BP62: - | BS62: リストボックス
AW63: 開始時刻（分） | BK63: 〇 | BP63: - | BS63: リストボックス
AW64: 終了時刻（時） | BK64: 〇 | BP64: - | BS64: リストボックス
AW65: 終了時刻（分） | BK65: 〇 | BP65: - | BS65: リストボックス
...

Sheet 勤務入力（教員・担当者）
A1: システム名 | I1: =タイトル!I40 -> 学生勤務管理システム | AE1: 工 程 | AL1: 機能設計 | BI1: 作 成 | BM1: =タイトル!I46 -> 木田 優 | BW1: =タイトル!I47 -> 45201 | CF1: 管理記号 | CK1: =タイトル!I50 -> DUC010
A2: サブシステム名 | I2: 共通機能 | AE2: ドキュメント | AL2: =タイトル!I44 -> GA-010_勤務入力 | BI2: 改 訂 | BM2: 木田 優 | BW2: 45819
A4: 画面名称 | I4: =" " & RIGHT(CELL("filename",A1),LEN(CELL("filename",A1))-FIND("]",CELL("filename",A1))) -> 勤務入力（教員・担当者） | AL4: 画面ＩＤ | AS4: GA-010-01G | BI4: 利用想定ユーザー | BT4: 教員、担当者
A5: 画面レイアウト | BI5: 機能概要
AD7: 代理入力 | BJ7: ・ | BK7: 勤務データの承認や修正、差戻をする時に使用する画面。
BJ8: ・ | BK8: 学生の勤務時間の代理入力が可能。
BI12: 画面説明 （処理内容・アクション等）
BJ13: ・ | BK13: 代理入力する場合は勤務日以下の情報は全て入力可能だが、勤務データを
BK14: 編集する場合は、勤務日、雇用情報、学生ＩＤ/氏名は変更不可。
BK15: ※学生、雇用情報は承認ルートに影響を及ぼすため、変更不可の項目を
BK16: 変更したい場合は、学生に差し戻して、学生で修正を行う。
BJ18: 〇代理入力画面の場合
BJ19: ・ | BK19: 勤務日のカレンダーを押下すると、カレンダーを表示する
BJ20: ・ | BK20: 学生ID/氏名が入力されると学生が雇用されている雇用情報を
BK21: リストボックスに表示する。
BJ22: ・ | BK22: 代理入力ボタンを押下すると、バリデーション、エラーチェックを行い、
BK23: 表示されている内容を登録する。
BK24: ※次の承認者が教員の場合、教員へ承認依頼メールを送信する。
BL25: ただし、メール通知が許可されている教員のみ | CT25: 2025年度改修_項番11
BJ26: 〇勤務編集画面の場合
BJ27: ・ | BK27: 承認ボタンを押下すると、表示されている内容を登録し、次の承認者へ
BK28: 承認申請を行う。
BJ29: ・ | BK29: 修正ボタンを押下すると、入力可能項目を活性化し、登録ボタンを
BK30: 表示する。登録ボタンを押下すると、バリデーション、エラーチェックを
BK31: 行い、表示されている内容を登録する。
BK32: 「修正しました」とガイダンス行に表示する。
BK33: ※学生へ勤務修正メールを送信する。
BJ34: ・ | BK34: 差戻ボタンを押下すると、入力可能項目を活性化し、登録ボタンを
BK35: 表示する。
A36: リストボックス | BK36: 差戻先が未指定の場合はエラーメッセージを表示する。
A37: 項目名 | K37: 内容 | AW37: 並び順 | BK37: ※差戻先が学生又は教員の場合、勤務差戻メールを送信する。
A38: 雇用情報 | K38: 職種+曜日講時+科目+クラスコード+主担当教員（姓） [LA]職種+雇用部課名 [一般]職種+雇用部課名+業務内容等 | AW38: 昇順 | BL38: ただし、メール通知が許可されている教員のみ | CT38: 2025年度改修_項番11
BI39: 権限による画面制御
A40: 開始時刻（時） | K40: 5～22 | AW40: 昇順
A41: 開始時刻（分） | K41: 00～59 | AW41: 昇順 | BJ41: ユーザ区分が教員、担当者の場合に勤務承認・修正・差戻画面として表示
A42: 終了時刻（時） | K42: 5～22 | AW42: 昇順 | BJ42: ※メニューの勤務代理入力から遷移した場合は代理入力画面として表示する。
A43: 終了時刻（分） | K43: 00～59 | AW43: 昇順
A44: 控除時間（時） | K44: 0～6 | AW44: 昇順 | BI44: 一覧の並び順
A45: 控除時間（分） | K45: 00～59 | AW45: 昇順
A46: 校地移動 | K46: しない | する | AW46: 昇順
...

Sheet 勤務入力（管理者・担当者）
A1: システム名 | I1: =タイトル!I40 -> 学生勤務管理システム | AE1: 工 程 | AL1: 機能設計 | BI1: 作 成 | BM1: =タイトル!I46 -> 木田 優 | BW1: =タイトル!I47 -> 45201 | CF1: 管理記号 | CK1: =タイトル!I50 -> DUC010
A2: サブシステム名 | I2: 共通機能 | AE2: ドキュメント | AL2: =タイトル!I44 -> GA-010_勤務入力 | BI2: 改 訂 | BM2: 木田 優 | BW2: 45818
A4: 画面名称 | I4: =" " & RIGHT(CELL("filename",A1),LEN(CELL("filename",A1))-FIND("]",CELL("filename",A1))) -> 勤務入力（管理者・担当者） | AL4: 画面ＩＤ | AS4: GA-010-01G | BI4: 利用想定ユーザー | BT4: 管理者、担当者
A5: 画面レイアウト | BI5: 機能概要
BJ7: ・ | BK7: 管理者が勤務データを照会する時に使用する。
BK8: ※担当者も照会する時に使用する。
BI12: 画面説明 （処理内容・アクション等）
BJ14: ○出力項目
BJ15: 項目名 | BS15: 編集内容等
BJ16: 支給日 | BS16: 給与支給日
BJ17: ステータス | BS17: 承認待ち | 再承認待ち | 承認済み | 差戻
BJ19: 勤務日 | BS19: yyyy/m/d
BJ20: 学生ID/氏名
BJ21: 雇用情報
BJ22: 開始時刻 | BS22: hh : mm
BJ23: 終了時刻 | BS23: hh : mm
BJ24: 控除時間 | BS24: hh : mm
BJ25: 校地移動
BJ26: 修正/差戻理由
BJ27: 差戻先 | BS27: ステータスが差戻の場合は差戻先を表示
BJ28: 勤務情報最終更新日 | BS28: yyyy/m/d | CT28: 2025年度改修_項番6、2025年度保守_項番51
BJ30: ・ | BK30: 削除ボタンを押下すると、削除の確認ダイアログを表示する。
A38: リストボックス | BI38: 権限による画面制御
A39: 項目名 | K39: 内容 | AW39: 並び順
BJ40: ユーザ区分が管理者、または担当者の照会モードの場合は、勤務入力画面を
BJ41: 照会モードで表示
BI43: 一覧の並び順

Sheet 勤務情報一覧
A1: システム名 | I1: =タイトル!I40 -> 学生勤務管理システム | AE1: 工 程 | AL1: 機能設計 | BI1: 作 成 | BM1: =タイトル!I46 -> 木田 優 | BW1: =タイトル!I47 -> 45201 | CF1: 管理記号 | CK1: =タイトル!I50 -> DUC010
A2: サブシステム名 | I2: 共通機能 | AE2: ドキュメント | AL2: =タイトル!I44 -> GA-010_勤務入力 | BI2: 改 訂
A4: 画面名称 | I4: =" " & RIGHT(CELL("filename",A1),LEN(CELL("filename",A1))-FIND("]",CELL("filename",A1))) -> 勤務情報一覧 | AL4: 画面ＩＤ | AS4: GA-010-02G | BI4: 利用想定ユーザー | BT4: 学生
A5: 画面レイアウト | BI5: 機能概要
BJ7: ・ | BK7: 登録した勤務時間を確認する時に使用する画面。
BJ8: ・ | BK8: 差戻された勤務データを編集するための選択画面。
BI12: 画面説明 （処理内容・アクション等）
BJ14: ・ | BK14: システム日付から取得できうる給与支給日の最大値までを選択可能とする。
BK15: 例：システム日付 = 2023/10/5
BL16: 選択できる給与支給日の最大値は勤務月が2023年10月の給与支給日
BL17: （2023/11/25）となる。2023年12月以降の給与支給日は選択不可とする。
BJ19: ・ | BK19: 選択ボタンを押下すると、勤務入力画面を表示する。
BJ21: ・ | BK21: ステータスが「承認待ち」「再承認待ち」「承認済」の場合、行全体に
BK22: 色をつけて、編集ができない勤務データと判断しやすいようにする。
A38: リストボックス | BI38: 権限による画面制御
A39: 項目名 | K39: 内容 | AW39: 並び順
A40: 支給日（年） | K40: 給与支給日マスタの給与支給日の年 | AW40: 降順
A41: 支給日（月日） | K41: 支給日（年）に一致する給与支給日マスタの給与支給日の月日 | AW41: 降順
BI43: 一覧の並び順
BJ45: ステータス（昇順） | BS45: → | BU45: 勤務日（昇順） | CB45: → | CD45: 開始時刻（昇順）
A48: 画 面 補 足 説 明
B50: ○入力項目（検索条件）
B51: 項目名 | P51: 入力必須 | U51: 桁数 | X51: 入力制限等
B52: 支給日（年） | P52: 〇 | U52: - | X52: リストボックス
B53: 支給日（月日） | P53: 〇 | U53: - | X53: リストボックス y/m
B55: ○出力項目
B56: 項目名 | K56: 編集内容等
B57: 勤務日 | K57: yyyy/m/d(aaa)
B58: 開始時刻 | K58: hh:mm
B59: 終了時刻 | K59: hh:mm
B60: 控除時間 | K60: hh:mm
B61: ステータス
B63: ○リストボックス
C64: 【支給日】
D65: 支給日 | T65: ▼ | AD65: ▼
L66: 2023 | V66: 9/23
L67: 2022 | V67: 8/23
L68: 2021 | V68: 7/23
C70: 支給日（年）の選択結果に連動して、支給日（月）のリストボックスを変動させる。
C71: 支給日（年）を未選択にすると、支給日（月）は未選択にする。
...

Sheet 補足資料_勤務処理フロー
A1: 【補足資料_勤務処理フロー】

Sheet 補足資料_勤務データフロー
A1: 【補足資料_勤務データフロー】
A2: 処理1 | B2: 勤務入力（学生）
G3: ①勤務入力画面で勤務入力を登録確定。 ※教員に承認依頼メールを送信
H4: 【勤務情報テーブル】
H5: 勤務番号 | I5: 雇用情報ＩＤ | J5: 複数身分ＩＤ | K5: 社員ＩＤ | L5: 勤務日 | M5: 勤務開始時刻 | N5: 勤務終了時刻 | O5: 控除時間 | P5: 勤務内容 | Q5: 校地移動フラグ | R5: 理由 | S5: 最終ステータス | T5: 最終承認日 | U5: 給与支給日 | V5: 給与計算処理実施日
H6: 10001 | I6: 1 | J6: 110ta001 | K6: 12345678901 | L6: 2023/11/20 | M6: 0900 | N6: 1030 | O6: 0000 | P6: 採点補助 | Q6: 0：しない | R6: Null | S6: 3：承認待ち | T6: Null | U6: 45192 | V6: Null | W6: ←給与支給日に勤務入力時の支給日をセット
H8: 【勤務承認テーブル】
H9: 勤務番号 | I9: 承認階層 | J9: 承認枝番 | K9: 主担当教員コード | L9: 雇用部課コード | M9: 承認権限 | N9: 承認社員ＩＤ | O9: ステータス | P9: 処理日時 | Q9: 有効フラグ | R9: 差戻フラグ
H10: 10001 | I10: 1 | J10: 1 | K10: 123456 | L10: Null | M10: １ | N10: Null | O10: 3：承認待ち | P10: Null | Q10: True | R10: False
H11: 10001 | I11: 2 | J11: 1 | K11: Null | L11: 110 | M11: 2 | N11: Null | O11: 3：承認待ち | P11: Null | Q11: False | R11: False
H12: 10001 | I12: 3 | J12: 1 | K12: Null | L12: 110 | M12: 3 | N12: Null | O12: 3：承認待ち | P12: Null | Q12: False | R12: False
H13: 10001 | I13: 4 | J13: 1 | K13: Null | L13: 110 | M13: 9 | N13: Null | O13: 3：承認待ち | P13: Null | Q13: False | R13: False
A15: 処理2 | B15: 勤務承認（教員）
G16: ②勤務承認画面で勤務データを承認。
H17: 【勤務情報テーブル】
H18: 勤務番号 | I18: 雇用情報ＩＤ | J18: 複数身分ＩＤ | K18: 社員ＩＤ | L18: 勤務日 | M18: 勤務開始時刻 | N18: 勤務終了時刻 | O18: 控除時間 | P18: 勤務内容 | Q18: 校地移動フラグ | R18: 理由 | S18: 最終ステータス | T18: 最終承認日 | U18: 給与支給日 | V18: 給与計算処理実施日
H19: 10001 | I19: 1 | J19: 110ta001 | K19: 12345678901 | L19: 2023/11/20 | M19: 0900 | N19: 1030 | O19: 0000 | P19: 採点補助 | Q19: 0：しない | R19: Null | S19: 3：承認待ち | T19: Null | U19: 45192 | V19: Null | W19: ←値の変更なし
H21: 【勤務承認テーブル】
H22: 勤務番号 | I22: 承認階層 | J22: 承認枝番 | K22: 主担当教員コード | L22: 雇用部課コード | M22: 承認権限 | N22: 承認社員ＩＤ | O22: ステータス | P22: 処理日時 | Q22: 有効フラグ | R22: 差戻フラグ
H23: 10001 | I23: 1 | J23: 1 | K23: 123456 | L23: Null | M23: １ | N23: 3456789012 | O23: 5：承認済み | P23: 2023/11/20 | Q23: True | R23: False | S23: ←承認内容を反映
H24: 10001 | I24: 2 | J24: 1 | K24: Null | L24: 110 | M24: 2 | N24: Null | O24: 3：承認待ち | P24: Null | Q24: True | R24: False | S24: ←有効フラグをFALSEからTRUEに更新
H25: 10001 | I25: 3 | J25: 1 | K25: Null | L25: 110 | M25: 3 | N25: Null | O25: 3：承認待ち | P25: Null | Q25: False | R25: False
H26: 10001 | I26: 4 | J26: 1 | K26: Null | L26: 110 | M26: 9 | N26: Null | O26: 3：承認待ち | P26: Null | Q26: False | R26: False
A28: 処理3 | B28: 勤務承認（雇用部課担当者）
G29: ③勤務承認画面で勤務データを承認。
H30: 【勤務情報テーブル】
H31: 勤務番号 | I31: 雇用情報ＩＤ | J31: 複数身分ＩＤ | K31: 社員ＩＤ | L31: 勤務日 | M31: 勤務開始時刻 | N31: 勤務終了時刻 | O31: 控除時間 | P31: 勤務内容 | Q31: 校地移動フラグ | R31: 理由 | S31: 最終ステータス | T31: 最終承認日 | U31: 給与支給日 | V31: 給与計算処理実施日
H32: 10001 | I32: 1 | J32: 110ta001 | K32: 12345678901 | L32: 2023/11/20 | M32: 0900 | N32: 1030 | O32: 0000 | P32: 採点補助 | Q32: 0：しない | R32: Null | S32: 3：承認待ち | T32: Null | U32: 45192 | V32: Null | W32: ←値の変更なし
H34: 【勤務承認テーブル】
H35: 勤務番号 | I35: 承認階層 | J35: 承認枝番 | K35: 主担当教員コード | L35: 雇用部課コード | M35: 承認権限 | N35: 承認社員ＩＤ | O35: ステータス | P35: 処理日時 | Q35: 有効フラグ | R35: 差戻フラグ
H36: 10001 | I36: 1 | J36: 1 | K36: 123456 | L36: Null | M36: １ | N36: 3456789012 | O36: 5：承認済み | P36: 2023/11/20 | Q36: True | R36: False
H37: 10001 | I37: 2 | J37: 1 | K37: Null | L37: 110 | M37: 2 | N37: 5678901234 | O37: 5：承認済み | P37: 2023/11/21 | Q37: True | R37: False | S37: ←承認内容を反映
H38: 10001 | I38: 3 | J38: 1 | K38: Null | L38: 110 | M38: 3 | N38: Null | O38: 3：承認待ち | P38: Null | Q38: True | R38: False | S38: ←有効フラグをFALSEからTRUEに更新
H39: 10001 | I39: 4 | J39: 1 | K39: Null | L39: 110 | M39: 9 | N39: Null | O39: 3：承認待ち | P39: Null | Q39: False | R39: False
A41: 処理4 | B41: 勤務承認（雇用部課事務長）
G42: ④勤務承認画面で勤務データを承認。
H43: 【勤務情報テーブル】
H44: 勤務番号 | I44: 雇用情報ＩＤ | J44: 複数身分ＩＤ | K44: 社員ＩＤ | L44: 勤務日 | M44: 勤務開始時刻 | N44: 勤務終了時刻 | O44: 控除時間 | P44: 勤務内容 | Q44: 校地移動フラグ | R44: 理由 | S44: 最終ステータス | T44: 最終承認日 | U44: 給与支給日 | V44: 給与計算処理実施日
H45: 10001 | I45: 1 | J45: 110ta001 | K45: 12345678901 | L45: 2023/11/20 | M45: 0900 | N45: 1030 | O45: 0000 | P45: 採点補助 | Q45: 0：しない | R45: Null | S45: 3：承認待ち | T45: Null | U45: 45192 | V45: Null | W45: ←値の変更なし
H47: 【勤務承認テーブル】
...
