Workbook
Name _Toc94971774: '1.前提条件'!#REF!
Name _Toc94971774: '2.ガイドライン'!#REF!
Name _Toc94971774: '2.画面レイアウト基準'!$D$44
Name _Toc94971775: '1.前提条件'!#REF!
Name _Toc94971775: '2.ガイドライン'!#REF!
Name _Toc94971775: '2.画面レイアウト基準'!#REF!
Name シート数: #REF!
Name シート数: #REF!

Sheet タイトル
G11: =I40 -> 学生勤務管理システム
G14: =I44 -> 要件定義書
G17: =I42 -> 画面基準
G20: =I51 -> 【 Ver 1.20 】
J27: =TEXT(I47,"yyyy年")&IF(LEFT(TEXT(I47,"mm"),1)="0"," ","")&TEXT(I47,"m月")&IF(LEFT(TEXT(I47,"dd"),1)="0"," ","")&TEXT(I47,"d日")&"作成" -> 2023年 9月 6日作成
J29: =IF(I49=" ※ページ毎に個別入力"," 年 月 日改訂",TEXT(I49,"yyyy年")&IF(LEFT(TEXT(I49,"mm"),1)="0"," ","")&TEXT(I49,"m月")&IF(LEFT(TEXT(I49,"dd"),1)="0"," ","")&TEXT(I49,"d日")&"改訂") -> 2024年 3月13日改訂
B38: 見出し部タイトル制御テーブル
B39: タイトル項目 | I39: タイトル項目埋め込み内容
B40: ①システム名 | I40: 学生勤務管理システム
B41: ②サブシステム名
B42: ③分類名 | I42: 画面基準
B43: ④作業工程名 | I43: 要件定義
B44: ⑤ドキュメント代表名 | I44: 要件定義書
B45: ⑥ドキュメント詳細名 | I45: ※ページ毎に個別入力
B46: ⑦作成者 | I46: 木田 優
B47: ⑧作成日 | I47: 45175
B48: ⑦改定者 | I48: ※ページ毎に個別入力
B49: ⑧改定日 | I49: =TEXT(MAX(改訂履歴!J5:J992),"yyyy/mm/dd") -> 2024/03/13
B50: ⑨管理記号 | I50: DUB013
B51: ⑩Ｖｅｒ | I51: ="【 Ver " & TEXT(MAX(改訂履歴!E5:E1000),"0.00") & " 】" -> 【 Ver 1.20 】
B53: （注1） ①～⑤は、埋め込み内容の先頭１文字は空白にする。
B55: （注2） ⑦と⑧でシート毎に異なる場合は、各シートの該当項目に直接、作成者、作成日を入力する。
B57: (注3） 文字はタイトル部：ＭＳゴシック、本文部：ＭＳ明朝で統一
B59: （注4） 管理番号は、ドキュメント体系の管理番号を使用する。
B61: （注5） ドキュメントＩＤの付け方
C63: 管理記号-分類区分（任意に設定）
C65: ※管理記号は、別紙 プロジェクト計画書のドキュメント体系を参照
B67: (注6） システム階層の概要
C69: システム名 | J69: ⇒ | L69: 人事給与システム
D71: サブシステム名 | J71: ⇒ | L71: 人事システム
L72: 給与システム
L73: 移行システム
E75: 機能名
F78: 処理名

Sheet 改訂履歴
A1: 改訂履歴 | G1: =タイトル!I42 -> 画面基準
A3: No | E3: Ver | J3: 新規／改訂日 | R3: 区分 | W3: 改訂箇所 | AH3: 改訂理由 | BR3: 新規／改訂者
W4: 頁 | AA4: 項番
A5: 1 | E5: 1 | J5: =タイトル!I47 -> 45175 | R5: 新規 | AH5: 新規作成 | BR5: =タイトル!I46 -> 木田 優
A6: 2 | E6: 1.1 | J6: 45195 | R6: 変更 | W6: 2 | AA6: 2.1 | AH6: 画面レイアウトのそれぞれの役割を変更 | BR6: 木田 優
A7: 3 | J7: 45195 | R7: 変更 | W7: 3 | AA7: 2.2 | AH7: ヘッダ部とフッタ部の要件を変更 | BR7: 木田 優
A8: 4 | J8: 45195 | R8: 変更 | W8: 4 | AA8: 2.3 | AH8: メニューの要件を変更 | BR8: 木田 優
A9: 5 | J9: 45195 | R9: 変更 | W9: 5 | AA9: 2.4 | AH9: Copyrightの表記をホーム画面のみに限定した。 （ボタンへの圧迫感を感じるため） | BR9: 木田 優
A10: 6 | E10: 1.2 | J10: 45201 | R10: 変更 | W10: 2 | AA10: 2.1 | AH10: 通常画面とメニュー表示時画面のイメージを追加 | BR10: 木田 優
A11: 7 | J11: 45201 | R11: 変更 | W11: 3 | AA11: 2.2 | AH11: ヘッダ部のツールチップの表示内容を変更 | BR11: 木田 優
A12: 8 | J12: 45201 | R12: 変更 | W12: 3 | AA12: 2.2 | AH12: ヘッダ部の「学生勤務管理システム」画像押下でホーム画面に遷移するように機能追加 | BR12: 木田 優
A13: 9 | J13: 45201 | R13: 変更 | W13: 3 | AA13: 2.2 | AH13: フッタ部に戻るボタンを配置するように変更 | BR13: 木田 優
A14: 10 | J14: 45201 | R14: 変更 | W14: 4 | AA14: 2.3 | AH14: メニュー部レイアウトのユーザIDを社員IDに文言修正 | BR14: 木田 優
A15: 11 | J15: 45201 | R15: 変更 | W15: 6 | AA15: 2.4.1 | AH15: 「編集」を押された場合という誤表記を削除 | BR15: 木田 優
A16: 12 | J16: 45364 | R16: 変更 | AH16: 画面イメージを実画面に差し替え | BR16: 木田 優

Sheet 目次
C1: 目次
C5: １． 前提条件
D6: １．１ 概要/目的
D7: １．２ 対応OS/ブラウザ
D8: １．３ 文字コード
D9: １．４ ディスプレイ設定
D10: １．５ 使用するWeb技術
C12: ２． 画面レイアウト基準
D13: ２．１ 画面レイアウト
D14: ２．２ ヘッダ部、フッタ部レイアウト
D15: ２．３ メニュー部レイアウト
D16: ２．４ ボディ部レイアウト
D17: ２．４．１ 一覧画面と単票画面の関係
D18: ２．４．２ 内容部レイアウト(一覧画面)
D19: ２．４．３ 内容部レイアウト(単票画面)
D20: ２．４．４ 内容部レイアウト(表示の切替)
D21: ２．５ 画面サンプル
D22: ２．６ 画面作成上のガイドライン

Sheet 1.前提条件
A1: システム名 | I1: =タイトル!I40 -> 学生勤務管理システム | AE1: 工 程 | AL1: =タイトル!I43 -> 要件定義 | BI1: 作 成 | BM1: =タイトル!I46 -> 木田 優 | BW1: =タイトル!I47 -> 45175 | CF1: 管理記号 | CK1: =タイトル!I50 -> DUB013
A2: サブシステム名 | I2: =タイトル!I41 | AE2: ドキュメント | AL2: =タイトル!I44 -> 要件定義書 | BI2: 改 訂
AL3: =タイトル!I42 -> 画面基準
B5: １． 前提条件
C7: １．１ 概要/目的
D9: ・学生や教職員の方にとって使いやすく見やすい画面とするため、統一された画面デザイン、操作性となるように基準を定める。
C11: １．２ 対応OS/ブラウザ
D13: ・管理者及び担当者が利用する機能については、OSはWindows10以上（大学内事務ユーザ（管理者・担当者を含む）はWindows10LTSCを利用）、
D14: WebブラウザはMicrosoft Edge/Google Chrome/Mozilla Firefoxに対応すること。
D15: ・承認者・利用者が利用する機能については、デスクトップOSは、Windows10、MacOS、
D16: WebブラウザはMicrosoft Edge/Google Chrome/Mozilla Firefox/Safariに対応すること。
D17: ・承認者・利用者が利用する機能については、モバイルOSは、iOS、Android、WebブラウザはGoogle Chrome/Mozilla Firefox/Safariにも対応すること。
D18: また、スマートフォン(iOS、Android)については、完全対応ではなく、なるべく動作して不具合のないように注意を払うものとする。
C20: １．３ 文字コード
D22: ・文字コードは Unicode(UTF-8) を使用すること。
D23: ・Unicodeで増えた文字(JIS第三水準、JIS第四水準)の文字を表示するため、フォントはメイリオ(Mac OS Xの場合は、ヒラギノ角ゴシックProN)を利用する。
D24: 字形は JIS2004 となる。
D25: ・外字は使用しない。
C27: １．４ ディスプレイ設定
D29: ・モバイル端末で表示する画面サイズが最小320pxであることを前提にレイアウトする。
D30: ・色数は、16,777,216色が使えるものとする。
D31: ・ウインドウサイズは可変とする。
D32: ・ウインドウサイズを変更した場合に、画面の部品が追随するようにする。(ウインドウサイズを広げた場合は、それに合わせて表示が広がるようになる)
C34: １．５ 使用するWeb技術
D36: ・「１．２ 対応OS/ブラウザ」で挙げたブラウザに対応するため、以下のWeb技術を使用して画面を作成すること。
E37: ・文書および文書構造は、「XHTML 1.0 移行版(Transitional)」を用いて記述すること。
E38: ・画面の見た目は、「カスケーディングスタイルシート(CSS) 2.1」を用いて記述すること。
E39: ・端末側の動作は、「JavaSctipt 1.5」を用いて記述すること。
E40: ・JavaScriptのライブラリ(部品群)は、「jQuery 1.9」を用いること。
D41: ・ブラウザ独自のタグやスタイルシートは極力使用しないこと。

Sheet 2.画面レイアウト基準
A1: システム名 | I1: =タイトル!I40 -> 学生勤務管理システム | AE1: 工 程 | AL1: =タイトル!I43 -> 要件定義 | BI1: 作 成 | BM1: =タイトル!I46 -> 木田 優 | BW1: =タイトル!I47 -> 45175 | CF1: 管理記号 | CK1: =タイトル!I50 -> DUB013
A2: サブシステム名 | I2: =タイトル!I41 | AE2: ドキュメント | AL2: =タイトル!I44 -> 要件定義書 | BI2: 改 訂 | BM2: 木田 優 | BW2: 45201
AL3: =タイトル!I42 -> 画面基準
B5: ２． 画面レイアウト基準
C7: ２．１ 画面レイアウト
D9: ・画面はヘッダ部、フッタ部、ボディ部で構成する。
D10: ・ヘッダ部にあるボタンで日本語と英語を切り替えられるようにする。
D11: ・フッタ部、最下部にCopyrightを表示する。
D12: ・メニュー部は非表示とし、画面右上のメニューアイコン押下時にのみ表示する。
E14: 【通常画面】
E15: ヘッダ部
AW16: 【通常画面】 | BV16: 【メニュー表示時】
E17: ボディ部
E27: フッタ部
E29: COPYRIGHT © 2024 DOSHISHA UNIVERSITY ALL RIGHTS RESERVED.
E31: 【メニュー表示時】
E32: メニュー部
C49: ２．２ ヘッダ部、フッタ部レイアウト
D51: ・ヘッダ部は、同志社大学ロゴ、学生勤務管理システム、日本語/英語の切り替え、メニューアイコン、ナビゲーションで構成する。
E52: ただし、担当者・管理者は日本語のみでの使用となるので、日本語/英語の切替はなしとする。
D57: 担当者・管理者の場合
D62: [同志社大学ロゴ]・[学生勤務管理システム]部分を押下することで、ホーム画面を表示する。
D68: ・フッタ部はガイダンスとボタンで構成し、最下部にCopyrightを表示する。
D69: ・ガイダンス行は3行とし、エラー時等の情報を一覧で表示する。3つ以上表示する場合は、縦スクロールバーを表示する。
D70: ・ボタン行は1行とし、ボタンの配置は8個までとし、左から詰めて並べる。
E71: ただし、画面サイズが小さい場合など、ボタン行が1行で足りない場合は2行とする
D72: ・「新規」「変更」「削除」のいずれかがある場合は、それらのボタンを左からこの順で並べる。
D73: ・ホームページは、ユーザー情報に日本語/英語の切り替えと、氏名、ログアウトボタンを表示する。 | E73: フッタ部に戻るボタンを表示する。
E74: ただし、メニューから画面遷移した場合など、戻り先の画面が確定できていない画面については戻るボタンは表示しない
D75: ・ホーム画面のフッタ部にはCopyrightを表示する。
C93: ２．３ メニュー部レイアウト
D95: ・メニュー部は、社員ID、社員名、メニュー、ヘルプ、ログアウトボタンを表示する。
D96: ・メニュー部はヘッダ部のメニューアイコンが押下されることにより表示する。
C137: ２．４ ボディ部レイアウト
D139: ・ボディ部は、内容部のみで構成する。
D141: ２．４．１ 一覧画面と単票画面
E143: ・一覧画面で「新規」ボタンを押された場合、単票画面に遷移し、新規登録ができるようにする。
E144: ・一覧画面で行を選択された場合、単票画面に遷移し、選択した情報の変更ができるようにする。
E145: ・単票画面で「戻る」ボタンを押した場合、データベースへ登録せず、一覧に戻る。
E146: ・単票画面で「登録」ボタンを押した場合、入力チェックや関連チェックを行った後、データベースへの登録を行う。
...

Sheet 2.ガイドライン
A1: システム名 | I1: =タイトル!I40 -> 学生勤務管理システム | AE1: 工 程 | AL1: =タイトル!I43 -> 要件定義 | BI1: 作 成 | BM1: =タイトル!I46 -> 木田 優 | BW1: =タイトル!I47 -> 45175 | CF1: 管理記号 | CK1: =タイトル!I50 -> DUB013
A2: サブシステム名 | I2: =タイトル!I41 | AE2: ドキュメント | AL2: =タイトル!I44 -> 要件定義書 | BI2: 改 訂 | BM2: 木田 優 | BW2: 45195
AL3: =タイトル!I42 -> 画面基準
C5: ３．６ 画面作成上のガイドライン
D7: （１）画面遷移のガイドライン
E8: ・ | F8: 画面遷移は、次のガイドラインに沿って、機能から選択するように作成すること。
F10: 【変更の画面遷移】
F11: １）ホーム画面のメニューより「機能」を選択する | AL11: ２）機能に応じた一覧画面が表示されるため、 | BO11: ３）単票画面で必要事項を入力し、「承認」ボタンを押す。
AL12: リンクをクリックして、変更対象を選択する。
BP44: ４）登録対象に間違いなければ「はい」を押す。
BQ45: データが登録され、元の画面に戻る。
F49: 【削除の画面遷移】
F50: １）ホーム画面のメニューより「機能」を選択する | AI50: ２）機能に応じた一覧画面が表示されるため、 | BM50: ３）単票画面で内容を確認し、「削除」ボタンを押す。
AI51: リンクをクリックして、削除対象を選択する。
BU87: ４）削除対象に間違いなければ「はい」を押す。
BU88: データが削除され、元の画面に戻る。
F93: 【新規の画面遷移】
F94: １）ホーム画面のメニューより「機能」を選択する | AZ94: ２）機能に応じた一覧画面が表示される。
AZ95: 新規作成を押す。
F113: ３）単票画面で必要事項を入力し、「登録」ボタンを押すと、
F114: データが登録され、一覧に戻る。
AX129: ４）データが登録され、元の画面に戻る。
D137: （２）一覧画面のガイドライン
E139: ・ | F139: 一覧画面の選択は一番左の列にボタンを表示する。 | AI139: ・ | AJ139: 【禁止事項】一覧画面の選択機能としてリンクを使用する。
BL142: ・ | BM142: 「登録」「削除」などの処理はすべて単票画面で実施するので
BM143: そのための画面遷移は全て一番左列に配置されたボタンより遷移する。
E150: ・ | F150: ボタンを複数配置する場合、左側にまとめて配置する。 | AI150: ・ | AJ150: 【禁止事項】ボタンを左右に配置する。
BL151: ・ | BM151: ボタンが右にあったり左にあったりすると、マウスを左右に
BM152: 動かさないといけなくなり、操作性が悪くなる。
BL153: ・ | BM153: ボタンは極力１つにして、誤操作を抑制すること。
D181: （３）単票画面のガイドライン
E183: ・ | F183: ボタンを画面のガイダンス行の下部に配置すること。 | AI183: ・ | AJ183: 【禁止事項】ポップアップ画面を開く時の参照ボタンをガイダンス行の下部に配置しないこと。
BL185: ・ | BM185: どの項目に対しての参照なのかわからないため、参照ボタンは
BM186: 項目の右側に配置する。
E200: ・ | F200: 参照ボタン（ポップアップ画面）を項目の右側に配置すること。
E215: ・ | F215: 単票形式画面に一覧が含まれる場合、一覧部分については一覧画面のガイドラインに準ずること。
D225: （４）ガイダンスメッセージのガイドライン
E227: ・ | F227: 入力内容にエラーがあった場合には、項目の下側にメッセージを表示すること。
F228: 下側に表示するメッセージは、「xxを入力してください。」「xxは数字で入力してください。」等、その項目に関するメッセージとすること。
E229: ・ | F229: 登録完了メッセージや関連チェックなど複数の項目にまたがるメッセージは、専用の枠に表示すること。メッセージがない場合には、枠自体を表示しない。
...
