Workbook
Name _Toc94971774: サーバ設計!#REF!
Name _Toc94971774: 'システムパラメータ設計(APDB)'!#REF!
Name _Toc94971774: ネットワーク設計!#REF!
Name _Toc94971774: バックアップ設計!#REF!
Name _Toc94971774: ユーザセキュリティ設計!#REF!
Name _Toc94971774: 環境図!#REF!
Name _Toc94971774: 構成図!#REF!
Name _Toc94971775: サーバ設計!#REF!
Name _Toc94971775: 'システムパラメータ設計(APDB)'!#REF!
Name _Toc94971775: ネットワーク設計!#REF!
Name _Toc94971775: バックアップ設計!#REF!
Name _Toc94971775: ユーザセキュリティ設計!#REF!
Name _Toc94971775: 環境図!#REF!
Name _Toc94971775: 構成図!#REF!
Name 使用FCポート名: OFFSET(#REF!,0,0,SUMPRODUCT((#REF!<>"")*1),1)

Sheet タイトル
G11: =I40 -> 教務システム
G14: =I44 -> システム環境定義書
G17: =I42 -> 社内開発機
G20: =I51 -> 【 Ver 1.00 】
J27: =TEXT(I47,"yyyy年")&IF(LEFT(TEXT(I47,"mm"),1)="0"," ","")&TEXT(I47,"m月")&IF(LEFT(TEXT(I47,"dd"),1)="0"," ","")&TEXT(I47,"d日")&"作成" -> 2024年 2月14日作成
B38: 見出し部タイトル制御テーブル
B39: タイトル項目 | I39: タイトル項目埋め込み内容
B40: ①システム名 | I40: 教務システム
B41: ②サブシステム名 | I41: 基盤構築
B42: ③分類名 | I42: 社内開発機
B43: ④作業工程名 | I43: 構築手順書の作成
B44: ⑤ドキュメント代表名 | I44: システム環境定義書
B45: ⑥ドキュメント詳細名 | I45: ※ページ毎に個別入力
B46: ⑦作成者 | I46: 大久保 梓沙
B47: ⑧作成日 | I47: 45336
B48: ⑦改訂者 | I48: ※ページ毎に個別入力
B49: ⑧改訂日
B50: ⑨管理記号
B51: ⑩Ｖｅｒ | I51: ="【 Ver " & TEXT(MAX(改訂履歴!E5:E999),"0.00") & " 】" -> 【 Ver 1.00 】
B53: （注1） ①～⑤は、埋め込み内容の先頭１文字は空白にする。
B55: （注2） ⑦と⑧でシート毎に異なる場合は、各シートの該当項目に直接、作成者、作成日を入力する。
B57: (注3） 文字はタイトル部：ＭＳゴシック、本文部：ＭＳ明朝で統一
B59: （注4） 管理番号は、ドキュメント体系の管理番号を使用する。
B61: （注5） ドキュメントＩＤの付け方
C63: 管理記号-分類区分（任意に設定）
C65: ※管理記号は、別紙 プロジェクト計画書のドキュメント体系を参照
B67: (注6） システム階層の概要
C69: システム名 | J69: ⇒ | L69: 人事給与システム
D71: サブシステム名 | J71: ⇒ | L71: 人事システム
L72: 給与システム
L73: 移行システム
E75: 機能名
F78: 処理名

Sheet 改訂履歴
A1: 改訂履歴 | G1: =タイトル!I42 -> 社内開発機
A3: No | E3: Ver | J3: 新規／改訂日 | R3: 区分 | W3: 改訂箇所 | AH3: 改訂理由 | BR3: 新規／改訂者
W4: 頁 | AA4: 項番
A5: 1 | E5: 1 | J5: =タイトル!I47 -> 45336 | R5: 新規 | AH5: 新規作成 | BR5: =タイトル!I46 -> 大久保 梓沙

Sheet 目次
C1: 目次
C5: １．システム環境定義
D6: １．１ | I6: 構成図
D7: １．２ | I7: 環境図
D8: １．３ | I8: サーバ設計
D9: １．４ | I9: ネットワーク設計
D10: １．５ | I10: ユーザ／セキュリティ設計
D11: １．６ | I11: バックアップ設計
D12: １．７ | I12: ジョブスケジュール設計
D13: １．８ | I13: 通知設計
D14: １．９ | I14: SSO連携
D15: １．１０ | I15: 統合DB連携
D16: １．１１ | I16: システムパラメータ設計(APDB)

Sheet 構成図
A1: システム名 | I1: =タイトル!$I$40 -> 教務システム | AE1: 工 程 | AL1: =タイトル!$I$43 -> 構築手順書の作成 | BG1: 作 成 | BK1: =タイトル!$I$46 -> 大久保 梓沙 | BU1: =タイトル!$I$47 -> 45336 | CD1: 管理記号 | CI1: =タイトル!$I$50
A2: サブシステム名 | I2: =タイトル!$I$41 -> 基盤構築 | AE2: ドキュメント | AL2: =タイトル!$I$44 -> システム環境定義書 | BG2: 改 訂
I3: ハードウェア構成図 | AL3: =タイトル!$I$42 -> 社内開発機
B5: １. システム環境定義（検証機）
C7: １．１ 構成図

Sheet 環境図
A1: システム名 | I1: =タイトル!$I$40 -> 教務システム | AE1: 工 程 | AL1: =タイトル!$I$43 -> 構築手順書の作成 | BG1: 作 成 | BK1: =タイトル!$I$46 -> 大久保 梓沙 | BU1: =タイトル!$I$47 -> 45336 | CD1: 管理記号 | CI1: =タイトル!$I$50
A2: サブシステム名 | I2: =タイトル!$I$41 -> 基盤構築 | AE2: ドキュメント | AL2: =タイトル!$I$44 -> システム環境定義書 | BG2: 改 訂
I3: 環境図 | AL3: =タイトル!$I$42 -> 社内開発機
C5: １．２ 環境図
C7: （１）環境図(業務系)
B13: 管理者
B15: 職員
B17: 学生
B19: 教員
C39: 検証環境は、１環境用意する。
C41: ｼｽﾃﾑ | N41: 環境 | V41: ｺﾝﾃｷｽﾄﾊﾟｽ | AD41: ﾛｰﾄﾞﾊﾞﾗﾝｻｰ | AT41: Apache Tomcat | CA41: DB
AD42: サービス名 | AL42: HTTPﾎﾟｰﾄ | AT42: サービス名 | BB42: HTTPﾎﾟｰﾄ | BG42: AJPﾎﾟｰﾄ | BM42: Shutdownﾎﾟｰﾄ | BT42: JMXﾎﾟｰﾄ | CA42: ｽｷｰﾏ
C43: 学生勤務管理 | N43: 本番保守用 | V43: /gakuseikinmu | AD43: Apache2.4 | AL43: httpd 80/tcp | AT43: Catalina-gf | BB43: - | BG43: 50000/tcp | BM43: 50040/tcp | BT43: 3300/tcp | CA43: gakuseikinmu
C44: 学生勤務管理 | N44: CT | V44: /gakuseikinmu01 | AD44: Apache2.4-gf01 | AL44: httpd 85/tcp | AT44: Catalina-gf01 | BB44: - | BG44: 50001/tcp | BM44: 50041/tcp | BT44: 3301/tcp | CA44: gakuseikinmu01

Sheet サーバ設計
A1: システム名 | I1: =タイトル!$I$40 -> 教務システム | AE1: 工 程 | AL1: =タイトル!$I$43 -> 構築手順書の作成 | BG1: 作 成 | BK1: =タイトル!$I$46 -> 大久保 梓沙 | BU1: =タイトル!$I$47 -> 45336 | CD1: 管理記号 | CI1: =タイトル!$I$50
A2: サブシステム名 | I2: =タイトル!$I$41 -> 基盤構築 | AE2: ドキュメント | AL2: =タイトル!$I$44 -> システム環境定義書 | BG2: 改 訂
I3: サーバ設計 | AL3: =タイトル!$I$42 -> 社内開発機
C5: １．３ サーバ設計
C7: （１）ゲストOS
D9: ゲストｻｰﾊﾞ名 | P9: OS | AM9: インスタンス数 | AR9: インスタンスタイプ | AW9: コア数 | BB9: メモリ (GiB) | BG9: ﾃﾞｨｽｸ (GB)
D11: 社内開発ｻｰﾊﾞ | P11: Windows Server 2022 Datacenter | AM11: 1 | AR11: t3.medium | AW11: 2 | BB11: 4 | BG11: 50

Sheet ネットワーク設計
A1: システム名 | I1: =タイトル!$I$40 -> 教務システム | AE1: 工 程 | AL1: =タイトル!$I$43 -> 構築手順書の作成 | BG1: 作 成 | BK1: =タイトル!$I$46 -> 大久保 梓沙 | BU1: =タイトル!$I$47 -> 45336 | CD1: 管理記号 | CI1: =タイトル!$I$50
A2: サブシステム名 | I2: =タイトル!$I$41 -> 基盤構築 | AE2: ドキュメント | AL2: =タイトル!$I$44 -> システム環境定義書 | BG2: 改 訂
I3: ネットワーク設計 | AL3: =タイトル!$I$42 -> 社内開発機
C5: １．４ ネットワーク設計
C7: （１）ホスト名/IPアドレス
D8: ドメイン: | J8: kss.local
D9: 端末 | Q9: ＯＳ | Z9: ホスト名 | AH9: IPｱﾄﾞﾚｽ(社内LAN) | AR9: IPｱﾄﾞﾚｽ(ﾊﾞｯｸｱｯﾌﾟ用) | BB9: IPｱﾄﾞﾚｽ(AlwaysOn用) | BL9: 備考 | BW9: MACアドレス
D10: EC2 | F10: APｻｰﾊﾞｰ | Q10: Windows Server 2022 Datacenter | Z10: v20gksvr | AH10: 172.16.1.46 | AR10: - | BB10: -

Sheet ユーザセキュリティ設計
A1: システム名 | I1: =タイトル!$I$40 -> 教務システム | AE1: 工 程 | AL1: =タイトル!$I$43 -> 構築手順書の作成 | BG1: 作 成 | BK1: =タイトル!$I$46 -> 大久保 梓沙 | BU1: =タイトル!$I$47 -> 45336 | CD1: 管理記号 | CI1: =タイトル!$I$50
A2: サブシステム名 | I2: =タイトル!$I$41 -> 基盤構築 | AE2: ドキュメント | AL2: =タイトル!$I$44 -> システム環境定義書 | BG2: 改 訂
I3: ユーザ／セキュリティ設計 | AL3: =タイトル!$I$42 -> 社内開発機
B5: １．５ ユーザ／セキュリティ設計
C7: ユーザーアカウント
C8: 対象 | S8: ユーザ | AE8: ユーザ名 | AO8: パスワード | AY8: グループ
C9: 社内開発ｻｰﾊﾞ | S9: システム管理者 | AE9: admingksvr | AO9: ps-v20gksvr | AY9: Administrators
C12: PostgeSQLアカウント
C13: データベース | M13: ユーザ名 | W13: パスワード | AG13: テーブル空間 | AP13: 用途
C14: gakuseikinmu | M14: gakuseikinmu | W14: psgakuseikinmu | AG14: gakuseikinmu | AP14: 本番保守用
C15: gakuseikinmu01 | M15: gakuseikinmu01 | W15: psgakuseikinmu01 | AG15: gakuseikinmu | AP15: CT用
C18: PostgeSQLアカウントの権限
C19: ユーザ名 | M19: 権限
C20: gakuseikinmu | M20: pg_read_server_files
C21: gakuseikinmu01 | M21: pg_read_server_files
C24: Tomcat Administrator
C25: ログインユーザ名 | M25: パスワード | W25: ロール

Sheet バックアップ設計
A1: システム名 | I1: =タイトル!$I$40 -> 教務システム | AE1: 工 程 | AL1: =タイトル!$I$43 -> 構築手順書の作成 | BG1: 作 成 | BK1: =タイトル!$I$46 -> 大久保 梓沙 | BU1: =タイトル!$I$47 -> 45336 | CD1: 管理記号 | CI1: =タイトル!$I$50
A2: サブシステム名 | I2: =タイトル!$I$41 -> 基盤構築 | AE2: ドキュメント | AL2: =タイトル!$I$44 -> システム環境定義書 | BG2: 改 訂
I3: バックアップ設計 | AL3: =タイトル!$I$42 -> 社内開発機
B5: １．６ バックアップ設計
D7: （１）EC2サーバーの日次バックアップ
F19: 自動でバックアップを行う。
F20: ①AWS上にスナップショットを保存。(2世代前まで保持）
D23: （２）EC2バックアップ設定(日次)
F25: バックアップ対象 | N25: インスタンス名 | AG25: 時間 | AT25: 曜日指定 | BO25: 世代管理
F26: 社内開発サーバ | N26: Ｓ事-v20gksvr | AG26: 0.041666667 | AT26: 月、火、水、木、金 | BO26: 2世代

Sheet ジョブスケジュール設計
A1: システム名 | I1: =タイトル!$I$40 -> 教務システム | AE1: 工 程 | AL1: =タイトル!$I$43 -> 構築手順書の作成 | BG1: 作 成 | BK1: =タイトル!$I$46 -> 大久保 梓沙 | BU1: =タイトル!$I$47 -> 45336 | CD1: 管理記号 | CI1: =タイトル!$I$50
A2: サブシステム名 | I2: =タイトル!$I$41 -> 基盤構築 | AE2: ドキュメント | AL2: =タイトル!$I$44 -> システム環境定義書 | BG2: 改 訂
I3: 通知設計 | AL3: =タイトル!$I$42 -> 社内開発機
B5: １．７ ジョブスケジュール
E7: 社内開発サーバのため、ジョブスケジュールは行わないものとする。
E8: ※Windows タスクスケジューラのジョブの登録のみしておき、定期実行はしない。

Sheet SSO連携
A1: システム名 | I1: =タイトル!$I$40 -> 教務システム | AE1: 工 程 | AL1: =タイトル!$I$43 -> 構築手順書の作成 | BG1: 作 成 | BK1: =タイトル!$I$46 -> 大久保 梓沙 | BU1: =タイトル!$I$47 -> 45336 | CD1: 管理記号 | CI1: =タイトル!$I$50
A2: サブシステム名 | I2: =タイトル!$I$41 -> 基盤構築 | AE2: ドキュメント | AL2: =タイトル!$I$44 -> システム環境定義書 | BG2: 改 訂
I3: 通知設計 | AL3: =タイトル!$I$42 -> 社内開発機
B5: １．９ SSO連携
D7: 社内開発環境（UT/CT）にはSSO機構（Shibboleth、saml）が導入されていないため、LDAP認証を行うことで類似の挙動を実現する。
D10: 社内開発サーバ（v20gksvr）
G14: メニュー画面 | AD14: CC010-90G | AR14: リダイレクト | BB14: CC020-01G
AE15: ログイン処理 | BC15: ホーム
H16: ID
H17: PW | U17: ログインID
N18: Login | U18: パスワード
U19: ※ﾘｸｴｽﾄﾊﾟﾗﾒｰﾀ
AC27: 教務管理サーバ（v20dukns）
AG29: LDAP

Sheet 統合DB連携
A1: システム名 | I1: =タイトル!$I$40 -> 教務システム | AE1: 工 程 | AL1: =タイトル!$I$43 -> 構築手順書の作成 | BG1: 作 成 | BK1: =タイトル!$I$46 -> 大久保 梓沙 | BU1: =タイトル!$I$47 -> 45336 | CD1: 管理記号 | CI1: =タイトル!$I$50
A2: サブシステム名 | I2: =タイトル!$I$41 -> 基盤構築 | AE2: ドキュメント | AL2: =タイトル!$I$44 -> システム環境定義書 | BG2: 改 訂
I3: 通知設計 | AL3: =タイトル!$I$42 -> 社内開発機
B5: １．１０ 統合DB連携
C7: バッチ処理にて、統合DBのデータベースからCSVデータを作成し、PostgeSQLの機能にてCSVデータの一括インポートを行う。
C8: ※教務DBサーバのデータベース「TOGODB」に学生勤務用のスキーマとテーブルを作成し、接続する。
D10: 社内開発サーバ（v20gksvr)
E12: CSVでデータの受け渡しを行い、postgeSQLに一括インポートを行う | BE12: DBサーバ側で入替えたデータを基に、社員マスタを更新する
C50: ○統合DB接続情報
E52: ホスト名 | Q52: v20dudbs | AP52: IPアドレス | BB52: 172.16.1.24
E54: DBバージョン | Q54: SQL Server 2017 | AP54: ポート | BB54: TCP1433(標準ポート）
E56: DB識別子 | Q56: TOGODB | AP56: スキーマ名 | BB56: gakuseikinmu
E58: 接続方法 | Q58: ODBC(SQL Server用ドライバー)
C62: ○接続アカウント
E64: ユーザID | Q64: gakuseikinmu | AP64: パスワード | BB64: psgakuseikinmu
C68: ○参照View
E70: データ参照ビュー | Q70: VU_GK_LDAP_ALL | AP70: VU_GK_学年暦マスタ
Q72: VU_GK_社員基本情報 | AP72: VU_GK_部署マスタ
Q74: VU_GK_学生基本 | AP74: VU_GK_業務マスタ
Q76: VU_GK_教員基本 | AP76: VU_GK_予算
Q78: VU_GK_所属名称マスタ | AP78: VU_GK_配分先マスタ
Q80: VU_GK_科目マスタ
Q82: VU_GK_開講科目マスタ
Q84: VU_GK_授業マスタ
Q86: VU_GK_授業担当マスタ

Sheet システムパラメータ設計(APDB)
A1: システム名 | I1: =タイトル!$I$40 -> 教務システム | AE1: 工 程 | AL1: =タイトル!$I$43 -> 構築手順書の作成 | BG1: 作 成 | BK1: =タイトル!$I$46 -> 大久保 梓沙 | BU1: =タイトル!$I$47 -> 45336 | CD1: 管理記号 | CI1: =タイトル!$I$50
A2: サブシステム名 | I2: =タイトル!$I$41 -> 基盤構築 | AE2: ドキュメント | AL2: =タイトル!$I$44 -> システム環境定義書 | BG2: 改 訂
I3: システムパラメータ設計(APDB) | AL3: =タイトル!$I$42 -> 社内開発機
B5: １．１１ システムパラメータ設計(APDB)
C7: （１）システム
E9: コンピュータ名 | O9: このコンピューターのプライマリ DNS サフィックス | AM9: ワークグループ | AW9: ドメイン
E10: =ネットワーク設計!Z10 -> v20gksvr | O10: kss.local | AM10: - | AW10: kss.local
C13: （２）ディスク構成
E15: ディスク | N15: ボリューム | W15: 種類 | AE15: ファイルシステム | AN15: 容量 | AW15: 備考
E16: ディスク0 | N16: システムで予約 | W16: ベーシック | AE16: NTFS | AN16: 0.1
N17: C: | W17: ベーシック | AE17: NTFS | AN17: =AN18-AN16 -> 49.9 | AW17: 残りすべて
N18: 計 | AN18: 50
C21: （３）システム環境変数
G23: 変数名 | U23: 値 | BA23: 備考
E24: 1 | G24: JAVA_HOME | U24: C:\jdk | BA24: Javaホームディレクトリ | BS24: ※日立Java
E25: 2 | G25: PATH | U25: %SystemRoot%System32
U26: %SystemRoot%
U27: %SystemRoot%System32\Wbem
U28: %SYSTEMROOT%\System32\WindowsPowerShell\v1.0\
U29: %SYSTEMROOT%\System32\OpenSSH\
U30: C:Program Files\Amazon\cfn-bootstrap\
U31: C:\jdk\jre\bin | BA31: Java
U32: C:\jdk\bin | BA32: Java
U33: C:\Apache24\bin | BA33: Apache2.4
U34: C:\Program Files\Apache Software Foundation\Tomcat 9.0\bin | BA34: Tomcat9
U35: C:\Program Files\PostgreSQL\16rc1\bin | BA35: PostgreSQL
U36: C:Program Files\Microsoft SQL Server\Client SDK\ODBC\170\Tools\Bi\ | BA36: MSSQL SQLCMD
U37: C:\Program Files\TortoiseSVN\bin | BA37: SVN更新用
C40: （４）仮想メモリ
E42: システムで自動設定
C49: （５）ネットワーク設定
E51: インターフェイス
E52: ネットワーク名 | W52: -
E53: IPアドレス | W53: =ネットワーク設計!AH10 -> 172.16.1.46
E54: サブネットマスク | W54: 255.255.252.0
E55: ゲートウェイアドレス | W55: 172.16.1.1
E56: DNSｻｰﾊﾞｰ | W56: 10.3.9.51,172.16.2.11,172.16.0.2
E57: 以下のDNSサフィックスを順に追加する | W57: - | AL57: デフォルト
E58: この接続のDNSサフィックス | W58: kss.local
E59: DNS登録する | W59: チェックする
...
