Workbook

Sheet タイトル
G11: =I40 -> 顧客名：同志社大学 教務システム
G14: =I44 -> プロジェクト計画書
G17: =I42
G20: =I51 -> 【 Ver 1.0 】
J27: =TEXT(I47,"yyyy年")&IF(LEFT(TEXT(I47,"mm"),1)="0"," ","")&TEXT(I47,"m月")&IF(LEFT(TEXT(I47,"dd"),1)="0"," ","")&TEXT(I47,"d日")&"作成" -> 2023年 9月 1日作成
J29: =IF(I49=" ※ページ毎に個別入力"," 年 月 日改訂",TEXT(I49,"yyyy年")&IF(LEFT(TEXT(I49,"mm"),1)="0"," ","")&TEXT(I49,"m月")&IF(LEFT(TEXT(I49,"dd"),1)="0"," ","")&TEXT(I49,"d日")&"改訂") -> 年 月 日改訂
B38: 見出し部タイトル制御テーブル
B39: タイトル項目 | I39: タイトル項目埋め込み内容
B40: ①システム名 | I40: 顧客名：同志社大学 教務システム
B41: ②サブシステム名
B42: ③分類名
B43: ④作業工程名 | I43: プロジェクト計画
B44: ⑤ドキュメント代表名 | I44: プロジェクト計画書
B45: ⑥ドキュメント詳細名
B46: ⑦作成者 | I46: 中村 恒太郎
B47: ⑧作成日 | I47: 45170
B48: ⑦改定者 | I48: ※ページ毎に個別入力
B49: ⑧改定日 | I49: ※ページ毎に個別入力
B50: ⑨管理記号
B51: ⑩Ｖｅｒ | I51: 【 Ver 1.0 】
B53: （注1） ①～⑤は、埋め込み内容の先頭１文字は空白にする。
B55: （注2） ⑦と⑧でシート毎に異なる場合は、各シートの該当項目に直接、作成者、作成日を入力する。
B57: (注3） 文字はタイトル部：ＭＳゴシック、本文部：ＭＳ明朝で統一
B59: （注4） 管理番号は、ドキュメント体系の管理番号を使用する。

Sheet 改訂履歴
A1: 改訂履歴
A3: No | D3: Ver | H3: 新規／改訂日 | P3: 区分 | U3: 改訂箇所 | AC3: 改訂理由 | BL3: 新規／改訂者 | BS3: 承認者
U4: 頁 | X4: 項番
A5: 1 | D5: 1 | H5: =タイトル!I47 -> 45170 | P5: 新規 | AC5: 新規作成 | BL5: =タイトル!I46 -> 中村 恒太郎 | BS5: 岡井 計允

Sheet プロジェクト計画書
A1: システム名 | I1: =タイトル!I40 -> 顧客名：同志社大学 教務システム | AE1: 工 程 | AL1: =タイトル!I43 -> プロジェクト計画 | BI1: 作 成 | BM1: =タイトル!I46 -> 中村 恒太郎 | BW1: =タイトル!I47 -> 45170 | CF1: 管理記号
A2: サブシステム名 | I2: =タイトル!I41 | AE2: ドキュメント | AL2: =タイトル!I44 -> プロジェクト計画書 | BI2: 改 訂
B5: １．プロジェクト概要
C7: 1.1 プロジェクトの背景／目的
D9: 学生勤務管理システムの構築
D10: ※月々の勤務管理及び承認決裁業務をシステム化し、業務効率化を図る。
C14: 1.2 作業概要（機能要件／前提条件／作業範囲）
E15: ・学生勤務管理システムの開発作業
E16: ①学生WEB勤怠登録・申請機能
E17: ②勤務表電子承認機能
E18: ③勤務表データ抽出機能
E19: ・システム導入作業
E20: ・初期データ移行
E23: 下記の提案資料に記載
F24: Z:\#営業\DUSK_同志社大学\2023年度\DUSK3070：2023年度学生勤務管理システム\提出資料\00_初回提出_20230718
F25: Z:\#営業\DUSK_同志社大学\2023年度\DUSK3070：2023年度学生勤務管理システム\提出資料\01_再提案20230803\09_提出資料
C29: 1.3 システム環境
D31: (1)稼動システムの環境
E33: システム形態 | P33: Ｗｅｂ系
E34: サーバＯＳ | P34: Windows Server 2022（同志社 AWS 3台）
E35: 使用ＤＢ | P35: PostgreSQL 16
E36: クライアントＯＳ | P36: Windows 10,11
E37: 使用ミドルウエア等 | P37: Apache 2.4、Tomcat 9.0、Java 8（日立Java）
D40: (2)開発環境
E42: 開発クライアントＯＳ | P42: Windows 10,11
E43: 開発言語 | P43: Java8
E44: 統合開発環境（IDE） | P44: Eclipse Photon Release 4.8.0
E45: フレームワーク | P45: Seasar2
C49: 1.4 プロジェクト成果物
D51: 本プロジェクトで作成する成果物については、【別紙１】の通りである。
C53: 1.5 プロジェクトの予定原価
AL54: (単位：人日)
E55: 工 程 | S55: SA | W55: SE | AA55: PE | AE55: PG | AI55: 合計
E56: 要件定義 | W56: 7.8 | AI56: =SUM(S56:AH56) -> 7.8 | CT56: 要件定義～システムテストは作業概算シートより
E57: 基本設計 | W57: 16.2 | AI57: =SUM(S57:AH57) -> 16.2 | DI57: SA | DM57: SE | DQ57: PE | DU57: PG | DY57: 合計
E58: 詳細設計 | AA58: 35.8 | AI58: =SUM(S58:AH58) -> 35.8 | CU58: 開発 | DM58: 28.6 | DQ58: 46.8 | DU58: 68.8 | DY58: =SUM(DI58:DX58) -> 144.2
E59: 製造・単体テスト | AE59: 68.8 | AI59: =SUM(S59:AH59) -> 68.8
E60: 結合テスト | AA60: 11 | AI60: =SUM(S60:AH60) -> 11
E61: システムテスト | W61: 4.6 | AI61: =SUM(S61:AH61) -> 4.6
E62: 運用テスト | W62: 4.9 | AI62: =SUM(S62:AH62) -> 4.9
...

Sheet (別紙1）プロジェクト成果物
A1: システム名 | I1: =タイトル!I40 -> 顧客名：同志社大学 教務システム | AE1: 工 程 | AL1: =タイトル!I43 -> プロジェクト計画 | BI1: 作 成 | BM1: =タイトル!I46 -> 中村 恒太郎 | BW1: =タイトル!I47 -> 45170 | CF1: 管理記号
A2: サブシステム名 | I2: =タイトル!I41 | AE2: ドキュメント | AL2: =タイトル!I44 -> プロジェクト計画書 | BI2: 改 訂
A5: 【別紙１】プロジェクト成果物
D7: 項番 | F7: 工程 | Q7: 成果物一覧 ※■作成する成果物
D8: 1 | F8: プロジェクト計画 | R8: ■ | S8: プロジェクト計画書 | AD8: □ | AE8: テスト計画書 | AP8: □ | AQ8: 移行計画書
R9: ■ | S9: レビュー記録表
R10: □ | S10: その他（ | AZ10: ）
D11: 2 | F11: 要件定義 | R11: □ | S11: ヒアリング票 | AD11: □ | AE11: 業務一覧 | AP11: ■ | AQ11: 業務フロー
R12: ■ | S12: 機能要件 | AD12: ■ | AE12: 機能一覧 | AP12: ■ | AQ12: 非機能要件関連
R13: ■ | S13: ネーミング基準書 | AD13: ■ | AE13: コード設計書 | AP13: ■ | AQ13: メッセージ設計書
R14: □ | S14: 共通ルール／方式設計 | AD14: ■ | AE14: 画面共通設計書 | AP14: □ | AQ14: 帳票共通設計書
R15: □ | S15: バッチ共通設計書 | AD15: ■ | AE15: システム環境設計書 | AP15: ■ | AQ15: レビュー記録表
R16: □ | S16: 議事録
R17: ■ | S17: その他（ | W17: 要件定義資料 | AZ17: ）
D18: 3 | F18: 基本設計 | R18: ■ | S18: コード定義書 | AD18: ■ | AE18: メッセージ定義書 | AP18: □ | AQ18: データフロー
R19: ■ | S19: ER図 | AD19: ■ | AE19: テーブル項目定義 | AP19: □ | AQ19: CRUD図
R20: ■ | S20: 画面遷移図 | AD20: ■ | AE20: 画面設計書 | AP20: ■ | AQ20: 帳票設計書
R21: ■ | S21: バッチ設計書 | AD21: ■ | AE21: 外部インタフェース設計書
R22: ■ | S22: 結合テスト設計書（CCL) | AD22: ■ | AE22: レビュー記録表
R23: ■ | S23: その他（ | W23: 基本設計顧客レビュー議事録 | AZ23: ）
D24: 4 | F24: 詳細設計 | R24: ■ | S24: 共通モジュール設計書 | AD24: ■ | AE24: 画面設計書 | AP24: ■ | AQ24: 帳票設計書
R25: ■ | S25: バッチ設計書 | AD25: ■ | AE25: DAO設計書 | AP25: ■ | AQ25: 単体テスト設計書（PCL)
R26: ■ | S26: レビュー記録表
R27: □ | S27: その他（ | AZ27: ）
D28: 5 | F28: 製造・単体テスト | R28: ■ | S28: プログラムソース | AD28: ■ | AE28: レビュー記録表 | AP28: □ | AQ28: 単体テスト設計書（PCL)
R29: ■ | S29: 単体テスト結果報告書 | AD29: ■ | AE29: PCLの消し込み | AP29: ■ | AQ29: 不具合票
R30: □ | S30: その他（ | AZ30: ）
D31: 6 | F31: 結合テスト | R31: □ | S31: 結合テスト設計書（CCL) | AD31: ■ | AE31: 結合テスト結果報告書 | AP31: ■ | AQ31: CCLの消し込み
R32: ■ | S32: 不具合票 | AD32: ■ | AE32: レビュー記録表
R33: □ | S33: その他（ | AZ33: ）
D34: 7 | F34: システムテスト | R34: ■ | S34: システムテスト設計書（SCL) | AP34: ■ | AQ34: システムテスト結果報告書
R35: ■ | S35: SCLの消し込み | AD35: ■ | AE35: 不具合票 | AP35: ■ | AQ35: レビュー記録表
R36: □ | S36: その他（ | AZ36: ）
D37: 8 | F37: システム移行 | R37: ■ | S37: 移行手順書 | AD37: ■ | AE37: レビュー記録表
R38: □ | S38: その他（ | AZ38: ）
D39: 9 | F39: マニュアル作成 | R39: □ | S39: 操作マニュアル | AD39: □ | AE39: 運用マニュアル | AP39: □ | AQ39: 操作研修用マニュアル
R40: □ | S40: その他（ | AZ40: ）

Sheet (別紙2）人員計画
A1: システム名 | I1: =タイトル!I40 -> 顧客名：同志社大学 教務システム | AE1: 工 程 | AL1: =タイトル!I43 -> プロジェクト計画 | BI1: 作 成 | BM1: =タイトル!I46 -> 中村 恒太郎 | BW1: =タイトル!I47 -> 45170 | CF1: 管理記号
A2: サブシステム名 | I2: =タイトル!I41 | AE2: ドキュメント | AL2: =タイトル!I44 -> プロジェクト計画書 | BI2: 改 訂
A5: 【別紙２】人員計画（山積み）
C7: 項番 | E7: 要員 | J7: 計画 工数 | N7: 45017 | AO7: =EOMONTH(N7,9) -> 45322
N8: =N7 -> 45017 | Q8: =EOMONTH(N8,1) -> 45077 | T8: =EOMONTH(Q8,1) -> 45107 | W8: =EOMONTH(T8,1) -> 45138 | Z8: =EOMONTH(W8,1) -> 45169 | AC8: =EOMONTH(Z8,1) -> 45199 | AF8: =EOMONTH(AC8,1) -> 45230 | AI8: =EOMONTH(AF8,1) -> 45260 | AL8: =EOMONTH(AI8,1) -> 45291 | AO8: =EOMONTH(AL8,1) -> 45322 | AR8: =EOMONTH(AO8,1) -> 45351 | AU8: =EOMONTH(AR8,1) -> 45382
C9: 1 | E9: 岡井 | J9: =SUM(N9:AW9) -> 0 | N9: 0 | Q9: 0 | T9: 0 | W9: 0 | Z9: 0 | AC9: 0 | AF9: 0 | AI9: 0 | AL9: 0 | AO9: 0 | AR9: 0 | AU9: 0
C10: 2 | E10: 鳥羽 | J10: =SUM(N10:AW10) -> 0.1 | N10: 0 | Q10: 0 | T10: 0 | W10: 0 | Z10: 0.1 | AC10: 0 | AF10: 0 | AI10: 0 | AL10: 0 | AO10: 0 | AR10: 0 | AU10: 0
C11: 3 | E11: 中村 | J11: =SUM(N11:AW11) -> 2.3 | N11: 0 | Q11: 0 | T11: 0 | W11: 0 | Z11: 0.2 | AC11: 0.3 | AF11: 0.4 | AI11: 0.3 | AL11: 0.4 | AO11: 0.3 | AR11: 0.2 | AU11: 0.2 | AX11: PL
C12: 4 | E12: 我部山 | J12: =SUM(N12:AW12) -> 0.7 | N12: 0 | Q12: 0 | T12: 0 | W12: 0 | Z12: 0 | AC12: 0 | AF12: 0 | AI12: 0 | AL12: 0.7 | AO12: 0 | AR12: 0 | AU12: 0 | AX12: 製造・単体テスト
C13: 5 | E13: 山下 | J13: =SUM(N13:AW13) -> 0.4 | N13: 0 | Q13: 0 | T13: 0 | W13: 0 | Z13: 0 | AC13: 0 | AF13: 0.1 | AI13: 0.1 | AL13: 0.1 | AO13: 0.1 | AR13: 0 | AU13: 0 | AX13: 設計・製造レビューア
C14: 6 | E14: 西山 | J14: =SUM(N14:AW14) -> 0.9 | N14: 0 | Q14: 0 | T14: 0 | W14: 0 | Z14: 0 | AC14: 0 | AF14: 0 | AI14: 0 | AL14: 0 | AO14: 0.7 | AR14: 0.2 | AU14: 0 | AX14: 環境構築
C15: 7 | E15: 柴田 | J15: =SUM(N15:AW15) -> 2 | N15: 0 | Q15: 0 | T15: 0 | W15: 0 | Z15: 0 | AC15: 0 | AF15: 0 | AI15: 1 | AL15: 0.9 | AO15: 0.1 | AR15: 0 | AU15: 0 | AX15: 製造・単体テスト
C16: 8 | E16: 木田 | J16: =SUM(N16:AW16) -> 4.5 | N16: 0 | Q16: 0 | T16: 0 | W16: 0 | Z16: 0.5 | AC16: 1 | AF16: 1 | AI16: 1 | AL16: 0 | AO16: 1 | AR16: 0 | AU16: 0 | AX16: 要件定義、基本設計、詳細設計、CT、ST
C17: 9 | E17: 小田桐 | J17: =SUM(N17:AW17) -> 1.1 | N17: 0 | Q17: 0 | T17: 0 | W17: 0 | Z17: 0 | AC17: 0 | AF17: 0 | AI17: 0 | AL17: 0.6 | AO17: 0.5 | AR17: 0 | AU17: 0 | AX17: 製造・単体テスト
J18: =SUM(J9:J17) -> 12
J21: 理由

Sheet (別紙3）完了判定計画
A1: システム名 | I1: =タイトル!I40 -> 顧客名：同志社大学 教務システム | AE1: 工 程 | AL1: =タイトル!I43 -> プロジェクト計画 | BI1: 作 成 | BM1: =タイトル!I46 -> 中村 恒太郎 | BW1: =タイトル!I47 -> 45170 | CF1: 管理記号
A2: サブシステム名 | I2: =タイトル!I41 | AE2: ドキュメント | AL2: =タイトル!I44 -> プロジェクト計画書 | BI2: 改 訂
A5: 【別紙３】工程毎の完了判定計画
D6: 中規模
D7: 項番 | F7: 工程 | Q7: インプット | AB7: アウトプット （作業成果物) | AQ7: 品質管理 | BC7: 終了条件 | BU7: 終了基準を満たされない場合の対処 | CM7: 工程完了の承認者
D9: 1 | F9: 設計合否判定 | Q9: ①プロジェクト計画書 ②課題管理表 ③リスク管理表 ④WBS ⑤要件定義のアウトプット ⑥設計工程のアウトプット | AB9: 合否判定会議の議事録 | AQ9: 残課題および残リスクの件数／分析 | BC9: ①要件定義の顧客レビューが完了し、 課題が明確になっている ②製造工程以降の作業計画が完了し 課題が明確になっている ③製造工程以降のリスクが洗出され、 対応方針が決定している。 | BU9: 合否判定会議での決定結果に従う | CM9: ＰＭ
D17: 2 | F17: リリース | Q17: ①プロジェクト計画書 ②課題管理表 ③リスク管理表 ④製造工程のアウトプット ⑤テスト工程のアウトプット | AB17: リリース判定会議の議事録 | AQ17: ・品質目標の分析／評価 ・残課題および残リスク の件数／分析 | BC17: ①品質目標が達成されている。 ②品質目標が達成されていない場合、 品質分析が実施され問題無い事が 確認されている。 ③リリースに影響が有る課題・リスク が全て解決されている。 | BU17: リリース判定会議での決定結果に従う | CM17: ＰＭ
