Workbook
Name _Toc94971774: '1.信頼性'!#REF!
Name _Toc94971774: '2.性能'!#REF!
Name _Toc94971774: '3.運用'!#REF!
Name _Toc94971774: '4.システム構成'!$D$36
Name _Toc94971775: '1.信頼性'!#REF!
Name _Toc94971775: '2.性能'!#REF!
Name _Toc94971775: '3.運用'!#REF!
Name _Toc94971775: '4.システム構成'!#REF!

Sheet タイトル
G11: =I40 -> 学生勤務管理システム
G14: =I44 -> 信頼性・性能・運用設計
G17: =I42
G20: =I51 -> 【 Ver 1.0 】
J27: =TEXT(I47,"yyyy年")&IF(LEFT(TEXT(I47,"mm"),1)="0"," ","")&TEXT(I47,"m月")&IF(LEFT(TEXT(I47,"dd"),1)="0"," ","")&TEXT(I47,"d日")&"作成" -> 2023年11月13日作成
J29: =IF(I49=" ※ページ毎に個別入力"," 年 月 日改訂",TEXT(I49,"yyyy年")&IF(LEFT(TEXT(I49,"mm"),1)="0"," ","")&TEXT(I49,"m月")&IF(LEFT(TEXT(I49,"dd"),1)="0"," ","")&TEXT(I49,"d日")&"改訂") -> 年 月 日改訂
B38: 見出し部タイトル制御テーブル
B39: タイトル項目 | I39: タイトル項目埋め込み内容
B40: ①システム名 | I40: 学生勤務管理システム
B41: ②サブシステム名
B42: ③分類名
B43: ④作業工程名 | I43: システム設計精査業務
B44: ⑤ドキュメント代表名 | I44: 信頼性・性能・運用設計
B45: ⑥ドキュメント詳細名 | I45: ※ページ毎に個別入力
B46: ⑦作成者 | I46: 木田 優
B47: ⑧作成日 | I47: 45243
B48: ⑦改定者 | I48: ※ページ毎に個別入力
B49: ⑧改定日 | I49: ※ページ毎に個別入力
B50: ⑨管理記号 | I50: DUC060
B51: ⑩Ｖｅｒ | I51: 【 Ver 1.0 】
B53: （注1） ①～⑤は、埋め込み内容の先頭１文字は空白にする。
B55: （注2） ⑦と⑧でシート毎に異なる場合は、各シートの該当項目に直接、作成者、作成日を入力する。
B57: (注3） 文字はタイトル部：ＭＳゴシック、本文部：ＭＳ明朝で統一
B59: （注4） 管理番号は、ドキュメント体系の管理番号を使用する。
B61: （注5） ドキュメントＩＤの付け方
C63: 管理記号-分類区分（任意に設定）
C65: ※管理記号は、別紙 プロジェクト計画書のドキュメント体系を参照
B67: (注6） システム階層の概要
C69: システム名 | J69: ⇒ | L69: 教務システム
D71: サブシステム名 | J71: ⇒ | L71: 学籍システム
L72: 開講システム
L73: 登録システム
E75: 機能名
F78: 処理名

Sheet 改訂履歴
A1: 改訂履歴
A3: No | E3: Ver | J3: 変更日 | R3: 区分 | W3: 変更箇所 | AH3: 変更内容 | BR3: 変更者
W4: 頁 | AA4: 項番
A5: 1 | E5: 1 | J5: =タイトル!I47 -> 45243 | R5: 新規 | AH5: 新規作成 | BR5: =タイトル!I46 -> 木田 優
A6: 2 | E6: 1.1 | J6: 45247 | R6: 変更 | AH6: ・ウィルス対策方式で記載するソフト名をWindows Defenderに変更 ・PostgreSQLのバックアップDUMPを7世代管理に変更 | BR6: 木田 優

Sheet 目次
C1: 目次
C5: １． 信頼性
D6: １．１ 障害検知方式 | AC6: ･･･ | AE6: 1
D7: １．２ ウイルス対策方式
D8: １．３ バックアップ方式
C10: ２． 性能
D11: ２．１ APサーバーの性能目標 | AC11: ･･･ | AE11: 3
D12: ２．３ APサーバーの必要性能
D13: ２．４ DBサーバーの性能目標
D14: ２．５ DBサーバーの必要性能
C16: ３． システム運用 | AC16: ･･･ | AE16: 4
D17: ３．１ サービス時間
D18: ３．２ 夜間処理
C20: ４． システム構成 | AC20: ･･･ | AE20: 5
D21: ４．１ ハードウェア構成
D22: ４．２ ソフトウェア構成

Sheet 1.信頼性
A1: システム名 | I1: =タイトル!I40 -> 学生勤務管理システム | AE1: 工 程 | AL1: =タイトル!I43 -> システム設計精査業務 | BG1: 作 成 | BK1: =タイトル!I46 -> 木田 優 | BU1: =改訂履歴!J5 -> 45243 | CD1: 管理記号 | CI1: =タイトル!I50 -> DUC060
A2: サブシステム名 | AE2: ドキュメント | AL2: =タイトル!I44 -> 信頼性・性能・運用設計 | BG2: 改 訂 | BK2: 木田 優 | BU2: 45247
B5: １. 信頼性
C6: １．１ 障害検知方式
E8: 監視サーバ(Amazon CloudWatch)より、定期的な稼動確認を行うことにより、障害検知を行う。 | CR8: AWS環境の障害検知（CLOUD watch）
E25: ① 監視サーバより稼動確認メッセージ送信
E26: ②－１ 各サーバから稼動確認メッセージ返信
E27: ②－２ 障害が発生し稼動確認メッセージが返信できない
C31: １．２ ウイルス対策方式
E33: Webサーバ、APサーバ、DBサーバのサーバに対してウィルス対策ソフトは貴学にて用意いただいたWindows Defenderを導入する。
C49: １．３ バックアップ方式
E51: ・各サーバのバックアップはAWSのバックアップ機能で行う。
F52: 全学サーバ基盤で30世代のバックアップ（スナップショット）を行う。
CR53: AWSのバックアップ機能で行う
E54: ・PostgreSQL のバックアップ（7世代管理）を行う。 | CR54: 同志社作業
CR55: バックアップの世代に関しては同志社にきめてもらう。
CR56: システム的には直前のバックアップさえあれば問題ないので、
R57: pg_dumpの全テーブルのバック | CR57: どれだけ残すか。
R58: アップ作成 | CR58: DBのDUMPは行う。（１世代で提案。要相談）
AG59: 内部領域 | AR59: （7世代管理）
CR60: AWSのバックアップの範囲の確認とリストの状態、時間ってどんなもん？（同志社に確認）
G61: バックアップ | P61: 毎日 | S61: AM 6:00 ～ AM 8:00
E77: バックアップからリストアした後は問い合わせオプティマイザが有用な統計情報を使用できるようにANALYZEを実行する。

Sheet 2.性能
A1: システム名 | I1: =タイトル!I40 -> 学生勤務管理システム | AE1: 工 程 | AL1: =タイトル!I43 -> システム設計精査業務 | BG1: 作 成 | BK1: =タイトル!I46 -> 木田 優 | BU1: =改訂履歴!J5 -> 45243 | CD1: 管理記号 | CI1: =タイトル!I50 -> DUC060
A2: サブシステム名 | AE2: ドキュメント | AL2: =タイトル!I44 -> 信頼性・性能・運用設計 | BG2: 改 訂
B5: ２. 性能
C7: ２．１ APサーバーの性能目標
E9: RFP より、以下の数値を目標値として性能設計を行う。
E11: Webレスポンスタイム | P11: 通常5秒以内、最大15秒以内
C14: ２．２ APサーバーの必要性能
E16: APサーバー（学外用） | X16: APサーバー（学内用）
E17: CPU | L17: 4コア | X17: CPU | AE17: 4コア
E18: メモリ | L18: 16ギガバイト | X18: メモリ | AE18: 32ギガバイト
E19: ディスク | L19: 150ギガバイト | X19: ディスク | AE19: 150ギガバイト
C22: ２．３ DBサーバーの性能目標
E24: RFP より、以下の数値を目標値として性能設計を行う。
CR25: 検証用追記
E26: Webレスポンスタイム | P26: 通常5秒以内、最大15秒以内
E27: バッチ処理時間 | P27: 全バッチを数時間（夜間）で終了すること
C30: ２．４ DBサーバーの必要性能
F32: DBサーバー
F33: CPU | M33: 8コア
F34: メモリ | M34: 32ギガバイト
F35: ディスク | M35: システム SAS 150ギガバイト
F36: DBMS | M36: PostgreSQL 16
E38: 検証環境も同一サーバー内に構築する。

Sheet 3.運用
A1: システム名 | I1: =タイトル!I40 -> 学生勤務管理システム | AE1: 工 程 | AL1: =タイトル!I43 -> システム設計精査業務 | BG1: 作 成 | BK1: =タイトル!I46 -> 木田 優 | BU1: =改訂履歴!J5 -> 45243 | CD1: 管理記号 | CI1: =タイトル!I50 -> DUC060
A2: サブシステム名 | AE2: ドキュメント | AL2: =タイトル!I44 -> 信頼性・性能・運用設計 | BG2: 改 訂
B5: ３. システム運用
C7: ３．１ サービス時間
E9: サービス時間 | N9: 毎日 | Q9: AM 8:00 ～ AM 6:00
C12: ３．２ 夜間処理
E14: RFP より、以下の時間を夜間バッチの目標値として運用設計を行う。
E16: バッチ処理時間 | P16: 全バッチを数時間（夜間）で終了すること
E18: 業務で必要な夜間処理を行う。
E19: 夜間処理については、タスクスケジューラにより処理を起動する。
E20: 統合DBへの最終連携時間が5時19分終了予定（教務システムとの連携）なので、収集のバッファを考慮し、6時からバッチを実行し、統合DBとの連携を行うこととする。
E21: また、「１．３ バックアップ」で記載したデータベースのバックアップも夜間処理として行う。
E23: スケジュール | N23: 毎日 | Q23: AM 6:00 ～ AM 8:00
BR26: 2:00 AWSBK | BZ26: 5:19 統合DB収集終了
Q29: 8 | T29: 9 | W29: 10 | Z29: 11 | AC29: 12 | AF29: 13 | AI29: 14 | AL29: 15 | AO29: 16 | AR29: 17 | AU29: 18 | AX29: 19 | BA29: 20 | BD29: 21 | BG29: 22 | BJ29: 23 | BM29: 0 | BP29: 1 | BS29: 2 | BV29: 3 | BY29: 4 | CB29: 5 | CE29: 6 | CH29: 7
E30: 学生勤務（学内） | Q30: オンライン | CE30: システム停止
E31: 学生勤務（学外） | Q31: オンライン | CE31: システム停止
E32: 学生勤務データベース | Q32: オンライン | CE32: システム停止
E33: 夜間処理 | CE33: バッチ処理

Sheet 4.システム構成
A1: システム名 | I1: =タイトル!I40 -> 学生勤務管理システム | AE1: 工 程 | AL1: =タイトル!I43 -> システム設計精査業務 | BG1: 作 成 | BK1: =タイトル!I46 -> 木田 優 | BU1: =改訂履歴!J5 -> 45243 | CD1: 管理記号 | CI1: =タイトル!I50 -> DUC060
A2: サブシステム名 | AE2: ドキュメント | AL2: =タイトル!I44 -> 信頼性・性能・運用設計 | BG2: 改 訂
B5: ４. システム構成
C7: ４．１ ハードウェア構成
D9: 本システムを構築するに当たって、ハードウェア構成は次の通りとする。
D10: 各サーバーは、貴学にご用意いただいた機器上に構築を行う。サーバーはAWS上にゲストとして構築する。
CR13: 教研ねっとワーク→誰が使える
S14: インターネット | AI14: 教研ネットワーク
CR16: 津田さんに確認
I44: 新規 | T44: 既設
I46: 本番環境 | T46: テスト環境 | AB46: ※テスト環境のサーバーは保守でも利用する。
C49: ４．２ ソフトウェア構成
D51: 本システムを構築するに当たって、ソフトウェア構成は次の通りとする。
D52: OS および ブラウザ 以外は、弊社で用意したソフトウェアを導入する。
E54: ハードウェア | O54: 分類 | V54: 名称 | AT54: バージョン※2 | BD54: メーカー | BO54: 用途
E55: クライアント パソコン※1 | O55: OS | V55: Windows | AT55: 10 または10LTSC | BD55: Microsoft | BO55: デスクトップOS
V56: Mac | AT56: 11(Big Sur)以上 | BD56: Apple | BO56: デスクトップOS
O57: ミドルウェア | V57: Microsoft Edge | AT57: 116以上 | BD57: Microsoft | BO57: ブラウザ
V58: Google Chrome | AT58: 116以上 | BD58: Google | BO58: ブラウザ
V59: Mozilla Firefox | AT59: 117以上 | BD59: Mozilla | BO59: ブラウザ
V60: Safari | AT60: 16.6以上 | BD60: Apple | BO60: ブラウザ
V61: EXCEL | AT61: Office2016以上 | BD61: Microsoft | BO61: Office
E62: クライアント スマートフォン※1 | O62: OS | V62: iOS | AT62: 16以上 | BD62: Apple | BO62: モバイルOS
V63: Android | AT63: 12以上 | BD63: Google | BO63: モバイルOS
O64: ミドルウェア | V64: Safari | AT64: － | BD64: Apple | BO64: ブラウザ
V65: Google Chrome | AT65: － | BD65: Google | BO65: ブラウザ
E66: 学生勤務（学内） APサーバー | O66: OS | V66: Windows Server 2022 Standard Edition | AT66: 2022 | BD66: Microsoft | BO66: OS
O67: ミドルウェア | V67: Apache HTTPD | AT67: 2.4※3 | BD67: Apache | BO67: Webサーバー
V68: Apache Tomcat | AT68: 9.0 | BD68: Apache | BO68: APサーバー
V69: 日立Java | AT69: 1.8.0_371 | BD69: 日立 | BO69: APサーバー
V70: 弊社フレームワーク | AT70: － | BD70: 弊社 | BO70: 画面・バッチ
O71: 開発物件 | V71: 業務アプリケーション | AT71: － | BD71: 弊社 | BO71: 画面・バッチ
E72: 学生勤務フロント APサーバー | O72: OS | V72: Windows Server 2022 Standard Edition | AT72: 2022 | BD72: Microsoft | BO72: OS
O73: ミドルウェア | V73: Apache HTTPD | AT73: 2.4※3 | BD73: Apache | BO73: Webサーバー
V74: Apache Tomcat | AT74: 9.0 | BD74: Apache | BO74: APサーバー
V75: 日立Java | AT75: 1.8.0_371 | BD75: 日立 | BO75: APサーバー
V76: 弊社フレームワーク | AT76: － | BD76: 弊社 | BO76: 画面
O77: 開発物件 | V77: 業務アプリケーション | AT77: － | BD77: 弊社 | BO77: 画面
E78: DBサーバー | O78: OS | V78: Windows Server 2022 Standard Edition | AT78: 2022 | BD78: Microsoft | BO78: OS
O79: ミドルウェア | V79: PostgreSQL 16 | AT79: 16 | BD79: フリーのオープンソース | BO79: データベース
...
