Workbook

Sheet タイトル
G11: =I40 -> 学生勤務管理システム
G14: =I44 -> CK-020_給与計算処理
G17: =I42
G20: =I51 -> 【 Ver 1.20 】
J27: =TEXT(I47,"yyyy年")&IF(LEFT(TEXT(I47,"mm"),1)="0"," ","")&TEXT(I47,"m月")&IF(LEFT(TEXT(I47,"dd"),1)="0"," ","")&TEXT(I47,"d日")&"作成" -> 2023年10月 5日作成
J29: =IF(I49=" ※ページ毎に個別入力"," 年 月 日改訂",TEXT(I49,"yyyy年")&IF(LEFT(TEXT(I49,"mm"),1)="0"," ","")&TEXT(I49,"m月")&IF(LEFT(TEXT(I49,"dd"),1)="0"," ","")&TEXT(I49,"d日")&"改訂") -> 2025年 7月17日改訂
B38: 見出し部タイトル制御テーブル
B39: タイトル項目 | I39: タイトル項目埋め込み内容
B40: ①システム名 | I40: 学生勤務管理システム
B41: ②サブシステム名 | I41: 共通機能
B42: ③分類名
B43: ④作業工程名 | I43: 機能設計
B44: ⑤ドキュメント代表名 | I44: CK-020_給与計算処理
B45: ⑥ドキュメント詳細名 | I45: ※ページ毎に個別入力
B46: ⑦作成者 | I46: 木田 優
B47: ⑧作成日 | I47: 45204
B48: ⑦改定者 | I48: ※ページ毎に個別入力
B49: ⑧改定日 | I49: =TEXT(MAX(改訂履歴!J5:J992),"yyyy/mm/dd") -> 2025/07/17
B50: ⑨管理記号 | I50: DUC010
B51: ⑩Ｖｅｒ | I51: ="【 Ver " & TEXT(MAX(改訂履歴!E5:E992),"0.00") & " 】" -> 【 Ver 1.20 】

Sheet 改訂履歴
A1: 改訂履歴
A3: No | E3: Ver | J3: 新規／改訂日 | R3: 区分 | W3: 改訂箇所 | AH3: 改訂理由 | BR3: 新規／改訂者
W4: 頁 | AA4: 機能
A5: 1 | E5: 1 | J5: =タイトル!I47 -> 45204 | R5: 新規 | AH5: 新規作成 | BR5: 木田 優
A6: 2 | E6: 1.01 | J6: 45224 | R6: 変更 | AH6: タイトルの変更、ダウンロードするフォーマットの変更 | BR6: 木田 優
A7: 3 | E7: 1.02 | J7: 45239 | R7: 変更 | AH7: 二校地間移動回数表の追加と勤務時間アラートフォーマットの変更 | BR7: 木田 優
A8: 4 | E8: 1.03 | J8: 45259 | R8: 変更 | AH8: 勤務時間集計表出力時間の仕様変更 | BR8: 木田 優
A9: 5 | E9: 1.04 | J9: 45265 | R9: 変更 | AH9: 勤務入力時に給与支給日を登録する仕様を変更したため 勤務時間集計表の勤怠集計の仕様が件数になっていたので、時間合計に変更 | BR9: 木田 優
A10: 6 | E10: 1.05 | J10: 45267 | R10: 変更 | AH10: インタフェース定義資料変更に基づくフォーマット内容の変更反映 | BR10: 木田 優
A11: 7 | E11: 1.06 | J11: 45296 | R11: 変更 | AH11: 勤務時間アラートの1セメスターのアラート条件と職種の複数条件時の出力内容の情報を追記 | BR11: 木田 優
A12: 8 | E12: 1.07 | J12: 45315 | R12: 変更 | AA12: 画面遷移図 | AH12: 戻るボタンの廃止 | BR12: 木田 優
A13: 9 | J13: 45315 | R13: 変更 | AA13: 勤務データ仮集計 | AH13: 検索条件の変更 | BR13: 木田 優
A14: 10 | E14: 1.08 | J14: 45454 | R14: 変更 | AA14: 勤務データ仮集計 | AH14: ダウンロードファイル名の変更 （2024年度保守_項番24） | BR14: 木田 優
A15: 11 | E15: 1.09 | J15: 45485 | R15: 変更 | AA15: 給与計算処理 | AH15: 勤務情報集計表と勤務時間仮集計表の勤務時間の端数処理の補足説明を追記 | BR15: 木田 優
A16: 12 | E16: 1.1 | J16: 45510 | R16: 変更 | AA16: 給与計算処理 | AH16: 勤務時間アラートの留学生の週28時間チェックを28時間以上から28時間超に変更 | BR16: 木田 優
A17: 13 | E17: 1.2 | J17: 45855 | R17: 変更 | AA17: 給与計算処理 | AH17: 勤務時間アラートの職種合計の対象職種からSAを除外する 勤務時間アラートを担当者が出力する時、別雇用部課の勤務時間要因によるアラートは出力しない （2025年度改修_項番2） | BR17: 木田 優

Sheet 機能概要・画面遷移図
A1: システム名 | I1: =タイトル!I40 -> 学生勤務管理システム | AE1: 工 程 | AL1: =タイトル!I43 -> 機能設計 | BI1: 作 成 | BM1: =タイトル!I46 -> 木田 優 | BW1: =タイトル!I47 -> 45204 | CF1: 管理記号
A2: サブシステム名 | I2: =タイトル!I41 -> 共通機能 | AE2: ドキュメント | AL2: =タイトル!I44 -> CK-020_給与計算処理 | BI2: 改 訂 | BM2: 木田 優 | BW2: 45315
A4: 機能名称 | I4: =" " & RIGHT(タイトル!I44,LEN(タイトル!I44)-8) -> 給与計算処理 | AL4: 機能ＩＤ | AS4: =LEFT(タイトル!I44,7) -> CK-020 | BI4: 利用想定ユーザー | BT4: 管理者、担当者
A5: 機 能 概 要
B7: 勤務データの給与計算処理を行う時に使用する。
B8: 勤務データの勤務時間集計表、二校地間移動回数表、勤務時間アラート情報、勤務時間集計データ（仮）を出力することができる。
A10: 画 面 遷 移 図
C13: ○ホーム画面（管理者のみ） | AG13: ○給与計算処理画面 | BJ13: 勤務時間集計データ出力
D14: （CC-020-01G） | AH14: （CK-020-01G） | BJ14: 二校地間移動回数データ出力 | CF14: 勤務時間アラート情報出力
V15: 給与計算処理ボタン | AZ15: ＤＬボタン | BJ15: （CK-020-03C） | CF15: （CK-020-05E）
C26: ○ホーム画面（管理者・担当者） | AG26: ○勤務データ仮集計画面
D27: （CC-020-01G） | AH27: （CK-020-02G） | BJ27: 勤務時間集計データ（仮）出力
V28: 勤務データ仮集計 | AZ28: 仮集計ボタン | BJ28: （CK-020-04E）
V29: ボタン

Sheet 給与計算処理
A1: システム名 | I1: =タイトル!I40 -> 学生勤務管理システム | AE1: 工 程 | AL1: 機能設計 | BI1: 作 成 | BM1: =タイトル!I46 -> 木田 優 | BW1: =タイトル!I47 -> 45204 | CF1: 管理記号
A2: サブシステム名 | I2: 共通機能 | AE2: ドキュメント | AL2: =タイトル!I44 -> CK-020_給与計算処理 | BI2: 改 訂 | BM2: 木田 優 | BW2: 45855
A4: 画面名称 | I4: =" " & RIGHT(CELL("filename",A1),LEN(CELL("filename",A1))-FIND("]",CELL("filename",A1))) -> 給与計算処理 | AL4: 画面ＩＤ | AS4: CK-010-02G | BI4: 利用想定ユーザー | BT4: 管理者
A5: 画面レイアウト | BI5: 機能概要
BJ7: ・ | BK7: 勤務データの給与計算処理を行う時に使用する。
BJ8: ・ | BK8: 勤務データの給与計算、給与再計算、勤務時間集計表、
BK9: 勤務時間アラート情報を出力することができる。
BI12: 画面説明 （処理内容・アクション等）
BJ14: ・ | BK14: 支給日は直近の給与計算の対象となる給与支給日を初期値とする。
BJ16: ・ | BK16: 給与計算ボタンを押下すると、確認メッセージを表示したうえで
BK17: 給与計算を行う。
BK18: ※支給日を給与計算済みの日に設定した場合は、給与計算のボタンは
BK19: 給与再計算ボタンに変更する。
BL20: （ただし、当月中に限る）
BK21: ※給与計算処理を行うと、勤務時間集計表、二校地間移動回数表、
BK22: 勤務情報アラート情報を出力する。
BJ24: ・ | BK24: 給与計算済みの支給日を選択した場合は、計算時の勤務データをDL
BK25: できるDLボタンを表示する。
BK26: DLボタンを押下すると、勤務時間集計表、勤務時間アラート情報を
BK27: 出力する。
A38: リストボックス | BI38: 権限による画面制御
A39: 項目名 | K39: 内容 | AW39: 並び順
A40: 支給日（年） | K40: 給与支給日マスタの給与支給日の年 | AW40: 降順
A41: 支給日（月日） | K41: 支給日（年）に一致する給与支給日マスタの給与支給日の月日 | AW41: 降順
BI43: 一覧の並び順
A48: 画 面 補 足 説 明
B50: 〇給与計算時の画面の流れ | AW50: ○入力項目
AW51: 項目名 | BK51: 入力必須 | BP51: 桁数 | BS51: 入力制限等
C52: 給与計算実行 | AW52: 支給日（年） | BK52: 〇 | BP52: － | BS52: リストボックス
AW53: 支給日（月） | BK53: 〇 | BP53: － | BS53: リストボックス
AW55: ○リストボックス
AX56: 【支給日】
AY57: 支給日 | BO57: ▼ | BY57: ▼
BG58: 2023 | BQ58: 9/23
BG59: 2022 | BQ59: 8/23
BG60: 2021 | BQ60: 7/23
AX62: 支給日（年）の選択結果に連動して、支給日（月）のリストボックスを変動させる。
AX63: 支給日（年）を未選択にすると、支給日（月）はクリアする。
AW65: ○給与計算ボタン
AX66: 給与計算の抽出条件に該当する全ての勤務データを集計する。
...

Sheet 勤務データ仮集計
A1: システム名 | I1: =タイトル!I40 -> 学生勤務管理システム | AE1: 工 程 | AL1: 機能設計 | BI1: 作 成 | BM1: =タイトル!I46 -> 木田 優 | BW1: =タイトル!I47 -> 45204 | CF1: 管理記号
A2: サブシステム名 | I2: 共通機能 | AE2: ドキュメント | AL2: =タイトル!I44 -> CK-020_給与計算処理 | BI2: 改 訂 | BM2: 木田 優 | BW2: 45454
A4: 画面名称 | I4: =" " & RIGHT(CELL("filename",A1),LEN(CELL("filename",A1))-FIND("]",CELL("filename",A1))) -> 勤務データ仮集計 | AL4: 画面ＩＤ | AS4: CK-010-02G | BI4: 利用想定ユーザー | BT4: 管理者、担当者
A5: 画面レイアウト | BI5: 機能概要
BJ7: ・ | BK7: 勤務データを集計して勤務時間集計表、勤務時間アラート情報を
BK8: 出力することができる。
BI12: 画面説明 （処理内容・アクション等）
BJ14: ・ | BK14: 支給日は直近の給与計算の対象となる給与支給日を初期値とする。
BJ16: ・ | BK16: 仮集計ボタンを押下すると、出力者が所属する部署に雇用されている
BK17: 学生分の勤務時間仮集計表と勤務時間アラートが出力される。
BK18: ※管理者の場合は、全部署が対象
A38: リストボックス | BI38: 権限による画面制御
A39: 項目名 | K39: 内容 | AW39: 並び順
A40: 支給日（年） | K40: 給与支給日マスタの給与支給日の年 | AW40: 降順
A41: 支給日（月日） | K41: 支給日（年）に一致する給与支給日マスタの給与支給日の月日 | AW41: 降順
BI43: 一覧の並び順
A48: 画 面 補 足 説 明
B50: ○入力項目 | AX50: ○仮集計ボタン
B51: 項目名 | P51: 入力必須 | U51: 桁数 | X51: 入力制限等 | AY51: 出力者が所属する部署に雇用されている学生の勤務データを集計し、集計表を出力する。
B52: 支給日（年） | P52: 〇 | U52: － | X52: リストボックス | AY52: なお、勤務アラートの条件に一致する勤務データが存在した場合は、勤務アラート情報を出力する。
B53: 支給日（月） | P53: 〇 | U53: － | X53: リストボックス | AY53: ※管理者の場合は、全部署が対象
AY55: 仮集計の抽出条件
B56: ○リストボックス | AY56: # | AZ56: 条件
C57: 【支給日】 | AY57: 1 | AZ57: 勤務データの最終ステータスが承認済
D58: 支給日 | T58: ▼ | AD58: ▼ | AY58: 2 | AZ58: 勤務データの勤務日が給与支給日マスタの勤務月まで（ただし、同一年度に限る）
L59: 2023 | V59: 9/23 | AZ59: 例として、給与支給日マスタの勤務月が「2023年10月」の場合、対象となる勤務データは
L60: 2022 | V60: 8/23 | AZ60: 2023年10月31日までの勤務日が登録されている勤務データとする。
L61: 2021 | V61: 7/23
AX62: 〇仮集計フォーマット | BK62: ファイル名：『勤務時間仮集計表_[ユーザID]_yyyymmdd.xlsx』
C63: 支給日（年）の選択結果に連動して、支給日（月）のリストボックスを変動させる。 | AY63: 仮集計表は2シートで構成する。
C64: 支給日（年）を未選択にすると、支給日（月）はクリアする。
AY65: 【シート1：仮集計結果】 | BT65: 【シート2：仮集計対象データ一覧】
AZ66: 項目名 | BU66: 項目名
AZ67: 処理年 | BU67: 処理年
AZ68: 処理月 | BU68: 処理月
AZ69: 学生ID/氏名 | BU69: 学生ID/氏名
AZ70: 複数身分ID | BU70: 複数身分ID
AZ71: 勤怠集計※1（項目IDごとの集計は不要） | BU71: 雇用情報
AZ72: 二校地移動回数 | BU72: 職種
BU73: 開講科目コード
...
