Workbook
Name _Toc94971774: 機能概要・画面遷移図!#REF!
Name _Toc94971775: 機能概要・画面遷移図!#REF!
Name AitemDic: #REF!

Sheet タイトル
G11: =I40 -> 学生勤務管理システム
G14: =I44 -> CK-010_勤務データ承認(照会)
G17: =I42
G20: =I51 -> 【 Ver 1.16 】
J27: =TEXT(I47,"yyyy年")&IF(LEFT(TEXT(I47,"mm"),1)="0"," ","")&TEXT(I47,"m月")&IF(LEFT(TEXT(I47,"dd"),1)="0"," ","")&TEXT(I47,"d日")&"作成" -> 2023年10月 4日作成
J29: =IF(I49=" ※ページ毎に個別入力"," 年 月 日改訂",TEXT(I49,"yyyy年")&IF(LEFT(TEXT(I49,"mm"),1)="0"," ","")&TEXT(I49,"m月")&IF(LEFT(TEXT(I49,"dd"),1)="0"," ","")&TEXT(I49,"d日")&"改訂") -> 2025年11月13日改訂
B38: 見出し部タイトル制御テーブル
B39: タイトル項目 | I39: タイトル項目埋め込み内容
B40: ①システム名 | I40: 学生勤務管理システム
B41: ②サブシステム名 | I41: 共通機能
B42: ③分類名
B43: ④作業工程名 | I43: 機能設計
B44: ⑤ドキュメント代表名 | I44: CK-010_勤務データ承認(照会)
B45: ⑥ドキュメント詳細名 | I45: ※ページ毎に個別入力
B46: ⑦作成者 | I46: 木田 優
B47: ⑧作成日 | I47: 45203
B48: ⑦改定者 | I48: ※ページ毎に個別入力
B49: ⑧改定日 | I49: =TEXT(MAX(改訂履歴!J5:J995),"yyyy/mm/dd") -> 2025/11/13
B50: ⑨管理記号 | I50: DUC010
B51: ⑩Ｖｅｒ | I51: ="【 Ver " & TEXT(MAX(改訂履歴!E5:E995),"0.00") & " 】" -> 【 Ver 1.16 】

Sheet 改訂履歴
A1: 改訂履歴
A3: No | E3: Ver | J3: 新規／改訂日 | R3: 区分 | W3: 改訂箇所 | AH3: 改訂理由 | BR3: 新規／改訂者
W4: 頁 | AA4: 機能
A5: 1 | E5: 1 | J5: =タイトル!I47 -> 45203 | R5: 新規 | AH5: 新規作成 | BR5: 木田 優
A6: 2 | E6: 1.01 | J6: 45224 | R6: 変更 | AH6: 検索条件、一覧表示内容の変更 | BR6: 木田 優
A7: 3 | E7: 1.02 | J7: 45238 | R7: 変更 | AA7: 勤務データ承認 | AH7: 勤務ステータスの詳細情報を追記 承認一括時に再承認待ちの勤務を承認した時にアラートを表示するように追記 担当者の承認画面に教員コード・氏名を追加表示 | BR7: 木田 優
A8: 4 | J8: 45238 | R8: 変更 | AA8: 勤務データUL | AH8: 更新ステータスのデフォルト値の補足説明を追加 | BR8: 木田 優
A9: 5 | E9: 1.03 | J9: 45247 | R9: 変更 | AA9: 勤務データUL | AH9: 勤務データ内容を勤務データフォーマットに追加 | BR9: 木田 優
A10: 6 | E10: 1.04 | J10: 45265 | R10: 変更 | AA10: 機能概要・画面遷移図 | AH10: ホーム画面からの遷移時は、戻るボタンはなしとする 兼任・代理承認画面からの遷移を追加 | BR10: 大久保 梓沙
A11: 7 | E11: 〃 | J11: 45265 | R11: 変更 | AA11: 勤務データ承認（教員） | AH11: ステータスの初期値を変更 学生ID/氏名の活性化制御を削除（職種と雇用部課の両方が選択されていないと、空リストが表示されるため、非活性は不要） 日付をyyyy/m/d形式に変更 | BR11: 大久保 梓沙
A12: 8 | E12: 〃 | J12: 45265 | R12: 変更 | AA12: 勤務データ承認（担当者） | AH12: ステータスの初期値を変更 一覧の表示件数を1,000件に変更 日付をyyyy/m/d形式に変更 | BR12: 大久保 梓沙
A13: 9 | E13: 〃 | J13: 45265 | R13: 変更 | AA13: 勤務データ承認（管理者） | AH13: 一覧の表示件数を1,000件に変更 日付をyyyy/m/d形式に変更 給与計算済かどうかを判定する条件と一覧項目を追加 | BR13: 大久保 梓沙
A14: 10 | E14: 〃 | J14: 45265 | R14: 変更 | AA14: 勤務データUL | AH14: 勤務データの項目を追加 | BR14: 大久保 梓沙
A15: 11 | E15: 〃 | J15: 45265 | R15: 変更 | AA15: 勤務データUL | AH15: メール送信について追記 | BR15: 大久保 梓沙
A16: 12 | E16: 1.05 | J16: 45267 | R16: 変更 | AA16: 勤務データ承認（教員） | AH16: 兼任・代理承認中と文言を表示したイメージを追加 | BR16: 木田 優
A17: 13 | E17: 〃 | J17: 45267 | R17: 変更 | AA17: 勤務データ承認（担当者） | AH17: 兼任・代理承認中と文言を表示したイメージを追加 | BR17: 木田 優
A18: 14 | E18: 1.06 | J18: 45314 | R18: 変更 | AH18: 検索条件、一覧表示内容の変更 | BR18: 木田 優
A19: 15 | E19: 1.07 | J19: 45630 | R19: 変更 | AA19: 勤務データ承認（管理者） 勤務データＵＬ | AH19: 勤務データ承認（管理者）の使用ユーザに担当者を追加 勤務データDLのフォーマット一覧に担当者の照会モードの場合の出力仕様を追加 （2024年度改修_項番1） | BR19: 木田 優
A20: 16 | E20: 1.08 | J20: 45642 | R20: 変更 | AA20: 勤務データ承認（担当者） 勤務データＵＬ | AH20: 担当者承認のみ給与改定日を過ぎた勤務は承認できないように制御を追加 （2024年度改修_項番5） | BR20: 木田 優
A21: 17 | E21: 1.09 | J21: 45803 | R21: 変更 | AA21: 勤務データ承認（教員） 勤務データ承認（担当者） 勤務データ照会（管理者、担当者） | AH21: 支給日（年・月）のデフォルト表示をNULLにする （2025年度改修_項番8） | BR21: 木田 優
A22: 18 | E22: 1.1 | J22: 45814 | R22: 変更 | AA22: 勤務データ承認（教員） 勤務データ承認（担当者） 勤務データ照会（管理者、担当者） | AH22: 検索結果一覧の出力項目を変更 教員・担当者（承認） 追加：「学生ID（学生欄の左）」「勤務内容（校地移動の左）」 削除：「最終更新者」「最終更新日時」 担当者（照会）・管理者 追加：「学生ID（学生欄の左）」のみ 削除：「勤務承認日時」 （2025年度改修_項番4） | BR22: 木田 優
A23: 19 | E23: 1.11 | J23: 45818 | R23: 変更 | AA23: 勤務データ照会（管理者、担当者） 勤務データＵＬ | AH23: 勤務情報入力日（勤務情報最終更新日）の項目を追加する （2025年度改修_項番6） | BR23: 木田 優
A24: 20 | E24: 1.12 | J24: 45818 | R24: 変更 | AA24: 勤務データ承認（教員） 勤務データ承認（担当者） 勤務データ照会（管理者、担当者） | AH24: RAの場合の雇用情報の表示に雇用部課を追加する （2025年度改修_項番7） | BR24: 木田 優
A25: 21 | E25: 1.13 | J25: 45818 | R25: 変更 | AA25: 勤務データＵＬ | AH25: 勤務データダウンロード項目に業務・予算・配分先項目を追加する （2025年度改修_項番9） | BR25: 木田 優
A26: 22 | E26: 1.14 | J26: 45861 | R26: 変更 | AA26: 勤務データ照会（管理者、担当者） | AH26: 支給日（年・月）のデフォルト表示を直近の給与計算の対象となる給与支給日にする。 （2025年度改修_項番8） | BR26: 木田 優
A27: 23 | E27: 1.15 | J27: 45863 | R27: 変更 | AA27: 勤務データ承認（担当者） 勤務データ照会（管理者、担当者） | AH27: 画面を表示したと同時に検索処理を実行する機能の説明を追記 （2025年度改修_項番8） | BR27: 木田 優
A28: 24 | E28: 1.16 | J28: 45974 | R28: 変更 | AA28: 勤務データ照会（管理者、担当者） 勤務データＵＬ | AH28: 勤務情報入力日のタイトルを勤務情報最終更新日に変更する 勤務情報最終更新日の更新補足を追記 （2025年度保守_項番51） | BR28: 木田 優

Sheet 機能概要・画面遷移図
A1: システム名 | I1: =タイトル!I40 -> 学生勤務管理システム | AE1: 工 程 | AL1: =タイトル!I43 -> 機能設計 | BI1: 作 成 | BM1: =タイトル!I46 -> 木田 優 | BW1: =タイトル!I47 -> 45203 | CF1: 管理記号 | CK1: =タイトル!I50 -> DUC010
A2: サブシステム名 | I2: =タイトル!I41 -> 共通機能 | AE2: ドキュメント | AL2: =タイトル!I44 -> CK-010_勤務データ承認(照会) | BI2: 改 訂
A4: 機能名称 | I4: =" " & RIGHT(タイトル!I44,LEN(タイトル!I44)-8) -> 勤務データ承認(照会) | AL4: 機能ＩＤ | AS4: =LEFT(タイトル!I44,7) -> CK-010 | BI4: 利用想定ユーザー | BT4: 管理者・担当者・教員
A5: 機 能 概 要
B7: 登録されている勤務データを承認・修正・差戻・照会する時に使用する。
B8: 勤務データをダウンロード、アップロードを行う時に使用する。
A10: 画 面 遷 移 図
C13: ○ホーム画面（教員、担当者） | AG13: ○勤務データ承認（照会）画面 | BK13: ○勤務入力画面
D14: （CC-020-01G） | AH14: （CK-010-01G） | BL14: （GA-010-01G）
V15: 勤務データ承認ボタン | AZ15: 選択ボタン
AZ20: 戻るボタン
BK24: ○勤務データＵＬ画面
AJ25: 勤務ＤＬ | AZ25: 承認ＵＬボタン | BL25: （CK-010-02G）
AJ26: ボタン
AG27: （CK-010-04E）
AZ30: 戻るボタン
C36: ○ホーム画面（管理者） | AG36: ○勤務データ承認（照会）画面 | BK36: ○勤務入力画面
D37: （CC-020-01G） | AH37: （CK-010-01G） | BL37: （GA-010-01G）
V38: 勤務データ照会ボタン | AZ38: 選択ボタン
AZ43: 戻るボタン
A48: 画 面 遷 移 図
C53: ○兼任・代理承認画面
D54: （CK-030-01G）
X55: 兼任・代理承認へボタン
Y62: ○勤務データ承認（照会）画面
Z63: （CK-010-01G）
C71: ○兼任・代理承認画面
D72: （CK-030-01G）
W75: 兼任・代理承認へボタン

Sheet 勤務データ承認（教員）
A1: システム名 | I1: =タイトル!I40 -> 学生勤務管理システム | AE1: 工 程 | AL1: 機能設計 | BI1: 作 成 | BM1: =タイトル!I46 -> 木田 優 | BW1: =タイトル!I47 -> 45203 | CF1: 管理記号 | CK1: =タイトル!I50 -> DUC010
A2: サブシステム名 | I2: 共通機能 | AE2: ドキュメント | AL2: =タイトル!I44 -> CK-010_勤務データ承認(照会) | BI2: 改 訂 | BM2: 木田 優 | BW2: 45818
A4: 画面名称 | I4: =" " & RIGHT(CELL("filename",A1),LEN(CELL("filename",A1))-FIND("]",CELL("filename",A1))) -> 勤務データ承認（教員） | AL4: 画面ＩＤ | AS4: CK-010-01G | BI4: 利用想定ユーザー | BT4: 教員
A5: 画面レイアウト | BI5: 機能概要
AF7: 一覧を右スクロールした場合 | BJ7: ・ | BK7: 登録されている勤務データを承認・修正・差戻・照会する時に使用する。
BJ8: ・ | BK8: 勤務データのダウンロード、アップロードを行う時に使用する。
BI10: 画面説明 （処理内容・アクション等）
BJ12: ・ | BK12: 支給日は直近の給与計算の対象となる給与支給日を初期値とする。 | CT12: 2025年度改修_項番8
BJ14: ・ | BK14: ステータスは『承認待ち・差戻等」を初期値とする。
BJ16: ・ | BK16: ログインした教員が承認対象になっている勤務データのみを表示する。
BL17: ※教員は勤務承認テーブルの主担当教員コードとログインした教員が
BL18: 持つ教員コードが一致している勤務データを表示
BJ20: ・ | BK20: 画面を表示したと同時に、支給日とステータスを条件にして、 | CT20: 2025年度改修_項番8
BK21: 検索処理を実行する。
BJ23: ・ | BK23: 検索結果の行は30行を最大とし、31行目以降はページング機能を使用して
BK24: 表示する行を切り替える。
BJ26: ・ | BK26: 選択ボタンを押下すると、勤務入力画面を表示する。
BJ28: ・ | BK28: 承認ボタンを押下すると、承認にチェックが入っている勤務データを
BK29: 承認し、次の承認者へ承認申請を行う。
BK30: ※ステータスが差戻の勤務データを含み、一括承認する場合、
BL31: 差戻を含んでいる旨の確認メッセージを表示すること。
BJ33: ・ | BK33: 勤務ＤＬボタンを押下すると、画面に表示されている全結果を
BK34: ＥＸＣＥＬダウンロードする。
BJ36: ・ | BK36: 承認ＵＬボタンを押下すると、勤務データＵＬ画面を表示する。
A38: リストボックス | BI38: 権限による画面制御
A39: 項目名 | K39: 内容 | AW39: 並び順
A40: 支給日（年） | K40: 給与支給マスタの給与支給日の年 | AW40: 降順
A41: 支給日（月日） | K41: 支給日（年）に一致する給与支給日マスタの給与支給日の月日 | AW41: 降順
A42: ステータス | K42: ステータス（※選択肢に「承認待ち・差戻等」を追加し、先頭に表示する）[C00021] | AW42: 昇順
A43: 職種 | K43: 職種 | AW43: 昇順 | BI43: 一覧の並び順
A44: 雇用部課 | K44: 雇用部課 | AW44: 昇順
BJ45: ステータス（昇順）→ 学生ＩＤ[非表示]（昇順）→ 勤務日（昇順）
BJ46: → 勤務時間（昇順）
A48: 画 面 補 足 説 明
B50: ○入力項目（検索条件） | AY50: ○リストボックス（続き）
B51: 項目名 | P51: 入力必須 | U51: 桁数 | X51: 入力制限等 | AY51: 【職種】
B52: 支給日（年） | P52: △ | U52: － | X52: リストボックス | AZ52: 職種 | BU52: ▼ | CT52: 2025年度改修_項番8
B53: 支給日（月） | P53: △ | U53: － | X53: リストボックス | BH53: TA | CT53: 2025年度改修_項番8
B54: ステータス | P54: × | U54: － | X54: リストボックス | BH54: SA
B55: 職種 | P55: × | U55: － | X55: リストボックス | BH55: RA
...

Sheet 勤務データ承認（担当者）
A1: システム名 | I1: =タイトル!I40 -> 学生勤務管理システム | AE1: 工 程 | AL1: 機能設計 | BI1: 作 成 | BM1: =タイトル!I46 -> 木田 優 | BW1: =タイトル!I47 -> 45203 | CF1: 管理記号 | CK1: =タイトル!I50 -> DUC010
A2: サブシステム名 | I2: 共通機能 | AE2: ドキュメント | AL2: =タイトル!I44 -> CK-010_勤務データ承認(照会) | BI2: 改 訂 | BM2: 木田 優 | BW2: 45818
A4: 画面名称 | I4: =" " & RIGHT(CELL("filename",A1),LEN(CELL("filename",A1))-FIND("]",CELL("filename",A1))) -> 勤務データ承認（担当者） | AL4: 画面ＩＤ | AS4: CK-010-01G | BI4: 利用想定ユーザー | BT4: 担当者
A5: 画面レイアウト | BI5: 機能概要
BJ7: ・ | BK7: 登録されている勤務データを承認・修正・差戻・照会する時に使用する。
BJ8: ・ | BK8: 勤務データのダウンロード、アップロードを行う時に使用する。
BI12: 画面説明 （処理内容・アクション等）
BJ14: ・ | BK14: 支給日は直近の給与計算の対象となる給与支給日を初期値とする。 | CT14: 2025年度改修_項番8
BJ16: ・ | BK16: ステータスは『承認待ち・差戻等」を初期値とする。
BJ17: ・ | BK17: 画面を表示したと同時に、ステータスを条件にして、 | CT17: 2025/7/25 追加
BK18: 検索処理を実行する。
BJ19: ・ | BK19: ログインした担当者が承認対象になっている勤務データのみを表示する。
BL20: ※担当者は勤務承認テーブルの雇用部課、承認権限とログインした
BL21: 担当者が持つ雇用部課、承認権限が一致している勤務データを表示
BJ23: ・ | BK23: 検索結果の行は500行を最大とし、501行目以降はページング機能を
BK24: 使用して表示する行を切り替える。
BJ26: ・ | BK26: 選択ボタンを押下すると、勤務入力画面を表示する。
BJ28: ・ | BK28: 承認ボタンを押下すると、承認にチェックが入っている勤務データを
BK29: 承認し、次の承認者へ承認申請を行う。
BK30: ※ステータスが差戻の勤務データを含み、一括承認する場合、
BL31: 差戻を含んでいる旨の確認メッセージを表示すること。
BJ33: ・ | BK33: 勤務ＤＬボタンを押下すると、画面に表示されている全結果を
BK34: ＥＸＣＥＬダウンロードする。
BJ35: ・ | BK35: 承認ＵＬボタンを押下すると、勤務データＵＬ画面を表示する。
A38: リストボックス | BI38: 権限による画面制御
A39: 項目名 | K39: 内容 | AW39: 並び順
A40: 支給日（年） | K40: 給与支給マスタの給与支給日の年 | AW40: 降順
A41: 支給日（月日） | K41: 支給日（年）に一致する給与支給日マスタの給与支給日の月日 | AW41: 降順
A42: ステータス | K42: ステータス（※選択肢に「承認待ち・差戻等」を追加し、先頭に表示する）[C00021] | AW42: 昇順
A43: 職種 | K43: 職種 | AW43: 昇順 | BI43: 一覧の並び順
A44: 雇用部課 | K44: 雇用部課 | AW44: 昇順
BJ45: ステータス（昇順）→ 学生ＩＤ[非表示]（昇順）→ 勤務日（昇順）
BJ46: → 勤務時間（昇順）
A48: 画 面 補 足 説 明
B50: ○入力項目（検索条件） | AY50: ○リストボックス（続き）
B51: 項目名 | P51: 入力必須 | U51: 桁数 | X51: 入力制限等 | BA51: 【雇用部課】
B52: 支給日（年） | P52: △ | U52: － | X52: リストボックス | BB52: 雇用部課 | BW52: ▼ | CT52: 2025年度改修_項番8
B53: 支給日（月） | P53: △ | U53: － | X53: リストボックス | BJ53: 101：法人事務室 | CT53: 2025年度改修_項番8
B54: ステータス | P54: × | U54: － | X54: リストボックス | BJ54: 102：監査室
B55: 職種 | P55: × | U55: － | X55: リストボックス | BJ55: 103：募金課
...

Sheet 勤務データ照会（管理者、担当者）
A1: システム名 | I1: =タイトル!I40 -> 学生勤務管理システム | AE1: 工 程 | AL1: 機能設計 | BI1: 作 成 | BM1: =タイトル!I46 -> 木田 優 | BW1: =タイトル!I47 -> 45203 | CF1: 管理記号 | CK1: =タイトル!I50 -> DUC010
A2: サブシステム名 | I2: 共通機能 | AE2: ドキュメント | AL2: =タイトル!I44 -> CK-010_勤務データ承認(照会) | BI2: 改 訂 | BM2: 木田 優 | BW2: 45818
A4: 画面名称 | I4: =" " & RIGHT(CELL("filename",A1),LEN(CELL("filename",A1))-FIND("]",CELL("filename",A1))) -> 勤務データ照会（管理者、担当者） | AL4: 画面ＩＤ | AS4: CK-010-01G | BI4: 利用想定ユーザー | BT4: 管理者、担当者
A5: 画面レイアウト | BI5: 機能概要
B6: 担当者
BJ7: ・ | BK7: 登録されている勤務データを照会する時に使用する。
BJ8: ・ | BK8: 勤務データのダウンロードを行う時に使用する。
BI12: 画面説明 （処理内容・アクション等）
BJ14: ・ | BK14: 支給日は直近の給与計算の対象となる給与支給日を初期値とする。 | CT14: 2025年度改修_項番8
BJ16: ・ | BK16: ステータスは『承認待ち・差戻等」を初期値とする。
AX18: 管理者 | BJ18: ・ | BK18: 画面を表示したと同時に、支給日とステータスを条件にして、 | CT18: 2025年度改修_項番8
BK19: 検索処理を実行する。 | CT19: 2025/7/25 追加
BJ21: ・ | BK21: 検索結果の行は500行を最大とし、501行目以降はページング機能を
BK22: 使用して表示する行を切り替える。
BJ24: ・ | BK24: 選択ボタンを押下すると、勤務入力画面を表示する。
BJ26: ・ | BK26: 勤務ＤＬボタンを押下すると、画面に表示されている全結果を
BK27: ＥＸＣＥＬダウンロードする。
BJ29: ・ | BK29: 担当者の場合、担当者の雇用部課を初期表示し、雇用部課は非活性とする。
BJ30: ※ | BK30: 担当者の承認権限が4:留学生課担当者,5:留学生課事務長,6:国際センター所長
BK31: の場合、且つ、職種を05：留学生チューターにした場合のみ、雇用部課は
BK32: 活性化し、変更可能とする。
A38: リストボックス | BI38: 権限による画面制御
A39: 項目名 | K39: 内容 | AW39: 並び順
A40: 支給日（年） | K40: 給与支給マスタの給与支給日の年 | AW40: 降順
A41: 支給日（月日） | K41: 支給日（年）に一致する給与支給日マスタの給与支給日の月日 | AW41: 降順
A42: ステータス | K42: ステータス（※選択肢に「承認待ち・差戻等」を追加し、先頭に表示する）[C00021] | AW42: 昇順
A43: 職種 | K43: 職種 | AW43: 昇順 | BI43: 一覧の並び順
A44: 雇用部課 | K44: 雇用部課 | AW44: 昇順
BJ45: ステータス（昇順）→ 雇用部課コード（昇順）
BJ46: → 学生ＩＤ[非表示]（昇順）→ 勤務日（昇順）→ 勤務時間（昇順）
A48: 画 面 補 足 説 明
B50: ○入力項目（検索条件） | AY50: ○リストボックス（続き）
B51: 項目名 | P51: 入力必須 | U51: 桁数 | X51: 入力制限等 | AY51: 【職種】
B52: 支給日（年） | P52: △ | U52: － | X52: リストボックス | AZ52: 職種 | BU52: ▼ | CT52: 2025年度改修_項番8
B53: 支給日（月） | P53: △ | U53: － | X53: リストボックス | BH53: TA | CT53: 2025年度改修_項番8
B54: ステータス | P54: × | U54: － | X54: リストボックス | BH54: SA
B55: 職種 | P55: × | U55: － | X55: リストボックス | BH55: RA
B56: 雇用部課 | P56: × | U56: － | X56: リストボックス | BH56: LA
B57: ※ステータスが『承認待ち・差戻等』以外で支給日（年・月）が空白の場合、エラーメッセージを表示する。 | BH57: 留学生チューター | CT57: 2025年度改修_項番8
C58: エラーメッセージ：ステータスが承認待ち・差戻等以外の場合は支給日を入力してください。 | BH58: 研究活動等支援員
...

Sheet ステータスの流れ
A1: パータン① ・・・通常
B3: 最終ステータス | H3: 最終ステータス | M3: ユーザが行った操作
B4: 承認待ち | H4: 承認済
A5: 学生 | M5: プログラムが自動設定する処理
C6: 申請
A7: 教員（承認階層１） | L7: ステータス
L8: ｘｘｘｘ | M8: 勤務承認テーブルのステータスの状態
B9: ステータス | D9: ステータス
B10: 承認待ち | D10: 承認済 | L10: 最終ステータス
B11: 承認枝番：1 | C11: 承認 | D11: 承認枝番：1 | L11: ｘｘｘｘ | M11: 勤務情報テーブルの最終ステータスの状態
A13: 担当者（承認階層2）
D15: ステータス | F15: ステータス
D16: 承認待ち | E16: 承認 | F16: 承認済
D17: 承認枝番：1 | F17: 承認枝番：1
A19: 最終承認者（承認階層3）
F21: ステータス | H21: ステータス
F22: 承認待ち | H22: 承認済
F23: 承認枝番：1 | G23: 承認 | H23: 承認枝番：1
A25: パータン② ・・・１つ前の承認者に差し戻す
B27: 最終ステータス | P27: 最終ステータス
B28: 承認待ち | P28: 承認済
A29: 学生
C30: 申請
A31: 教員（承認階層１）
B33: ステータス | D33: ステータス | J33: ステータス | K33: 承認 | L33: ステータス
B34: 承認待ち | D34: 承認済 | J34: 差戻 | L34: 承認済
B35: 承認枝番：1 | C35: 承認 | D35: 承認枝番：1 | J35: 承認枝番：3 | L35: 承認枝番：3
A37: 担当者（承認階層2）
D39: ステータス | F39: ステータス | H39: ステータス | I39: 差戻 | J39: ステータス | L39: ステータス | N39: ステータス
D40: 承認待ち | F40: 承認済 | H40: 差戻 | J40: 修正依頼中 | L40: 再承認待ち | N40: 承認済
D41: 承認枝番：1 | E41: 承認 | F41: 承認枝番：1 | H41: 承認枝番：2 | J41: 承認枝番：2 | L41: 承認枝番：3 | M41: 承認 | N41: 承認枝番：3
A43: 最終承認者（承認階層3）
F45: ステータス | H45: ステータス | N45: ステータス | P45: ステータス
F46: 承認待ち | G46: 差戻 | H46: 修正依頼中 | N46: 再承認待ち | P46: 承認済
F47: 承認枝番：1 | H47: 承認枝番：1 | N47: 承認枝番：3 | O47: 承認 | P47: 承認枝番：3
A51: パータン③・・・学生の差し戻す
B53: 最終ステータス | H53: 最終ステータス | J53: 最終ステータス | P53: 最終ステータス
B54: 承認待ち | H54: 差戻 | J54: 再承認待ち | P54: 承認済
A55: 学生
C56: 申請 | K56: 再申請
...

Sheet 勤務データＵＬ
A1: システム名 | I1: =タイトル!I40 -> 学生勤務管理システム | AE1: 工 程 | AL1: 機能設計 | BI1: 作 成 | BM1: =タイトル!I46 -> 木田 優 | BW1: =タイトル!I47 -> 45203 | CF1: 管理記号 | CK1: =タイトル!I50 -> DUC010
A2: サブシステム名 | I2: 共通機能 | AE2: ドキュメント | AL2: =タイトル!I44 -> CK-010_勤務データ承認(照会) | BI2: 改 訂 | BM2: 木田 優 | BW2: 45818
A4: 画面名称 | I4: =" " & RIGHT(CELL("filename",A1),LEN(CELL("filename",A1))-FIND("]",CELL("filename",A1))) -> 勤務データＵＬ | AL4: 画面ＩＤ | AS4: CK-010-02G | BI4: 利用想定ユーザー | BT4: 担当者・教員
A5: 画面レイアウト | BI5: 機能概要
BJ7: ・ | BK7: 勤務データをアップロードし、一括承認を行う時に使用する。
BI12: 画面説明 （処理内容・アクション等）
BJ14: ・ | BK14: 取込ファイルはファイルを取込んだ後に取り込んだファイル名を表示する。
BJ16: ・ | BK16: 実行結果には取込に成功し登録した件数を表示する。
BL17: 承認件数
BJ19: ・ | BK19: アップロードボタンを押下すると、指定されたファイルを取り込む。
BK20: ※取り込む際にバリデーションチェックを行い、エラーがあれば
BL21: 取り込みを中止する。
BK22: ※取り込むデータの元ステータスが差戻で、更新ステータスを１（承認）
BL23: にしている場合は、差戻を含んでいる旨の確認メッセージを
BK24: 表示すること。
A38: リストボックス | BI38: 権限による画面制御
A39: 項目名 | K39: 内容 | AW39: 並び順
BI43: 一覧の並び順
A48: 画 面 補 足 説 明
B50: ○勤務データフォーマット | BH50: 〇エラー時
C51: No. | E51: 項目名 | S51: 備考 | AQ51: ユーザ区分 | BI51: 取込するファイルに問題があり、取込失敗した場合はエラー内容を表示する。
AQ52: 2:教員 | AU52: 3:担当者 | AY52: 3:担当者 | BC52: 4:管理者
AQ53: 勤務データ承認 | AY53: 勤務データ照会
C54: 1 | E54: 更新ステータス※1 | S54: 1：承認、2：修正、3：差戻 ※デフォルトは１ | AQ54: 〇 | AU54: 〇 | AY54: 空白 | BC54: 空白
C55: 2 | E55: 勤務番号 | S55: 変更不可項目 ※勤務データのレコードキー項目 | AQ55: 〇 | AU55: 〇 | AY55: 〇 | BC55: 〇
C56: 3 | E56: 承認階層 | S56: 変更不可項目 ※勤務データのレコードキー項目 | AQ56: 〇 | AU56: 〇 | AY56: 〇 | BC56: 〇
C57: 4 | E57: 承認枝番 | S57: 変更不可項目 ※勤務データのレコードキー項目 | AQ57: 〇 | AU57: 〇 | AY57: 〇 | BC57: 〇
C58: 5 | E58: 勤務日 | S58: 変更不可項目 | AQ58: 〇 | AU58: 〇 | AY58: 〇 | BC58: 〇
C59: 6 | E59: 雇用情報 | S59: 変更不可項目 | AQ59: 〇 | AU59: 〇 | AY59: 〇 | BC59: 〇
C60: 7 | E60: 業務コード | S60: 変更不可項目 | AQ60: 空白 | AU60: 空白 | AY60: 〇 | BC60: 〇 | CT60: 2025年度改修_項番9
C61: 8 | E61: 業務コード名称 | S61: 変更不可項目 | AQ61: 空白 | AU61: 空白 | AY61: 〇 | BC61: 〇 | CT61: 2025年度改修_項番9
C62: 9 | E62: 予算コード | S62: 変更不可項目 | AQ62: 空白 | AU62: 空白 | AY62: 〇 | BC62: 〇 | CT62: 2025年度改修_項番9
C63: 10 | E63: 予算コード名称 | S63: 変更不可項目 | AQ63: 空白 | AU63: 空白 | AY63: 〇 | BC63: 〇 | CT63: 2025年度改修_項番9
C64: 11 | E64: 配分先コード | S64: 変更不可項目 | AQ64: 空白 | AU64: 空白 | AY64: 〇 | BC64: 〇 | CT64: 2025年度改修_項番9
C65: 12 | E65: 配分先コード名称 | S65: 変更不可項目 | AQ65: 空白 | AU65: 空白 | AY65: 〇 | BC65: 〇 | CT65: 2025年度改修_項番9
C66: 13 | E66: 雇用部課 | S66: 変更不可項目 | AQ66: 〇 | AU66: 〇 | AY66: 〇 | BC66: 〇
C67: 14 | E67: 学生ＩＤ | S67: 変更不可項目 | AQ67: 〇 | AU67: 〇 | AY67: 〇 | BC67: 〇 | BI67: 取込みしたデータに不備があり、取込失敗した場合はエラー内容画面ボタンを
C68: 15 | E68: 学生氏名 | S68: 変更不可項目 | AQ68: 〇 | AU68: 〇 | AY68: 〇 | BC68: 〇 | BI68: 表示し、エラー内容ボタン押下でエラー詳細を表示する。
C69: 16 | E69: 複数身分ＩＤ | S69: 変更不可項目 | AQ69: 〇 | AU69: 〇 | AY69: 〇 | BC69: 〇
C70: 17 | E70: ステータス※2 | S70: 変更不可項目 ※取込み前のステータス名 | AQ70: 〇 | AU70: 〇 | AY70: 〇 | BC70: 〇
...
