Workbook
Name _Toc94971774: 'ER図（メール送信）'!#REF!
Name _Toc94971774: 'ER図（給与計算）'!#REF!
Name _Toc94971774: 'ER図（勤務入力）'!#REF!
Name _Toc94971774: 'ER図（雇用情報マスタ）'!#REF!
Name _Toc94971774: 'ER図（社員マスタ）'!#REF!
Name _Toc94971774: 説明!$C$27
Name _Toc94971775: 'ER図（メール送信）'!#REF!
Name _Toc94971775: 'ER図（給与計算）'!#REF!
Name _Toc94971775: 'ER図（勤務入力）'!#REF!
Name _Toc94971775: 'ER図（雇用情報マスタ）'!#REF!
Name _Toc94971775: 'ER図（社員マスタ）'!#REF!
Name _Toc94971775: 説明!#REF!

Sheet 説明
A1: システム名 | I1: =タイトル!I40 -> 学生勤務管理システム | AE1: 工 程 | AL1: =タイトル!I43 -> 基本設計 | BI1: 作 成 | BM1: =タイトル!I46 -> ＫＳＳ | BW1: =タイトル!I47 -> 45196 | CF1: 管理記号 | CK1: =タイトル!I50 -> DUC030
A2: サブシステム名 | I2: =タイトル!I41 | AE2: ドキュメント | AL2: =タイトル!I44 -> データベース設計 | BI2: 改 訂
AL3: =タイトル!I42 -> ER図
C5: ER図（英: Entity-Relationship Diagram, ERD, 実体関連図）とは、システムのデータモデルを図で表現したものである。
C7: ER図は、3つの要素(実体/関連/属性)で構成される：
D9: 記述内容 | AB9: 記述内容の説明
E10: 実体（Entity,エンティティ） | AC10: データのまとまり。
E13: 関連 (Relationship,リレーション) | AC13: 「1対多」などエンティティとエンティティの関係を表す。
E16: 属性 (Attribute,アトリビュート) | AC16: エンティティに関する情報。
C21: 多重度(Cardinality, カーディナリティ) ：リレーションには多重度を記述する。
D22: 表記方法は下記のような二つ種類がある。
D24: ① Aに対してBは、1つ存在(下限が1で上限が1) | AT24: 例）
U26: あるいは、
D29: ② Aに対してBは、1つ以上存在(下限が1で上限が多)
U31: あるいは、
D34: ③ Aに対してBは、0または1つ存在(下限が0で上限が1)
U36: あるいは、
D39: ④ Aに対してBは、0以上存在(下限が0で上限が多)
U41: あるいは、
D44: ※本標準では、左の表記方法を採用する。

Sheet タイトル
G11: =I40 -> 学生勤務管理システム
G14: =I44 -> データベース設計
G17: =I42 -> ER図
G20: =I51 -> 【 Ver 1.20 】
J27: =TEXT(I47,"yyyy年")&IF(LEFT(TEXT(I47,"mm"),1)="0"," ","")&TEXT(I47,"m月")&IF(LEFT(TEXT(I47,"dd"),1)="0"," ","")&TEXT(I47,"d日")&"作成" -> 2023年 9月27日作成
J29: =IF(I49=" ※ページ毎に個別入力"," 年 月 日改訂",TEXT(I49,"yyyy年")&IF(LEFT(TEXT(I49,"mm"),1)="0"," ","")&TEXT(I49,"m月")&IF(LEFT(TEXT(I49,"dd"),1)="0"," ","")&TEXT(I49,"d日")&"改訂") -> 年 月 日改訂
B38: 見出し部タイトル制御テーブル
B39: タイトル項目 | I39: タイトル項目埋め込み内容
B40: ①システム名 | I40: 学生勤務管理システム
B41: ②サブシステム名
B42: ③分類名 | I42: ER図
B43: ④作業工程名 | I43: 基本設計
B44: ⑤ドキュメント代表名 | I44: データベース設計
B45: ⑥ドキュメント詳細名
B46: ⑦作成者 | I46: ＫＳＳ
B47: ⑧作成日 | I47: 45196
B48: ⑦改定者 | I48: ※ページ毎に個別入力
B49: ⑧改定日 | I49: ※ページ毎に個別入力
B50: ⑨管理記号 | I50: DUC030
B51: ⑩Ｖｅｒ | I51: ="【 Ver " & TEXT(MAX(改訂履歴!E5:E1014),"0.00") & " 】" -> 【 Ver 1.20 】
B53: （注1） ①～⑤は、埋め込み内容の先頭１文字は空白にする。
B55: （注2） ⑦と⑧でシート毎に異なる場合は、各シートの該当項目に直接、作成者、作成日を入力する。
B57: （注3） 文字はYu Gothic UIで統一
B59: （注4） 管理番号は、ドキュメント体系の管理番号を使用する。
B61: （注5） ドキュメントＩＤの付け方
C63: 管理記号-分類区分（任意に設定）
C65: ※管理記号は、別紙 プロジェクト計画書のドキュメント体系を参照

Sheet 改訂履歴
A1: 改訂履歴 | G1: =タイトル!I42 -> ER図
A3: No | E3: Ver | J3: 新規／改訂日 | R3: 区分 | W3: 改訂箇所 | AH3: 改訂理由 | BR3: 新規／改訂者
W4: 頁 | AA4: 項番
A5: 1 | E5: 1 | J5: =タイトル!I47 -> 45196 | R5: 新規 | AH5: 新規作成 | BR5: 木田 優
A6: 2 | E6: 1.1 | J6: 45376 | R6: 変更 | AH6: 社員マスタ・雇用情報マスタを分離し、整理 | BR6: 木田 優
A7: 3 | E7: 1.2 | J7: 45377 | R7: 変更 | AH7: 勤務入力・給与計算・メール送信を追加 | BR7: 木田 優

Sheet ER図（社員マスタ）
A1: システム名 | I1: =タイトル!I40 -> 学生勤務管理システム | AE1: 工 程 | AL1: =タイトル!I43 -> 基本設計 | BI1: 作 成 | BM1: =タイトル!I46 -> ＫＳＳ | BW1: =タイトル!I47 -> 45196 | CF1: 管理記号 | CK1: =タイトル!I50 -> DUC030
A2: サブシステム名 | I2: =タイトル!I41 | AE2: ドキュメント | AL2: =タイトル!I44 -> データベース設計 | BI2: 改 訂 | BM2: 木田 優 | BW2: 45376
I3: 社員マスタ | AL3: =タイトル!I42 -> ER図
B5: 学生基本 | F5: ※必要カラムのみ抜粋 | V5: LDAP_ALLテーブル | AP5: 社員マスタ
B6: 学生ID | V6: ユーザID | AP6: 社員ID
B7: 在籍区分※1 | O7: 1 | U7: 1 | V7: 個人ID | AI7: 1 | AO7: 1 | AP7: 漢字氏名 | BE7: 社員マスタの補足説明
B8: 学生所属コード | V8: 学生ID | AP8: 英字氏名 | BE8: ・ | BF8: 教職員の英字氏名はNull
B9: 漢字氏名 | U9: 1 | V9: 教員コード | AO9: 1 | AP9: カナ氏名 | BF9: （社員基本では英字カラムがなく、英字含めて全て姓名に登録されているため）
B10: カナ氏名 | V10: 社員番号 | AP10: 姓 | BE10: ・ | BF10: ユーザ区分は給与支給区分、組織コードによって決定される
B11: 漢字氏名 | V11: 英字氏名 | AP11: 名 | BG11: 1：学生
B12: 英字氏名 | V12: 表示用氏名 | AP12: 在籍区分 | BH12: ※学生基本から連携した場合は全て学生
B13: 在学年次 | V13: 漢字氏名 | AP13: メールアドレス | BG13: 2：教員
B14: 課程コード | V14: メールアドレス | AP14: 留学生情報管理フラグ | BH14: ※給与支給区分（10・21・22・23・24・25・26）によって教員と判断
B15: 学部研究科コード | V15: 構成員コード | AP15: 給与支給区分 | BG15: 3：担当者・事務長
B16: 学科専攻コード | V16: 雇用区分コード | AP16: ユーザ区分 | BH16: ※給与支給区分（30・41・42・52）によって教員と判断
B17: コースクラスターコード | V17: アカウント無効フラグ※1 | AP17: 承認権限 | BG17: 4：管理者（給与厚生課）
B18: 留学生情報管理フラグ | V18: 更新日時 | AP18: 有効フラグ | BH18: ※ユーザコードマスタ（UC0004）のコード値名称5が「1」の組織コードが登録されていると管理者
B19: ※1：籍あり（1）のみ抽出 | V19: ※学生は学生IDが連結キー | AP19: 代理承認フラグ
V20: ※教職員は社員番号が連結キー | AP20: 代理承認者コード1 | BE20: ・ | BF20: 承認権限は給与支給区分、役職コード、組織コードによって決定される
B21: 社員基本 | AP21: 代理承認者コード2 | BG21: 1：教員
B22: ー | AP22: 代理承認者コード3 | BG22: 2：担当者
B23: 会社コード | AP23: 会社コード | BG23: 3：事務長
B24: 社員番号 | O24: 1 | V24: 教員基本 | Z24: ※必要カラムのみ抜粋 | AP24: 認証区分 | BG24: 9：所属長
B25: 姓 | V25: 教員コード | AP25: 雇用部課コード | BG25: 4：留学生課担当者
B26: 名 | O26: 1 | U26: 1 | V26: 人事コード（社員ID） | AI26: 1 | AP26: 社員所属コード | BG26: 5：留学生課事務長
B27: ミドルネーム | AP27: 教員コード | BG27: 6：留学生課センター所長
B28: カナ姓 | AP28: 役職コード | BH28: ※4～6の留学生課はユーザコードマスタ（UC0004）のコード値名称4が「1」の組織コードが
B29: カナ名 | AP29: 学生所属コード | BH29: 登録されている場合、役職が担当者の場合は「4」、事務長の場合は「5」、
B30: カナミドルネーム | AP30: 課程コード | BH30: 所属長の場合は「6」となる
B31: 入社年月日 | AP31: 学部研究科コード
B32: 退職年月日 | AP32: 学科専攻コード
B33: 在籍区分※1 | AP33: コースクラスターコード | BC33: 1
B34: 在籍区分名称 | AP34: 在学年次 | BK34: ユーザコードマスタ | BR34: ※必要カラムのみ抜粋
B35: 給与支給区分 | AP35: ユーザID | BK35: コードID※1
B36: 給与支給区分名称 | AP36: 言語区分 | BK36: コード値 | BZ36: ※1：UC0004/組織マスタ
B37: 組織コード | BK37: コード名称 | CB37: UC0005/役職マスタ
B38: 発令区分 | BJ38: 1 | BK38: ソート順
B39: 兼務順※2 | BK39: コード値名称1
B40: 所属分類コード※3 | BK40: コード値名称2
B41: 組織名称漢字 | BK41: コード値名称3
...

Sheet ER図（雇用情報マスタ）
A1: システム名 | I1: =タイトル!I40 -> 学生勤務管理システム | AE1: 工 程 | AL1: =タイトル!I43 -> 基本設計 | BI1: 作 成 | BM1: =タイトル!I46 -> ＫＳＳ | BW1: =タイトル!I47 -> 45196 | CF1: 管理記号 | CK1: =タイトル!I50 -> DUC030
A2: サブシステム名 | I2: =タイトル!I41 | AE2: ドキュメント | AL2: =タイトル!I44 -> データベース設計 | BI2: 改 訂 | BM2: 木田 優 | BW2: 45376
I3: 雇用情報マスタ | AL3: =タイトル!I42 -> ER図
B5: 雇用情報マスタ | V5: 開講科目マスタ | AB5: ※必要カラムのみ抜粋 | AP5: 科目マスタ | AU5: ※必要カラムのみ抜粋
B6: 雇用情報ID | I6: [Sequence] | V6: 開講年度 | AP6: 科目コード
B7: 雇用年度 | O7: 1 | U7: 1 | V7: 科目コード | AI7: 1 | AO7: 1 | AP7: 科目名
B8: 社員ID | V8: クラスコード | AP8: 科目名（英語）
B9: 職種 | V9: 主担当教員コード | AI9: 1
B10: 雇用部課コード | AP10: 授業マスタ | AU10: ※必要カラムのみ抜粋 | BJ10: 授業担当マスタ | BP10: ※必要カラムのみ抜粋
B11: 科目コード | AP11: 開講年度 | BJ11: 開講年度
B12: クラスコード | AN12: 1..＊ | AP12: 科目コード | BC12: 1 | BI12: 1 | BJ12: 科目コード
B13: 主担当教員コード | AP13: クラスコード | BJ13: クラスコード
B14: 予算区分 | AP14: コマ番 | BC14: 1 | BJ14: コマ番
B15: 雇用開始日 | AP15: 授業期間コード | BJ15: 教員コード
B16: 雇用終了日 | AP16: 曜日コード
B17: 業務コード | O17: 1 | AP17: 講時コード
B18: 予算コード | AP18: 授業開始時間 | BJ18: 学年暦マスタ | BP18: ※必要カラムのみ抜粋
B19: 配分先コード | AP19: 授業終了時間 | BJ19: 年度
B20: 業務内容等 | BI20: 1 | BJ20: 学年暦種別
B21: 複数身分ID | BJ21: 期間コード
B22: 個別単価 | BJ22: 期間開始日
BJ23: 期間終了日
V26: 部署マスタ | AP26: 業務マスタ | BJ26: 予算マスタ
V27: 部署連番 | AP27: 業務連番 | BJ27: 予算連番
U28: 1 | V28: 切替日 | AI28: 1 | AN28: 1..＊ | AP28: 切替日 | BC28: 1 | BI28: 1 | BJ28: 予算回数
V29: 部署コード※1 | AP29: 業務コード | BJ29: 査定回数
V30: 部署名 | AI30: 1 | AP30: 業務名称 | BJ30: 切替日
V31: 部署正式名 | AP31: 業務略称 | BJ31: 予算コード
V32: 無効日 | AP32: ソートキー | BJ32: 申請部署連番
V33: 無効フラグ | AP33: 申請部署連番※1 | BJ33: 業務連番
V34: 付替フラグ | AP34: 無効日 | BJ34: 科目連番
V35: ※1：雇用部課コードと紐づくのは | AP35: ※1：申請部署連番と紐づくのは | BJ35: 予算区分
X36: 部署コード | AR36: 部署マスタの部署連番 | BJ36: 申請摘要1
BJ37: 無効日
AP38: 配分先マスタ
AP39: 配分先連番
AN40: 1..＊ | AP40: 切替日
AP41: 配分先コード
AP42: 配分先名称
AP43: 無効日
...

Sheet ER図（勤務入力）
A1: システム名 | I1: =タイトル!I40 -> 学生勤務管理システム | AE1: 工 程 | AL1: =タイトル!I43 -> 基本設計 | BI1: 作 成 | BM1: =タイトル!I46 -> ＫＳＳ | BW1: =タイトル!I47 -> 45196 | CF1: 管理記号 | CK1: =タイトル!I50 -> DUC030
A2: サブシステム名 | I2: =タイトル!I41 | AE2: ドキュメント | AL2: =タイトル!I44 -> データベース設計 | BI2: 改 訂 | BM2: 木田 優 | BW2: 45377
I3: 勤務入力 | AL3: =タイトル!I42 -> ER図
B5: 雇用情報マスタ | V5: 勤務情報 | AP5: 勤務承認
B6: 雇用情報ID | I6: [Sequence] | V6: 勤務番号 | AC6: [Sequence] | AP6: 勤務番号
B7: 雇用年度 | O7: 1 | T7: 1..＊ | V7: 雇用情報ID | AI7: 1 | AN7: 1..＊ | AP7: 承認階層 | BE7: ※勤務承認テーブルは勤務登録時にユーザコードマスタから承認フローマスタを取得し、
B8: 社員ID | V8: 複数身分ID | AP8: 承認枝番 | BF8: 必要階層分レコードを登録する。なお、次の承認者のみ有効フラグを有効にし、承認者が承認することで
B9: 職種 | O9: 1 | T9: 1..＊ | V9: 社員ID | AN9: 1..＊ | AP9: 主担当教員コード | BF9: 次の承認者（階層）のレコードが有効になるようにする。
B10: 雇用部課コード | V10: 勤務日 | AP10: 雇用部課コード
B11: 科目コード | V11: 曜日区分 | AP11: 承認権限 | BF11: 【承認フローマスタ】 2024/3/25時点
B12: クラスコード | V12: 勤務開始時刻 | AP12: 承認社員ID | BF12: 職種 | BJ12: 承認1 | BO12: 承認2 | BT12: 承認3 | BY12: 承認4 | CD12: 承認5 | CI12: 承認6
B13: 主担当教員コード | V13: 勤務終了時刻 | AP13: ステータス | BF13: 01：TA | BJ13: 1：教員 | BO13: 2：担当者 | BT13: 3：事務長 | BY13: 9：所属長
B14: 予算区分 | V14: 控除時間 | AP14: 処理日時
B15: 雇用開始日 | V15: 勤務内容 | AP15: 有効フラグ | BF15: 02：SA | BJ15: 1：教員 | BO15: 2：担当者 | BT15: 3：事務長 | BY15: 9：所属長
B16: 雇用終了日 | V16: 校地移動フラグ | AP16: 差戻フラグ
B17: 業務コード | V17: 理由 | AP17: 差戻者 | BF17: 03：RA | BJ17: 1：教員 | BO17: 2：担当者 | BT17: 3：事務長
B18: 予算コード | V18: 最終ステータス
B19: 配分先コード | V19: 最終承認日時 | BF19: 04：LA | BJ19: 2：担当者 | BO19: 3：事務長 | BT19: 9：所属長
B20: 業務内容等 | V20: 給与支給日
B21: 複数身分ID | V21: 給与計算処理実施日 | BF21: 05：IS | BJ21: 1：教員 | BO21: 2：担当者 | BT21: 3：事務長 | BY21: 4：留学生課担当者 | CD21: 5：留学生課事務長 | CI21: 6：留学生課センター長
B22: 個別単価
V23: ユーザコードマスタ | AC23: ※必要カラムのみ抜粋 | BF23: 06：RS | BJ23: 6：教員 | BO23: 7：担当者 | BT23: 8：事務長 | BY23: 14：所属長
B24: 社員マスタ | G24: ※必要カラムのみ抜粋 | U24: 1 | V24: コードID※1
B25: 社員ID | V25: コード値 | BF25: 51：PJ | BJ25: 7：教員 | BO25: 8：担当者 | BT25: 9：事務長 | BY25: 15：所属長
B26: 漢字氏名 | O26: 1 | V26: コード名称 | AI26: 1
B27: 英字氏名 | V27: ソート順
B28: カナ氏名 | V28: コード値名称1 | BF28: 【勤務承認レコード例】 | BO28: ※職種TAで学生が勤務入力した時点
B29: 姓 | V29: コード値名称2 | BF29: 勤務番号 | BH29: 承認階層 | BJ29: 承認枝番 | BL29: 主担当教員コード | BP29: 雇用部課コード | BT29: 承認権限 | BW29: 承認社員ID | BZ29: ステータス | CC29: 処理日時 | CF29: 有効フラグ | CI29: 差戻フラグ | CL29: 差戻者
B30: 名 | V30: コード値名称3
V31: コード値名称4
V32: コード値名称5
V33: コード値名称6
V34: ※1：ユーザコードマスタ（UC0003）のコード値が職種と一致するコード値名称1～6を取得し、 | BF34: 1 | BH34: 1 | BJ34: 1 | BL34: 10001 | BP34: Null | BT34: 1 | BW34: Null | BZ34: 3 | CC34: Null | CF34: TRUE | CI34: FALSE | CL34: Null
W35: コード値名称分、勤務承認テーブルの階層を登録する
X36: [承認権限] | BF36: 1 | BH36: 2 | BJ36: 1 | BL36: Null | BP36: 201 | BT36: 2 | BW36: Null | BZ36: 3 | CC36: Null | CF36: FALSE | CI36: FALSE | CL36: Null
X37: 1：教員
X38: 2：担当者 | BF38: 1 | BH38: 3 | BJ38: 1 | BL38: Null | BP38: 201 | BT38: 3 | BW38: Null | BZ38: 3 | CC38: Null | CF38: FALSE | CI38: FALSE | CL38: Null
X39: 3：事務長
X40: 9：所属長 | BF40: 1 | BH40: 4 | BJ40: 1 | BL40: Null | BP40: 201 | BT40: 9 | BW40: Null | BZ40: 3 | CC40: Null | CF40: FALSE | CI40: FALSE | CL40: Null
X41: 4：留学生課担当者
...

Sheet ER図（給与計算）
A1: システム名 | I1: =タイトル!I40 -> 学生勤務管理システム | AE1: 工 程 | AL1: =タイトル!I43 -> 基本設計 | BI1: 作 成 | BM1: =タイトル!I46 -> ＫＳＳ | BW1: =タイトル!I47 -> 45196 | CF1: 管理記号 | CK1: =タイトル!I50 -> DUC030
A2: サブシステム名 | I2: =タイトル!I41 | AE2: ドキュメント | AL2: =タイトル!I44 -> データベース設計 | BI2: 改 訂 | BM2: 木田 優 | BW2: 45377
I3: 給与計算 | AL3: =タイトル!I42 -> ER図
B5: 勤務情報 | V5: 勤務時間集計Work
B6: 勤務番号 | I6: [Sequence] | V6: ー
B7: 雇用情報ID | O7: 1..＊ | T7: 1..＊ | V7: 処理年 | AR7: 【仮集計】
B8: 複数身分ID | V8: 処理月 | AS8: 勤務情報 | BM8: 勤務時間アラート仮Work
B9: 社員ID | O9: 1..＊ | V9: 社員ID | AS9: 勤務番号 | AZ9: [Sequence] | BM9: ー
B10: 勤務日 | V10: 複数身分ID | AS10: 雇用情報ID | BF10: 1..＊ | BK10: 1..＊ | BM10: ログインID
B11: 曜日区分 | O11: 1..＊ | V11: 項目ID | AS11: 複数身分ID | BM11: 部署コード
B12: 勤務開始時刻 | V12: 勤怠集計時間 | AS12: 社員ID | BM12: 部署名
B13: 勤務終了時刻 | AS13: 勤務日 | BM13: 職種名
B14: 控除時間 | V14: 校地移動回数Work | AS14: 曜日区分 | BM14: 社員ID
B15: 勤務内容 | V15: ー | AS15: 勤務開始時刻 | BM15: 漢字氏名
B16: 校地移動フラグ | T16: 1..＊ | V16: 処理年 | AS16: 勤務終了時刻 | BM16: 複数身分ID
B17: 理由 | V17: 処理月 | AS17: 控除時間 | BM17: アラート
B18: 最終ステータス | V18: 社員ID | AS18: 勤務内容 | BM18: 雇用情報
B19: 最終承認日時 | V19: 複数身分ID | AS19: 校地移動フラグ | BM19: 対象期間
B20: 給与支給日 | V20: 項目ID | AS20: 理由 | BM20: 勤務時間
B21: 給与計算処理実施日 | V21: 金額 | AS21: 最終ステータス
AS22: 最終承認日時
V23: 勤務時間アラートWork | AS23: 給与支給日
V24: ー | AS24: 給与計算処理実施日
T25: 1..＊ | V25: 勤務月
V26: 部署コード
V27: 部署名
V28: 職種名
V29: 社員ID
V30: 漢字氏名
V31: 複数身分ID
V32: アラート
V33: 雇用情報
V34: 対象期間
V35: 勤務時間

Sheet ER図（メール送信）
A1: システム名 | I1: =タイトル!I40 -> 学生勤務管理システム | AE1: 工 程 | AL1: =タイトル!I43 -> 基本設計 | BI1: 作 成 | BM1: =タイトル!I46 -> ＫＳＳ | BW1: =タイトル!I47 -> 45196 | CF1: 管理記号 | CK1: =タイトル!I50 -> DUC030
A2: サブシステム名 | I2: =タイトル!I41 | AE2: ドキュメント | AL2: =タイトル!I44 -> データベース設計 | BI2: 改 訂 | BM2: 木田 優 | BW2: 45377
I3: メール送信 | AL3: =タイトル!I42 -> ER図
B5: 勤務情報 | V5: 勤務承認 | AP5: メール管理マスタ | BJ5: メール管理マスタ
B6: 勤務番号 | I6: [Sequence] | V6: 勤務番号 | AP6: メール種別コード | BJ6: メール種別コード
B7: 雇用情報ID | O7: 1 | T7: 1..＊ | V7: 承認階層 | AI7: 1 | AO7: 1 | AP7: メール種別名 | BC7: 1 | BI7: 1 | BJ7: メール置換文言コード
B8: 複数身分ID | V8: 承認枝番 | AP8: メールタイトル | BJ8: メール置換文言説明
B9: 社員ID | V9: 主担当教員コード | AP9: メールタイトル（英語）
B10: 勤務日 | V10: 雇用部課コード | AP10: メール本文
B11: 曜日区分 | V11: 承認権限 | AP11: メール本文英語
B12: 勤務開始時刻 | V12: 承認社員ID | AP12: 同報メール送信先1
B13: 勤務終了時刻 | V13: ステータス | AP13: 同報メール送信先2
B14: 控除時間 | V14: 処理日時 | AP14: 同報メール送信先3
B15: 勤務内容 | V15: 有効フラグ | AP15: 同報メール送信先4
B16: 校地移動フラグ | V16: 差戻フラグ | AP16: 同報メール送信先5
B17: 理由 | V17: 差戻者 | AP17: メール区分
B18: 最終ステータス | AP18: スケジュール送信区分
B19: 最終承認日時
B20: 給与支給日
B21: 給与計算処理実施日
