Workbook
Name _Toc94971774: 機能概要・画面遷移図!#REF!
Name _Toc94971775: 機能概要・画面遷移図!#REF!

Sheet タイトル
G11: =I40 -> 学生勤務管理システム
G14: =I44 -> CZ-020_社員マスタ
G17: =I42
G20: =I51 -> 【 Ver 1.07 】
J27: =TEXT(I47,"yyyy年")&IF(LEFT(TEXT(I47,"mm"),1)="0"," ","")&TEXT(I47,"m月")&IF(LEFT(TEXT(I47,"dd"),1)="0"," ","")&TEXT(I47,"d日")&"作成" -> 2023年 9月28日作成
J29: =IF(I49=" ※ページ毎に個別入力"," 年 月 日改訂",TEXT(I49,"yyyy年")&IF(LEFT(TEXT(I49,"mm"),1)="0"," ","")&TEXT(I49,"m月")&IF(LEFT(TEXT(I49,"dd"),1)="0"," ","")&TEXT(I49,"d日")&"改訂") -> 2024年 1月24日改訂
B38: 見出し部タイトル制御テーブル
B39: タイトル項目 | I39: タイトル項目埋め込み内容
B40: ①システム名 | I40: 学生勤務管理システム
B41: ②サブシステム名 | I41: 共通機能
B42: ③分類名
B43: ④作業工程名 | I43: 機能設計
B44: ⑤ドキュメント代表名 | I44: CZ-020_社員マスタ
B45: ⑥ドキュメント詳細名 | I45: ※ページ毎に個別入力
B46: ⑦作成者 | I46: 木田 優
B47: ⑧作成日 | I47: 45197
B48: ⑦改定者 | I48: ※ページ毎に個別入力
B49: ⑧改定日 | I49: =TEXT(MAX(改訂履歴!J5:J993),"yyyy/mm/dd") -> 2024/01/24
B50: ⑨管理記号 | I50: DUC010
B51: ⑩Ｖｅｒ | I51: ="【 Ver " & TEXT(MAX(改訂履歴!E5:E993),"0.00") & " 】" -> 【 Ver 1.07 】

Sheet 改訂履歴
A1: 改訂履歴
A3: No | E3: Ver | J3: 新規／改訂日 | R3: 区分 | W3: 改訂箇所 | AH3: 改訂理由 | BR3: 新規／改訂者
W4: 頁 | AA4: 機能
A5: 1 | E5: 1 | J5: =タイトル!I47 -> 45197 | R5: 新規 | AH5: 新規作成 | BR5: 木田 優
A6: 2 | E6: 1.01 | J6: 45209 | R6: 変更 | AA6: 社員マスタ | AH6: 社員マスタに学生、承認者、担当者、管理者を判別するユーザ区分を追加 | BR6: 木田 優
A7: 3 | J7: 45209 | R7: 変更 | AA7: 社員マスタ | AH7: 学生/教員/職員所属コードを社員所属コードに統一 | BR7: 木田 優
A8: 4 | J8: 45209 | R8: 変更 | AA8: 社員マスタ編集 | AH8: 学生/教員/職員所属コードを社員所属コードに統一 | BR8: 木田 優
A9: 5 | J9: 45212 | R9: 変更 | AA9: 社員マスタ | AH9: 検索条件の見直し | BR9: 木田 優
A10: 6 | J10: 45212 | R10: 変更 | AA10: 社員マスタ編集 | AH10: 課程を追加 SSO認証社員の権限の変更は不可 | BR10: 木田 優
A11: 7 | E11: 1.02 | J11: 45216 | R11: 変更 | AA11: 社員マスタ、編集 | AH11: 教員コードを追加 | BR11: 木田 優
A12: 8 | J12: 45216 | R12: 変更 | AA12: 社員マスタ | AH12: 検索条件の氏名に入力された情報から英字氏名、カナも検索する | BR12: 木田 優
A13: 9 | J13: 45216 | R13: 変更 | AA13: 社員マスタ | AH13: 社員マスタ連携マトリックスの修正 | BR13: 木田 優
A14: 10 | J14: 45216 | R14: 変更 | AA14: 社員マスタ編集 | AH14: 学生/教職員、権限を削除し、ユーザ区分を追加 教員コードを追加 UA有効フラグを追加 | BR14: 木田 優
A15: 11 | J15: 45223 | R15: 変更 | AA15: 社員マスタ編集 | AH15: アカウントのロックと解除を追加 | BR15: 木田 優
A16: 12 | E16: 1.03 | J16: 45238 | R16: 変更 | AA16: 社員マスタ | AH16: 検索条件、一覧内容を変更 | BR16: 木田 優
A17: 13 | J17: 45238 | R17: 変更 | AA17: 社員マスタ編集 | AH17: ローカルユーザの有効フラグ制御を追加 | BR17: 木田 優
A18: 14 | E18: 1.04 | J18: 45247 | R18: 変更 | AA18: 社員マスタ編集 | AH18: ローカルユーザーの時の有効フラグを必須項目に変更 | BR18: 木田 優
A19: 15 | E19: 1.05 | J19: 45250 | R19: 変更 | AA19: 社員マスタ | AH19: 承認権限の設定仕様を変更 | BR19: 木田 優
A20: 16 | E20: 1.06 | J20: 45261 | R20: 変更 | AA20: 社員マスタ 社員マスタ編集 | AH20: 代理承認を兼任・代理承認に変更するため、仕様を変更 | BR20: 木田 優
A21: 17 | E21: 1.07 | J21: 45315 | R21: 変更 | AA21: 画面遷移図 | AH21: 戻るボタンの廃止 | BR21: 木田 優

Sheet 機能概要・画面遷移図
A1: システム名 | I1: =タイトル!I40 -> 学生勤務管理システム | AE1: 工 程 | AL1: =タイトル!I43 -> 機能設計 | BI1: 作 成 | BM1: =タイトル!I46 -> 木田 優 | BW1: =タイトル!I47 -> 45197 | CF1: 管理記号 | CK1: =タイトル!I50 -> DUC010
A2: サブシステム名 | I2: =タイトル!I41 -> 共通機能 | AE2: ドキュメント | AL2: =タイトル!I44 -> CZ-020_社員マスタ | BI2: 改 訂
A4: 機能名称 | I4: =" " & RIGHT(タイトル!I44,LEN(タイトル!I44)-8) -> 社員マスタ | AL4: 機能ＩＤ | AS4: =LEFT(タイトル!I44,7) -> CZ-020 | BI4: 利用想定ユーザー | BT4: 管理者
A5: 機 能 概 要
B7: 社員マスタを登録・編集する時に使用する。
A10: 画 面 遷 移 図
C13: ○ホーム画面 | AH13: ○社員マスタ画面 | BA13: 新規作成ボタン | BM13: ○社員マスタ編集画面
D14: （CC-020-01G） | AI14: （CZ-020-01G） | BA14: or | BN14: （CZ-020-02G）
V15: 社員マスタボタン | BA15: 選択ボタン
BA20: 戻るボタン

Sheet 社員マスタ
A1: システム名 | I1: =タイトル!I40 -> 学生勤務管理システム | AE1: 工 程 | AL1: 機能設計 | BI1: 作 成 | BM1: =タイトル!I46 -> 木田 優 | BW1: =タイトル!I47 -> 45197 | CF1: 管理記号 | CK1: =タイトル!I50 -> DUC010
A2: サブシステム名 | I2: 共通機能 | AE2: ドキュメント | AL2: =タイトル!I44 -> CZ-020_社員マスタ | BI2: 改 訂 | BM2: 木田 優 | BW2: 45238
A4: 画面名称 | I4: =" " & RIGHT(CELL("filename",A1),LEN(CELL("filename",A1))-FIND("]",CELL("filename",A1))) -> 社員マスタ | AL4: 画面ＩＤ | AS4: CZ-020-01G | BI4: 利用想定ユーザー | BT4: 管理者
A5: 画面レイアウト | BI5: 機能概要
BJ7: ・ | BK7: 社員マスタの照会、登録・編集画面への遷移元画面。
BI12: 画面説明 （処理内容・アクション等）
BJ14: ・ | BK14: 社員検索ボタンを押下すると、社員選択ポップアップを表示する。
BJ16: ・ | BK16: 氏名に入力された情報で英字氏名、カナも部分一致検索を行う。
BJ18: ・ | BK18: 社員所属は雇用部課に該当する所属を表示する。
BK19: ※画面補足説明参照
BJ21: ・ | BK21: 検索結果の行は30行を最大とし、31行目以降はページング機能を使用して
BK22: 表示する行を切り替える。
BJ24: ・ | BK24: 選択ボタンを押下すると、社員マスタ編集画面を表示する。
BJ26: ・ | BK26: 新規作成ボタンを押下すると、社員マスタ編集画面を表示する。
A38: リストボックス | BI38: 権限による画面制御
A39: 項目名 | K39: 内容 | AW39: 並び順
A40: ユーザ区分 | K40: ユーザ区分 | AW40: 昇順
A41: 雇用部課 | K41: 雇用部課 | AW41: 昇順
A42: 社員所属 | K42: 社員所属 | AW42: 昇順
A43: 社員役職 | K43: 社員役職 | AW43: 昇順 | BI43: 一覧の並び順
A44: 認証区分 | K44: 認証区分 | AW44: 昇順
A45: 有効フラグ | K45: 有効フラグ | AW45: 昇順 | BJ45: 社員ＩＤ（昇順）
A48: 画 面 補 足 説 明
B50: ○入力項目（検索条件） | AY50: ○出力項目
B51: 項目名 | P51: 入力必須 | U51: 桁数 | X51: 入力制限等 | AY51: 項目名 | BH51: 編集内容等
B52: 社員ＩＤ | P52: × | U52: 11 | X52: 半角数字、前方一致 | AY52: 社員ID
B53: 氏名 | P53: × | U53: 100 | X53: 英字氏名、カナを含む部分一致 | AY53: 氏名
B54: ユーザ区分 | P54: 〇 | U54: － | X54: リストボックス | AY54: ユーザ区分 | BH54: ユーザ区分名称
B55: 教員コード | P55: × | U55: 6 | X55: 半角数字 | AY55: 社員所属
B56: 雇用部課 | P56: × | U56: － | X56: リストボックス | AY56: 社員役職
B57: 社員所属 | P57: × | U57: － | X57: リストボックス | AY57: 認証 | BH57: 認証区分 ＋ 有効フラグ
B58: 社員役職 | P58: × | U58: － | X58: リストボックス
B59: 認証区分 | P59: × | U59: － | X59: リストボックス
B60: 有効フラグ | P60: × | U60: － | X60: リストボックス
B62: 〇リストボックス
C63: 【ユーザ区分】 | V63: 【社員役職】
D64: ユーザ区分 | S64: ▼ | W64: 社員役職 | AL64: ▼
K65: 学生 | AD65: 総長
K66: 教員 | AD66: 理事長
K67: 担当者 | AD67: 常務理事
...

Sheet 社員マスタ編集
A1: システム名 | I1: =タイトル!I40 -> 学生勤務管理システム | AE1: 工 程 | AL1: 機能設計 | BI1: 作 成 | BM1: =タイトル!I46 -> 木田 優 | BW1: =タイトル!I47 -> 45197 | CF1: 管理記号 | CK1: =タイトル!I50 -> DUC010
A2: サブシステム名 | I2: 共通機能 | AE2: ドキュメント | AL2: =タイトル!I44 -> CZ-020_社員マスタ | BI2: 改 訂 | BM2: 木田 優 | BW2: 45261
A4: 画面名称 | I4: =" " & RIGHT(CELL("filename",A1),LEN(CELL("filename",A1))-FIND("]",CELL("filename",A1))) -> 社員マスタ編集 | AL4: 画面ＩＤ | AS4: CZ-020-02G | BI4: 利用想定ユーザー | BT4: 管理者
A5: 画面レイアウト | BI5: 機能概要
BJ7: ・ | BK7: SSO認証の社員情報を編集する場合に表示される画面。
BK8: 兼任・代理承認者を設定する時に使用する。
BI12: 画面説明 （処理内容・アクション等）
BJ14: ・ | BK14: 社員IDは非活性で表示する。
BJ15: ・ | BK15: ユーザIDは非活性で表示する。
BJ16: ・ | BK16: 氏名は非活性で表示する。
BJ17: ・ | BK17: 英字氏名は非活性で表示する。
BJ18: ・ | BK18: メールアドレスは非活性で表示する。
BJ19: ・ | BK19: ユーザ区分は非活性で表示する。
BJ20: ・ | BK20: 留学生は非活性で表示する。
BJ21: ・ | BK21: 給与支給は非活性で表示する。
BJ23: ・ | BK23: 兼任・代理承認者検索ボタンを押下すると、社員選択ポップアップを
BK24: 表示する。
BK25: ※学生を選択した場合は、エラーメッセージを表示する。
BJ27: ・ | BK27: 雇用部課は非活性で表示する。
BJ28: ・ | BK28: 社員所属は非活性で表示する。
BJ29: ・ | BK29: 社員役職は非活性で表示する。
BJ30: ・ | BK30: 教員コードは非活性で表示する。
BJ31: ・ | BK31: 課程は非活性で表示する。
BJ32: ・ | BK32: 学生在学年次は非活性で表示する。
BJ33: ・ | BK33: 認証区分は非活性で表示する。
BJ34: ・ | BK34: 有効フラグは非活性で表示する。
BJ36: ・ | BK36: 更新ボタンを押下すると、社員マスタの情報を更新する。
A38: リストボックス | BI38: 権限による画面制御
A39: 項目名 | K39: 内容 | AW39: 並び順
A40: 兼任・代理承認 | K40: 兼任・代理承認 | AW40: 昇順 | BJ40: 社員マスタの認証区分が0（SSO認証）の場合に表示される画面となる。
BI43: 一覧の並び順
BJ45: 項番（昇順）
A48: 画 面 補 足 説 明
B50: ○入力項目 | AZ50: 〇リストボックス
B51: 項目名 | P51: 入力必須 | U51: 桁数 | X51: 入力制限等 | AZ51: 【兼任・代理承認】
B52: 兼任・代理承認 | P52: ○ | U52: - | X52: リストボックス | BA52: 兼任・代理承認 | BP52: ▼
B53: 兼任・代理承認者コード1 | P53: △ | U53: 11 | X53: 半角数字 | BH53: 許可しない
B54: 兼任・代理承認者名1 | P54: × | U54: - | X54: 表示項目 | BH54: 許可する
B55: 兼任・代理承認者コード2 | P55: △ | U55: 11 | X55: 半角数字
B56: 兼任・代理承認者名2 | P56: × | U56: - | X56: 表示項目
...
