Workbook
Name _Toc94971774: 機能概要・画面遷移図!#REF!
Name _Toc94971775: 機能概要・画面遷移図!#REF!

Sheet タイトル
G11: =I40 -> 学生勤務管理システム
G14: =I44 -> CZ-010_雇用情報マスタ
G17: =I42
G20: =I51 -> 【 Ver 1.12 】
J27: =TEXT(I47,"yyyy年")&IF(LEFT(TEXT(I47,"mm"),1)="0"," ","")&TEXT(I47,"m月")&IF(LEFT(TEXT(I47,"dd"),1)="0"," ","")&TEXT(I47,"d日")&"作成" -> 2023年 9月27日作成
J29: =IF(I49=" ※ページ毎に個別入力"," 年 月 日改訂",TEXT(I49,"yyyy年")&IF(LEFT(TEXT(I49,"mm"),1)="0"," ","")&TEXT(I49,"m月")&IF(LEFT(TEXT(I49,"dd"),1)="0"," ","")&TEXT(I49,"d日")&"改訂") -> 2025年 6月12日改訂
B38: 見出し部タイトル制御テーブル
B39: タイトル項目 | I39: タイトル項目埋め込み内容
B40: ①システム名 | I40: 学生勤務管理システム
B41: ②サブシステム名 | I41: 共通機能
B42: ③分類名
B43: ④作業工程名 | I43: 機能設計
B44: ⑤ドキュメント代表名 | I44: CZ-010_雇用情報マスタ
B45: ⑥ドキュメント詳細名 | I45: ※ページ毎に個別入力
B46: ⑦作成者 | I46: 木田 優
B47: ⑧作成日 | I47: 45196
B48: ⑦改定者 | I48: ※ページ毎に個別入力
B49: ⑧改定日 | I49: =TEXT(MAX(改訂履歴!J5:J992),"yyyy/mm/dd") -> 2025/06/12
B50: ⑨管理記号 | I50: DUC010
B51: ⑩Ｖｅｒ | I51: ="【 Ver " & TEXT(MAX(改訂履歴!E5:E992),"0.00") & " 】" -> 【 Ver 1.12 】

Sheet 改訂履歴
A1: 改訂履歴
A3: No | E3: Ver | J3: 新規／改訂日 | R3: 区分 | W3: 改訂箇所 | AH3: 改訂理由 | BR3: 新規／改訂者
W4: 頁 | AA4: 機能
A5: 1 | E5: 1 | J5: =タイトル!I47 -> 45196 | R5: 新規 | AH5: 新規作成 | BR5: 木田 優
A6: 2 | E6: 1.01 | J6: 45209 | R6: 変更 | AA6: 雇用情報マスタ | AH6: 人事給与連携データフォーマットを全職種共通仕様に変更 | BR6: 木田 優
A7: 3 | E7: 1.02 | J7: 45216 | R7: 変更 | AA7: 雇用情報マスタ | AH7: 検索条件に開講年度を雇用年度に変更 検索条件に更新日を追加 一覧から身分と複数身分IDを削除 | BR7: 木田 優
A8: 4 | J8: 45216 | R8: 変更 | AA8: 雇用情報マスタ編集 | AH8: 雇用年度の位置を変更し、開講年度を削除 身分を削除 業務、予算、配分先コードをリストボックスに変更 | BR8: 木田 優
A9: 5 | J9: 45216 | R9: 変更 | AA9: 雇用情報マスタ取込 | AH9: 雇用情報データフォーマットを編集項目に合わせて修正 | BR9: 木田 優
A10: 6 | J10: 45223 | R10: 変更 | AA10: 雇用情報マスタ取込 | AH10: 複数身分IDの採番ルールを追記 | BR10: 木田 優
A11: 7 | E11: 1.03 | J11: 45238 | R11: 変更 | AA11: 雇用情報マスタ | AH11: 検索条件の必須条件を追加 一覧に雇用情報を表示 人事給与連携データフォーマットの組織コードの設定内容を変更 | BR11: 木田 優
A12: 8 | J12: 45238 | R12: 変更 | AA12: 雇用情報マスタ編集 | AH12: 職種が一般の場合、業務内容等を必須にする 業務・予算・配分先コードと雇用部課の紐付き説明を追記 | BR12: 木田 優
A13: 9 | J13: 45238 | R13: 変更 | AA13: 雇用情報マスタ取込 | AH13: 雇用情報フォーマットに必須項目列を追加し、補足説明を追記 | BR13: 木田 優
A14: 10 | J14: 45238 | R14: 変更 | AA14: 雇用情報マスタ編集 | AH14: 雇用年度のリストボックスの取得仕様を変更 | BR14: 木田 優
A15: 11 | J15: 45267 | R15: 変更 | AA15: 雇用情報マスタ | AH15: インタフェース定義資料変更に基づくフォーマット内容の変更反映 | BR15: 木田 優
A16: 12 | E16: 1.04 | J16: 45274 | R16: 変更 | AA16: 雇用情報マスタ編集 | AH16: 業務、予算、配分先のリストボックスの抽出キーを雇用部課から部署連番に変更 登録、更新時に過去年度の登録はエラー | BR16: 木田 優
A17: 13 | E17: 1.05 | J17: 45278 | R17: 変更 | AA17: 雇用情報マスタ編集 | AH17: 雇用開始日、終了日を学年暦から取得する際の方法を明記 | BR17: 中村 恒太郎
A18: 14 | J18: 45278 | R18: 変更 | AA18: 雇用情報マスタ編集 | AH18: 一般（学生アルバイト）の複数身分IDの採番方法を見直し。 | BR18: 中村 恒太郎
A19: 15 | J19: 45278 | R19: 変更 | AA19: 雇用情報マスタ | AH19: に情報ダウンロードフォーマット作成日時、最終更新者、処理ＩＤ、更新日時を追加。 | BR19: 中村 恒太郎
A20: 16 | E20: 1.06 | J20: 45314 | R20: 変更 | AA20: 雇用情報マスタ | AH20: 検索条件の削減 | BR20: 木田 優
A21: 17 | J21: 45314 | R21: 変更 | AA21: 雇用情報マスタ編集 | AH21: 複数身分IDの採番ルールを変更 | BR21: 木田 優
A22: 18 | E22: 1.07 | J22: 45454 | R22: 変更 | AA22: 雇用情報マスタ | AH22: ダウンロードファイル名の変更 （2024年度保守_項番24） | BR22: 木田 優
A23: 19 | E23: 1.08 | J23: 45639 | R23: 変更 | AA23: 雇用情報マスタ編集 雇用情報マスタ取込 | AH23: TA/SAの時の教員リストボックスを廃止し、テキストボックスに変更 （2024年度改修_項番2） | BR23: 木田 優
A24: 20 | E24: 1.09 | J24: 45639 | R24: 変更 | AA24: 雇用情報マスタ | AH24: 人事給与連携データフォーマット任意項目コード1に配分先をセットする （2024年度改修_項番3） | BR24: 木田 優
A25: 21 | E25: 1.1 | J25: 45642 | R25: 変更 | AA25: 雇用情報マスタ編集 雇用情報マスタ取込 | AH25: 管理者権限では雇用部課と業務・予算コードの制御を除いて登録できるようにする （2024年度改修_項番4） | BR25: 木田 優
A26: 22 | E26: 1.11 | J26: 45706 | R26: 変更 | AA26: 雇用情報マスタ取込 | AH26: 雇用情報取込時に雇用年度の存在チェックを追加 （2024年度改修_保守３） | BR26: 木田 優
A27: 23 | E27: 1.12 | J27: 45820 | R27: 変更 | AA27: 雇用情報マスタ | AH27: 単価一覧の処理年・月は無条件にNULLを出力する （2025年度改修_項番18） | BR27: 木田 優

Sheet 機能概要・画面遷移図
A1: システム名 | I1: =タイトル!I40 -> 学生勤務管理システム | AE1: 工 程 | AL1: =タイトル!I43 -> 機能設計 | BI1: 作 成 | BM1: =タイトル!I46 -> 木田 優 | BW1: =タイトル!I47 -> 45196 | CF1: 管理記号 | CK1: =タイトル!I50 -> DUC010
A2: サブシステム名 | I2: =タイトル!I41 -> 共通機能 | AE2: ドキュメント | AL2: =タイトル!I44 -> CZ-010_雇用情報マスタ | BI2: 改 訂
A4: 機能名称 | I4: =" " & RIGHT(タイトル!I44,LEN(タイトル!I44)-8) -> 雇用情報マスタ | AL4: 機能ＩＤ | AS4: =LEFT(タイトル!I44,7) -> CZ-010 | BI4: 利用想定ユーザー | BT4: 管理者・担当者
A5: 機 能 概 要
B7: 雇用情報を登録・編集・照会する時に使用する。
B8: EXCELを取り込み、雇用情報の一括登録（更新）をする時に使用する。
A10: 画 面 遷 移 図
C13: ○ホーム画面 | AH13: ○雇用情報マスタ画面 | BK13: ○雇用情報マスタ編集画面
D14: （CC-020-01G） | AI14: （CZ-010-01G） | BA14: 選択ボタン | BL14: （CZ-010-02G）
V15: 雇用情報マスタボタン | BA15: or
BA16: 新規作成ボタン
BA20: 戻るボタン
P25: 人事給与連携データ作成ボタン | AK25: 雇用情報ダウンロード
Q26: （CZ-010-03C） | AK26: ボタン | BC26: 雇用情報取込ボタン
AH27: （CZ-010-06E） | AS27: 戻るボタン
AV29: ○雇用情報マスタ取込画面
AW30: （CZ-010-04G）

Sheet 雇用情報マスタ
A1: システム名 | I1: =タイトル!I40 -> 学生勤務管理システム | AE1: 工 程 | AL1: 機能設計 | BI1: 作 成 | BM1: =タイトル!I46 -> 木田 優 | BW1: =タイトル!I47 -> 45196 | CF1: 管理記号 | CK1: =タイトル!I50 -> DUC010
A2: サブシステム名 | I2: 共通機能 | AE2: ドキュメント | AL2: =タイトル!I44 -> CZ-010_雇用情報マスタ | BI2: 改 訂 | BM2: 木田 優 | BW2: 45820
A4: 画面名称 | I4: =" " & RIGHT(CELL("filename",A1),LEN(CELL("filename",A1))-FIND("]",CELL("filename",A1))) -> 雇用情報マスタ | AL4: 画面ＩＤ | AS4: CZ-010-01G | BI4: 利用想定ユーザー | BT4: 管理者、担当者
A5: 画面レイアウト | BI5: 機能概要
BJ7: ・ | BK7: 雇用情報を登録・照会・編集する時に使用する。
BJ8: ・ | BK8: 雇用マスタ取込画面への遷移機能がある。
BJ9: ・ | BK9: 照会した結果を人事給与連携データとしてＣＳＶ出力することができる。
BJ10: ・ | BK10: EXCELを取り込み、雇用情報の一括登録（更新）をする時に使用する。
BI12: 画面説明 （処理内容・アクション等）
BJ14: ・ | BK14: 雇用年度はシステム日付に該当する年度を初期表示する。
BJ15: ・ | BK15: 更新日のカレンダーを押下すると、カレンダーを表示する。
BJ17: ・ | BK17: 雇用年度、学生ID、学生氏名、雇用部課
BK18: のいづれかが検索条件にないとエラーとする。
BJ20: ・ | BK20: 検索ボタンを押下すると、入力された検索条件を基に該当する雇用情報を
BK21: 表示する。
BJ22: ・ | BK22: 検索結果の行は30行を最大とし、31行目以降はページング機能を使用して
BK23: 表示する行を切り替える。
BJ25: ・ | BK25: 選択ボタンを押下すると、雇用情報マスタ編集画面を表示する。
BJ27: ・ | BK27: 新規作成ボタンを押下すると、雇用情報マスタ編集画面を表示する。
BJ29: ・ | BK29: 雇用情報ダウンロードボタンを押下すると、画面に表示されている全結果を
BK30: ＥＸＣＥＬダウンロードする。
BJ32: ・ | BK32: 雇用情報取込ボタンを押下すると、雇用情報マスタ取込画面を表示する。
BJ34: ・ | BK34: 人事給与連携データ作成ボタンを押下すると、画面に表示されている
BK35: 全結果をＣＳＶ出力する。
BK36: 又、併せて複数身分ＩＤごとの単価一覧をＥＸＣＥＬ出力する。
A38: リストボックス | BI38: 権限による画面制御
A39: 項目名 | K39: 内容 | AW39: 並び順
A40: 雇用年度 | K40: 雇用情報マスタの雇用年度をグループ化して表示 | AW40: 雇用年度の降順 | BJ40: 権限が担当者の場合は、人事給与連携データ作成ボタンは非表示にする。
A41: 職種 | K41: 職種 | AW41: 昇順
A42: 雇用部課 | K42: 雇用部課 | AW42: 昇順
BI43: 一覧の並び順
BJ45: 雇用年度（昇順）→学生ID（昇順）→雇用情報ID（昇順）
A48: 画 面 補 足 説 明
B50: ○入力項目（検索条件） | AY50: ○リストボックス（続き）
B51: 項目名 | P51: 入力必須 | U51: 桁数 | X51: 入力制限等 | AZ51: 【雇用部課】
B52: 雇用年度 | P52: △ | U52: - | X52: リストボックス | BA52: 雇用部課 | BW52: ▼
B53: 学生ID | P53: △ | U53: 11 | X53: 半角数字、前方一致検索 | BH53: 101：法人事務室
B54: 学生氏名 | P54: △ | U54: 100 | X54: 前方一致検索 | BH54: 102：監査室
B55: 職種 | P55: × | U55: - | X55: リストボックス | BH55: 103：募金課
B56: 雇用部課 | P56: △ | U56: 3 | BH56: 104：150周年記念事務室
...

Sheet 雇用情報マスタ編集
A1: システム名 | I1: =タイトル!I40 -> 学生勤務管理システム | AE1: 工 程 | AL1: 機能設計 | BI1: 作 成 | BM1: =タイトル!I46 -> 木田 優 | BW1: =タイトル!I47 -> 45196 | CF1: 管理記号 | CK1: =タイトル!I50 -> DUC010
A2: サブシステム名 | I2: 共通機能 | AE2: ドキュメント | AL2: =タイトル!I44 -> CZ-010_雇用情報マスタ | BI2: 改 訂 | BM2: 木田 優 | BW2: 45642
A4: 画面名称 | I4: =" " & RIGHT(CELL("filename",A1),LEN(CELL("filename",A1))-FIND("]",CELL("filename",A1))) -> 雇用情報マスタ編集 | AL4: 画面ＩＤ | AS4: CZ-010-02G | BI4: 利用想定ユーザー | BT4: 管理者、担当者
A5: 画面レイアウト | BI5: 機能概要
BJ7: ・ | BK7: 雇用情報を登録・編集・削除する時に使用する。
BI12: 画面説明 （処理内容・アクション等）
BJ14: ・ | BK14: 学生検索ボタンを押下すると、社員選択ポップアップを表示する。
BJ16: ・ | BK16: 科目検索ボタンを押下すると、科目選択ポップアップを表示する。
BJ18: ・ | BK18: 雇用開始日、雇用終了日のカレンダーを押下すると、
BK19: カレンダーを表示する。
BJ21: ・ | BK21: 職種によって、必須項目が変動する。
BK22: ※画面補足説明参照
BJ24: ・ | BK24: 登録、更新時に雇用年度がシステム日付の年度より過去年度の場合は、
BK25: 登録、更新できないようにエラーを表示する。
BK26: 「システム日付年度より過去の年度は登録できません。」
A38: リストボックス | BI38: 権限による画面制御
A39: 項目名 | K39: 内容 | AW39: 並び順
A40: 雇用年度 | K40: 給与支給日マスタの雇用年度をグループ化して表示 | AW40: 降順
A41: 職種 | K41: 職種 | AW41: 昇順
A42: 雇用部課 | K42: 雇用部課 | AW42: 昇順
A43: 予算区分 | K43: 予算区分 | AW43: 昇順 | BI43: 一覧の並び順
A44: 業務コード | K44: 業務 | AW44: 昇順
A45: 予算コード | K45: 予算 | AW45: 昇順
A46: 配分先コード | K46: 配分先 | AW46: 昇順
A48: 画 面 補 足 説 明
B50: 〇個別単価について | AW50: ○入力項目
C51: 職種からユーザコードマスタ[UC0001]（職種マスタ）を参照し、個別単価設定可否フラグが1（可）の | AW51: 項目名 | BK51: 入力必須 | BP51: 桁数 | BS51: 入力制限等
C52: 場合、活性にて表示する。個別単価設定可否フラグが0（否）の場合、非活性にて表示する。 | AW52: 雇用情報ＩＤ | BK52: × | BP52: - | BS52: 新規作成：登録時に採番するので空白を表示 編集：登録されている雇用情報ＩＤを表示
C54: 活性 | AW54: 雇用年度 | BK54: 〇 | BP54: - | BS54: リストボックス ※新規作成の場合、システム日付より年度を設定
D55: 個別単価
AW56: 学生ID | BK56: 〇 | BP56: 11 | BS56: 半角数字
AW57: 学生氏名 | BK57: × | BP57: - | BS57: 表示項目
C58: 非活性 | AW58: 職種 | BK58: 〇 | BP58: - | BS58: リストボックス
D59: 個別単価 | AW59: 雇用部課 | BK59: 〇 | BP59: - | BS59: リストボックス
AW61: ●選択した職種によって科目コードから雇用終了日の制御が異なる
B62: 〇 | C62: 登録モード、編集モードの切替 | AW62: 職種：TA・SA
C63: 雇用情報マスタ画面の新規作成ボタンを押下し、雇用情報編集画面を表示した場合は、登録モードとする。 | AW63: 科目コード | BK63: 〇 | BP63: 8 | BS63: 半角数字
C64: 雇用情報マスタ画面の選択ボタンを押下し、雇用情報編集画面を表示した場合は、編集モードとする。 | AW64: クラスコード | BK64: 〇 | BP64: 3 | BS64: 半角数字
C65: 登録モード、編集モードではフッタ部のボタンの表示を変更する。 | AW65: 科目名 | BK65: × | BP65: - | BS65: 表示項目
AW66: 教員 | BK66: 〇 | BP66: - | BS66: 社員選択ポップアップより教員を選択
...

Sheet 雇用情報マスタ取込
A1: システム名 | I1: =タイトル!I40 -> 学生勤務管理システム | AE1: 工 程 | AL1: 機能設計 | BI1: 作 成 | BM1: =タイトル!I46 -> 木田 優 | BW1: =タイトル!I47 -> 45196 | CF1: 管理記号 | CK1: =タイトル!I50 -> DUC010
A2: サブシステム名 | I2: 共通機能 | AE2: ドキュメント | AL2: =タイトル!I44 -> CZ-010_雇用情報マスタ | BI2: 改 訂 | BM2: 木田 優 | BW2: 45706
A4: 画面名称 | I4: =" " & RIGHT(CELL("filename",A1),LEN(CELL("filename",A1))-FIND("]",CELL("filename",A1))) -> 雇用情報マスタ取込 | AL4: 画面ＩＤ | AS4: CZ-010-04G | BI4: 利用想定ユーザー | BT4: 管理者、担当者
A5: 画面レイアウト | BI5: 機能概要
BJ7: ・ | BK7: 雇用情報マスタの一括登録又は一括更新を行う時に使用する。
BI12: 画面説明 （処理内容・アクション等）
BJ14: ・ | BK14: 取込ファイルはファイルを取込んだ後に取り込んだファイル名を表示する。
BJ16: ・ | BK16: 実行結果には入力されていた件数と取込に成功し登録した件数を表示する。
BJ18: ・ | BK18: アップロードボタンを押下すると、指定されたファイルを取り込む。
BK19: ※取り込む際にバリデーションチェックを行い、エラーがあれば
BL20: 取り込みを中止する。
BK21: ※管理者に限り、取込時のエラーチェックに特別対応が存在する
BL22: （画面補足説明の「管理者限定の特別対応について」参照）
A38: リストボックス | BI38: 権限による画面制御
A39: 項目名 | K39: 内容 | AW39: 並び順
BI43: 一覧の並び順
A48: 画 面 補 足 説 明
B50: ○雇用情報データフォーマット | AX50: 〇複数身分IDの採番ルール
C51: 項目名 | Q51: 入力必須 | V51: 備考 | AY51: 登録する各項目より複数身分IDを採番する
C52: 雇用情報通番 | Q52: 〇 | V52: 新規の時は空白、変更の時は雇用情報ダウンロード時に出力されている番号のまま
BE53: 1 | BH53: 0 | BK53: 1 | BN53: t | BQ53: a | BT53: 0 | BW53: 0 | BZ53: 1
C54: 雇用年度 | Q54: 〇
C55: 社員番号 | Q55: 〇 | V55: 学生ＩＤ
C56: 職種 | Q56: 〇 | V56: 01：ＴＡ、02：ＳＡ、03：ＲＡ、04：ＬＡ、05：留学生チューター、06：研究活動等支援員、51：一般
AY57: 未使用 | BB57: 未使用 | BE57: 雇用部課コード | BN57: 職種コード | BT57: 学生 | BW57: 予算区分
C58: 雇用部課コード | Q58: 〇 | V58: 101：法人事務室、102：監査室、103：募金課・・・・
C59: 予算区分 | Q59: 〇 | V59: 00：－、01：TA 学部、02：TA 大学院 ・・・・・ | AY59: (１）雇用部課コード | BJ59: ： | BL59: 学生雇用を募集した部課コードを表す。
C60: 科目コード | Q60: △ | BL60: ※入力されている雇用部課をそのまま設定
C61: クラスコード | Q61: △ | AY61: (２）職種コード | BJ61: ： | BL61: 学生雇用を募集した職種コードを表す。
C62: 科目名 | Q62: △ | BL62: ※ユーザコードマスタ[UC0001]（職種マスタ）より職種に
C63: 教員コード | Q63: △ | BL63: 一致する名称3を設定
C64: 雇用開始日 | Q64: 〇 | AY64: (３）学生所属コード | BJ64: ： | BL64: 学生基本の学生所属コード・在学年次を表す。
C65: 雇用終了日 | Q65: 〇 | BL65: ※学生所属コードの先頭1桁目でコードマスタ[C00003]に
C66: 業務コード | Q66: × | BL66: 一致するコード値名称1を設定
C67: 予算コード | Q67: × | AY67: (４）予算区分コード | BJ67: ： | BL67: 学生雇用の予算を表す。
C68: 配分先コード | Q68: × | BL68: ※入力されている予算区分を設定
C69: 業務内容等 | Q69: △ | BL69: ※職種が一般の場合、重複チェックあり
C70: 複数身分ＩＤ | Q70: - | V70: 新規の時は空白、変更の時は雇用情報ダウンロード時に出力されている番号のまま
AZ71: 職種コード
C72: 個別単価 | Q72: × | BA72: 職種コード | BG72: 職種 | BP72: 変換値
...
