Workbook

Sheet タイトル
G11: =I40 -> 学生勤務管理システム
G14: =I44 -> CZ-040_メール自動送信
G17: =I42
G20: =I51 -> 【 Ver 1.03 】
J27: =TEXT(I47,"yyyy年")&IF(LEFT(TEXT(I47,"mm"),1)="0"," ","")&TEXT(I47,"m月")&IF(LEFT(TEXT(I47,"dd"),1)="0"," ","")&TEXT(I47,"d日")&"作成" -> 2023年10月 6日作成
J29: =IF(I49=" ※ページ毎に個別入力"," 年 月 日改訂",TEXT(I49,"yyyy年")&IF(LEFT(TEXT(I49,"mm"),1)="0"," ","")&TEXT(I49,"m月")&IF(LEFT(TEXT(I49,"dd"),1)="0"," ","")&TEXT(I49,"d日")&"改訂") -> 2025年 6月11日改訂
B38: 見出し部タイトル制御テーブル
B39: タイトル項目 | I39: タイトル項目埋め込み内容
B40: ①システム名 | I40: 学生勤務管理システム
B41: ②サブシステム名 | I41: 共通機能
B42: ③分類名
B43: ④作業工程名 | I43: 機能設計
B44: ⑤ドキュメント代表名 | I44: CZ-040_メール自動送信
B45: ⑥ドキュメント詳細名 | I45: ※ページ毎に個別入力
B46: ⑦作成者 | I46: 木田 優
B47: ⑧作成日 | I47: 45205
B48: ⑦改定者 | I48: ※ページ毎に個別入力
B49: ⑧改定日 | I49: =TEXT(MAX(改訂履歴!J5:J1007),"yyyy/mm/dd") -> 2025/06/11
B50: ⑨管理記号 | I50: DUC010
B51: ⑩Ｖｅｒ | I51: ="【 Ver " & TEXT(MAX(改訂履歴!E5:E995),"0.00") & " 】" -> 【 Ver 1.03 】

Sheet 改訂履歴
A1: 改訂履歴
A3: No | E3: Ver | J3: 新規／改訂日 | R3: 区分 | W3: 改訂箇所 | AH3: 改訂理由 | BR3: 新規／改訂者
W4: 頁 | AA4: 機能
A5: 1 | E5: 1 | J5: =タイトル!I47 -> 45205 | R5: 新規 | AH5: 新規作成 | BR5: 木田 優
A6: 2 | E6: 1.01 | J6: 45238 | R6: 変更 | AA6: メール自動送信 | AH6: メール自動送信対象に代理入力時を追加 勤務申請・修正・差戻時のスケジュール送信を削除 | BR6: 木田 優
A7: 3 | E7: 1.02 | J7: 45315 | R7: 変更 | AA7: メール自動送信 | AH7: スケジュール送信するメール以外の記載を削除 | BR7: 木田 優
A8: 4 | E8: 1.03 | J8: 45819 | R8: 変更 | AA8: メール自動送信 | AH8: 教員へのメールは通知を許可している教員のみに変更 ←廃止 （2025年度改修_項番11） | BR8: 木田 優

Sheet 機能概要・機能説明
A1: システム名 | I1: =タイトル!I40 -> 学生勤務管理システム | AE1: 工 程 | AL1: =タイトル!I43 -> 機能設計 | BI1: 作 成 | BM1: =タイトル!I46 -> 木田 優 | BW1: =タイトル!I47 -> 45205 | CF1: 管理記号 | CK1: =タイトル!I50 -> DUC010
A2: サブシステム名 | I2: =タイトル!I41 -> 共通機能 | AE2: ドキュメント | AL2: =タイトル!I44 -> CZ-040_メール自動送信 | BI2: 改 訂
A4: 機能名称 | I4: =" " & RIGHT(タイトル!I44,LEN(タイトル!I44)-8) -> メール自動送信 | AL4: 機能ＩＤ | AS4: =LEFT(タイトル!I44,7) -> CZ-040 | BI4: 利用想定ユーザー | BT4: 管理者
A5: 機 能 概 要
B7: ・指定された日時にメールを自動送信する機能。
C8: スケジュールはタスクスケジューラで設定することとする。
A10: 機 能 説 明
B12: 【メールの自動送信イメージ】
C14: 1.タスクスケジューラでメール自動送信バッチを起動 （メールIDをバッチの引数に指定）
L19: 名前 | S19: トリガー | AD19: 引数
L20: 督促 | S20: 毎月1日 8:30に起動 | AD20: CZ-04003B
C28: 2.メール自動送信テーブルから起動するバッチを取得し、バッチを起動
E30: バッチID | T30: バッチ名
E31: CZ-040-03B | T31: 督促メール送信
AX39: メール送信
AY40: 学生・教員

Sheet メール自動送信
A1: システム名 | I1: =タイトル!I40 -> 学生勤務管理システム | AE1: 工 程 | AL1: =タイトル!I43 -> 機能設計 | BI1: 作 成 | BM1: =タイトル!I46 -> 木田 優 | BW1: =タイトル!I47 -> 45205 | CF1: 管理記号 | CK1: =タイトル!I50 -> DUC010
A2: サブシステム名 | I2: =タイトル!I41 -> 共通機能 | AE2: ドキュメント | AL2: =タイトル!I44 -> CZ-040_メール自動送信 | BI2: 改 訂 | BM2: 木田 優 | BW2: 45819
A4: 機能名称 | I4: =" " & RIGHT(CELL("filename",A1),LEN(CELL("filename",A1))-FIND("]",CELL("filename",A1))) -> メール自動送信 | AL4: 機能ＩＤ | AS4: CZ-040-03B | BI4: 利用想定ユーザー | BT4: 管理者
A5: 機 能 概 要
B7: ・メールを自動送信する機能。
A10: 機 能 説 明
B12: 〇メール送信対象データの抽出
C14: メールID | J14: バッチID | S14: バッチ名 | AB14: バッチの起動条件 | AM14: メール送信対象
C15: CZ-04005 | J15: CZ-040-03B | S15: 督促メール送信 | AB15: タスクスケジュール | AM15: 勤務情報テーブルの最終ステータスが「差戻」になっている勤務データの学生を対象とする。
C17: CZ-04006 | J17: CZ-040-03B | S17: 督促メール送信 | AB17: タスクスケジュール | AM17: 勤務承認テーブルのステータスが「承認済み」以外になっている勤務データの承認者（教員）を対象とする。
AM18: ※メール通知が許可されている教員のみ ←廃止
B21: 〇メールのまとめ処理について
C23: 通知メールが該当する結果によっては、一度に大量のメールが送信される可能性があるので、1回のバッチで送信されるメール送信処理内でメールの宛先毎に1通のメールに集約し、
C24: メールの受信数を最低限に減らすこととする。
C25: なお、メールの集約を前提としたメールのタイトル・本文となるようにしておくこととする。

Sheet 補足資料_メール本文
A1: メール内容について
B3: No | C3: メール名 | F3: 送信タイミング | S3: 対象者
B4: 1 | C4: 勤務申請受理 | F4: 勤務入力で登録確定時 | S4: 教員
B5: 2 | C5: 勤務差戻 | F5: 勤務入力で差戻時 | S5: 学生、教員
B6: 3 | C6: 勤務修正 | F6: 勤務入力で修正時 | S6: 学生
B7: 4 | C7: 勤務代理入力 | F7: 勤務代理入力で代理入力時 | S7: 学生
B8: 5 | C8: 学生督促 | F8: スケジュールにて月初に自動送信 | S8: 学生
B9: 6 | C9: 承認者督促 | F9: スケジュールにて月初に自動送信 | S9: 教員
A12: No.1
B13: メール件名 | Z13: メール管理マスタの内容
C14: 日本語
D15: 【学生勤務管理システムからのお知らせ】 ｛①学生氏名｝ 様から勤務データの承認依頼があります。 | Z15: 【学生勤務管理システムからのお知らせ】 ｛1｝ 様から勤務データの承認依頼があります。
C16: 英語
D17: [Notices from the student work management system] Dear.{①学生氏名} has requested work approval. | Z17: [Notices from the student work management system] Dear.{1} has requested work approval.
B19: メール本文
C20: 日本語
D21: ｛②教員氏名｝ 様 | Z21: ｛2｝ 様 {1}様から、勤務承認依頼があります。 下記、ＵＲＬより勤務の内容をご確認の上、 「承認」もしくは「差戻」をお願い致します。 ●ＵＲＬ https://学生勤務管理システムのURL ※本メールは送信専用です。返信はできませんのでご了承ください。
D23: {①学生氏名}様から、勤務承認依頼があります。
D24: 下記、ＵＲＬより勤務の内容をご確認の上、
D25: 「承認」もしくは「差戻」をお願い致します。
D27: ●ＵＲＬ
D28: https://学生勤務管理システムのURL
D30: ※本メールは送信専用です。返信はできませんのでご了承ください。
C33: 英語
D34: Dear. ｛②教員氏名｝ | Z34: Dear. ｛2｝ {1} has requested work approval. Please check the details of the work from the URL below, and then either "Approve" or "Return". ●ＵＲＬ https://学生勤務管理システムのURL ※This email is for sending only. Please note that we are unable to reply.
D36: {①学生氏名} has requested work approval.
D37: Please check the details of the work from the URL below,
D38: and then either "Approve" or "Return".
D40: ●ＵＲＬ
D41: https://学生勤務管理システムのURL
D43: ※This email is for sending only. Please note that we are unable to reply.
B46: メール表示文言
B47: {1} | C47: 勤務登録した学生氏名
B48: {2} | C48: 勤務承認する教員氏名
A51: No.2
B52: メール件名
C53: 日本語
D54: 【学生勤務管理システムからのお知らせ】 勤務データの差戻があります。 | Z54: 【学生勤務管理システムからのお知らせ】 勤務データの差戻があります。
C55: 英語
D56: [Notice from the student work management system] Your work has been returned. | Z56: [Notice from the student work management system] Your work has been returned.
...
