Workbook
Name _Toc94971774: 機能概要・画面遷移図!#REF!
Name _Toc94971775: 機能概要・画面遷移図!#REF!

Sheet タイトル
G11: =I40 -> 学生勤務管理システム
G14: =I44 -> CZ-030_給与支給日マスタ
G17: =I42
G20: =I51 -> 【 Ver 1.04 】
J27: =TEXT(I47,"yyyy年")&IF(LEFT(TEXT(I47,"mm"),1)="0"," ","")&TEXT(I47,"m月")&IF(LEFT(TEXT(I47,"dd"),1)="0"," ","")&TEXT(I47,"d日")&"作成" -> 2023年 9月29日作成
J29: =IF(I49=" ※ページ毎に個別入力"," 年 月 日改訂",TEXT(I49,"yyyy年")&IF(LEFT(TEXT(I49,"mm"),1)="0"," ","")&TEXT(I49,"m月")&IF(LEFT(TEXT(I49,"dd"),1)="0"," ","")&TEXT(I49,"d日")&"改訂") -> 2024年12月16日改訂
B38: 見出し部タイトル制御テーブル
B39: タイトル項目 | I39: タイトル項目埋め込み内容
B40: ①システム名 | I40: 学生勤務管理システム
B41: ②サブシステム名 | I41: 共通機能
B42: ③分類名
B43: ④作業工程名 | I43: 機能設計
B44: ⑤ドキュメント代表名 | I44: CZ-030_給与支給日マスタ
B45: ⑥ドキュメント詳細名 | I45: ※ページ毎に個別入力
B46: ⑦作成者 | I46: 木田 優
B47: ⑧作成日 | I47: 45198
B48: ⑦改定者 | I48: ※ページ毎に個別入力
B49: ⑧改定日 | I49: =TEXT(MAX(改訂履歴!J5:J995),"yyyy/mm/dd") -> 2024/12/16
B50: ⑨管理記号 | I50: DUC010
B51: ⑩Ｖｅｒ | I51: ="【 Ver " & TEXT(MAX(改訂履歴!E5:E995),"0.00") & " 】" -> 【 Ver 1.04 】

Sheet 改訂履歴
A1: 改訂履歴
A3: No | E3: Ver | J3: 新規／改訂日 | R3: 区分 | W3: 改訂箇所 | AH3: 改訂理由 | BR3: 新規／改訂者
W4: 頁 | AA4: 機能
A5: 1 | E5: 1 | J5: =タイトル!I47 -> 45198 | R5: 新規 | AH5: 新規作成 | BR5: 木田 優
A6: 2 | E6: 1.01 | J6: 45216 | R6: 変更 | AA6: 給与支給日マスタ | AH6: タイトルや項目名の変更 | BR6: 木田 優
A7: 3 | E7: 1.02 | J7: 45238 | R7: 変更 | AA7: 給与支給日マスタ | AH7: 一覧の並び順の項目名称を変更 ホーム（学生）表示文言を追加 | BR7: 木田 優
A8: 4 | E8: 1.03 | J8: 45315 | R8: 変更 | AA8: 画面遷移図 | AH8: 戻るボタンの廃止 | BR8: 木田 優
A9: 5 | E9: 1.04 | J9: 45642 | R9: 変更 | AA9: 給与支給日マスタ | AH9: 給与改定日の追加 （2024年度改修_項番5） | BR9: 木田 優

Sheet 機能概要・画面遷移図
A1: システム名 | I1: =タイトル!I40 -> 学生勤務管理システム | AE1: 工 程 | AL1: =タイトル!I43 -> 機能設計 | BI1: 作 成 | BM1: =タイトル!I46 -> 木田 優 | BW1: =タイトル!I47 -> 45198 | CF1: 管理記号 | CK1: =タイトル!I50 -> DUC010
A2: サブシステム名 | I2: =タイトル!I41 -> 共通機能 | AE2: ドキュメント | AL2: =タイトル!I44 -> CZ-030_給与支給日マスタ | BI2: 改 訂 | BM2: 木田 優 | BW2: 45315
A4: 機能名称 | I4: =" " & RIGHT(タイトル!I44,LEN(タイトル!I44)-8) -> 給与支給日マスタ | AL4: 機能ＩＤ | AS4: =LEFT(タイトル!I44,7) -> CZ-030 | BI4: 利用想定ユーザー | BT4: 管理者
A5: 機 能 概 要
B7: 給与支給日と給与計算処理予定日を編集する時に使用する。
A10: 画 面 遷 移 図
C13: ○ホーム画面 | AI13: ○給与支給日マスタ画面
D14: （CC-020-01G） | AJ14: （CZ-030-01G）
V15: 支払給与月マスタボタン

Sheet 給与支給日マスタ
A1: システム名 | I1: =タイトル!I40 -> 学生勤務管理システム | AE1: 工 程 | AL1: 機能設計 | BI1: 作 成 | BM1: =タイトル!I46 -> 木田 優 | BW1: =タイトル!I47 -> 45198 | CF1: 管理記号 | CK1: =タイトル!I50 -> DUC010
A2: サブシステム名 | I2: 共通機能 | AE2: ドキュメント | AL2: =タイトル!I44 -> CZ-030_給与支給日マスタ | BI2: 改 訂 | BM2: 木田 優 | BW2: 45642
A4: 画面名称 | I4: =" " & RIGHT(CELL("filename",A1),LEN(CELL("filename",A1))-FIND("]",CELL("filename",A1))) -> 給与支給日マスタ | AL4: 画面ＩＤ | AS4: CZ-030-01G | BI4: 利用想定ユーザー | BT4: 管理者
A5: 画面レイアウト | BI5: 機能概要
BJ7: ・ | BK7: 給与支給日と給与計算処理予定日を編集する時に使用する。
BI12: 画面説明 （処理内容・アクション等）
BJ14: ・ | BK14: 雇用年度は画面初期表示時に処理日に該当する雇用年度を初期表示する。 | DC14: 給与改定日
BK15: 例として、処理日が2023/9/29の場合には雇用年度は「2023」を表示する。
DC16: 2024/4/1(月) | DN16: 無効
BJ17: ・ | BK17: 初期表示時に雇用年度を基に検索処理を行い、一覧を表示する。
DC18: 2024/5/1(水) | DN18: 有効
BJ19: ・ | BK19: 選択ボタンを押下すると、対象の勤務月と給与支給日、
BK20: 給与計算処理予定日を下部に表示する。
BK21: ※勤務月は非活性項目とする。
BJ23: ・ | BK23: 給与支給日のカレンダーを押下すると、カレンダーを表示する。
CV24: 給与改定日 | DC24: 45383 | DN24: ☑ | DQ24: 有効
BJ25: ・ | BK25: 給与計算処理予定日のカレンダーを押下すると、カレンダーを表示する。
BJ27: ・ | BK27: 更新ボタンを押下すると、対象の勤務月に対して、給与支給日と
BK28: 給与計算処理予定日の更新を行う。
BJ30: ・ | BK30: 翌年度作成ボタンを押下すると、表示されている雇用年度の翌年分の
BK31: 給与支給日マスタ（4月～3月までの1年分）を作成する。
BL32: 給与支給日：月度の翌25日(土日祝の場合、前倒しし、平日を設定)
BL33: 給与計算処理予定日：月度の翌10日(土日祝の場合、前倒しし、平日を設定)
BL34: ※土日は共通関数から取得し、土日の場合、前倒し、平日を設定する。
BL35: ※祝日はユーザーコードマスタの種別：祝日を参照し、給与支給日、
BL36: 給与計算処理予定日が祝日に該当する場合、前倒し、平日を
BL37: 設定する。
A38: リストボックス | BI38: 権限による画面制御
A39: 項目名 | K39: 内容 | AW39: 並び順
A40: 雇用年度 | K40: 給与支給日マスタに登録されている雇用年度 | AW40: 降順
BI43: 一覧の並び順
BJ45: 勤務月（昇順）
A48: 画 面 補 足 説 明
B50: ○入力項目（検索条件）
B51: 項目名 | P51: 入力必須 | U51: 桁数 | X51: 入力制限等
B52: 雇用年度 | P52: 〇 | U52: - | X52: リストボックス
B54: 雇用年度を変更した時に、検索処理を行い、結果を一覧に表示する。
B57: ○出力項目
B58: 項目名 | K58: 編集内容等
B59: 勤務月 | K59: yyyy/m
...
