Workbook
Name _Toc94971774: 機能概要・画面遷移図!#REF!
Name _Toc94971775: 機能概要・画面遷移図!#REF!

Sheet タイトル
G11: =I40 -> 学生勤務管理システム
G14: =I44 -> CC-020_ホーム
G17: =I42
G20: =I51 -> 【 Ver 1.08 】
J27: =TEXT(I47,"yyyy年")&IF(LEFT(TEXT(I47,"mm"),1)="0"," ","")&TEXT(I47,"m月")&IF(LEFT(TEXT(I47,"dd"),1)="0"," ","")&TEXT(I47,"d日")&"作成" -> 2023年10月 3日作成
J29: =IF(I49=" ※ページ毎に個別入力"," 年 月 日改訂",TEXT(I49,"yyyy年")&IF(LEFT(TEXT(I49,"mm"),1)="0"," ","")&TEXT(I49,"m月")&IF(LEFT(TEXT(I49,"dd"),1)="0"," ","")&TEXT(I49,"d日")&"改訂") -> 2025年 6月11日改訂
B38: 見出し部タイトル制御テーブル
B39: タイトル項目 | I39: タイトル項目埋め込み内容
B40: ①システム名 | I40: 学生勤務管理システム
B41: ②サブシステム名 | I41: 共通機能
B42: ③分類名
B43: ④作業工程名 | I43: 機能設計
B44: ⑤ドキュメント代表名 | I44: CC-020_ホーム
B45: ⑥ドキュメント詳細名 | I45: ※ページ毎に個別入力
B46: ⑦作成者 | I46: 木田 優
B47: ⑧作成日 | I47: 45202
B48: ⑦改定者 | I48: ※ページ毎に個別入力
B49: ⑧改定日 | I49: =TEXT(MAX(改訂履歴!J5:J991),"yyyy/mm/dd") -> 2025/06/11
B50: ⑨管理記号 | I50: DUC010
B51: ⑩Ｖｅｒ | I51: ="【 Ver " & TEXT(MAX(改訂履歴!E5:E991),"0.00") & " 】" -> 【 Ver 1.08 】

Sheet 改訂履歴
A1: 改訂履歴
A3: No | E3: Ver | J3: 新規／改訂日 | R3: 区分 | W3: 改訂箇所 | AH3: 改訂理由 | BR3: 新規／改訂者
W4: 頁 | AA4: 機能
A5: 1 | E5: 1 | J5: =タイトル!I47 -> 45202 | R5: 新規 | AH5: 新規作成 | BR5: 木田 優
A6: 2 | E6: 1.01 | J6: 45215 | R6: 変更 | AH6: メニューアイコン押下時のイメージを差し替え | BR6: 木田 優
A7: 3 | E7: 1.02 | J7: 45215 | R7: 変更 | AH7: 教員・担当者・管理者の勤務申請状況の件数表示を変更 | BR7: 木田 優
A8: 4 | J8: 45215 | R8: 変更 | AH8: 担当者メニューに勤務承認と代理入力を追加 | BR8: 木田 優
A9: 5 | E9: 1.03 | J9: 45222 | R9: 変更 | AH9: 支給日の表示をyyyy年m月d日支給予定分と変更 | BR9: 木田 優
A10: 6 | J10: 45222 | R10: 変更 | AH10: 勤務申請状況件数で学生の登録確定/承認中、管理者の承認中を「承認待ち」に変更 教員、担当者の差戻件数を削除 | BR10: 木田 優
A11: 7 | E11: 1.04 | J11: 45239 | R11: 変更 | AH11: 支給予定日の下にお知らせ機能を追加 勤務申請状況の取得表現を変更 管理者の勤務申請状況に給与計算待ちを追加 | BR11: 木田 優
A12: 8 | E12: 1.05 | J12: 45261 | R12: 変更 | AH12: 代理承認を兼任・代理承認に変更 承認待ち件数に再承認待ち件数を追加 | BR12: 木田 優
A13: 9 | E13: 1.06 | J13: 45303 | R13: 変更 | AA13: ホーム（教員） | AH13: 学生督促ボタンを廃止 | BR13: 木田 優
A14: 10 | J14: 45303 | R14: 変更 | AA14: ホーム（担当者） | AH14: 学生督促ボタンを廃止 承認者督促ボタンを廃止 | BR14: 木田 優
A15: 11 | J15: 45303 | R15: 変更 | AA15: ホーム（管理者） | AH15: 学生督促ボタンを廃止 承認者督促ボタンを廃止 | BR15: 木田 優
A16: 12 | R16: 変更 | AA16: 画面遷移図 | AH16: 推奨環境画面を廃止 | BR16: 木田 優
A17: 13 | E17: 1.07 | J17: 45630 | R17: 変更 | AA17: ホーム（担当者） | AH17: 勤務データ承認（照会）を照会用（管理者用）として表示できるメニューを追加 （2024年度改修_項番1） | BR17: 木田 優
A18: 14 | E18: 1.08 | J18: 45819 | R18: 変更 | AA18: ホーム（教員） | AH18: メール送信有効・無効フラグを追加（教員画面のみ） （2025年度改修_項番11） | BR18: 木田 優

Sheet 機能概要・画面遷移図
A1: システム名 | I1: =タイトル!I40 -> 学生勤務管理システム | AE1: 工 程 | AL1: =タイトル!I43 -> 機能設計 | BI1: 作 成 | BM1: =タイトル!I46 -> 木田 優 | BW1: =タイトル!I47 -> 45202 | CF1: 管理記号 | CK1: =タイトル!I50 -> DUC010
A2: サブシステム名 | I2: =タイトル!I41 -> 共通機能 | AE2: ドキュメント | AL2: =タイトル!I44 -> CC-020_ホーム | BI2: 改 訂 | BM2: 木田 優 | BW2: 45303
A4: 機能名称 | I4: =" " & RIGHT(タイトル!I44,LEN(タイトル!I44)-8) -> ホーム | AL4: 機能ＩＤ | AS4: =LEFT(タイトル!I44,7) -> CC-020 | BI4: 利用想定ユーザー | BT4: 全ユーザー
A5: 機 能 概 要
B7: 学生勤務管理システムにログインし、認証成功時に表示する画面。
B8: 勤務の申請状況の確認、各機能へ遷移するメニュー表示を行う。
A10: 画 面 遷 移 図
C13: ○ホーム画面 | V13: 各メニューボタン | BJ13: ○各画面
D14: （CC-020-01G）
AJ17: 同志社大学ロゴ・学生勤務管理システム部分を押下
AO22: マニュアルボタン
C25: ENGLISHボタン
C26: 日本語ボタン
AM28: 戻るボタン
AJ30: ○マニュアル画面
AK31: （CC-020-03G）

Sheet ホーム（学生）
A1: システム名 | I1: =タイトル!I40 -> 学生勤務管理システム | AE1: 工 程 | AL1: 機能設計 | BI1: 作 成 | BM1: =タイトル!I46 -> 木田 優 | BW1: =タイトル!I47 -> 45202 | CF1: 管理記号 | CK1: =タイトル!I50 -> DUC010
A2: サブシステム名 | I2: 共通機能 | AE2: ドキュメント | AL2: =タイトル!I44 -> CC-020_ホーム | BI2: 改 訂 | BM2: 木田 優 | BW2: 45239
A4: 画面名称 | I4: =" " & RIGHT(CELL("filename",A1),LEN(CELL("filename",A1))-FIND("]",CELL("filename",A1))) -> ホーム（学生） | AL4: 画面ＩＤ | AS4: CC-020-01G | BI4: 利用想定ユーザー | BT4: 学生
A5: 画面レイアウト | BI5: 機能概要
BJ7: ・ | BK7: 学生勤務管理システムにログインし、認証成功時に表示する画面。
AD8: メニューアイコン押下時 | BJ8: ・ | BK8: 勤務の申請状況の確認、各機能へ遷移するメニュー表示を行う。
BJ9: ・ | BK9: 学生専用メニュー。
BI12: 画面説明 （処理内容・アクション等）
BJ14: ・ | BK14: 初期表示で以下の項目を表示する。
BJ15: ○出力項目
BJ16: 項目名 | BS16: 編集内容等
BJ17: 給与支給日 | BS17: 給与支給日マスタの給与計算処理予定日の期間中に
BS18: 該当する給与支給日
BJ19: お知らせ | BS19: 給与支給日マスタのホーム表示文言を表示する
BJ20: 承認待ち | BS20: 給与支給の対象となる勤務データの中で最終ステータスが
BS21: 承認待ち・再承認待ちの総件数
BJ22: 承認完了 | BS22: 給与支給の対象となる勤務データの中で最終ステータスが
BS23: 承認済みの総件数
BJ24: 差戻 | BS24: 給与支給の対象となる勤務データの中で最終ステータスが
BS25: 差戻の総件数
BJ26: ・ | BK26: 各機能へ遷移するメニューボタンを配置する。
BJ27: ボタン名 | BS27: 遷移先
BJ28: 勤務入力 | BS28: GA-010-01G：勤務入力
BJ29: 勤務情報一覧 | BS29: GA-010-02G：勤務情報一覧
BJ30: 雇用情報一覧 | BS30: GA-020-01G：雇用情報一覧
BJ31: ・ | BK31: サイドメニューのみ表示
BJ32: ボタン名 | BS32: 遷移先
BJ33: マニュアル | BS33: CC-020-03G：ヘルプ
BJ34: ・ | BK34: LOGOUTボタンを押下すると、学生勤務管理システムからログアウトする。
BK35: ログアウトすると、ブラウザのタブを閉じる。
A38: リストボックス | BI38: 権限による画面制御
A39: 項目名 | K39: 内容 | AW39: 並び順
BJ40: ユーザ区分が学生のみ
BI43: 一覧の並び順
A48: 画 面 補 足 説 明
B50: 〇ヘルプページ | AX50: 〇給与支給日と勤務申請状況件数の関係について
AY69: 勤務申請状況件数には表示している給与支給日に該当する勤務分の件数のみを表示しますので、
AY70: 給与計算処理が実施されるまでの期間、承認待ち件数が実際の件数とは一致しない場合があります。
AY72: 例：給与支給日=2023/11/25
AY73: 2023/9/1 | BJ73: 2023/10/01 | BW73: 2023/11/01 | CL73: 2023/12/01
...

Sheet ホーム（教員）
A1: システム名 | I1: =タイトル!I40 -> 学生勤務管理システム | AE1: 工 程 | AL1: 機能設計 | BI1: 作 成 | BM1: =タイトル!I46 -> 木田 優 | BW1: =タイトル!I47 -> 45202 | CF1: 管理記号 | CK1: =タイトル!I50 -> DUC010
A2: サブシステム名 | I2: 共通機能 | AE2: ドキュメント | AL2: =タイトル!I44 -> CC-020_ホーム | BI2: 改 訂 | BM2: 木田 優 | BW2: 45819
A4: 画面名称 | I4: =" " & RIGHT(CELL("filename",A1),LEN(CELL("filename",A1))-FIND("]",CELL("filename",A1))) -> ホーム（教員） | AL4: 画面ＩＤ | AS4: CC-020-01G | BI4: 利用想定ユーザー | BT4: 教員
A5: 画面レイアウト | BI5: 機能概要
BJ7: ・ | BK7: 学生勤務管理システムにログインし、認証成功時に表示する画面。
AD8: メニューアイコン押下時 | BJ8: ・ | BK8: 勤務の申請状況の確認、各機能へ遷移するメニュー表示を行う。
BJ9: ・ | BK9: 教員専用メニュー。
BI12: 画面説明 （処理内容・アクション等）
BJ14: ・ | BK14: 初期表示で以下の項目を表示する。
BJ15: ○出力項目
BJ16: 項目名 | BS16: 編集内容等
BJ17: 給与支給日 | BS17: 給与支給日マスタの給与計算処理予定日の期間中に
BS18: 該当する給与支給日
BJ19: 承認待ち | BS19: ログインした教員の教員コードあてに勤務申請が登録されている勤務データの中で承認待ち、再承認待ち、又は差戻された勤務データ総件数
BJ22: 承認完了 | BS22: ログインした教員の教員コードあてに勤務申請が登録されている勤務データの中で承認済、且つ、差戻されていない勤務データ総件数
BJ25: ※承認待ちは教員への差戻された件数を含む。
BJ26: ・ | BK26: 各機能へ遷移するメニューボタンを配置する。
BJ27: ボタン名 | BT27: 遷移先
BJ28: 勤務データ承認(照会) | BT28: CK-010-01G：勤務データ承認(照会)
BJ29: 勤務代理入力 | BT29: GA-010-01G：勤務入力
BJ30: 雇用情報一覧 | BT30: GA-020-01G：雇用情報一覧
BJ31: 兼任・代理承認 | BT31: CK-030-01G：兼任・代理承認
BJ32: ・ | BK32: メール通知のON/OFFを切り替えるボタンを表示する。 | CT32: 2025年度改修_項番11
BJ34: ・ | BK34: サイドメニューのみ表示 | CV34: メール通知
BJ35: ボタン名 | BT35: 遷移先 | CW35: OFF
BJ36: マニュアル | BT36: CC-020-03G：ヘルプ
BJ37: ・ | BK37: LOGOUTボタンを押下すると、学生勤務管理システムからログアウトする。
A38: リストボックス | BK38: ログアウトすると、ブラウザのタブを閉じる。
A39: 項目名 | K39: 内容 | AW39: 並び順
BI40: 権限による画面制御
BJ42: ユーザ区分が教員のみ
BI44: 一覧の並び順

Sheet ホーム（担当者）
A1: システム名 | I1: =タイトル!I40 -> 学生勤務管理システム | AE1: 工 程 | AL1: 機能設計 | BI1: 作 成 | BM1: =タイトル!I46 -> 木田 優 | BW1: =タイトル!I47 -> 45202 | CF1: 管理記号 | CK1: =タイトル!I50 -> DUC010
A2: サブシステム名 | I2: 共通機能 | AE2: ドキュメント | AL2: =タイトル!I44 -> CC-020_ホーム | BI2: 改 訂 | BM2: 木田 優 | BW2: 45630
A4: 画面名称 | I4: =" " & RIGHT(CELL("filename",A1),LEN(CELL("filename",A1))-FIND("]",CELL("filename",A1))) -> ホーム（担当者） | AL4: 画面ＩＤ | AS4: CC-020-01G | BI4: 利用想定ユーザー | BT4: 担当者
A5: 画面レイアウト | BI5: 機能概要
BJ7: ・ | BK7: 学生勤務管理システムにログインし、認証成功時に表示する画面。
BJ8: ・ | BK8: 勤務の申請状況の確認、各機能へ遷移するメニュー表示を行う。
BJ9: ・ | BK9: 担当者専用メニュー。
BI12: 画面説明 （処理内容・アクション等）
BJ14: ・ | BK14: 初期表示で以下の項目を表示する。
BJ15: ○出力項目
BJ16: 項目名 | BS16: 編集内容等
BJ17: 給与支給日 | BS17: 給与支給日マスタの給与計算処理予定日の期間中に
BS18: 該当する給与支給日
AR19: メニューアイコン押下時 | BJ19: 承認待ち | BS19: ログインした職員の雇用部課と役職あてに勤務申請が登録されている勤務データの中で承認待ち、再承認待ち、又は差戻された勤務データ総件数
BJ22: 承認完了 | BS22: ログインした職員の雇用部課と役職あてに勤務申請が登録されている勤務データの中で承認済、且つ、差戻されていない勤務データ総件数
BJ25: ・ | BK25: 各機能へ遷移するメニューボタンを配置する。
BJ26: ボタン名 | BT26: 遷移先
BJ27: 勤務データ承認 | BT27: CK-010-01G：勤務データ承認(照会) ※承認用
BJ28: 勤務データ照会 | BT28: CK-010-01G：勤務データ承認(照会) ※照会用
BJ29: 勤務データ仮集計 | BT29: CK-020-01G：勤務データ仮集計
BJ30: 勤務代理入力 | BT30: GA-010-01G：勤務入力
BJ31: 雇用情報マスタ | BT31: CZ-010-01G：雇用情報一覧
BJ32: 兼任・代理承認 | BT32: CK-030-01G：兼任・代理承認
BJ33: ・ | BK33: サイドメニューのみ表示
BJ34: ボタン名 | BT34: 遷移先
BJ35: マニュアル | BT35: CC-020-03G：ヘルプ
BJ36: ・ | BK36: LOGOUTボタンを押下すると、学生勤務管理システムからログアウトする。
BK37: ログアウトすると、ブラウザのタブを閉じる。
A38: リストボックス | BI38: 権限による画面制御
A39: 項目名 | K39: 内容 | AW39: 並び順
BJ40: ユーザ区分が担当者のみ
BI43: 一覧の並び順

Sheet ホーム（管理者）
A1: システム名 | I1: =タイトル!I40 -> 学生勤務管理システム | AE1: 工 程 | AL1: 機能設計 | BI1: 作 成 | BM1: =タイトル!I46 -> 木田 優 | BW1: =タイトル!I47 -> 45202 | CF1: 管理記号 | CK1: =タイトル!I50 -> DUC010
A2: サブシステム名 | I2: 共通機能 | AE2: ドキュメント | AL2: =タイトル!I44 -> CC-020_ホーム | BI2: 改 訂 | BM2: 木田 優 | BW2: 45222
A4: 画面名称 | I4: =" " & RIGHT(CELL("filename",A1),LEN(CELL("filename",A1))-FIND("]",CELL("filename",A1))) -> ホーム（管理者） | AL4: 画面ＩＤ | AS4: CC-020-01G | BI4: 利用想定ユーザー | BT4: 管理者
A5: 画面レイアウト | BI5: 機能概要
BJ7: ・ | BK7: 学生勤務管理システムにログインし、認証成功時に表示する画面。
BJ8: ・ | BK8: 勤務の申請状況の確認、各機能へ遷移するメニュー表示を行う。
BJ9: ・ | BK9: 管理者専用メニュー。
BI12: 画面説明 （処理内容・アクション等）
BJ14: ・ | BK14: 初期表示で以下の項目を表示する。
BJ15: ○出力項目
BJ16: 項目名 | BS16: 編集内容等
BJ17: 給与支給日 | BS17: 給与支給日マスタの給与計算処理予定日の期間中に
BS18: 該当する給与支給日
AR19: メニューアイコン押下時 | BJ19: 承認待ち | BS19: 最終ステータスが承認済以外の勤務データ総件数
BJ20: 給与計算待ち | BS20: 最終ステータスが承認済、且つ、給与計算が
BS21: 未実施の勤務データ総件数
BJ22: ・ | BK22: 各機能へ遷移するメニューボタンを配置する。
BJ23: ボタン名 | BT23: 遷移先
BJ24: 勤務データ承認(照会) | BT24: CK-010-01G：勤務データ承認(照会)
BJ25: 給与計算処理 | BT25: CK-020-01G：給与計算処理
BJ26: 勤務データ仮集計 | BT26: CK-020-01G：勤務データ仮集計
BJ27: 兼任・代理承認 | BT27: CK-030-01G：兼任・代理承認
BJ28: 雇用情報マスタ | BT28: CZ-010-01G：雇用情報一覧
BJ29: 社員マスタ | BT29: CZ-020-01G：社員マスタ一覧
BJ30: 給与支給日マスタ | BT30: CZ-030-01G：給与支給日マスタメンテ
BJ31: ・ | BK31: サイドメニューのみ表示
BJ32: ボタン名 | BT32: 遷移先
BJ33: マニュアル | BT33: CC-020-03G：ヘルプ
BJ34: ・ | BK34: LOGOUTボタンを押下すると、学生勤務管理システムからログアウトする。
BK35: ログアウトすると、ブラウザのタブを閉じる。
A38: リストボックス | BI38: 権限による画面制御
A39: 項目名 | K39: 内容 | AW39: 並び順
BJ40: ユーザ区分が管理者のみ
BI43: 一覧の並び順

Sheet マニュアル
A1: システム名 | I1: =タイトル!I40 -> 学生勤務管理システム | AE1: 工 程 | AL1: 機能設計 | BI1: 作 成 | BM1: =タイトル!I46 -> 木田 優 | BW1: =タイトル!I47 -> 45202 | CF1: 管理記号 | CK1: =タイトル!I50 -> DUC010
A2: サブシステム名 | I2: 共通機能 | AE2: ドキュメント | AL2: =タイトル!I44 -> CC-020_ホーム | BI2: 改 訂 | BM2: 木田 優 | BW2: 45222
A4: 画面名称 | I4: =" " & RIGHT(CELL("filename",A1),LEN(CELL("filename",A1))-FIND("]",CELL("filename",A1))) -> マニュアル | AL4: 画面ＩＤ | AS4: CC-020-03G | BI4: 利用想定ユーザー | BT4: 全ユーザー
A5: 画面レイアウト | BI5: 機能概要
BJ7: ・ | BK7: 学生勤務管理システムの推奨環境を通知する画面。
BI12: 画面説明 （処理内容・アクション等）
BJ14: ・ | BK14: マニュアルはユーザ区分（学生、教員、担当者）によって、別ファイルを
BK15: ダウンロードできるようにマニュアルを保存する。
BJ17: ・ | BK17: APサーバの指定の場所にマニュアルを保存し、マニュアルの変更は
BK18: 直接ファイルを上書きして対応する。
A38: リストボックス | BI38: 権限による画面制御
A39: 項目名 | K39: 内容 | AW39: 並び順
BI43: 一覧の並び順
