Workbook
Name _Toc94971774: 機能概要・画面遷移図!#REF!
Name _Toc94971775: 機能概要・画面遷移図!#REF!

Sheet タイトル
G11: =I40 -> 学生勤務管理システム
G14: =I44 -> CC-800_ポップアップ
G17: =I42
G20: =I51 -> 【 Ver 1.03 】
J27: =TEXT(I47,"yyyy年")&IF(LEFT(TEXT(I47,"mm"),1)="0"," ","")&TEXT(I47,"m月")&IF(LEFT(TEXT(I47,"dd"),1)="0"," ","")&TEXT(I47,"d日")&"作成" -> 2023年10月 6日作成
J29: =IF(I49=" ※ページ毎に個別入力"," 年 月 日改訂",TEXT(I49,"yyyy年")&IF(LEFT(TEXT(I49,"mm"),1)="0"," ","")&TEXT(I49,"m月")&IF(LEFT(TEXT(I49,"dd"),1)="0"," ","")&TEXT(I49,"d日")&"改訂") -> 2025年 6月12日改訂
B38: 見出し部タイトル制御テーブル
B39: タイトル項目 | I39: タイトル項目埋め込み内容
B40: ①システム名 | I40: 学生勤務管理システム
B41: ②サブシステム名 | I41: 共通機能
B42: ③分類名
B43: ④作業工程名 | I43: 機能設計
B44: ⑤ドキュメント代表名 | I44: CC-800_ポップアップ
B45: ⑥ドキュメント詳細名 | I45: ※ページ毎に個別入力
B46: ⑦作成者 | I46: 木田 優
B47: ⑧作成日 | I47: 45205
B48: ⑦改定者 | I48: ※ページ毎に個別入力
B49: ⑧改定日 | I49: =TEXT(MAX(改訂履歴!J5:J996),"yyyy/mm/dd") -> 2025/06/12
B50: ⑨管理記号 | I50: DUC010
B51: ⑩Ｖｅｒ | I51: ="【 Ver " & TEXT(MAX(改訂履歴!E5:E996),"0.00") & " 】" -> 【 Ver 1.03 】

Sheet 改訂履歴
A1: 改訂履歴
A3: No | E3: Ver | J3: 新規／改訂日 | R3: 区分 | W3: 改訂箇所 | AH3: 改訂理由 | BR3: 新規／改訂者
W4: 頁 | AA4: 機能
A5: 1 | E5: 1 | J5: =タイトル!I47 -> 45205 | R5: 新規 | AH5: 新規作成 | BR5: 木田 優
A6: 2 | E6: 1.01 | J6: 45222 | R6: 変更 | AH6: 雇用部課選択を削除 | BR6: 木田 優
A7: 3 | J7: 45222 | R7: 変更 | AH7: 社員選択の検索条件を変更 | BR7: 木田 優
A8: 4 | J8: 45222 | R8: 変更 | AH8: 科目選択の検索条件を変更 | BR8: 木田 優
A9: 5 | J9: 45244 | R9: 変更 | AH9: 社員選択の検索条件の「認証」を「認証区分」に変更 | BR9: 木田 優
A10: 6 | E10: 1.02 | J10: 45313 | R10: 変更 | AA10: 社員選択 | AH10: 検索条件を変更 | BR10: 木田 優
A11: 7 | E11: 1.03 | J11: 45820 | R11: 変更 | AA11: 社員選択 | AH11: 有効フラグが無効の社員も検索対象にする （2025年度保守） | BR11: 木田 優

Sheet 機能概要・画面遷移図
A1: システム名 | I1: =タイトル!I40 -> 学生勤務管理システム | AE1: 工 程 | AL1: =タイトル!I43 -> 機能設計 | BI1: 作 成 | BM1: =タイトル!I46 -> 木田 優 | BW1: =タイトル!I47 -> 45205 | CF1: 管理記号 | CK1: =タイトル!I50 -> DUC010
A2: サブシステム名 | I2: =タイトル!I41 -> 共通機能 | AE2: ドキュメント | AL2: =タイトル!I44 -> CC-800_ポップアップ | BI2: 改 訂
A4: 機能名称 | I4: =" " & RIGHT(タイトル!I44,LEN(タイトル!I44)-8) -> ポップアップ | AL4: 機能ＩＤ | AS4: =LEFT(タイトル!I44,7) -> CC-800 | BI4: 利用想定ユーザー | BT4: 全ユーザー
A5: 機 能 概 要
B7: 名称などの情報を選択するためのサポート画面。
B8: 選択した結果の情報を呼び出し元画面に渡す。
A10: 画 面 遷 移 図
C13: ○呼び出し元画面 | AL13: ○ポップアップ | BF13: ポップアップ一覧
AM14: （CC-800-01S） | BF14: CC-800-01S | BN14: 社員選択
V15: 検索アイコンクリック | BF15: CC-800-02S | BN15: 科目選択
AL26: ○ポップアップ
AM27: （CC-800-02S）

Sheet 社員選択
A1: システム名 | I1: =タイトル!I40 -> 学生勤務管理システム | AE1: 工 程 | AL1: 機能設計 | BI1: 作 成 | BM1: =タイトル!I46 -> 木田 優 | BW1: =タイトル!I47 -> 45205 | CF1: 管理記号 | CK1: =タイトル!I50 -> DUC010
A2: サブシステム名 | I2: 共通機能 | AE2: ドキュメント | AL2: =タイトル!I44 -> CC-800_ポップアップ | BI2: 改 訂 | BM2: 木田 優 | BW2: 45820
A4: 画面名称 | I4: =" " & RIGHT(CELL("filename",A1),LEN(CELL("filename",A1))-FIND("]",CELL("filename",A1))) -> 社員選択 | AL4: 画面ＩＤ | AS4: CC-800-01S | BI4: 利用想定ユーザー | BT4: 管理者、担当者
A5: 画面レイアウト | BI5: 機能概要
BJ7: ・ | BK7: 社員（学生・教員・職員）を選択するための画面。
BI12: 画面説明 （処理内容・アクション等）
BJ14: ・ | BK14: 学生、教員、職員区分をパラメータで受け取った場合は、画面の
BK15: ユーザ区分に設定し、非活性とする。
BJ17: ・ | BK17: 検索結果の行は30行を最大とし、31行目以降はページング機能を使用して
BK18: 表示する行を切り替える。
BJ20: ・ | BK20: ユーザ区分によって、検索条件の表示、非表示を切り替える。
BK21: 検索条件 | BV21: ユーザ区分
BV22: 学生 | BZ22: 教員 | CD22: 職員
BK23: 学生所属 | BV23: 表示 | BZ23: 非表示 | CD23: 非表示
BK24: 教員コード | BV24: 非表示 | BZ24: 表示 | CD24: 表示
BJ26: ・ | BK26: 社員マスタの有効フラグが無効の社員も検索対象に含める | CT26: 2025年度保守
A38: リストボックス | BI38: 権限による画面制御
A39: 項目名 | K39: 内容 | AW39: 並び順
A40: ユーザ区分 | K40: ユーザ区分 | AW40: 昇順 | BJ40: ユーザ区分による検索条件の表示・非表示切替あり
A41: 在籍区分 | K41: 在籍区分 | AW41: 昇順
A42: 学生所属 | K42: 課程、学部・研究科、学科・専攻、コース・クラスター | AW42: 昇順
BI43: 一覧の並び順
BJ45: 社員ＩＤ（昇順）
A48: 画 面 補 足 説 明
B50: ○入力項目（検索条件） | AY50: 〇リストボックス
B51: 項目名 | P51: 入力必須 | U51: 桁数 | X51: 入力制限等 | AZ51: 【ユーザ区分】 | BS51: 【在籍区分】
B52: ユーザ区分 | P52: 〇 | U52: － | X52: リストボックス | BA52: ユーザ区分 | BP52: ▼ | BT52: 在籍区分 | CE52: ▼
B53: 在籍区分 | P53: × | U53: － | X53: リストボックス 初期値：籍あり | BH53: 学生 | CA53: 籍あり
B54: 社員ＩＤ | P54: × | U54: 11 | X54: 半角数字、前方一致 | BH54: 承認者 | CA54: 籍なし
B55: 氏名 | P55: × | U55: 100 | X55: 英字氏名、カナ含む部分一致検索 | BH55: 担当者
B56: 学生所属 | G56: 課程 | P56: × | U56: － | X56: リストボックス | BH56: 管理者
G57: 学部・研究科 | P57: × | U57: － | X57: リストボックス
G58: 学科・専攻 | P58: × | U58: － | X58: リストボックス
G59: コース・クラスター | P59: × | U59: － | X59: リストボックス | AZ59: 【学生所属】
B60: 教員コード | P60: × | U60: 6 | X60: 半角数字 | BA60: 学生所属 | BO60: ▼
BA61: ↓ | BB61: 学生所属の課程を選択すると
BA62: ↓ | BB62: 学部・研究科を選択するリストボックスを表示する。
BA63: 学生所属 | BH63: 1：学部 | BO63: ▼ | BX63: ▼
B64: ○出力項目 | BA64: ↓ | BB64: 学部・研究科を選択すると
B65: 項目名 | K65: 編集内容等 | BA65: ↓ | BB65: 学科・専攻を選択するリストボックスを表示する。
...

Sheet 科目選択
A1: システム名 | I1: =タイトル!I40 -> 学生勤務管理システム | AE1: 工 程 | AL1: 機能設計 | BI1: 作 成 | BM1: =タイトル!I46 -> 木田 優 | BW1: =タイトル!I47 -> 45205 | CF1: 管理記号 | CK1: =タイトル!I50 -> DUC010
A2: サブシステム名 | I2: 共通機能 | AE2: ドキュメント | AL2: =タイトル!I44 -> CC-800_ポップアップ | BI2: 改 訂 | BM2: 木田 優 | BW2: 45222
A4: 画面名称 | I4: =" " & RIGHT(CELL("filename",A1),LEN(CELL("filename",A1))-FIND("]",CELL("filename",A1))) -> 科目選択 | AL4: 画面ＩＤ | AS4: CC-800-02S | BI4: 利用想定ユーザー | BT4: 管理者、担当者
A5: 画面レイアウト | BI5: 機能概要
BJ7: ・ | BK7: 科目を選択するための画面。
BI12: 画面説明 （処理内容・アクション等）
BJ14: ・ | BK14: 検索結果の行は30行を最大とし、31行目以降はページング機能を使用して
BK15: 表示する行を切り替える。
A38: リストボックス | BI38: 権限による画面制御
A39: 項目名 | K39: 内容 | AW39: 並び順
A40: 開講年度 | K40: 開講マスタの開講年度 | AW40: 降順
A41: 主設置所属 | K41: 課程コード | AW41: 昇順
A42: 開講期間 | K42: 開講期間 | AW42: 昇順
A43: 曜日講時 | K43: 曜日コード 、講時コード | AW43: 昇順 | BI43: 一覧の並び順
BJ45: 科目コード（昇順）→クラスコード（昇順）
A48: 画 面 補 足 説 明
B50: ○入力項目（検索条件） | BA50: 〇リストボックス
B51: 項目名 | P51: 入力必須 | U51: 桁数 | X51: 入力制限等 | BB51: 【開講年度】
B52: 開講年度 | P52: 〇 | U52: - | X52: リストボックス | BC52: 開講年度 | BR52: ▼
B53: 主設置所属 | P53: × | U53: - | X53: リストボックス | BJ53: 2023
B54: 開講科目コード | P54: × | U54: 8 | X54: 半角数字、前方一致 | BJ54: 2022
B55: クラスコード | P55: × | U55: 3 | X55: 半角数字 | BJ55: 2021
B56: 科目名 | P56: × | U56: 100 | X56: 部分一致 | BJ56: 2020
B57: 開講期間 | P57: × | U57: - | X57: リストボックス
B58: 曜日講時 | H58: 曜日 | P58: × | U58: - | X58: リストボックス
H59: 講時 | P59: × | U59: - | X59: リストボックス | BB59: 【主設置所属】
B60: 教員コード | P60: × | U60: 6 | X60: 半角数字、前方一致 | BC60: 主設置所属 | BR60: ▼
B61: 教員氏名 | P61: × | U61: 100 | X61: 部分一致 | BJ61: 1：学部
BJ62: 2：第２部
B63: ○出力項目 | BJ63: 3：博前・修士
B64: 項目名 | K64: 編集内容等 | BJ64: 4：博後
B65: 科目コード
B66: 科目名
B67: クラス | BB67: 【開講期間】
B68: 主担当者 | BC68: 開講期間 | BR68: ▼
B69: 曜日講時 | BJ69: 通年
BJ70: 春
BJ71: 秋
BJ72: 春前
B73: 〇選択
...
